Workbook

Sheet Flood (national AAL PML)
A2: Base year 2020 (no climate change)
A4: RP | B4: Housing | D4: Services Sector | F4: Productive Sector | H4: Roads | L4: Schools | P4: Health Centers
B5: US$ million | C5: % of total asset value | D5: US$ million | E5: % of total asset value | F5: US$ million | G5: % of total asset value | H5: km | I5: % of asset | J5: US$ million | K5: % of total asset value | L5: Number | M5: % of asset | N5: US$ million | O5: % of total asset value | P5: Number | Q5: % of asset | R5: US$ million | S5: % of total asset value
A6: 10 | B6: 143.31727 | C6: 2.3974696 | D6: 425.75334 | E6: 2.1874696 | F6: 596.21941 | G6: 2.5574696 | H6: 368.49446 | I6: 2.3000715 | J6: 10.488044 | K6: 2.3029641 | L6: 496.5 | M6: 4.340035 | N6: 10.655136 | O6: 1.7573453 | P6: 79 | Q6: 5.3414469 | R6: 3.764998 | S6: 3.7994591
A7: 25 | B7: 196.29287 | C7: 3.283667 | D7: 598.23642 | E7: 3.073667 | F7: 802.8174 | G7: 3.443667 | H7: 488.35441 | I7: 3.0482143 | J7: 14.441043 | K7: 3.1709633 | L7: 663.5 | M7: 5.7998252 | N7: 12.251157 | O7: 2.0205761 | P7: 95 | Q7: 6.423259 | R7: 4.1006345 | S7: 4.1381677
A8: 100 | B8: 227.90368 | C8: 3.8124654 | D8: 701.15794 | E8: 3.6024654 | F8: 926.09546 | G8: 3.9724654 | H8: 585.72523 | I8: 3.6559842 | J8: 16.716692 | K8: 3.6706501 | L8: 755 | M8: 6.5996503 | N8: 15.411483 | O8: 2.5418069 | P8: 117 | Q8: 7.9107505 | R8: 5.243755 | S8: 5.2917512
A9: 200 | B9: 265.75028 | C9: 4.4455787 | D9: 824.38254 | E9: 4.2355787 | F9: 1073.6923 | G9: 4.6055787 | H9: 605.66124 | I9: 3.780421 | J9: 17.308958 | K9: 3.8006999 | L9: 778 | M9: 6.8006993 | N9: 15.740921 | O9: 2.5961408 | P9: 120.5 | Q9: 8.1473969 | R9: 5.412327 | S9: 5.4618661
A10: AAL | B10: 90.086927 | C10: 1.5070107 | D10: 252.44084 | E10: 1.2970107 | F10: 388.62795 | G10: 1.6670107 | H10: 262.24893 | I10: 1.6369073 | J10: 7.6272752 | K10: 1.6747966 | L10: 355.81183 | M10: 3.1102433 | N10: 6.5066182 | O10: 1.0731327 | P10: 53.117333 | Q10: 3.5914357 | R10: 2.1989038 | S10: 2.2190304
A13: Year 2050 (SSP585, no adaptation, no socio-economic projections)
A15: RP | B15: Housing | D15: Services Sector | F15: Productive Sector | H15: Roads | L15: Schools | P15: Health Centers
B16: US$ million | C16: % of total asset value | D16: US$ million | E16: % of total asset value | F16: US$ million | G16: % of total asset value | H16: km | I16: % of asset | J16: US$ million | K16: % of total asset value | L16: Number | M16: % of asset | N16: US$ million | O16: % of total asset value | P16: Number | Q16: % of asset | R16: US$ million | S16: % of total asset value
A17: 10 | B17: =B6*'WRI data (for mock generation)'!$C$8 -> 554.77654 | C17: =C6*'WRI data (for mock generation)'!$C$8 -> 9.2805275 | D17: =D6*'WRI data (for mock generation)'!$C$8 -> 1648.0774 | E17: =E6*'WRI data (for mock generation)'!$C$8 -> 8.4676243 | F17: =F6*'WRI data (for mock generation)'!$C$8 -> 2307.9461 | G17: =G6*'WRI data (for mock generation)'!$C$8 -> 9.8998824 | H17: =H6*'WRI data (for mock generation)'!$C$8 -> 1426.4302 | I17: =I6*'WRI data (for mock generation)'!$C$8 -> 8.9035028 | ... S17: =S6*'WRI data (for mock generation)'!$C$8 -> 14.707584
A18: 25 | B18: =B7*'WRI data (for mock generation)'!$C$8 -> 759.84338 | C18: =C7*'WRI data (for mock generation)'!$C$8 -> 12.710969 | D18: =D7*'WRI data (for mock generation)'!$C$8 -> 2315.7539 | E18: =E7*'WRI data (for mock generation)'!$C$8 -> 11.898066 | F18: =F7*'WRI data (for mock generation)'!$C$8 -> 3107.6803 | G18: =G7*'WRI data (for mock generation)'!$C$8 -> 13.330324 | H18: =H7*'WRI data (for mock generation)'!$C$8 -> 1890.4042 | I18: =I7*'WRI data (for mock generation)'!$C$8 -> 11.799539 | ... S18: =S7*'WRI data (for mock generation)'!$C$8 -> 16.018714
A19: 100 | B19: =B8*'WRI data (for mock generation)'!$C$8 -> 882.20779 | C19: =C8*'WRI data (for mock generation)'!$C$8 -> 14.757931 | D19: =D8*'WRI data (for mock generation)'!$C$8 -> 2714.1598 | E19: =E8*'WRI data (for mock generation)'!$C$8 -> 13.945027 | F19: =F8*'WRI data (for mock generation)'!$C$8 -> 3584.8856 | G19: =G8*'WRI data (for mock generation)'!$C$8 -> 15.377285 | H19: =H8*'WRI data (for mock generation)'!$C$8 -> 2267.3235 | I19: =I8*'WRI data (for mock generation)'!$C$8 -> 14.152197 | ... S19: =S8*'WRI data (for mock generation)'!$C$8 -> 20.484198
A20: 200 | B20: =B9*'WRI data (for mock generation)'!$C$8 -> 1028.7107 | C20: =C9*'WRI data (for mock generation)'!$C$8 -> 17.208692 | D20: =D9*'WRI data (for mock generation)'!$C$8 -> 3191.1582 | E20: =E9*'WRI data (for mock generation)'!$C$8 -> 16.395788 | F20: =F9*'WRI data (for mock generation)'!$C$8 -> 4156.2282 | G20: =G9*'WRI data (for mock generation)'!$C$8 -> 17.828046 | H20: =H9*'WRI data (for mock generation)'!$C$8 -> 2344.4951 | I20: =I9*'WRI data (for mock generation)'!$C$8 -> 14.633888 | ... S20: =S9*'WRI data (for mock generation)'!$C$8 -> 21.142708
A21: AAL | B21: =B10*'WRI data (for mock generation)'!$C$8 -> 348.72359 | C21: =C10*'WRI data (for mock generation)'!$C$8 -> 5.83359 | D21: =D10*'WRI data (for mock generation)'!$C$8 -> 977.19033 | E21: =E10*'WRI data (for mock generation)'!$C$8 -> 5.0206867 | F21: =F10*'WRI data (for mock generation)'!$C$8 -> 1504.3662 | G21: =G10*'WRI data (for mock generation)'!$C$8 -> 6.4529448 | H21: =H10*'WRI data (for mock generation)'!$C$8 -> 1015.1571 | I21: =I10*'WRI data (for mock generation)'!$C$8 -> 6.3364155 | ... S21: =S10*'WRI data (for mock generation)'!$C$8 -> 8.589795
A24: Year 2050 (SSP585, no adaptation, with socio-economic projections)
A26: RP | B26: Housing | D26: Services Sector | F26: Productive Sector | H26: Roads | L26: Schools | P26: Health Centers
B27: US$ million | C27: % of total asset value | D27: US$ million | E27: % of total asset value | F27: US$ million | G27: % of total asset value | H27: km | I27: % of asset | J27: US$ million | K27: % of total asset value | L27: Number | M27: % of asset | N27: US$ million | O27: % of total asset value | P27: Number | Q27: % of asset | R27: US$ million | S27: % of total asset value
A28: 10 | B28: 999999 | C28: 999999 | D28: 999999 | E28: 999999 | F28: 999999 | G28: 999999 | H28: 999999 | I28: 999999 | J28: 999999 | K28: 999999 | L28: 999999 | M28: 999999 | N28: 999999 | O28: 999999 | P28: 999999 | Q28: 999999 | R28: 999999 | S28: 999999
A29: 25 | B29: 999999 | C29: 999999 | D29: 999999 | E29: 999999 | F29: 999999 | G29: 999999 | H29: 999999 | I29: 999999 | J29: 999999 | K29: 999999 | L29: 999999 | M29: 999999 | N29: 999999 | O29: 999999 | P29: 999999 | Q29: 999999 | R29: 999999 | S29: 999999
A30: 100 | B30: 999999 | C30: 999999 | D30: 999999 | E30: 999999 | F30: 999999 | G30: 999999 | H30: 999999 | I30: 999999 | J30: 999999 | K30: 999999 | L30: 999999 | M30: 999999 | N30: 999999 | O30: 999999 | P30: 999999 | Q30: 999999 | R30: 999999 | S30: 999999
A31: 200 | B31: 999999 | C31: 999999 | D31: 999999 | E31: 999999 | F31: 999999 | G31: 999999 | H31: 999999 | I31: 999999 | J31: 999999 | K31: 999999 | L31: 999999 | M31: 999999 | N31: 999999 | O31: 999999 | P31: 999999 | Q31: 999999 | R31: 999999 | S31: 999999
A32: AAL | B32: 999999 | C32: 999999 | D32: 999999 | E32: 999999 | F32: 999999 | G32: 999999 | H32: 999999 | I32: 999999 | J32: 999999 | K32: 999999 | L32: 999999 | M32: 999999 | N32: 999999 | O32: 999999 | P32: 999999 | Q32: 999999 | R32: 999999 | S32: 999999
A35: Year 2050 (SSP126, no adaptation, no socio-economic projections)
A37: RP | B37: Housing | D37: Services Sector | F37: Productive Sector | H37: Roads | L37: Schools | P37: Health Centers
B38: US$ million | C38: % of total asset value | D38: US$ million | E38: % of total asset value | F38: US$ million | G38: % of total asset value | H38: km | I38: % of asset | J38: US$ million | K38: % of total asset value | L38: Number | M38: % of asset | N38: US$ million | O38: % of total asset value | P38: Number | Q38: % of asset | R38: US$ million | S38: % of total asset value
A39: 10 | B39: 999999 | C39: 999999 | D39: 999999 | E39: 999999 | F39: 999999 | G39: 999999 | H39: 999999 | I39: 999999 | J39: 999999 | K39: 999999 | L39: 999999 | M39: 999999 | N39: 999999 | O39: 999999 | P39: 999999 | Q39: 999999 | R39: 999999 | S39: 999999
A40: 25 | B40: 999999 | C40: 999999 | D40: 999999 | E40: 999999 | F40: 999999 | G40: 999999 | H40: 999999 | I40: 999999 | J40: 999999 | K40: 999999 | L40: 999999 | M40: 999999 | N40: 999999 | O40: 999999 | P40: 999999 | Q40: 999999 | R40: 999999 | S40: 999999
A41: 100 | B41: 999999 | C41: 999999 | D41: 999999 | E41: 999999 | F41: 999999 | G41: 999999 | H41: 999999 | I41: 999999 | J41: 999999 | K41: 999999 | L41: 999999 | M41: 999999 | N41: 999999 | O41: 999999 | P41: 999999 | Q41: 999999 | R41: 999999 | S41: 999999
A42: 200 | B42: 999999 | C42: 999999 | D42: 999999 | E42: 999999 | F42: 999999 | G42: 999999 | H42: 999999 | I42: 999999 | J42: 999999 | K42: 999999 | L42: 999999 | M42: 999999 | N42: 999999 | O42: 999999 | P42: 999999 | Q42: 999999 | R42: 999999 | S42: 999999
A43: AAL | B43: 999999 | C43: 999999 | D43: 999999 | E43: 999999 | F43: 999999 | G43: 999999 | H43: 999999 | I43: 999999 | J43: 999999 | K43: 999999 | L43: 999999 | M43: 999999 | N43: 999999 | O43: 999999 | P43: 999999 | Q43: 999999 | R43: 999999 | S43: 999999
A46: Year 2050 (SSP126, no adaptation, with socio-economic projections)
A48: RP | B48: Housing | D48: Services Sector | F48: Productive Sector | H48: Roads | L48: Schools | P48: Health Centers
B49: US$ million | C49: % of total asset value | D49: US$ million | E49: % of total asset value | F49: US$ million | G49: % of total asset value | H49: km | I49: % of asset | J49: US$ million | K49: % of total asset value | L49: Number | M49: % of asset | N49: US$ million | O49: % of total asset value | P49: Number | Q49: % of asset | R49: US$ million | S49: % of total asset value
A50: 10 | B50: 999999 | C50: 999999 | D50: 999999 | E50: 999999 | F50: 999999 | G50: 999999 | H50: 999999 | I50: 999999 | J50: 999999 | K50: 999999 | L50: 999999 | M50: 999999 | N50: 999999 | O50: 999999 | P50: 999999 | Q50: 999999 | R50: 999999 | S50: 999999
A51: 25 | B51: 999999 | C51: 999999 | D51: 999999 | E51: 999999 | F51: 999999 | G51: 999999 | H51: 999999 | I51: 999999 | J51: 999999 | K51: 999999 | L51: 999999 | M51: 999999 | N51: 999999 | O51: 999999 | P51: 999999 | Q51: 999999 | R51: 999999 | S51: 999999
A52: 100 | B52: 999999 | C52: 999999 | D52: 999999 | E52: 999999 | F52: 999999 | G52: 999999 | H52: 999999 | I52: 999999 | J52: 999999 | K52: 999999 | L52: 999999 | M52: 999999 | N52: 999999 | O52: 999999 | P52: 999999 | Q52: 999999 | R52: 999999 | S52: 999999
A53: 200 | B53: 999999 | C53: 999999 | D53: 999999 | E53: 999999 | F53: 999999 | G53: 999999 | H53: 999999 | I53: 999999 | J53: 999999 | K53: 999999 | L53: 999999 | M53: 999999 | N53: 999999 | O53: 999999 | P53: 999999 | Q53: 999999 | R53: 999999 | S53: 999999
A54: AAL | B54: 999999 | C54: 999999 | D54: 999999 | E54: 999999 | F54: 999999 | G54: 999999 | H54: 999999 | I54: 999999 | J54: 999999 | K54: 999999 | L54: 999999 | M54: 999999 | N54: 999999 | O54: 999999 | P54: 999999 | Q54: 999999 | R54: 999999 | S54: 999999
...

Sheet WRI data (for mock generation)
A1: WRI
A2: ssp 2 RCP 8.5 IPSL-CM5A-LR
B3: 2010 | C3: 2020 | D3: 2030 | E3: 2050 | F3: 2080
A4: Annual Expected Affected GDP | B4: 1.2G | C4: =(1.2+5)/2 -> 3.1 | D4: 5.0G | E4: 12G | F4: 29G
A5: Total GDP | B5: 28G | D5: 94G | E5: 210G | F5: 510G
A6: % Annual Expected Affected GDP | B6: 0.0423 | C6: =(B6+D6)/2 -> 0.0478 | D6: 0.0533 | E6: 0.0578 | F6: 0.0568
A7: Estimated Flood Protection Level | B7: 7 | D7: 6.4 | E7: 5.6 | F7: 5.2
C8: =12/3.1 -> 3.8709677

Sheet Drought (national AAL PML)
A2: Base year 2020 (no climate change)
A4: RP | B4: asset 1 | D4: asset 2 | F4: asset 3
B5: US$ million | C5: % of total asset value | D5: US$ million | E5: % of total asset value | F5: US$ million | G5: % of total asset value
A6: 10
A7: 25
A8: 100
A9: 200
A10: AAL
A13: Year 2050 (SSP585, no adaptation, no socio-economic projections)
A15: RP | B15: asset 1 | D15: asset 2 | F15: asset 3
B16: US$ million | C16: % of total asset value | D16: US$ million | E16: % of total asset value | F16: US$ million | G16: % of total asset value
A17: 10
A18: 25
A19: 100
A20: 200
A21: 500
A22: 1000
A23: AAL
A26: Year 2050 (SSP585, no adaptation, with socio-economic projections)
A28: RP | B28: asset 1 | D28: asset 2 | F28: asset 3
B29: US$ million | C29: % of total asset value | D29: US$ million | E29: % of total asset value | F29: US$ million | G29: % of total asset value
A30: 10
A31: 25
A32: 100
A33: 200
A34: 500
A35: 1000
A36: AAL
A39: Year 2050 (SSP126, no adaptation, no socio-economic projections)
A41: RP | B41: asset 1 | D41: asset 2 | F41: asset 3
B42: US$ million | C42: % of total asset value | D42: US$ million | E42: % of total asset value | F42: US$ million | G42: % of total asset value
A43: 10
A44: 25
A45: 100
A46: 200
A47: 500
A48: 1000
A49: AAL
A52: Year 2050 (SSP126, no adaptation, with socio-economic projections)
A54: RP | B54: asset 1 | D54: asset 2 | F54: asset 3
...

Sheet Flood Affected Population
B2: Base year | D2: no adaptation | L2: with adaptation
D3: 2050 | L3: 2050
D4: SSP126 | H4: SSP585 | L4: SSP126 | P4: SSP585
D5: no socio-economic projections | F5: with socio-economic projections | H5: no socio-economic projections | J5: with socio-economic projections | L5: no socio-economic projections | N5: with socio-economic projections | P5: no socio-economic projections | R5: with socio-economic projections
B6: Number | C6: % | D6: Number | E6: % | F6: Number | G6: % | H6: Number | I6: % | J6: Number | K6: % | L6: Number | M6: % | N6: Number | O6: % | P6: Number | Q6: % | R6: Number | S6: %
A7: Banteay Meanchey | B7: 1603.3048 | C7: 0.25814779 | D7: 999999 | E7: 999999 | F7: 999999 | G7: 999999 | H7: 999999 | I7: 999999 | J7: 999999 | K7: 999999 | L7: 999999 | M7: 999999 | N7: 999999 | O7: 999999 | P7: 999999 | Q7: 999999 | R7: 999999 | S7: 999999
A8: Battambang | B8: 3829.8006 | C8: 0.17845105 | D8: 999999 | E8: 999999 | F8: 999999 | G8: 999999 | H8: 999999 | I8: 999999 | J8: 999999 | K8: 999999 | L8: 999999 | M8: 999999 | N8: 999999 | O8: 999999 | P8: 999999 | Q8: 999999 | R8: 999999 | S8: 999999
A9: Kampong Cham | B9: 13205.662 | C9: 3.708988 | D9: 999999 | E9: 999999 | F9: 999999 | G9: 999999 | H9: 999999 | I9: 999999 | J9: 999999 | K9: 999999 | L9: 999999 | M9: 999999 | N9: 999999 | O9: 999999 | P9: 999999 | Q9: 999999 | R9: 999999 | S9: 999999
A10: Kampong Chhnang | B10: 6010.7442 | C10: 2.6125131 | D10: 999999 | E10: 999999 | F10: 999999 | G10: 999999 | H10: 999999 | I10: 999999 | J10: 999999 | K10: 999999 | L10: 999999 | M10: 999999 | N10: 999999 | O10: 999999 | P10: 999999 | Q10: 999999 | R10: 999999 | S10: 999999
A11: Kampong Speu | B11: 1168.53 | C11: 0.28295297 | D11: 999999 | E11: 999999 | F11: 999999 | G11: 999999 | H11: 999999 | I11: 999999 | J11: 999999 | K11: 999999 | L11: 999999 | M11: 999999 | N11: 999999 | O11: 999999 | P11: 999999 | Q11: 999999 | R11: 999999 | S11: 999999
A12: Kampong Thom | B12: 3687.5133 | C12: 1.0654101 | D12: 999999 | E12: 999999 | F12: 999999 | G12: 999999 | H12: 999999 | I12: 999999 | J12: 999999 | K12: 999999 | L12: 999999 | M12: 999999 | N12: 999999 | O12: 999999 | P12: 999999 | Q12: 999999 | R12: 999999 | S12: 999999
A13: Kampot | B13: 1774.8178 | C13: 0.32590659 | D13: 999999 | E13: 999999 | F13: 999999 | G13: 999999 | H13: 999999 | I13: 999999 | J13: 999999 | K13: 999999 | L13: 999999 | M13: 999999 | N13: 999999 | O13: 999999 | P13: 999999 | Q13: 999999 | R13: 999999 | S13: 999999
A14: Kandal | B14: 24797.286 | C14: 3.9428558 | D14: 999999 | E14: 999999 | F14: 999999 | G14: 999999 | H14: 999999 | I14: 999999 | J14: 999999 | K14: 999999 | L14: 999999 | M14: 999999 | N14: 999999 | O14: 999999 | P14: 999999 | Q14: 999999 | R14: 999999 | S14: 999999
A15: Koh Kong | B15: 362.29142 | C15: 0.67195987 | D15: 999999 | E15: 999999 | F15: 999999 | G15: 999999 | H15: 999999 | I15: 999999 | J15: 999999 | K15: 999999 | L15: 999999 | M15: 999999 | N15: 999999 | O15: 999999 | P15: 999999 | Q15: 999999 | R15: 999999 | S15: 999999
A16: Kratié | B16: 7171.5451 | C16: 2.8285279 | D16: 999999 | E16: 999999 | F16: 999999 | G16: 999999 | H16: 999999 | I16: 999999 | J16: 999999 | K16: 999999 | L16: 999999 | M16: 999999 | N16: 999999 | O16: 999999 | P16: 999999 | Q16: 999999 | R16: 999999 | S16: 999999
A17: Mondulkiri | B17: 613.94015 | C17: 0.4158601 | D17: 999999 | E17: 999999 | F17: 999999 | G17: 999999 | H17: 999999 | I17: 999999 | J17: 999999 | K17: 999999 | L17: 999999 | M17: 999999 | N17: 999999 | O17: 999999 | P17: 999999 | Q17: 999999 | R17: 999999 | S17: 999999
A18: Phnom Penh | B18: 25853.186 | C18: 1.0373306 | D18: 999999 | E18: 999999 | F18: 999999 | G18: 999999 | H18: 999999 | I18: 999999 | J18: 999999 | K18: 999999 | L18: 999999 | M18: 999999 | N18: 999999 | O18: 999999 | P18: 999999 | Q18: 999999 | R18: 999999 | S18: 999999
... A32: Total | B32: 169237.74 | C32: 1.0387505 | D32: 999999 | E32: 999999 | F32: 999999 | G32: 999999 | H32: 999999 | I32: 999999 | J32: 999999 | K32: 999999 | L32: 999999 | M32: 999999 | N32: 999999 | O32: 999999 | P32: 999999 | Q32: 999999 | R32: 999999 | S32: 999999

Sheet Drought Affected Population
B2: Base year | D2: no adaptation
D3: 2050
D4: SSP126 | H4: SSP585
D5: no socio-economic projections | F5: with socio-economic projections | H5: no socio-economic projections | J5: with socio-economic projections
B6: Number | C6: % | D6: Number | E6: % | F6: Number | G6: % | H6: Number | I6: % | J6: Number | K6: %
A7: Banteay Meanchey
A8: Battambang
A9: Kampong Cham
A10: Kampong Chhnang
A11: Kampong Speu
A12: Kampong Thom
A13: Kampot
A14: Kandal
A15: Koh Kong
A16: Kratié
A17: Mondulkiri
A18: Phnom Penh
... A32: Total

Sheet Flood AAL (admin 1)
B2: Base year | D2: no adaptation | L2: with adaptation
D3: 2050 | L3: 2050
D4: SSP126 | H4: SSP585 | L4: SSP126 | P4: SSP585
D5: no socio-economic projections | F5: with socio-economic projections | H5: no socio-economic projections | J5: with socio-economic projections | L5: no socio-economic projections | N5: with socio-economic projections | P5: no socio-economic projections | R5: with socio-economic projections
B6: Number | C6: % | D6: AAL | E6: % | F6: AAL | G6: % | H6: AAL | I6: % | J6: AAL | K6: % | L6: AAL | M6: % | N6: AAL | O6: % | P6: AAL | Q6: % | R6: AAL | S6: %
A7: Banteay Meanchey | B7: 999999 | C7: 999999 | D7: 999999 | E7: 999999 | F7: 999999 | G7: 999999 | H7: 999999 | I7: 999999 | J7: 999999 | K7: 999999 | L7: 999999 | M7: 999999 | N7: 999999 | O7: 999999 | P7: 999999 | Q7: 999999 | R7: 999999 | S7: 999999
A8: Battambang | B8: 999999 | C8: 999999 | D8: 999999 | E8: 999999 | F8: 999999 | G8: 999999 | H8: 999999 | I8: 999999 | J8: 999999 | K8: 999999 | L8: 999999 | M8: 999999 | N8: 999999 | O8: 999999 | P8: 999999 | Q8: 999999 | R8: 999999 | S8: 999999
A9: Kampong Cham | B9: 999999 | C9: 999999 | D9: 999999 | E9: 999999 | F9: 999999 | G9: 999999 | H9: 999999 | I9: 999999 | J9: 999999 | K9: 999999 | L9: 999999 | M9: 999999 | N9: 999999 | O9: 999999 | P9: 999999 | Q9: 999999 | R9: 999999 | S9: 999999
A10: Kampong Chhnang | B10: 999999 | C10: 999999 | D10: 999999 | E10: 999999 | F10: 999999 | G10: 999999 | H10: 999999 | I10: 999999 | J10: 999999 | K10: 999999 | L10: 999999 | M10: 999999 | N10: 999999 | O10: 999999 | P10: 999999 | Q10: 999999 | R10: 999999 | S10: 999999
A11: Kampong Speu | B11: 999999 | C11: 999999 | D11: 999999 | E11: 999999 | F11: 999999 | G11: 999999 | H11: 999999 | I11: 999999 | J11: 999999 | K11: 999999 | L11: 999999 | M11: 999999 | N11: 999999 | O11: 999999 | P11: 999999 | Q11: 999999 | R11: 999999 | S11: 999999
A12: Kampong Thom | B12: 999999 | C12: 999999 | D12: 999999 | E12: 999999 | F12: 999999 | G12: 999999 | H12: 999999 | I12: 999999 | J12: 999999 | K12: 999999 | L12: 999999 | M12: 999999 | N12: 999999 | O12: 999999 | P12: 999999 | Q12: 999999 | R12: 999999 | S12: 999999
A13: Kampot | B13: 999999 | C13: 999999 | D13: 999999 | E13: 999999 | F13: 999999 | G13: 999999 | H13: 999999 | I13: 999999 | J13: 999999 | K13: 999999 | L13: 999999 | M13: 999999 | N13: 999999 | O13: 999999 | P13: 999999 | Q13: 999999 | R13: 999999 | S13: 999999
A14: Kandal | B14: 999999 | C14: 999999 | D14: 999999 | E14: 999999 | F14: 999999 | G14: 999999 | H14: 999999 | I14: 999999 | J14: 999999 | K14: 999999 | L14: 999999 | M14: 999999 | N14: 999999 | O14: 999999 | P14: 999999 | Q14: 999999 | R14: 999999 | S14: 999999
A15: Koh Kong | B15: 999999 | C15: 999999 | D15: 999999 | E15: 999999 | F15: 999999 | G15: 999999 | H15: 999999 | I15: 999999 | J15: 999999 | K15: 999999 | L15: 999999 | M15: 999999 | N15: 999999 | O15: 999999 | P15: 999999 | Q15: 999999 | R15: 999999 | S15: 999999
A16: Kratié | B16: 999999 | C16: 999999 | D16: 999999 | E16: 999999 | F16: 999999 | G16: 999999 | H16: 999999 | I16: 999999 | J16: 999999 | K16: 999999 | L16: 999999 | M16: 999999 | N16: 999999 | O16: 999999 | P16: 999999 | Q16: 999999 | R16: 999999 | S16: 999999
A17: Mondulkiri | B17: 999999 | C17: 999999 | D17: 999999 | E17: 999999 | F17: 999999 | G17: 999999 | H17: 999999 | I17: 999999 | J17: 999999 | K17: 999999 | L17: 999999 | M17: 999999 | N17: 999999 | O17: 999999 | P17: 999999 | Q17: 999999 | R17: 999999 | S17: 999999
A18: Phnom Penh | B18: 999999 | C18: 999999 | D18: 999999 | E18: 999999 | F18: 999999 | G18: 999999 | H18: 999999 | I18: 999999 | J18: 999999 | K18: 999999 | L18: 999999 | M18: 999999 | N18: 999999 | O18: 999999 | P18: 999999 | Q18: 999999 | R18: 999999 | S18: 999999
... A32: Total | B32: 999999 | C32: 999999 | D32: 999999 | E32: 999999 | F32: 999999 | G32: 999999 | H32: 999999 | I32: 999999 | J32: 999999 | K32: 999999 | L32: 999999 | M32: 999999 | N32: 999999 | O32: 999999 | P32: 999999 | Q32: 999999 | R32: 999999 | S32: 999999

Sheet Drought AAL (admin 1)
B2: Base year | D2: no adaptation
D3: 2050
D4: SSP126 | H4: SSP585
D5: no socio-economic projections | F5: with socio-economic projections | H5: no socio-economic projections | J5: with socio-economic projections
B6: Number | C6: % | D6: AAL | E6: % | F6: AAL | G6: % | H6: AAL | I6: % | J6: AAL | K6: %
A7: Banteay Meanchey
A8: Battambang
A9: Kampong Cham
A10: Kampong Chhnang
A11: Kampong Speu
A12: Kampong Thom
A13: Kampot
A14: Kandal
A15: Koh Kong
A16: Kratié
A17: Mondulkiri
A18: Phnom Penh
... A32: Total
