Workbook

Sheet CGE
C4: CGE data interpolation
C5: % of asset (weighted average of all asset)
B6: 2020 | C6: ='Weighted Av.'!C9 -> 1.5580617 | D6: ='Flood (national AAL PML)'!AB7 -> -0.0095527654
B7: 2021 | C7: =C6+$D$6 -> 1.5485089
B8: 2022 | C8: =C7+$D$6 -> 1.5389562
B9: 2023 | C9: =C8+$D$6 -> 1.5294034
B10: 2024 | C10: =C9+$D$6 -> 1.5198506
B11: 2025 | C11: =C10+$D$6 -> 1.5102979
B12: 2026 | C12: =C11+$D$6 -> 1.5007451
B13: 2027 | C13: =C12+$D$6 -> 1.4911923
B14: 2028 | C14: =C13+$D$6 -> 1.4816396
B15: 2029 | C15: =C14+$D$6 -> 1.4720868
B16: 2030 | C16: =C15+$D$6 -> 1.462534
B17: 2031 | C17: =C16+$D$6 -> 1.4529813
B18: 2032 | C18: =C17+$D$6 -> 1.4434285
... B36: 2050 | C36: =C35+$D$6 -> 1.2714787

Sheet Weighted Av.
A1: 2020
A2: sector | B2: AAL | C2: %AAL per sector | D2: total asset value
A3: housing | B3: ='Flood (national AAL PML)'!B10 -> 56.327998 | C3: =(B3/D3)*100 -> 0.94947125 | D3: =('Flood (national AAL PML)'!B10*100)/'Flood (national AAL PML)'!C10 -> 5932.5649 | E3: =D3/$D$11 -> 0.19343015
A4: services | B4: ='Flood (national AAL PML)'!D10 -> 180.32301 | C4: =(B4/D4)*100 -> 59.583714 | D4: =('Flood (national AAL PML)'!D10+100)/'Flood (national AAL PML)'!E10 -> 302.63809 | E4: =D4/$D$11 -> 0.0098674572
A5: productive | B5: ='Flood (national AAL PML)'!F10 -> 216.18826 | C5: =(B5/D5)*100 -> 0.92611724 | D5: =('Flood (national AAL PML)'!F10*100)/'Flood (national AAL PML)'!G10 -> 23343.509 | E5: =D5/$D$11 -> 0.76111065
A6: roads | B6: ='Flood (national AAL PML)'!J10 -> 13.841958 | C6: =(B6/D6)*100 -> 3.5780179 | D6: =('Flood (national AAL PML)'!J10*100)/'Flood (national AAL PML)'!K10 -> 386.86106 | E6: =D6/$D$11 -> 0.012613531
A7: schools | B7: ='Flood (national AAL PML)'!N10 -> 8.079959 | C7: =(B7/D7)*100 -> 1.3337888 | D7: =('Flood (national AAL PML)'!N10*100)/'Flood (national AAL PML)'!O10 -> 605.79 | E7: =D7/$D$11 -> 0.019751668
A8: health centers | B8: ='Flood (national AAL PML)'!R10 -> 3.1013483 | C8: =(B8/D8)*100 -> 3.133973 | D8: =('Flood (national AAL PML)'!R10*100)/'Flood (national AAL PML)'!S10 -> 98.959 | E8: =D8/$D$11 -> 0.0032265394
C9: =SUMPRODUCT(C3:C8,D3:D8)/SUM(D3:D8) -> 1.5580617
A11: asset value (all sectors) | D11: =SUM(D3:D8) -> 30670.322
B14: =SUM(B3:B8)/D11 -> 0.015580617
A16: 2050
A17: sector | B17: AAL | C17: %AAL per sector | D17: total asset value
A18: housing | B18: ='Flood (national AAL PML)'!B21 -> 75.959706 | C18: =(B18/D18)*100 -> 1.2706848 | D18: =('Flood (national AAL PML)'!B21*100)/'Flood (national AAL PML)'!C21 -> 5977.8557 | E18: =D18/$D$26 -> 0.12051895
A19: services | B19: ='Flood (national AAL PML)'!D21 -> 206.44406 | C19: =(B19/D19)*100 -> 1.0606848 | D19: =('Flood (national AAL PML)'!D21*100)/'Flood (national AAL PML)'!E21 -> 19463.28 | E19: =D19/$D$26 -> 0.39239726
A20: productive | B20: ='Flood (national AAL PML)'!F21 -> 333.53361 | C20: =(B20/D20)*100 -> 1.4306848 | D20: =('Flood (national AAL PML)'!F21*100)/'Flood (national AAL PML)'!G21 -> 23312.864 | E20: =D20/$D$26 -> 0.47000833
A21: roads | B21: ='Flood (national AAL PML)'!J21 -> 6.8610879 | C21: =(B21/D21)*100 -> 1.5065573 | D21: =('Flood (national AAL PML)'!J21*100)/'Flood (national AAL PML)'!K21 -> 455.41501 | E21: =D21/$D$26 -> 0.0091815768
A22: schools | B22: ='Flood (national AAL PML)'!N21 -> 5.8761273 | C22: =(B22/D22)*100 -> 2.0092701 | D22: =('Flood (national AAL PML)'!N21*100)/'Flood (national AAL PML)'!O21 -> 292.45083 | E22: =D22/$D$26 -> 0.0058960722
A23: health centers | B23: ='Flood (national AAL PML)'!R21 -> 1.9910461 | C23: =(B23/D23)*100 -> 2.0092701 | D23: =('Flood (national AAL PML)'!R21*100)/'Flood (national AAL PML)'!S21 -> 99.093 | E23: =D23/$D$26 -> 0.0019978041
C24: =SUMPRODUCT(C18:C23,D18:D23)/SUM(D18:D23) -> 1.2714787
A26: asset value (all sectors) | D26: =SUM(D18:D23) -> 49600.959

Sheet Projected Tem
A1: ge | C1: Hist. Ref. Per., 1995-2014 | D1: SSP1-1.9 | E1: SSP1-2.6 | F1: SSP2-4.5 | G1: SSP3-7.0 | H1: SSP5-8.5
A2: 1995 | C2: 27.35
A3: 1996 | C3: 27.31
A4: 1997 | C4: 27.27
A5: 1998 | C5: 27.24
A6: 1999 | C6: 27.22
A7: 2000 | C7: 27.21
A8: 2001 | C8: 27.22
A9: 2002 | C9: 27.25
A10: 2003 | C10: 27.3
A11: 2004 | C11: 27.35
A12: 2005 | C12: 27.41
A13: 2006 | C13: 27.47
... A20: 2013 | C20: 27.41
A21: 2014 | C21: 27.36 | D21: 27.36 | E21: 27.36 | F21: 27.36 | G21: 27.36 | H21: 27.36
A22: 2015 | D22: 27.48 | E22: 27.32 | F22: 27.32 | G22: 27.27 | H22: 27.48
A23: 2016 | D23: 27.56 | E23: 27.46 | F23: 27.47 | G23: 27.37 | H23: 27.57
A24: 2017 | D24: 27.65 | E24: 27.59 | F24: 27.61 | G24: 27.47 | H24: 27.65
A25: 2018 | D25: 27.72 | E25: 27.7 | F25: 27.73 | G25: 27.57 | H25: 27.72
A26: 2019 | D26: 27.78 | E26: 27.8 | F26: 27.83 | G26: 27.65 | H26: 27.78 | I26: Relative changes SSP5-8.5
A27: 2020 | B27: 1 | D27: 27.82 | E27: 27.87 | F27: 27.9 | G27: 27.72 | H27: 27.81 | I27: =H27/$H$27 -> 1
A28: 2021 | B28: 2 | D28: 27.84 | E28: 27.9 | F28: 27.92 | G28: 27.77 | H28: 27.81 | I28: =H28/$H$27 -> 1
A29: 2022 | B29: 3 | D29: 27.85 | E29: 27.91 | F29: 27.92 | G29: 27.81 | H29: 27.79 | I29: =H29/$H$27 -> 0.99928083
A30: 2023 | B30: 4 | D30: 27.84 | E30: 27.9 | F30: 27.89 | G30: 27.83 | H30: 27.76 | I30: =H30/$H$27 -> 0.99820209
A31: 2024 | B31: 5 | D31: 27.83 | E31: 27.88 | F31: 27.85 | G31: 27.84 | H31: 27.74 | I31: =H31/$H$27 -> 0.99748292
A32: 2025 | B32: 6 | D32: 27.82 | E32: 27.86 | F32: 27.82 | G32: 27.84 | H32: 27.73 | I32: =H32/$H$27 -> 0.99712334
A33: 2026 | B33: 7 | D33: 27.83 | E33: 27.85 | F33: 27.81 | G33: 27.83 | H33: 27.76 | I33: =H33/$H$27 -> 0.99820209
A34: 2027 | B34: 8 | D34: 27.84 | E34: 27.85 | F34: 27.83 | G34: 27.81 | H34: 27.81 | I34: =H34/$H$27 -> 1
A35: 2028 | B35: 9 | D35: 27.87 | E35: 27.87 | F35: 27.87 | G35: 27.8 | H35: 27.89 | I35: =H35/$H$27 -> 1.0028767
A36: 2029 | B36: 10 | D36: 27.91 | E36: 27.89 | F36: 27.91 | G36: 27.8 | H36: 27.97 | I36: =H36/$H$27 -> 1.0057533
A37: 2030 | B37: 11 | D37: 27.95 | E37: 27.92 | F37: 27.97 | G37: 27.81 | H37: 28.03 | I37: =H37/$H$27 -> 1.0079108
A38: 2031 | B38: 12 | D38: 28 | E38: 27.96 | F38: 28.03 | G38: 27.85 | H38: 28.06 | I38: =H38/$H$27 -> 1.0089896
... A57: 2050 | B57: 31 | D57: 28.06 | E57: 28.4 | F57: 28.58 | G57: 28.9 | H57: 29 | I57: =H57/$H$27 -> 1.0427904
A58: 2051 | D58: 28.01 | E58: 28.39 | F58: 28.61 | G58: 28.91 | H58: 29.04
A59: 2052 | D59: 28 | E59: 28.38 | F59: 28.64 | G59: 28.92 | H59: 29.1
A60: 2053 | D60: 28.04 | E60: 28.37 | F60: 28.67 | G60: 28.92 | H60: 29.16
A61: 2054 | D61: 28.13 | E61: 28.36 | F61: 28.71 | G61: 28.91 | H61: 29.21
A62: 2055 | D62: 28.24 | E62: 28.35 | F62: 28.75 | G62: 28.91 | H62: 29.27
A63: 2056 | D63: 28.35 | E63: 28.34 | F63: 28.79 | G63: 28.92 | H63: 29.32
A64: 2057 | D64: 28.42 | E64: 28.35 | F64: 28.85 | G64: 28.94 | H64: 29.38
...

Sheet Flood (national AAL PML)
A2: Base year 2020 (no climate change) | AG2: Housing | AO2: Services | AW2: Productive Sector | BE2: Roads | BM2: Schools | BU2: Health Centers
A4: RP | B4: Housing | D4: Services Sector | F4: Productive Sector | H4: Roads | L4: Schools | P4: Health Centers | AF4: 1 | AG4: =1/AG5 -> 0.1 | AH4: =1/AH5 -> 0.04 | AI4: =1/AI5 -> 0.01 | AJ4: =1/AJ5 -> 0.005 | AO4: 1 | AP4: =1/AP5 -> 0.1 | AQ4: =1/AQ5 -> 0.04 | AR4: =1/AR5 -> 0.01 | AS4: =1/AS5 -> 0.005 | AW4: 1 | AX4: =1/AX5 -> 0.1 | AY4: =1/AY5 -> 0.04 | AZ4: =1/AZ5 -> 0.01 | BA4: =1/BA5 -> 0.005 | BE4: 1 | BF4: =1/BF5 -> 0.1 | BG4: =1/BG5 -> 0.04 | BH4: =1/BH5 -> 0.01 | BI4: =1/BI5 -> 0.005 | BM4: 1 | BN4: =1/BN5 -> 0.1 | BO4: =1/BO5 -> 0.04 | BP4: =1/BP5 -> 0.01 | BQ4: =1/BQ5 -> 0.005 | BU4: 1 | BV4: =1/BV5 -> 0.1 | BW4: =1/BW5 -> 0.04 | BX4: =1/BX5 -> 0.01 | BY4: =1/BY5 -> 0.005
B5: US$ million | C5: % of total asset value | D5: US$ million | E5: % of total asset value | F5: US$ million | G5: % of total asset value | H5: km | I5: % of asset | J5: US$ million | K5: % of total asset value | L5: Number | M5: % of asset | N5: US$ million | O5: % of total asset value | P5: Number | Q5: % of asset | R5: US$ million | S5: % of total asset value | AA5: CGE interpolation | AE5: RP | AF5: 1 | AG5: 10 | AH5: 25 | AI5: 100 | AJ5: 200 | AN5: RP | AO5: 1 | AP5: 10 | AQ5: 25 | AR5: 100 | AS5: 200 | AW5: 1 | AX5: 10 | AY5: 25 | AZ5: 100 | BA5: 200 | BE5: 1 | BF5: 10 | BG5: 25 | BH5: 100 | BI5: 200 | BM5: 1 | BN5: 10 | BO5: 25 | BP5: 100 | BQ5: 200 | BU5: 1 | BV5: 10 | BW5: 25 | BX5: 100 | BY5: 200
A6: 10 | B6: 92.689411 | C6: 1.5623834 | D6: 298.13222 | E6: 1.5314151 | F6: 357.43199 | G6: 1.5311837 | H6: 658.26636 | I6: 4.8198012 | J6: 19.126417 | K6: 4.9440017 | L6: 970 | M6: 8.4864392 | N6: 14.26354 | O6: 2.3545354 | P6: 156 | Q6: 10.56195 | R6: 5.5796796 | S6: 5.6383751 | AD6: =(AG36-AG6)/30 -> 0.037679677 | AE6: 2020 | AF6: 0 | AG6: =C6 -> 1.5623834 | AH6: =C7 -> 1.8158097 | AI6: =C8 -> 2.5044538 | AJ6: =C9 -> 2.6002784 | AM6: =($AP36-$AP6)/30 -> 0.031711955 | AN6: 2020 | AO6: 0 | AP6: =E6 -> 1.5314151 | AQ6: =E7 -> 1.7673307 | AR6: =E8 -> 2.4226856 | AS6: =E9 -> 2.5199447 | AV6: =(AX36-AX6)/30 -> 0.037053002 | AW6: 0 | AX6: =G6 -> 1.5311837 | AY6: =G7 -> 1.7667284 | AZ6: =G8 -> 2.4218742 | BA6: =G9 -> 2.5192071 | BD6: =(BF36-BF6)/30 -> -0.075276023 | BE6: 0 | BF6: =K6 -> 4.9440017 | BG6: =K7 -> 6.8530205 | BH6: =K8 -> 7.9104108 | BI6: =K9 -> 8.2320018 | BL6: =(BN36-BN6)/30 -> -0.01944378 | BM6: 0 | BN6: =O6 -> 2.3545354 | BO6: =O7 -> 2.7634156 | BP6: =O8 -> 3.4956868 | BQ6: =O9 -> 3.6356308 | BT6: =(BV36-BV6)/30 -> -0.059568554 | BU6: 0 | BV6: =S6 -> 5.6383751 | BW6: =S7 -> 6.4471226 | BX6: =S8 -> 8.0198375 | BY6: =S9 -> 8.3341909
A7: 25 | B7: 107.72409 | C7: 1.8158097 | D7: 344.05971 | E7: 1.7673307 | F7: 412.4164 | G7: 1.7667284 | H7: 868.77512 | I7: 6.3611383 | J7: 26.511668 | K7: 6.8530205 | L7: 1301 | M7: 11.382327 | N7: 16.740495 | O7: 2.7634156 | P7: 184 | Q7: 12.457684 | R7: 6.380008 | S7: 6.4471226 | Z7: 2020 | AA7: =$T$10 -> 1.5580617 | AB7: =($AA$37-$AA$7)/30 -> -0.0095527654 | AD7: =(AH36-AH6)/30 -> 0.059095809 | AE7: 2021 | AF7: 0 | AG7: =AG6+$AD$6 -> 1.6000631 | AH7: =AH6+$AD$7 -> 1.8749055 | AI7: =AI6+$AD$8 -> 2.5684639 | AJ7: =AJ6+$AD$9 -> 2.6796916 | AM7: =(AQ36-AQ6)/30 -> 0.053711775 | AN7: 2021 | AP7: =AP6+$AM$6 -> 1.563127 | AQ7: =AQ6+$AM$7 -> 1.8210425 | AR7: =AR6+$AM$8 -> 2.4824213 | AS7: =AS6+$AM$9 -> 2.5950357 | AV7: =(AY36-AY6)/30 -> 0.059065186 | AX7: =AX6+$AV$6 -> 1.5682367 | AY7: =AY6+$AV$7 -> 1.8257936 | AZ7: =AZ6+$AV$8 -> 2.4869702 | BA7: =BA6+$AV$9 -> 2.599656 | BD7: =(BG36-BG6)/30 -> -0.11380165 | BF7: =BF6+$BD$6 -> 4.8687257 | BG7: =BG6+$BD$7 -> 6.7392188 | BH7: =BH6+$BD$8 -> 7.7933261 | BI7: =BI6+$BD$9 -> 8.1097962 | BL7: =(BO36-BO6)/30 -> -0.019685502 | BN7: =BN6+$BL$6 -> 2.3350917 | BO7: =BO6+$BL$7 -> 2.7437301 | BP7: =BP6+$BL$8 -> 3.473208 | BQ7: =BQ6+$BL$9 -> 3.6117486 | BT7: =(BW36-BW6)/30 -> -0.072286325 | BV7: =BV6+$BT$6 -> 5.5788065 | BW7: =BW6+$BT$7 -> 6.3748362 | BX7: =BX6+$BT$8 -> 7.9499054 | BY7: =BY6+$BT$9 -> 8.260216
A8: 100 | B8: 148.57835 | C8: 2.5044538 | D8: 471.64263 | E8: 2.4226856 | F8: 565.35041 | G8: 2.4218742 | H8: 1049.4225 | I8: 7.6838313 | J8: 30.602299 | K8: 7.9104108 | L8: 1472 | M8: 12.87839 | N8: 21.176521 | O8: 3.4956868 | P8: 227 | Q8: 15.368991 | R8: 7.936351 | S8: 8.0198375 | Z8: 2021 | AA8: =AA7+$AB$7 -> 1.5485089 | AD8: =(AI36-AI6)/30 -> 0.06401006 | AE8: 2022 | AG8: =AG7+$AD$6 -> 1.6377428 | AH8: =AH7+$AD$7 -> 1.9340013 | AI8: =AI7+$AD$8 -> 2.6324739 | AJ8: =AJ7+$AD$9 -> 2.7591048 | AM8: =(AR36-AR6)/30 -> 0.059735665 | AN8: 2022 | AP8: =AP7+$AM$6 -> 1.594839 | AQ8: =AQ7+$AM$7 -> 1.8747543 | AR8: =AR7+$AM$8 -> 2.542157 | AS8: =AS7+$AM$9 -> 2.6701267 | AV8: =(AZ36-AZ6)/30 -> 0.065096047 | AX8: =AX7+$AV$6 -> 1.6052897 | AY8: =AY7+$AV$7 -> 1.8848588 | AZ8: =AZ7+$AV$8 -> 2.5520663 | BA8: =BA7+$AV$9 -> 2.6801049 | BD8: =(BH36-BH6)/30 -> -0.11708467 | BF8: =BF7+$BD$6 -> 4.7934497 | BG8: =BG7+$BD$7 -> 6.6254172 | BH8: =BH7+$BD$8 -> 7.6762415 | BI8: =BI7+$BD$9 -> 7.9875907 | BL8: =(BP36-BP6)/30 -> -0.022478778 | BN8: =BN7+$BL$6 -> 2.3156479 | BO8: =BO7+$BL$7 -> 2.7240446 | BP8: =BP7+$BL$8 -> 3.4507293 | BQ8: =BQ7+$BL$9 -> 3.5878665 | BT8: =(BX36-BX6)/30 -> -0.069932154 | BV8: =BV7+$BT$6 -> 5.519238 | BW8: =BW7+$BT$7 -> 6.3025499 | BX8: =BX7+$BT$8 -> 7.8799732 | BY8: =BY7+$BT$9 -> 8.1862411
A9: 200 | B9: 154.2632 | C9: 2.6002784 | D9: 490.57679 | E9: 2.5199447 | F9: 588.07132 | G9: 2.5192071 | H9: 1089.6601 | I9: 7.9784497 | J9: 31.846409 | K9: 8.2320018 | L9: 1502 | M9: 13.140857 | N9: 22.024288 | O9: 3.6356308 | P9: 234 | Q9: 15.842925 | R9: 8.247432 | S9: 8.3341909 | T9: weighted average (%of damage of total capital in the dataset) | Z9: 2022 | AA9: =AA8+$AB$7 -> 1.5389562 | AD9: =(AJ36-AJ6)/30 -> 0.079413194 | AE9: 2023 | AG9: =AG8+$AD$6 -> 1.6754225 | AH9: =AH8+$AD$7 -> 1.9930971 | AI9: =AI8+$AD$8 -> 2.696484 | AJ9: =AJ8+$AD$9 -> 2.838518 | AM9: =(AS36-AS6)/30 -> 0.075090983 | AN9: 2023 | AP9: =AP8+$AM$6 -> 1.626551 | AQ9: =AQ8+$AM$7 -> 1.9284661 | AR9: =AR8+$AM$8 -> 2.6018926 | AS9: =AS8+$AM$9 -> 2.7452177 | AV9: =(BA36-BA6)/30 -> 0.080448905 | AX9: =AX8+$AV$6 -> 1.6423427 | AY9: =AY8+$AV$7 -> 1.943924 | AZ9: =AZ8+$AV$8 -> 2.6171623 | BA9: =BA8+$AV$9 -> 2.7605538 | BD9: =(BI36-BI6)/30 -> -0.12220556 | BF9: =BF8+$BD$6 -> 4.7181737 | BG9: =BG8+$BD$7 -> 6.5116155 | BH9: =BH8+$BD$8 -> 7.5591568 | BI9: =BI8+$BD$9 -> 7.8653851 | BL9: =(BQ36-BQ6)/30 -> -0.023882186 | BN9: =BN8+$BL$6 -> 2.2962041 | BO9: =BO8+$BL$7 -> 2.7043591 | BP9: =BP8+$BL$8 -> 3.4282505 | BQ9: =BQ8+$BL$9 -> 3.5639843 | BT9: =(BY36-BY6)/30 -> -0.073974947 | BV9: =BV8+$BT$6 -> 5.4596694 | BW9: =BW8+$BT$7 -> 6.2302636 | BX9: =BX8+$BT$8 -> 7.8100411 | BY9: =BY8+$BT$9 -> 8.1122661
A10: AAL | B10: 56.327998 | C10: 0.94947125 | D10: 180.32301 | E10: 0.92626481 | F10: 216.18826 | G10: 0.92611724 | H10: 461.36248 | I10: 3.3780784 | J10: 13.841958 | K10: 3.5780179 | L10: 690.85067 | M10: 6.0441878 | N10: 8.079959 | O10: 1.3337888 | P10: 103.466 | Q10: 7.0051456 | R10: 3.1013483 | S10: 3.133973 | T10: ='Weighted Av.'!C9 -> 1.5580617 | Z10: 2023 | AA10: =AA9+$AB$7 -> 1.5294034 | AE10: 2024 | AG10: =AG9+$AD$6 -> 1.7131021 | AH10: =AH9+$AD$7 -> 2.0521929 | AI10: =AI9+$AD$8 -> 2.7604941 | AJ10: =AJ9+$AD$9 -> 2.9179312 | AN10: 2024 | AP10: =AP9+$AM$6 -> 1.6582629 | AQ10: =AQ9+$AM$7 -> 1.9821778 | AR10: =AR9+$AM$8 -> 2.6616283 | AS10: =AS9+$AM$9 -> 2.8203086 | AX10: =AX9+$AV$6 -> 1.6793957 | AY10: =AY9+$AV$7 -> 2.0029891 | AZ10: =AZ9+$AV$8 -> 2.6822584 | BA10: =BA9+$AV$9 -> 2.8410027 | BF10: =BF9+$BD$6 -> 4.6428976 | BG10: =BG9+$BD$7 -> 6.3978139 | BH10: =BH9+$BD$8 -> 7.4420721 | BI10: =BI9+$BD$9 -> 7.7431796 | BN10: =BN9+$BL$6 -> 2.2767603 | BO10: =BO9+$BL$7 -> 2.6846736 | BP10: =BP9+$BL$8 -> 3.4057717 | BQ10: =BQ9+$BL$9 -> 3.5401021 | BV10: =BV9+$BT$6 -> 5.4001009 | BW10: =BW9+$BT$7 -> 6.1579773 | BX10: =BX9+$BT$8 -> 7.7401089 | BY10: =BY9+$BT$9 -> 8.0382912
Z11: 2024 | AA11: =AA10+$AB$7 -> 1.5198506 | AE11: 2025 | AG11: =AG10+$AD$6 -> 1.7507818 | AH11: =AH10+$AD$7 -> 2.1112888 | AI11: =AI10+$AD$8 -> 2.8245041 | AJ11: =AJ10+$AD$9 -> 2.9973444 | AN11: 2025 | AP11: =AP10+$AM$6 -> 1.6899749 | AQ11: =AQ10+$AM$7 -> 2.0358896 | AR11: =AR10+$AM$8 -> 2.721364 | AS11: =AS10+$AM$9 -> 2.8953996 | AX11: =AX10+$AV$6 -> 1.7164487 | AY11: =AY10+$AV$7 -> 2.0620543 | AZ11: =AZ10+$AV$8 -> 2.7473544 | BA11: =BA10+$AV$9 -> 2.9214516 | BF11: =BF10+$BD$6 -> 4.5676216 | BG11: =BG10+$BD$7 -> 6.2840122 | BH11: =BH10+$BD$8 -> 7.3249875 | BI11: =BI10+$BD$9 -> 7.620974 | BN11: =BN10+$BL$6 -> 2.2573165 | BO11: =BO10+$BL$7 -> 2.6649881 | BP11: =BP10+$BL$8 -> 3.3832929 | BQ11: =BQ10+$BL$9 -> 3.5162199 | BV11: =BV10+$BT$6 -> 5.3405323 | BW11: =BW10+$BT$7 -> 6.0856909 | BX11: =BX10+$BT$8 -> 7.6701767 | BY11: =BY10+$BT$9 -> 7.9643162
Z12: 2025 | AA12: =AA11+$AB$7 -> 1.5102979 | AE12: 2026 | AG12: =AG11+$AD$6 -> 1.7884615 | AH12: =AH11+$AD$7 -> 2.1703846 | AI12: =AI11+$AD$8 -> 2.8885142 | AJ12: =AJ11+$AD$9 -> 3.0767576 | AN12: 2026 | AP12: =AP11+$AM$6 -> 1.7216868 | AQ12: =AQ11+$AM$7 -> 2.0896014 | AR12: =AR11+$AM$8 -> 2.7810996 | AS12: =AS11+$AM$9 -> 2.9704906 | AX12: =AX11+$AV$6 -> 1.7535017 | AY12: =AY11+$AV$7 -> 2.1211195 | AZ12: =AZ11+$AV$8 -> 2.8124505 | BA12: =BA11+$AV$9 -> 3.0019005 | BF12: =BF11+$BD$6 -> 4.4923456 | BG12: =BG11+$BD$7 -> 6.1702106 | BH12: =BH11+$BD$8 -> 7.2079028 | BI12: =BI11+$BD$9 -> 7.4987684 | BN12: =BN11+$BL$6 -> 2.2378728 | BO12: =BO11+$BL$7 -> 2.6453026 | BP12: =BP11+$BL$8 -> 3.3608141 | BQ12: =BQ11+$BL$9 -> 3.4923377 | BV12: =BV11+$BT$6 -> 5.2809638 | BW12: =BW11+$BT$7 -> 6.0134046 | BX12: =BX11+$BT$8 -> 7.6002446 | BY12: =BY11+$BT$9 -> 7.8903413
A13: Year 2050 (SSP585, no adaptation, no socio-economic projections) | Z13: 2026 | AA13: =AA12+$AB$7 -> 1.5007451 | AE13: 2027 | AG13: =AG12+$AD$6 -> 1.8261412 | AH13: =AH12+$AD$7 -> 2.2294804 | AI13: =AI12+$AD$8 -> 2.9525242 | AJ13: =AJ12+$AD$9 -> 3.1561708 | AN13: 2027 | AP13: =AP12+$AM$6 -> 1.7533988 | AQ13: =AQ12+$AM$7 -> 2.1433132 | AR13: =AR12+$AM$8 -> 2.8408353 | AS13: =AS12+$AM$9 -> 3.0455816 | AX13: =AX12+$AV$6 -> 1.7905547 | AY13: =AY12+$AV$7 -> 2.1801847 | AZ13: =AZ12+$AV$8 -> 2.8775465 | BA13: =BA12+$AV$9 -> 3.0823494 | BF13: =BF12+$BD$6 -> 4.4170696 | BG13: =BG12+$BD$7 -> 6.0564089 | BH13: =BH12+$BD$8 -> 7.0908181 | BI13: =BI12+$BD$9 -> 7.3765629 | BN13: =BN12+$BL$6 -> 2.218429 | BO13: =BO12+$BL$7 -> 2.6256171 | BP13: =BP12+$BL$8 -> 3.3383354 | BQ13: =BQ12+$BL$9 -> 3.4684555 | BV13: =BV12+$BT$6 -> 5.2213952 | BW13: =BW12+$BT$7 -> 5.9411183 | BX13: =BX12+$BT$8 -> 7.5303124 | BY13: =BY12+$BT$9 -> 7.8163663
Z14: 2027 | AA14: =AA13+$AB$7 -> 1.4911923 | AE14: 2028 | AG14: =AG13+$AD$6 -> 1.8638208 | AH14: =AH13+$AD$7 -> 2.2885762 | AI14: =AI13+$AD$8 -> 3.0165343 | AJ14: =AJ13+$AD$9 -> 3.235584 | AN14: 2028 | AP14: =AP13+$AM$6 -> 1.7851107 | AQ14: =AQ13+$AM$7 -> 2.1970249 | AR14: =AR13+$AM$8 -> 2.900571 | AS14: =AS13+$AM$9 -> 3.1206726 | AX14: =AX13+$AV$6 -> 1.8276077 | AY14: =AY13+$AV$7 -> 2.2392499 | AZ14: =AZ13+$AV$8 -> 2.9426426 | BA14: =BA13+$AV$9 -> 3.1627983 | BF14: =BF13+$BD$6 -> 4.3417935 | BG14: =BG13+$BD$7 -> 5.9426073 | BH14: =BH13+$BD$8 -> 6.9737335 | BI14: =BI13+$BD$9 -> 7.2543573 | BN14: =BN13+$BL$6 -> 2.1989852 | BO14: =BO13+$BL$7 -> 2.6059316 | BP14: =BP13+$BL$8 -> 3.3158566 | BQ14: =BQ13+$BL$9 -> 3.4445733 | BV14: =BV13+$BT$6 -> 5.1618267 | BW14: =BW13+$BT$7 -> 5.868832 | BX14: =BX13+$BT$8 -> 7.4603803 | BY14: =BY13+$BT$9 -> 7.7423914
A15: RP | B15: Housing | D15: Services Sector | F15: Productive Sector | H15: Roads | L15: Schools | P15: Health Centers | Z15: 2028 | AA15: =AA14+$AB$7 -> 1.4816396 | AE15: 2029 | AG15: =AG14+$AD$6 -> 1.9015005 | AH15: =AH14+$AD$7 -> 2.347672 | AI15: =AI14+$AD$8 -> 3.0805444 | AJ15: =AJ14+$AD$9 -> 3.3149971 | AN15: 2029 | AP15: =AP14+$AM$6 -> 1.8168227 | AQ15: =AQ14+$AM$7 -> 2.2507367 | AR15: =AR14+$AM$8 -> 2.9603066 | AS15: =AS14+$AM$9 -> 3.1957636 | AX15: =AX14+$AV$6 -> 1.8646607 | AY15: =AY14+$AV$7 -> 2.2983151 | AZ15: =AZ14+$AV$8 -> 3.0077386 | BA15: =BA14+$AV$9 -> 3.2432472 | BF15: =BF14+$BD$6 -> 4.2665175 | BG15: =BG14+$BD$7 -> 5.8288056 | BH15: =BH14+$BD$8 -> 6.8566488 | BI15: =BI14+$BD$9 -> 7.1321517 | BN15: =BN14+$BL$6 -> 2.1795414 | BO15: =BO14+$BL$7 -> 2.5862461 | BP15: =BP14+$BL$8 -> 3.2933778 | BQ15: =BQ14+$BL$9 -> 3.4206912 | BV15: =BV14+$BT$6 -> 5.1022581 | BW15: =BW14+$BT$7 -> 5.7965456 | BX15: =BX14+$BT$8 -> 7.3904481 | BY15: =BY14+$BT$9 -> 7.6684164
B16: US$ million | C16: % of total asset value | D16: US$ million | E16: % of total asset value | F16: US$ million | G16: % of total asset value | H16: km | I16: % of asset | J16: US$ million | K16: % of total asset value | L16: Number | M16: % of asset | N16: US$ million | O16: % of total asset value | P16: Number | Q16: % of asset | R16: US$ million | S16: % of total asset value | Z16: 2029 | AA16: =AA15+$AB$7 -> 1.4720868 | AE16: 2030 | AG16: =AG15+$AD$6 -> 1.9391802 | AH16: =AH15+$AD$7 -> 2.4067678 | AI16: =AI15+$AD$8 -> 3.1445544 | AJ16: =AJ15+$AD$9 -> 3.3944103 | AN16: 2030 | AP16: =AP15+$AM$6 -> 1.8485346 | AQ16: =AQ15+$AM$7 -> 2.3044485 | AR16: =AR15+$AM$8 -> 3.0200423 | AS16: =AS15+$AM$9 -> 3.2708545 | AX16: =AX15+$AV$6 -> 1.9017137 | AY16: =AY15+$AV$7 -> 2.3573803 | AZ16: =AZ15+$AV$8 -> 3.0728347 | BA16: =BA15+$AV$9 -> 3.3236961 | BF16: =BF15+$BD$6 -> 4.1912415 | BG16: =BG15+$BD$7 -> 5.7150039 | BH16: =BH15+$BD$8 -> 6.7395641 | BI16: =BI15+$BD$9 -> 7.0099462 | BN16: =BN15+$BL$6 -> 2.1600976 | BO16: =BO15+$BL$7 -> 2.5665606 | BP16: =BP15+$BL$8 -> 3.270899 | BQ16: =BQ15+$BL$9 -> 3.396809 | BV16: =BV15+$BT$6 -> 5.0426896 | BW16: =BW15+$BT$7 -> 5.7242593 | BX16: =BX15+$BT$8 -> 7.320516 | BY16: =BY15+$BT$9 -> 7.5944415
A17: 10 | B17: 160.97013 | C17: 2.6927737 | D17: 483.22921 | E17: 2.4827737 | F17: 665.06326 | G17: =E17+0.16 -> 2.6427737 | H17: 415.85769 | I17: 2.5957037 | J17: 12.231177 | K17: 2.685721 | L17: 586.5 | M17: 5.1267483 | N17: 10.739274 | O17: 1.7712221 | P17: 85.5 | Q17: 5.7809331 | R17: 3.816387 | S17: 3.8513185 | Z17: 2030 | AA17: =AA16+$AB$7 -> 1.462534 | AE17: 2031 | AG17: =AG16+$AD$6 -> 1.9768599 | AH17: =AH16+$AD$7 -> 2.4658636 | AI17: =AI16+$AD$8 -> 3.2085645 | AJ17: =AJ16+$AD$9 -> 3.4738235 | AN17: 2031 | AP17: =AP16+$AM$6 -> 1.8802466 | AQ17: =AQ16+$AM$7 -> 2.3581603 | AR17: =AR16+$AM$8 -> 3.079778 | AS17: =AS16+$AM$9 -> 3.3459455 | AX17: =AX16+$AV$6 -> 1.9387667 | AY17: =AY16+$AV$7 -> 2.4164455 | AZ17: =AZ16+$AV$8 -> 3.1379307 | BA17: =BA16+$AV$9 -> 3.404145 | BF17: =BF16+$BD$6 -> 4.1159655 | BG17: =BG16+$BD$7 -> 5.6012023 | BH17: =BH16+$BD$8 -> 6.6224795 | BI17: =BI16+$BD$9 -> 6.8877406 | BN17: =BN16+$BL$6 -> 2.1406539 | BO17: =BO16+$BL$7 -> 2.5468751 | BP17: =BP16+$BL$8 -> 3.2484203 | BQ17: =BQ16+$BL$9 -> 3.3729268 | BV17: =BV16+$BT$6 -> 4.983121 | BW17: =BW16+$BT$7 -> 5.651973 | BX17: =BX16+$BT$8 -> 7.2505838 | BY17: =BY16+$BT$9 -> 7.5204665
A18: 25 | B18: 214.52635 | C18: 3.588684 | D18: 657.60273 | E18: 3.378684 | F18: 873.9256 | G18: =E18+0.16 -> 3.538684 | H18: 528.18554 | I18: 3.2968325 | J18: 15.66159 | K18: 3.4389708 | L18: 735 | M18: 6.4248252 | N18: 13.174427 | O18: 2.1728505 | P18: 102 | Q18: 6.8965517 | R18: 4.2397265 | S18: 4.2785328 | Z18: 2031 | AA18: =AA17+$AB$7 -> 1.4529813 | AE18: 2032 | AG18: =AG17+$AD$6 -> 2.0145395 | AH18: =AH17+$AD$7 -> 2.5249594 | AI18: =AI17+$AD$8 -> 3.2725745 | AJ18: =AJ17+$AD$9 -> 3.5532367 | AN18: 2032 | AP18: =AP17+$AM$6 -> 1.9119585 | AQ18: =AQ17+$AM$7 -> 2.411872 | AR18: =AR17+$AM$8 -> 3.1395136 | AS18: =AS17+$AM$9 -> 3.4210365 | AX18: =AX17+$AV$6 -> 1.9758197 | AY18: =AY17+$AV$7 -> 2.4755106 | AZ18: =AZ17+$AV$8 -> 3.2030267 | BA18: =BA17+$AV$9 -> 3.4845939 | BF18: =BF17+$BD$6 -> 4.0406895 | BG18: =BG17+$BD$7 -> 5.4874006 | BH18: =BH17+$BD$8 -> 6.5053948 | BI18: =BI17+$BD$9 -> 6.7655351 | BN18: =BN17+$BL$6 -> 2.1212101 | BO18: =BO17+$BL$7 -> 2.5271896 | BP18: =BP17+$BL$8 -> 3.2259415 | BQ18: =BQ17+$BL$9 -> 3.3490446 | BV18: =BV17+$BT$6 -> 4.9235524 | BW18: =BW17+$BT$7 -> 5.5796867 | BX18: =BX17+$BT$8 -> 7.1806517 | BY18: =BY17+$BT$9 -> 7.4464916
A19: 100 | B19: 297.85707 | C19: 4.4247556 | D19: 928.91896 | E19: 4.2147556 | F19: 1198.9046 | G19: =E19+0.16 -> 4.3747556 | H19: 693.53492 | I19: 4.3289116 | J19: 20.028564 | K19: 4.3978708 | L19: 891 | M19: 7.7884615 | N19: 17.106248 | O19: 2.8213235 | P19: 139 | Q19: 9.3982421 | R19: 5.8681615 | S19: 5.9218729 | Z19: 2032 | AA19: =AA18+$AB$7 -> 1.4434285 | AE19: 2033 | AG19: =AG18+$AD$6 -> 2.0522192 | AH19: =AH18+$AD$7 -> 2.5840552 | AI19: =AI18+$AD$8 -> 3.3365846 | AJ19: =AJ18+$AD$9 -> 3.6326499 | AN19: 2033 | AP19: =AP18+$AM$6 -> 1.9436705 | AQ19: =AQ18+$AM$7 -> 2.4655838 | AR19: =AR18+$AM$8 -> 3.1992493 | AS19: =AS18+$AM$9 -> 3.4961275 | AX19: =AX18+$AV$6 -> 2.0128727 | AY19: =AY18+$AV$7 -> 2.5345758 | AZ19: =AZ18+$AV$8 -> 3.2681228 | BA19: =BA18+$AV$9 -> 3.5650428 | BF19: =BF18+$BD$6 -> 3.9654134 | BG19: =BG18+$BD$7 -> 5.373599 | BH19: =BH18+$BD$8 -> 6.3883101 | BI19: =BI18+$BD$9 -> 6.6433295 | BN19: =BN18+$BL$6 -> 2.1017663 | BO19: =BO18+$BL$7 -> 2.5075041 | BP19: =BP18+$BL$8 -> 3.2034627 | BQ19: =BQ18+$BL$9 -> 3.3251624 | BV19: =BV18+$BT$6 -> 4.8639839 | BW19: =BW18+$BT$7 -> 5.5074003 | BX19: =BX18+$BT$8 -> 7.1107195 | BY19: =BY18+$BT$9 -> 7.3725166
A20: 200 | B20: 314.01284 | C20: 4.9826742 | D20: 981.52046 | E20: 4.7726742 | F20: 1261.91 | G20: =E20+0.16 -> 4.9326742 | H20: 714.04189 | I20: 4.4569121 | J20: 20.793498 | K20: 4.565835 | L20: 924.5 | M20: 8.0812937 | N20: 17.699483 | O20: 2.9191653 | P20: 144.5 | Q20: 9.7701149 | R20: 6.05948 | S20: 6.1149425 | T20: weighted average | Z20: 2033 | AA20: =AA19+$AB$7 -> 1.4338757 | AE20: 2034 | AG20: =AG19+$AD$6 -> 2.0898989 | AH20: =AH19+$AD$7 -> 2.643151 | AI20: =AI19+$AD$8 -> 3.4005946 | AJ20: =AJ19+$AD$9 -> 3.7120631 | AN20: 2034 | AP20: =AP19+$AM$6 -> 1.9753825 | AQ20: =AQ19+$AM$7 -> 2.5192956 | AR20: =AR19+$AM$8 -> 3.258985 | AS20: =AS19+$AM$9 -> 3.5712185 | AX20: =AX19+$AV$6 -> 2.0499257 | AY20: =AY19+$AV$7 -> 2.593641 | AZ20: =AZ19+$AV$8 -> 3.3332188 | BA20: =BA19+$AV$9 -> 3.6454917 | BF20: =BF19+$BD$6 -> 3.8901374 | BG20: =BG19+$BD$7 -> 5.2597973 | BH20: =BH19+$BD$8 -> 6.2712254 | BI20: =BI19+$BD$9 -> 6.5211239 | BN20: =BN19+$BL$6 -> 2.0823225 | BO20: =BO19+$BL$7 -> 2.4878186 | BP20: =BP19+$BL$8 -> 3.1809839 | BQ20: =BQ19+$BL$9 -> 3.3012802 | BV20: =BV19+$BT$6 -> 4.8044153 | BW20: =BW19+$BT$7 -> 5.435114 | BX20: =BX19+$BT$8 -> 7.0407874 | BY20: =BY19+$BT$9 -> 7.2985417
A21: AAL | B21: 75.959706 | C21: 1.2706848 | D21: 206.44406 | E21: 1.0606848 | F21: 333.53361 | G21: 1.4306848 | H21: 236.06882 | I21: 1.4734962 | J21: 6.8610879 | K21: 1.5065573 | L21: 321.53483 | M21: 2.8106192 | N21: 5.8761273 | O21: 2.0092701 | P21: 48 | Q21: 3.2672865 | R21: 1.9910461 | S21: 2.0092701 | T21: ='Weighted Av.'!C24 -> 1.2714787 | Z21: 2034 | AA21: =AA20+$AB$7 -> 1.424323 | AE21: 2035 | AG21: =AG20+$AD$6 -> 2.1275786 | AH21: =AH20+$AD$7 -> 2.7022468 | AI21: =AI20+$AD$8 -> 3.4646047 | AJ21: =AJ20+$AD$9 -> 3.7914763 | AN21: 2035 | AP21: =AP20+$AM$6 -> 2.0070944 | AQ21: =AQ20+$AM$7 -> 2.5730074 | AR21: =AR20+$AM$8 -> 3.3187206 | AS21: =AS20+$AM$9 -> 3.6463095 | AX21: =AX20+$AV$6 -> 2.0869787 | AY21: =AY20+$AV$7 -> 2.6527062 | AZ21: =AZ20+$AV$8 -> 3.3983149 | BA21: =BA20+$AV$9 -> 3.7259406 | BF21: =BF20+$BD$6 -> 3.8148614 | BG21: =BG20+$BD$7 -> 5.1459957 | BH21: =BH20+$BD$8 -> 6.1541408 | BI21: =BI20+$BD$9 -> 6.3989184 | BN21: =BN20+$BL$6 -> 2.0628787 | BO21: =BO20+$BL$7 -> 2.4681331 | BP21: =BP20+$BL$8 -> 3.1585051 | BQ21: =BQ20+$BL$9 -> 3.277398 | BV21: =BV20+$BT$6 -> 4.7448468 | BW21: =BW20+$BT$7 -> 5.3628277 | BX21: =BX20+$BT$8 -> 6.9708552 | BY21: =BY20+$BT$9 -> 7.2245667
Z22: 2035 | AA22: =AA21+$AB$7 -> 1.4147702 | AE22: 2036 | AG22: =AG21+$AD$6 -> 2.1652583 | AH22: =AH21+$AD$7 -> 2.7613427 | AI22: =AI21+$AD$8 -> 3.5286148 | AJ22: =AJ21+$AD$9 -> 3.8708895 | AN22: 2036 | AP22: =AP21+$AM$6 -> 2.0388064 | AQ22: =AQ21+$AM$7 -> 2.6267191 | AR22: =AR21+$AM$8 -> 3.3784563 | AS22: =AS21+$AM$9 -> 3.7214004 | AX22: =AX21+$AV$6 -> 2.1240317 | AY22: =AY21+$AV$7 -> 2.7117714 | AZ22: =AZ21+$AV$8 -> 3.4634109 | BA22: =BA21+$AV$9 -> 3.8063895 | BF22: =BF21+$BD$6 -> 3.7395854 | BG22: =BG21+$BD$7 -> 5.032194 | BH22: =BH21+$BD$8 -> 6.0370561 | BI22: =BI21+$BD$9 -> 6.2767128 | BN22: =BN21+$BL$6 -> 2.043435 | BO22: =BO21+$BL$7 -> 2.4484476 | BP22: =BP21+$BL$8 -> 3.1360264 | BQ22: =BQ21+$BL$9 -> 3.2535159 | BV22: =BV21+$BT$6 -> 4.6852782 | BW22: =BW21+$BT$7 -> 5.2905414 | BX22: =BX21+$BT$8 -> 6.9009231 | BY22: =BY21+$BT$9 -> 7.1505918
Z23: 2036 | AA23: =AA22+$AB$7 -> 1.4052174 | AE23: 2037 | AG23: =AG22+$AD$6 -> 2.2029379 | AH23: =AH22+$AD$7 -> 2.8204385 | AI23: =AI22+$AD$8 -> 3.5926248 | AJ23: =AJ22+$AD$9 -> 3.9503027 | AN23: 2037 | AP23: =AP22+$AM$6 -> 2.0705183 | AQ23: =AQ22+$AM$7 -> 2.6804309 | AR23: =AR22+$AM$8 -> 3.4381919 | AS23: =AS22+$AM$9 -> 3.7964914 | AX23: =AX22+$AV$6 -> 2.1610847 | AY23: =AY22+$AV$7 -> 2.7708366 | AZ23: =AZ22+$AV$8 -> 3.528507 | BA23: =BA22+$AV$9 -> 3.8868385 | BF23: =BF22+$BD$6 -> 3.6643093 | BG23: =BG22+$BD$7 -> 4.9183924 | BH23: =BH22+$BD$8 -> 5.9199714 | BI23: =BI22+$BD$9 -> 6.1545073 | BN23: =BN22+$BL$6 -> 2.0239912 | BO23: =BO22+$BL$7 -> 2.4287621 | BP23: =BP22+$BL$8 -> 3.1135476 | BQ23: =BQ22+$BL$9 -> 3.2296337 | BV23: =BV22+$BT$6 -> 4.6257097 | BW23: =BW22+$BT$7 -> 5.218255 | BX23: =BX22+$BT$8 -> 6.8309909 | BY23: =BY22+$BT$9 -> 7.0766168
A24: Year 2050 (SSP585, no adaptation, with socio-economic projections) | Z24: 2037 | AA24: =AA23+$AB$7 -> 1.3956647 | AE24: 2038 | AG24: =AG23+$AD$6 -> 2.2406176 | AH24: =AH23+$AD$7 -> 2.8795343 | AI24: =AI23+$AD$8 -> 3.6566349 | AJ24: =AJ23+$AD$9 -> 4.0297159 | AN24: 2038 | AP24: =AP23+$AM$6 -> 2.1022303 | AQ24: =AQ23+$AM$7 -> 2.7341427 | AR24: =AR23+$AM$8 -> 3.4979276 | AS24: =AS23+$AM$9 -> 3.8715824 | AX24: =AX23+$AV$6 -> 2.1981377 | AY24: =AY23+$AV$7 -> 2.8299018 | AZ24: =AZ23+$AV$8 -> 3.593603 | BA24: =BA23+$AV$9 -> 3.9672874 | BF24: =BF23+$BD$6 -> 3.5890333 | BG24: =BG23+$BD$7 -> 4.8045907 | BH24: =BH23+$BD$8 -> 5.8028868 | BI24: =BI23+$BD$9 -> 6.0323017 | BN24: =BN23+$BL$6 -> 2.0045474 | BO24: =BO23+$BL$7 -> 2.4090766 | BP24: =BP23+$BL$8 -> 3.0910688 | BQ24: =BQ23+$BL$9 -> 3.2057515 | BV24: =BV23+$BT$6 -> 4.5661411 | BW24: =BW23+$BT$7 -> 5.1459687 | BX24: =BX23+$BT$8 -> 6.7610587 | BY24: =BY23+$BT$9 -> 7.0026419
Z25: 2038 | AA25: =AA24+$AB$7 -> 1.3861119 | AE25: 2039 | AG25: =AG24+$AD$6 -> 2.2782973 | AH25: =AH24+$AD$7 -> 2.9386301 | AI25: =AI24+$AD$8 -> 3.7206449 | AJ25: =AJ24+$AD$9 -> 4.1091291 | AN25: 2039 | AP25: =AP24+$AM$6 -> 2.1339422 | AQ25: =AQ24+$AM$7 -> 2.7878545 | AR25: =AR24+$AM$8 -> 3.5576633 | AS25: =AS24+$AM$9 -> 3.9466734 | AX25: =AX24+$AV$6 -> 2.2351907 | AY25: =AY24+$AV$7 -> 2.8889669 | AZ25: =AZ24+$AV$8 -> 3.6586991 | BA25: =BA24+$AV$9 -> 4.0477363 | BF25: =BF24+$BD$6 -> 3.5137573 | BG25: =BG24+$BD$7 -> 4.6907891 | BH25: =BH24+$BD$8 -> 5.6858021 | BI25: =BI24+$BD$9 -> 5.9100961 | BN25: =BN24+$BL$6 -> 1.9851036 | BO25: =BO24+$BL$7 -> 2.3893911 | BP25: =BP24+$BL$8 -> 3.06859 | BQ25: =BQ24+$BL$9 -> 3.1818693 | BV25: =BV24+$BT$6 -> 4.5065726 | BW25: =BW24+$BT$7 -> 5.0736824 | BX25: =BX24+$BT$8 -> 6.6911266 | BY25: =BY24+$BT$9 -> 6.928667
A26: RP | B26: Housing | D26: Services Sector | F26: Productive Sector | H26: Roads | L26: Schools | P26: Health Centers | Z26: 2039 | AA26: =AA25+$AB$7 -> 1.3765591 | AE26: 2040 | AG26: =AG25+$AD$6 -> 2.315977 | AH26: =AH25+$AD$7 -> 2.9977259 | AI26: =AI25+$AD$8 -> 3.784655 | AJ26: =AJ25+$AD$9 -> 4.1885423 | AN26: 2040 | AP26: =AP25+$AM$6 -> 2.1656542 | AQ26: =AQ25+$AM$7 -> 2.8415662 | AR26: =AR25+$AM$8 -> 3.6173989 | AS26: =AS25+$AM$9 -> 4.0217644 | AX26: =AX25+$AV$6 -> 2.2722437 | AY26: =AY25+$AV$7 -> 2.9480321 | AZ26: =AZ25+$AV$8 -> 3.7237951 | BA26: =BA25+$AV$9 -> 4.1281852 | BF26: =BF25+$BD$6 -> 3.4384813 | BG26: =BG25+$BD$7 -> 4.5769874 | BH26: =BH25+$BD$8 -> 5.5687174 | BI26: =BI25+$BD$9 -> 5.7878906 | BN26: =BN25+$BL$6 -> 1.9656598 | BO26: =BO25+$BL$7 -> 2.3697056 | BP26: =BP25+$BL$8 -> 3.0461113 | BQ26: =BQ25+$BL$9 -> 3.1579871 | BV26: =BV25+$BT$6 -> 4.447004 | BW26: =BW25+$BT$7 -> 5.0013961 | BX26: =BX25+$BT$8 -> 6.6211944 | BY26: =BY25+$BT$9 -> 6.854692
B27: US$ million | C27: % of total asset value | D27: US$ million | E27: % of total asset value | F27: US$ million | G27: % of total asset value | H27: km | I27: % of asset | J27: US$ million | K27: % of total asset value | L27: Number | M27: % of asset | N27: US$ million | O27: % of total asset value | P27: Number | Q27: % of asset | R27: US$ million | S27: % of total asset value | Z27: 2040 | AA27: =AA26+$AB$7 -> 1.3670064 | AE27: 2041 | AG27: =AG26+$AD$6 -> 2.3536566 | AH27: =AH26+$AD$7 -> 3.0568217 | AI27: =AI26+$AD$8 -> 3.8486651 | AJ27: =AJ26+$AD$9 -> 4.2679555 | AN27: 2041 | AP27: =AP26+$AM$6 -> 2.1973661 | AQ27: =AQ26+$AM$7 -> 2.895278 | AR27: =AR26+$AM$8 -> 3.6771346 | AS27: =AS26+$AM$9 -> 4.0968554 | AX27: =AX26+$AV$6 -> 2.3092967 | AY27: =AY26+$AV$7 -> 3.0070973 | AZ27: =AZ26+$AV$8 -> 3.7888912 | BA27: =BA26+$AV$9 -> 4.2086341 | BF27: =BF26+$BD$6 -> 3.3632053 | BG27: =BG26+$BD$7 -> 4.4631857 | BH27: =BH26+$BD$8 -> 5.4516328 | BI27: =BI26+$BD$9 -> 5.665685 | BN27: =BN26+$BL$6 -> 1.9462161 | BO27: =BO26+$BL$7 -> 2.3500201 | BP27: =BP26+$BL$8 -> 3.0236325 | BQ27: =BQ26+$BL$9 -> 3.1341049 | BV27: =BV26+$BT$6 -> 4.3874355 | BW27: =BW26+$BT$7 -> 4.9291097 | BX27: =BX26+$BT$8 -> 6.5512623 | BY27: =BY26+$BT$9 -> 6.7807171
A28: 10 | Z28: 2041 | AA28: =AA27+$AB$7 -> 1.3574536 | AE28: 2042 | AG28: =AG27+$AD$6 -> 2.3913363 | AH28: =AH27+$AD$7 -> 3.1159175 | AI28: =AI27+$AD$8 -> 3.9126751 | AJ28: =AJ27+$AD$9 -> 4.3473687 | AN28: 2042 | AP28: =AP27+$AM$6 -> 2.2290781 | AQ28: =AQ27+$AM$7 -> 2.9489898 | AR28: =AR27+$AM$8 -> 3.7368703 | AS28: =AS27+$AM$9 -> 4.1719463 | AX28: =AX27+$AV$6 -> 2.3463497 | AY28: =AY27+$AV$7 -> 3.0661625 | AZ28: =AZ27+$AV$8 -> 3.8539872 | BA28: =BA27+$AV$9 -> 4.289083 | BF28: =BF27+$BD$6 -> 3.2879292 | BG28: =BG27+$BD$7 -> 4.3493841 | BH28: =BH27+$BD$8 -> 5.3345481 | BI28: =BI27+$BD$9 -> 5.5434795 | BN28: =BN27+$BL$6 -> 1.9267723 | BO28: =BO27+$BL$7 -> 2.3303346 | BP28: =BP27+$BL$8 -> 3.0011537 | BQ28: =BQ27+$BL$9 -> 3.1102227 | BV28: =BV27+$BT$6 -> 4.3278669 | BW28: =BW27+$BT$7 -> 4.8568234 | BX28: =BX27+$BT$8 -> 6.4813301 | BY28: =BY27+$BT$9 -> 6.7067421
A29: 25 | Z29: 2042 | AA29: =AA28+$AB$7 -> 1.3479009 | AE29: 2043 | AG29: =AG28+$AD$6 -> 2.429016 | AH29: =AH28+$AD$7 -> 3.1750133 | AI29: =AI28+$AD$8 -> 3.9766852 | AJ29: =AJ28+$AD$9 -> 4.4267819 | AN29: 2043 | AP29: =AP28+$AM$6 -> 2.26079 | AQ29: =AQ28+$AM$7 -> 3.0027016 | AR29: =AR28+$AM$8 -> 3.7966059 | AS29: =AS28+$AM$9 -> 4.2470373 | AX29: =AX28+$AV$6 -> 2.3834027 | AY29: =AY28+$AV$7 -> 3.1252277 | AZ29: =AZ28+$AV$8 -> 3.9190833 | BA29: =BA28+$AV$9 -> 4.3695319 | BF29: =BF28+$BD$6 -> 3.2126532 | BG29: =BG28+$BD$7 -> 4.2355824 | BH29: =BH28+$BD$8 -> 5.2174634 | BI29: =BI28+$BD$9 -> 5.4212739 | BN29: =BN28+$BL$6 -> 1.9073285 | BO29: =BO28+$BL$7 -> 2.3106491 | BP29: =BP28+$BL$8 -> 2.9786749 | BQ29: =BQ28+$BL$9 -> 3.0863406 | BV29: =BV28+$BT$6 -> 4.2682983 | BW29: =BW28+$BT$7 -> 4.7845371 | BX29: =BX28+$BT$8 -> 6.411398 | BY29: =BY28+$BT$9 -> 6.6327672
A30: 100 | Z30: 2043 | AA30: =AA29+$AB$7 -> 1.3383481 | AE30: 2044 | AG30: =AG29+$AD$6 -> 2.4666957 | AH30: =AH29+$AD$7 -> 3.2341091 | AI30: =AI29+$AD$8 -> 4.0406952 | AJ30: =AJ29+$AD$9 -> 4.5061951 | AN30: 2044 | AP30: =AP29+$AM$6 -> 2.292502 | AQ30: =AQ29+$AM$7 -> 3.0564133 | AR30: =AR29+$AM$8 -> 3.8563416 | AS30: =AS29+$AM$9 -> 4.3221283 | AX30: =AX29+$AV$6 -> 2.4204557 | AY30: =AY29+$AV$7 -> 3.1842929 | AZ30: =AZ29+$AV$8 -> 3.9841793 | BA30: =BA29+$AV$9 -> 4.4499808 | BF30: =BF29+$BD$6 -> 3.1373772 | BG30: =BG29+$BD$7 -> 4.1217808 | BH30: =BH29+$BD$8 -> 5.1003788 | BI30: =BI29+$BD$9 -> 5.2990683 | BN30: =BN29+$BL$6 -> 1.8878847 | BO30: =BO29+$BL$7 -> 2.2909636 | BP30: =BP29+$BL$8 -> 2.9561961 | BQ30: =BQ29+$BL$9 -> 3.0624584 | BV30: =BV29+$BT$6 -> 4.2087298 | BW30: =BW29+$BT$7 -> 4.7122508 | BX30: =BX29+$BT$8 -> 6.3414658 | BY30: =BY29+$BT$9 -> 6.5587922
A31: 200 | Z31: 2044 | AA31: =AA30+$AB$7 -> 1.3287953 | AE31: 2045 | AG31: =AG30+$AD$6 -> 2.5043753 | AH31: =AH30+$AD$7 -> 3.2932049 | AI31: =AI30+$AD$8 -> 4.1047053 | AJ31: =AJ30+$AD$9 -> 4.5856082 | AN31: 2045 | AP31: =AP30+$AM$6 -> 2.324214 | AQ31: =AQ30+$AM$7 -> 3.1101251 | AR31: =AR30+$AM$8 -> 3.9160773 | AS31: =AS30+$AM$9 -> 4.3972193 | AX31: =AX30+$AV$6 -> 2.4575087 | AY31: =AY30+$AV$7 -> 3.2433581 | AZ31: =AZ30+$AV$8 -> 4.0492754 | BA31: =BA30+$AV$9 -> 4.5304297 | BF31: =BF30+$BD$6 -> 3.0621012 | BG31: =BG30+$BD$7 -> 4.0079791 | BH31: =BH30+$BD$8 -> 4.9832941 | BI31: =BI30+$BD$9 -> 5.1768628 | BN31: =BN30+$BL$6 -> 1.8684409 | BO31: =BO30+$BL$7 -> 2.271278 | BP31: =BP30+$BL$8 -> 2.9337174 | BQ31: =BQ30+$BL$9 -> 3.0385762 | BV31: =BV30+$BT$6 -> 4.1491612 | BW31: =BW30+$BT$7 -> 4.6399644 | BX31: =BX30+$BT$8 -> 6.2715337 | BY31: =BY30+$BT$9 -> 6.4848173
A32: AAL | Z32: 2045 | AA32: =AA31+$AB$7 -> 1.3192426 | AE32: 2046 | AG32: =AG31+$AD$6 -> 2.542055 | AH32: =AH31+$AD$7 -> 3.3523007 | AI32: =AI31+$AD$8 -> 4.1687154 | AJ32: =AJ31+$AD$9 -> 4.6650214 | AN32: 2046 | AP32: =AP31+$AM$6 -> 2.3559259 | AQ32: =AQ31+$AM$7 -> 3.1638369 | AR32: =AR31+$AM$8 -> 3.9758129 | AS32: =AS31+$AM$9 -> 4.4723103 | AX32: =AX31+$AV$6 -> 2.4945617 | AY32: =AY31+$AV$7 -> 3.3024232 | AZ32: =AZ31+$AV$8 -> 4.1143714 | BA32: =BA31+$AV$9 -> 4.6108786 | BF32: =BF31+$BD$6 -> 2.9868251 | BG32: =BG31+$BD$7 -> 3.8941775 | BH32: =BH31+$BD$8 -> 4.8662094 | BI32: =BI31+$BD$9 -> 5.0546572 | BN32: =BN31+$BL$6 -> 1.8489972 | BO32: =BO31+$BL$7 -> 2.2515925 | BP32: =BP31+$BL$8 -> 2.9112386 | BQ32: =BQ31+$BL$9 -> 3.014694 | BV32: =BV31+$BT$6 -> 4.0895927 | BW32: =BW31+$BT$7 -> 4.5676781 | BX32: =BX31+$BT$8 -> 6.2016015 | BY32: =BY31+$BT$9 -> 6.4108423
Z33: 2046 | AA33: =AA32+$AB$7 -> 1.3096898 | AE33: 2047 | AG33: =AG32+$AD$6 -> 2.5797347 | AH33: =AH32+$AD$7 -> 3.4113966 | AI33: =AI32+$AD$8 -> 4.2327254 | AJ33: =AJ32+$AD$9 -> 4.7444346 | AN33: 2047 | AP33: =AP32+$AM$6 -> 2.3876379 | AQ33: =AQ32+$AM$7 -> 3.2175487 | AR33: =AR32+$AM$8 -> 4.0355486 | AS33: =AS32+$AM$9 -> 4.5474013 | AX33: =AX32+$AV$6 -> 2.5316147 | AY33: =AY32+$AV$7 -> 3.3614884 | AZ33: =AZ32+$AV$8 -> 4.1794675 | BA33: =BA32+$AV$9 -> 4.6913275 | BF33: =BF32+$BD$6 -> 2.9115491 | BG33: =BG32+$BD$7 -> 3.7803758 | BH33: =BH32+$BD$8 -> 4.7491248 | BI33: =BI32+$BD$9 -> 4.9324516 | BN33: =BN32+$BL$6 -> 1.8295534 | BO33: =BO32+$BL$7 -> 2.231907 | BP33: =BP32+$BL$8 -> 2.8887598 | BQ33: =BQ32+$BL$9 -> 2.9908118 | BV33: =BV32+$BT$6 -> 4.0300241 | BW33: =BW32+$BT$7 -> 4.4953918 | BX33: =BX32+$BT$8 -> 6.1316694 | BY33: =BY32+$BT$9 -> 6.3368674
Z34: 2047 | AA34: =AA33+$AB$7 -> 1.300137 | AE34: 2048 | AG34: =AG33+$AD$6 -> 2.6174144 | AH34: =AH33+$AD$7 -> 3.4704924 | AI34: =AI33+$AD$8 -> 4.2967355 | AJ34: =AJ33+$AD$9 -> 4.8238478 | AN34: 2048 | AP34: =AP33+$AM$6 -> 2.4193498 | AQ34: =AQ33+$AM$7 -> 3.2712604 | AR34: =AR33+$AM$8 -> 4.0952843 | AS34: =AS33+$AM$9 -> 4.6224923 | AX34: =AX33+$AV$6 -> 2.5686677 | AY34: =AY33+$AV$7 -> 3.4205536 | AZ34: =AZ33+$AV$8 -> 4.2445635 | BA34: =BA33+$AV$9 -> 4.7717764 | BF34: =BF33+$BD$6 -> 2.8362731 | BG34: =BG33+$BD$7 -> 3.6665742 | BH34: =BH33+$BD$8 -> 4.6320401 | BI34: =BI33+$BD$9 -> 4.8102461 | BN34: =BN33+$BL$6 -> 1.8101096 | BO34: =BO33+$BL$7 -> 2.2122215 | BP34: =BP33+$BL$8 -> 2.866281 | BQ34: =BQ33+$BL$9 -> 2.9669296 | BV34: =BV33+$BT$6 -> 3.9704556 | BW34: =BW33+$BT$7 -> 4.4231055 | BX34: =BX33+$BT$8 -> 6.0617372 | BY34: =BY33+$BT$9 -> 6.2628924
A35: Year 2050 (SSP126, no adaptation, no socio-economic projections) | Z35: 2048 | AA35: =AA34+$AB$7 -> 1.2905843 | AE35: 2049 | AG35: =AG34+$AD$6 -> 2.6550941 | AH35: =AH34+$AD$7 -> 3.5295882 | AI35: =AI34+$AD$8 -> 4.3607455 | AJ35: =AJ34+$AD$9 -> 4.903261 | AN35: 2049 | AP35: =AP34+$AM$6 -> 2.4510618 | AQ35: =AQ34+$AM$7 -> 3.3249722 | AR35: =AR34+$AM$8 -> 4.1550199 | AS35: =AS34+$AM$9 -> 4.6975832 | AX35: =AX34+$AV$6 -> 2.6057207 | AY35: =AY34+$AV$7 -> 3.4796188 | AZ35: =AZ34+$AV$8 -> 4.3096596 | BA35: =BA34+$AV$9 -> 4.8522253 | BF35: =BF34+$BD$6 -> 2.7609971 | BG35: =BG34+$BD$7 -> 3.5527725 | BH35: =BH34+$BD$8 -> 4.5149554 | BI35: =BI34+$BD$9 -> 4.6880405 | BN35: =BN34+$BL$6 -> 1.7906658 | BO35: =BO34+$BL$7 -> 2.192536 | BP35: =BP34+$BL$8 -> 2.8438022 | BQ35: =BQ34+$BL$9 -> 2.9430474 | BV35: =BV34+$BT$6 -> 3.910887 | BW35: =BW34+$BT$7 -> 4.3508191 | BX35: =BX34+$BT$8 -> 5.991805 | BY35: =BY34+$BT$9 -> 6.1889175
Z36: 2049 | AA36: =AA35+$AB$7 -> 1.2810315 | AE36: 2050 | AG36: =C17 -> 2.6927737 | AH36: =C18 -> 3.588684 | AI36: =C19 -> 4.4247556 | AJ36: =C20 -> 4.9826742 | AN36: 2050 | AP36: =E17 -> 2.4827737 | AQ36: =E18 -> 3.378684 | AR36: =E19 -> 4.2147556 | AS36: =E20 -> 4.7726742 | AX36: =G17 -> 2.6427737 | AY36: =G18 -> 3.538684 | AZ36: =G19 -> 4.3747556 | BA36: =G20 -> 4.9326742 | BF36: =K17 -> 2.685721 | BG36: =K18 -> 3.4389708 | BH36: =K19 -> 4.3978708 | BI36: =K20 -> 4.565835 | BN36: =O17 -> 1.7712221 | BO36: =O18 -> 2.1728505 | BP36: =O19 -> 2.8213235 | BQ36: =O20 -> 2.9191653 | BV36: =S17 -> 3.8513185 | BW36: =S18 -> 4.2785328 | BX36: =S19 -> 5.9218729 | BY36: =S20 -> 6.1149425
A37: RP | B37: Housing | D37: Services Sector | F37: Productive Sector | H37: Roads | L37: Schools | P37: Health Centers | Z37: 2050 | AA37: =T21 -> 1.2714787
B38: US$ million | C38: % of total asset value | D38: US$ million | E38: % of total asset value | F38: US$ million | G38: % of total asset value | H38: km | I38: % of asset | J38: US$ million | K38: % of total asset value | L38: Number | M38: % of asset | N38: US$ million | O38: % of total asset value | P38: Number | Q38: % of asset | R38: US$ million | S38: % of total asset value
A39: 10
A40: 25
A41: 100
A42: 200
...

Sheet Drought (national AAL PML)
A2: Baseline period (1981 - 2016) | G2: This mock data is based on Iizumi (2019), covering 1981-2016.
A4: RP | B4: Crop Yield - Maize | D4: Crop Yield - Rice
B5: Production loss* (tonne/ha) | C5: Reduction (% below expected yield) | D5: Production loss* (tonne) | E5: Reduction (% below expected yield)
A6: 2 | B6: 0.12096701 | C6: 0.0224 | D6: 0.0061105529 | E6: 0.0012
A7: 5 | B7: 0.99426736 | C7: 0.16 | D7: 0.26392538 | E7: 0.054
A8: 10 | B8: 1.3261502 | C8: 0.2128 | D8: 0.40643754 | E8: 0.09
A9: 25 | B9: 1.8171128 | C9: 0.2928 | D9: 0.61930518 | E9: 0.1392
A10: AAL | B10: 0.37760392 | C10: 0.061168 | D10: 0.10479582 | E10: 0.022356
B11: *Production based on average expected production of last 5 years
A13: Year 2050 (SSP585, no adaptation, no socio-economic projections)
A15: RP | B15: Crop Yield - Maize | D15: Crop Yield - Rice
B16: Production* (tonne/ha) | C16: Reduction (% below expected yield) | D16: Production* (tonne) | E16: Reduction (% below expected yield)
A17: 2 | B17: =B6*1.5 -> 0.18145052 | C17: =C6*1.5 -> 0.0336 | D17: =D6*1.5 -> 0.0091658294 | E17: =E6*1.5 -> 0.0018
A18: 5 | B18: =B7*1.5 -> 1.491401 | C18: =C7*1.5 -> 0.24 | D18: =D7*1.5 -> 0.39588807 | E18: =E7*1.5 -> 0.081
A19: 10 | B19: =B8*1.5 -> 1.9892253 | C19: =C8*1.5 -> 0.3192 | D19: =D8*1.5 -> 0.6096563 | E19: =E8*1.5 -> 0.135
A20: 25 | B20: =B9*1.5 -> 2.7256692 | C20: =C9*1.5 -> 0.4392 | D20: =D9*1.5 -> 0.92895776 | E20: =E9*1.5 -> 0.2088
A21: AAL | B21: =B10*1.5 -> 0.56640589 | C21: =C10*1.5 -> 0.091752 | D21: =D10*1.5 -> 0.15719373 | E21: =E10*1.5 -> 0.033534
A24: Year 2050 (SSP585, no adaptation, with socio-economic projections)
A26: RP | B26: Crop Yield - Maize | D26: Crop Yield - Rice
B27: Production* (tonne/ha) | C27: Reduction (% below expected yield) | D27: Production* (tonne) | E27: Reduction (% below expected yield)
A28: 2
A29: 5
A30: 10
A31: 25
A32: AAL
A35: Year 2050 (SSP126, no adaptation, no socio-economic projections)
A37: RP | B37: Crop Yield - Maize | D37: Crop Yield - Rice
B38: Production* (tonne/ha) | C38: Reduction (% below expected yield) | D38: Production* (tonne) | E38: Reduction (% below expected yield)
A39: 2
A40: 5
A41: 10
A42: 25
A43: AAL
A46: Year 2050 (SSP126, no adaptation, with socio-economic projections)
A48: RP | B48: Crop Yield - Maize | D48: Crop Yield - Rice
B49: Production* (tonne/ha) | C49: Reduction (% below expected yield) | D49: Production* (tonne) | E49: Reduction (% below expected yield)
A50: 2
A51: 5
A52: 10
A53: 25
...

Sheet Flood Affected Population
B2: Base year | D2: no adaptation | L2: with adaptation
D3: 2050 | L3: 2050
D4: SSP126 | H4: SSP585 | L4: SSP126 | P4: SSP585
D5: no socio-economic projections | F5: with socio-economic projections | H5: no socio-economic projections | J5: with socio-economic projections | L5: no socio-economic projections | N5: with socio-economic projections | P5: no socio-economic projections | R5: with socio-economic projections
B6: Number | C6: % | D6: Number | E6: % | F6: Number | G6: % | H6: Number | I6: % | J6: Number | K6: % | L6: Number | M6: % | N6: Number | O6: % | P6: Number | Q6: % | R6: Number | S6: %
A7: Banteay Meanchey | B7: 1603.3048 | C7: 0.25814779 | H7: 1587.2188 | I7: 0.25555779
A8: Battambang | B8: 3829.8006 | C8: 0.17845105 | H8: 3526.453 | I8: 0.16431645
A9: Kampong Cham | B9: 13205.662 | C9: 3.708988 | H9: 11334.354 | I9: 3.1834058
A10: Kampong Chhnang | B10: 6010.7442 | C10: 2.6125131 | H10: 5464.8481 | I10: 2.3752445
A11: Kampong Speu | B11: 1168.53 | C11: 0.28295297 | H11: 708.50154 | I11: 0.17155966
A12: Kampong Thom | B12: 3687.5133 | C12: 1.0654101 | H12: 4020.015 | I12: 1.1614778
A13: Kampot | B13: 1774.8178 | C13: 0.32590659 | H13: 1819.1327 | I13: 0.33404404
A14: Kandal | B14: 24797.286 | C14: 3.9428558 | H14: 20223.687 | I14: 3.2156373
A15: Koh Kong | B15: 362.29142 | C15: 0.67195987 | H15: 169.38077 | I15: 0.31415891
A16: Kratié | B16: 7171.5451 | C16: 2.8285279 | H16: 6044.065 | I16: 2.3838386
A17: Mondulkiri | B17: 613.94015 | C17: 0.4158601 | H17: 483.55986 | I17: 0.32754536
A18: Phnom Penh | B18: 25853.186 | C18: 1.0373306 | H18: 24103.712 | I18: 0.96713495
... A32: Total | B32: 169237.74 | C32: 1.0387505 | H32: 149981.58 | I32: 0.92055968

Sheet Drought Affected Population
B2: Base year | D2: no adaptation
D3: 2050
D4: SSP126 | H4: SSP585
D5: no socio-economic projections | F5: with socio-economic projections | H5: no socio-economic projections | J5: with socio-economic projections
B6: Number | C6: % | D6: Number | E6: % | F6: Number | G6: % | H6: Number | I6: % | J6: Number | K6: %
A7: Banteay Meanchey
A8: Battambang
A9: Kampong Cham
A10: Kampong Chhnang
A11: Kampong Speu
A12: Kampong Thom
A13: Kampot
A14: Kandal
A15: Koh Kong
A16: Kratié
A17: Mondulkiri
A18: Phnom Penh
... A32: Total

Sheet Flood AAL (admin 1)
B2: Base year | D2: no adaptation | L2: with adaptation
D3: 2050 | L3: 2050
D4: SSP126 | H4: SSP585 | L4: SSP126 | P4: SSP585
D5: no socio-economic projections | F5: with socio-economic projections | H5: no socio-economic projections | J5: with socio-economic projections | L5: no socio-economic projections | N5: with socio-economic projections | P5: no socio-economic projections | R5: with socio-economic projections
B6: Number | C6: % | D6: AAL | E6: % | F6: AAL | G6: % | H6: AAL | I6: % | J6: AAL | K6: % | L6: AAL | M6: % | N6: AAL | O6: % | P6: AAL | Q6: % | R6: AAL | S6: %
A7: Banteay Meanchey
A8: Battambang
A9: Kampong Cham
A10: Kampong Chhnang
A11: Kampong Speu
A12: Kampong Thom
A13: Kampot
A14: Kandal
A15: Koh Kong
A16: Kratié
A17: Mondulkiri
A18: Phnom Penh
... A32: Total

Sheet Drought AAL (admin 1)
B2: Base year | D2: no adaptation
D3: 2050
D4: SSP126 | H4: SSP585
D5: no socio-economic projections | F5: with socio-economic projections | H5: no socio-economic projections | J5: with socio-economic projections
B6: Number | C6: % | D6: AAL | E6: % | F6: AAL | G6: % | H6: AAL | I6: % | J6: AAL | K6: %
A7: Banteay Meanchey
A8: Battambang
A9: Kampong Cham
A10: Kampong Chhnang
A11: Kampong Speu
A12: Kampong Thom
A13: Kampot
A14: Kandal
A15: Koh Kong
A16: Kratié
A17: Mondulkiri
A18: Phnom Penh
... A32: Total
