Workbook

Sheet CGE-Flood Weighted Av Calcs
A1: 2020
A2: sector | B2: AAL | C2: %AAL per sector | D2: total asset value
A3: housing | B3: ='Flood (national AAL PML)'!B10 -> 56.327998 | C3: =(B3/D3)*100 -> 0.94947125 | D3: =('Flood (national AAL PML)'!B10*100)/'Flood (national AAL PML)'!C10 -> 5932.5649 | E3: =D3/$D$11 -> 0.11179526
A4: services | B4: ='Flood (national AAL PML)'!D10 -> 180.32301 | C4: =(B4/D4)*100 -> 0.92626481 | D4: =('Flood (national AAL PML)'!D10*100)/'Flood (national AAL PML)'!E10 -> 19467.76 | E4: =D4/$D$11 -> 0.36685707
A5: productive | B5: ='Flood (national AAL PML)'!F10 -> 216.18826 | C5: =(B5/D5)*100 -> 0.92611724 | D5: =('Flood (national AAL PML)'!F10*100)/'Flood (national AAL PML)'!G10 -> 23343.509 | E5: =D5/$D$11 -> 0.43989299
A6: roads | B6: ='Flood (national AAL PML)'!J10 -> 116.41979 | C6: =(B6/D6)*100 -> 3.2180144 | D6: =('Flood (national AAL PML)'!J10*100)/'Flood (national AAL PML)'!K10 -> 3617.7522 | E6: =D6/$D$11 -> 0.068174148
A7: schools | B7: ='Flood (national AAL PML)'!N10 -> 8.079959 | C7: =(B7/D7)*100 -> 1.3337888 | D7: =('Flood (national AAL PML)'!N10*100)/'Flood (national AAL PML)'!O10 -> 605.79 | E7: =D7/$D$11 -> 0.011415712
A8: health centers | B8: ='Flood (national AAL PML)'!R10 -> 3.1013483 | C8: =(B8/D8)*100 -> 3.133973 | D8: =('Flood (national AAL PML)'!R10*100)/'Flood (national AAL PML)'!S10 -> 98.959 | E8: =D8/$D$11 -> 0.0018648169
C9: =SUMPRODUCT(C3:C8,D3:D8)/SUM(D3:D8) -> 1.0938015
A11: asset value (all sectors) | D11: =SUM(D3:D8) -> 53066.335
A16: 2050
A17: sector | B17: AAL | C17: %AAL per sector | D17: total asset value
A18: housing | B18: ='Flood (national AAL PML)'!B21 -> 75.959706 | C18: =(B18/D18)*100 -> 1.2706848 | D18: =('Flood (national AAL PML)'!B21*100)/'Flood (national AAL PML)'!C21 -> 5977.8557 | E18: =D18/$D$26 -> 0.12051895
A19: services | B19: ='Flood (national AAL PML)'!D21 -> 206.44406 | C19: =(B19/D19)*100 -> 1.0606848 | D19: =('Flood (national AAL PML)'!D21*100)/'Flood (national AAL PML)'!E21 -> 19463.28 | E19: =D19/$D$26 -> 0.39239726
A20: productive | B20: ='Flood (national AAL PML)'!F21 -> 333.53361 | C20: =(B20/D20)*100 -> 1.4306848 | D20: =('Flood (national AAL PML)'!F21*100)/'Flood (national AAL PML)'!G21 -> 23312.864 | E20: =D20/$D$26 -> 0.47000833
A21: roads | B21: ='Flood (national AAL PML)'!J21 -> 6.8610879 | C21: =(B21/D21)*100 -> 1.5065573 | D21: =('Flood (national AAL PML)'!J21*100)/'Flood (national AAL PML)'!K21 -> 455.41501 | E21: =D21/$D$26 -> 0.0091815768
A22: schools | B22: ='Flood (national AAL PML)'!N21 -> 5.8761273 | C22: =(B22/D22)*100 -> 2.0092701 | D22: =('Flood (national AAL PML)'!N21*100)/'Flood (national AAL PML)'!O21 -> 292.45083 | E22: =D22/$D$26 -> 0.0058960722
A23: health centers | B23: ='Flood (national AAL PML)'!R21 -> 1.9910461 | C23: =(B23/D23)*100 -> 2.0092701 | D23: =('Flood (national AAL PML)'!R21*100)/'Flood (national AAL PML)'!S21 -> 99.093 | E23: =D23/$D$26 -> 0.0019978041
C24: =SUMPRODUCT(C18:C23,D18:D23)/SUM(D18:D23) -> 1.2714787
A26: asset value (all sectors) | D26: =SUM(D18:D23) -> 49600.959

Sheet MINDSET-Flood MC
A1: Risk curves corresponding to flood (national AAL PML sheet) for 2020
A2: Housing
A3: Return Period | B3: 1 | C3: 10 | D3: 25 | E3: 100 | F3: 200
A4: Exceedance Probability (1/return period) | B4: =1/B3 -> 1 | C4: =1/C3 -> 0.1 | D4: =1/D3 -> 0.04 | E4: =1/E3 -> 0.01 | F4: =1/F3 -> 0.005
A5: Probable Maximum Losses (US$million) | B5: 0 | C5: 92.69 | D5: 107.72 | E5: 148.58 | F5: 154.26
A6: Probable Maximum Losses (% value) | B6: 0 | C6: ='[1]Flood (national AAL PML)'!$C$6 -> 1.5623834 | D6: ='[1]Flood (national AAL PML)'!$C$7 -> 1.8158097 | E6: 2.5 | F6: 2.6
A8: Services
A9: Return Period | B9: 1 | C9: 10 | D9: 25 | E9: 100 | F9: 200
A10: Exceedance Probability (1/return period) | B10: =1/B9 -> 1 | C10: =1/C9 -> 0.1 | D10: =1/D9 -> 0.04 | E10: =1/E9 -> 0.01 | F10: =1/F9 -> 0.005
A11: Probable Maximum Losses (US$million) | B11: 0 | C11: 298.13222 | D11: 344.05971 | E11: 471.64263 | F11: 490.57679
A12: Probable Maximum Losses (% value) | B12: 0 | C12: 1.5314151 | D12: 1.7673307 | E12: 2.42 | F12: 2.52
A13: % of innundated asset | B13: 0 | C13: 0.25 | D13: 0.29 | E13: 0.33 | F13: 0.34
A14: Innundation duration | B14: 0 | C14: 7 | D14: 8 | E14: 14 | F14: 21
A16: Productive
A17: Return Period | B17: 1 | C17: 10 | D17: 25 | E17: 100 | F17: 200
A18: Exceedance Probability (1/return period) | B18: 1 | C18: 0.1 | D18: 0.04 | E18: 0.01 | F18: 0.005
A19: Probable Maximum Losses (US$million) | B19: 0 | C19: 357.43199 | D19: 412.4164 | E19: 565.35041 | F19: 588.07132
A20: Probable Maximum Losses (% value) | B20: 0 | C20: 1.5311837 | D20: 1.7667284 | E20: 2.4218742 | F20: 2.5192071
A21: % of innundated asset | B21: 0 | C21: 0.29 | D21: 0.35 | E21: 0.39 | F21: 0.4
A23: Roads
A24: Return Period | B24: 1 | C24: 10 | D24: 25 | E24: 100 | F24: 200
A25: Exceedance Probability (1/return period) | B25: 1 | C25: 0.1 | D25: 0.04 | E25: 0.01 | F25: 0.005
A26: Probable Maximum Losses (US$million) | B26: 0 | C26: 19.126417 | D26: 26.511668 | E26: 30.602299 | F26: 31.846409
A27: Probable Maximum Losses (% value) | B27: 0 | C27: 4.9440017 | D27: 6.8530205 | E27: 7.9104108 | F27: 8.2320018
A30: Schools
A31: Return Period | B31: 1 | C31: 10 | D31: 25 | E31: 100 | F31: 200
A32: Exceedance Probability (1/return period) | B32: 1 | C32: 0.1 | D32: 0.04 | E32: 0.01 | F32: 0.005
A33: Probable Maximum Losses (US$million) | B33: 0 | C33: 14.26354 | D33: 16.740495 | E33: 21.176521 | F33: 22.024288
A34: Probable Maximum Losses (% value) | B34: 0 | C34: 2.3545354 | D34: 2.7634156 | E34: 3.4956868 | F34: 3.6356308
A37: Health centers
A38: Return Period | B38: 1 | C38: 10 | D38: 25 | E38: 100 | F38: 200
A39: Exceedance Probability (1/return period) | B39: 1 | C39: 0.1 | D39: 0.04 | E39: 0.01 | F39: 0.005
A40: Probable Maximum Losses (US$million) | B40: 0 | C40: 5.5796796 | D40: 6.380008 | E40: 7.936351 | F40: 8.247432
A41: Probable Maximum Losses | B41: 0 | C41: 5.6383751 | D41: 6.4471226 | E41: 8.0198375 | F41: 8.3341909
A44: Agriculture
A45: Return Period | B45: 1 | C45: 10 | D45: 25 | E45: 100 | F45: 200
A46: Exceedance Probability (1/return period) | B46: 1 | C46: 0.1 | D46: 0.04 | E46: 0.01 | F46: 0.005
A47: Probable Maximum Losses (US$million) | B47: 0 | C47: 144 | D47: 242 | E47: 330 | F47: 540
A50: Simlution results using 2020 estimates
A52: Flood | B52: Probability | C52: Estimated Damages (US$ million) | K52: Estimated Damages (% of asset) | R52: % of asset innundated | T52: Innundation Duration
...

Sheet Flood (national AAL PML)
A2: Base year 2020 (no climate change) | AH2: Housing | AP2: Services | AX2: Productive Sector | BF2: Roads | BN2: Schools | BV2: Health Centers
A4: RP | B4: Housing | D4: Services Sector | F4: Productive Sector | H4: Roads | L4: Schools | P4: Health Centers | T4: Agriculture | AG4: 1 | AH4: =1/AH5 -> 0.1 | AI4: =1/AI5 -> 0.04 | AJ4: =1/AJ5 -> 0.01 | AK4: =1/AK5 -> 0.005 | AP4: 1 | AQ4: =1/AQ5 -> 0.1 | AR4: =1/AR5 -> 0.04 | AS4: =1/AS5 -> 0.01 | AT4: =1/AT5 -> 0.005 | AX4: 1 | AY4: =1/AY5 -> 0.1 | AZ4: =1/AZ5 -> 0.04 | BA4: =1/BA5 -> 0.01 | BB4: =1/BB5 -> 0.005 | BF4: 1 | BG4: =1/BG5 -> 0.1 | BH4: =1/BH5 -> 0.04 | BI4: =1/BI5 -> 0.01 | BJ4: =1/BJ5 -> 0.005 | BN4: 1 | BO4: =1/BO5 -> 0.1 | BP4: =1/BP5 -> 0.04 | BQ4: =1/BQ5 -> 0.01 | BR4: =1/BR5 -> 0.005 | BV4: 1 | BW4: =1/BW5 -> 0.1 | BX4: =1/BX5 -> 0.04 | BY4: =1/BY5 -> 0.01 | BZ4: =1/BZ5 -> 0.005
B5: US$ million | C5: % of total asset value | D5: US$ million | E5: % of total asset value | F5: US$ million | G5: % of total asset value | H5: km | I5: % of asset | J5: US$ million | K5: % of total asset value | L5: Number | M5: % of asset | N5: US$ million | O5: % of total asset value | P5: Number | Q5: % of asset | R5: US$ million | S5: % of total asset value | T5: US$ million | AB5: CGE interpolation | AF5: RP | AG5: 1 | AH5: 10 | AI5: 25 | AJ5: 100 | AK5: 200 | AO5: RP | AP5: 1 | AQ5: 10 | AR5: 25 | AS5: 100 | AT5: 200 | AX5: 1 | AY5: 10 | AZ5: 25 | BA5: 100 | BB5: 200 | BF5: 1 | BG5: 10 | BH5: 25 | BI5: 100 | BJ5: 200 | BN5: 1 | BO5: 10 | BP5: 25 | BQ5: 100 | BR5: 200 | BV5: 1 | BW5: 10 | BX5: 25 | BY5: 100 | BZ5: 200
A6: 10 | B6: 92.689411 | C6: 1.5623834 | D6: 298.13222 | E6: 1.5314151 | F6: 357.43199 | G6: 1.5311837 | H6: 1569.0695 | I6: 3.6248928 | J6: 162.67653 | K6: 4.496619 | L6: 269.1568 | M6: 2.3531807 | N6: 14.26354 | O6: 2.3545354 | P6: 83.906 | Q6: 5.6808396 | R6: 5.5796796 | S6: 5.6383751 | T6: ='MINDSET-Flood MC'!C47 -> 144 | AE6: =(AH36-AH6)/30 -> 0.037679677 | AF6: 2020 | AG6: 0 | AH6: =C6 -> 1.5623834 | AI6: =C7 -> 1.8158097 | AJ6: =C8 -> 2.5044538 | AK6: =C9 -> 2.6002784 | AN6: =($AQ36-$AQ6)/30 -> 0.031711955 | AO6: 2020 | AP6: 0 | AQ6: =E6 -> 1.5314151 | AR6: =E7 -> 1.7673307 | AS6: =E8 -> 2.4226856 | AT6: =E9 -> 2.5199447 | AW6: =(AY36-AY6)/30 -> 0.037053002 | AX6: 0 | AY6: =G6 -> 1.5311837 | AZ6: =G7 -> 1.7667284 | BA6: =G8 -> 2.4218742 | BB6: =G9 -> 2.5192071 | BE6: =(BG36-BG6)/30 -> -0.060363266 | BF6: 0 | BG6: =K6 -> 4.496619 | BH6: =K7 -> 6.1083203 | BI6: =K8 -> 7.1574543 | BJ6: =K9 -> 7.4014819 | BM6: =(BO36-BO6)/30 -> -0.01944378 | BN6: 0 | BO6: =O6 -> 2.3545354 | BP6: =O7 -> 2.7634156 | BQ6: =O8 -> 3.4956868 | BR6: =O9 -> 3.6356308 | BU6: =(BW36-BW6)/30 -> -0.059568554 | BV6: 0 | BW6: =S6 -> 5.6383751 | BX6: =S7 -> 6.4471226 | BY6: =S8 -> 8.0198375 | BZ6: =S9 -> 8.3341909
A7: 25 | B7: 107.72409 | C7: 1.8158097 | D7: 344.05971 | E7: 1.7673307 | F7: 412.4164 | G7: 1.7667284 | H7: 2102.2128 | I7: 4.8565702 | J7: 220.98389 | K7: 6.1083203 | L7: 315.733 | M7: 2.7603865 | N7: 16.740495 | O7: 2.7634156 | P7: 95.926001 | Q7: 6.4946514 | R7: 6.380008 | S7: 6.4471226 | T7: ='MINDSET-Flood MC'!D47 -> 242 | AA7: 2020 | AB7: =U10 -> 1.0938015 | AC7: =(AB37-AB7)/30 -> 0.0059225745 | AE7: =(AI36-AI6)/30 -> 0.059095809 | AF7: 2021 | AG7: 0 | AH7: =AH6+$AE$6 -> 1.6000631 | AI7: =AI6+$AE$7 -> 1.8749055 | AJ7: =AJ6+$AE$8 -> 2.5684639 | AK7: =AK6+$AE$9 -> 2.6796916 | AN7: =(AR36-AR6)/30 -> 0.053711775 | AO7: 2021 | AQ7: =AQ6+$AN$6 -> 1.563127 | AR7: =AR6+$AN$7 -> 1.8210425 | AS7: =AS6+$AN$8 -> 2.4824213 | AT7: =AT6+$AN$9 -> 2.5950357 | AW7: =(AZ36-AZ6)/30 -> 0.059065186 | AY7: =AY6+$AW$6 -> 1.5682367 | AZ7: =AZ6+$AW$7 -> 1.8257936 | BA7: =BA6+$AW$8 -> 2.4869702 | BB7: =BB6+$AW$9 -> 2.599656 | BE7: =(BH36-BH6)/30 -> -0.088978316 | BG7: =BG6+$BE$6 -> 4.4362558 | BH7: =BH6+$BE$7 -> 6.019342 | BI7: =BI6+$BE$8 -> 7.0654682 | BJ7: =BJ6+$BE$9 -> 7.3069603 | BM7: =(BP36-BP6)/30 -> -0.019685502 | BO7: =BO6+$BM$6 -> 2.3350917 | BP7: =BP6+$BM$7 -> 2.7437301 | BQ7: =BQ6+$BM$8 -> 3.473208 | BR7: =BR6+$BM$9 -> 3.6117486 | BU7: =(BX36-BX6)/30 -> -0.072286325 | BW7: =BW6+$BU$6 -> 5.5788065 | BX7: =BX6+$BU$7 -> 6.3748362 | BY7: =BY6+$BU$8 -> 7.9499054 | BZ7: =BZ6+$BU$9 -> 8.260216
A8: 100 | B8: 148.57835 | C8: 2.5044538 | D8: 471.64263 | E8: 2.4226856 | F8: 565.35041 | G8: 2.4218742 | H8: 2478.753 | I8: 5.7264603 | J8: 258.93896 | K8: 7.1574543 | L8: 399.5764 | M8: 3.4934114 | N8: 21.176521 | O8: 3.4956868 | P8: 119.199 | Q8: 8.0703452 | R8: 7.936351 | S8: 8.0198375 | T8: ='MINDSET-Flood MC'!E47 -> 330 | AA8: 2021 | AB8: =AB7+$AC$7 -> 1.0997241 | AE8: =(AJ36-AJ6)/30 -> 0.06401006 | AF8: 2022 | AH8: =AH7+$AE$6 -> 1.6377428 | AI8: =AI7+$AE$7 -> 1.9340013 | AJ8: =AJ7+$AE$8 -> 2.6324739 | AK8: =AK7+$AE$9 -> 2.7591048 | AN8: =(AS36-AS6)/30 -> 0.059735665 | AO8: 2022 | AQ8: =AQ7+$AN$6 -> 1.594839 | AR8: =AR7+$AN$7 -> 1.8747543 | AS8: =AS7+$AN$8 -> 2.542157 | AT8: =AT7+$AN$9 -> 2.6701267 | AW8: =(BA36-BA6)/30 -> 0.065096047 | AY8: =AY7+$AW$6 -> 1.6052897 | AZ8: =AZ7+$AW$7 -> 1.8848588 | BA8: =BA7+$AW$8 -> 2.5520663 | BB8: =BB7+$AW$9 -> 2.6801049 | BE8: =(BI36-BI6)/30 -> -0.091986117 | BG8: =BG7+$BE$6 -> 4.3758925 | BH8: =BH7+$BE$7 -> 5.9303637 | BI8: =BI7+$BE$8 -> 6.973482 | BJ8: =BJ7+$BE$9 -> 7.2124388 | BM8: =(BQ36-BQ6)/30 -> -0.022478778 | BO8: =BO7+$BM$6 -> 2.3156479 | BP8: =BP7+$BM$7 -> 2.7240446 | BQ8: =BQ7+$BM$8 -> 3.4507293 | BR8: =BR7+$BM$9 -> 3.5878665 | BU8: =(BY36-BY6)/30 -> -0.069932154 | BW8: =BW7+$BU$6 -> 5.519238 | BX8: =BX7+$BU$7 -> 6.3025499 | BY8: =BY7+$BU$8 -> 7.8799732 | BZ8: =BZ7+$BU$9 -> 8.1862411
A9: 200 | B9: 154.2632 | C9: 2.6002784 | D9: 490.57679 | E9: 2.5199447 | F9: 588.07132 | G9: 2.5192071 | H9: 2546.5104 | I9: 5.8829946 | J9: 267.76727 | K9: 7.4014819 | L9: 419.1248 | M9: 3.664319 | N9: 22.024288 | O9: 3.6356308 | P9: 122.715 | Q9: 8.3083954 | R9: 8.247432 | S9: 8.3341909 | T9: ='MINDSET-Flood MC'!F47 -> 540 | U9: weighted average (%of damage of total capital in the dataset) | AA9: 2022 | AB9: =AB8+$AC$7 -> 1.1056466 | AE9: =(AK36-AK6)/30 -> 0.079413194 | AF9: 2023 | AH9: =AH8+$AE$6 -> 1.6754225 | AI9: =AI8+$AE$7 -> 1.9930971 | AJ9: =AJ8+$AE$8 -> 2.696484 | AK9: =AK8+$AE$9 -> 2.838518 | AN9: =(AT36-AT6)/30 -> 0.075090983 | AO9: 2023 | AQ9: =AQ8+$AN$6 -> 1.626551 | AR9: =AR8+$AN$7 -> 1.9284661 | AS9: =AS8+$AN$8 -> 2.6018926 | AT9: =AT8+$AN$9 -> 2.7452177 | AW9: =(BB36-BB6)/30 -> 0.080448905 | AY9: =AY8+$AW$6 -> 1.6423427 | AZ9: =AZ8+$AW$7 -> 1.943924 | BA9: =BA8+$AW$8 -> 2.6171623 | BB9: =BB8+$AW$9 -> 2.7605538 | BE9: =(BJ36-BJ6)/30 -> -0.094521565 | BG9: =BG8+$BE$6 -> 4.3155292 | BH9: =BH8+$BE$7 -> 5.8413854 | BI9: =BI8+$BE$8 -> 6.8814959 | BJ9: =BJ8+$BE$9 -> 7.1179172 | BM9: =(BR36-BR6)/30 -> -0.023882186 | BO9: =BO8+$BM$6 -> 2.2962041 | BP9: =BP8+$BM$7 -> 2.7043591 | BQ9: =BQ8+$BM$8 -> 3.4282505 | BR9: =BR8+$BM$9 -> 3.5639843 | BU9: =(BZ36-BZ6)/30 -> -0.073974947 | BW9: =BW8+$BU$6 -> 5.4596694 | BX9: =BX8+$BU$7 -> 6.2302636 | BY9: =BY8+$BU$8 -> 7.8100411 | BZ9: =BZ8+$BU$9 -> 8.1122661
A10: AAL | B10: 56.327998 | C10: 0.94947125 | D10: 180.32301 | E10: 0.92626481 | F10: 216.18826 | G10: 0.92611724 | H10: 1103.5644 | I10: 2.5494745 | J10: 116.41979 | K10: 3.2180144 | L10: 152.44233 | M10: 1.3327708 | N10: 8.079959 | O10: 1.3337888 | P10: 46.613182 | Q10: 3.1559365 | R10: 3.1013483 | S10: 3.133973 | U10: ='CGE-Flood Weighted Av Calcs'!C9 -> 1.0938015 | AA10: 2023 | AB10: =AB9+$AC$7 -> 1.1115692 | AF10: 2024 | AH10: =AH9+$AE$6 -> 1.7131021 | AI10: =AI9+$AE$7 -> 2.0521929 | AJ10: =AJ9+$AE$8 -> 2.7604941 | AK10: =AK9+$AE$9 -> 2.9179312 | AO10: 2024 | AQ10: =AQ9+$AN$6 -> 1.6582629 | AR10: =AR9+$AN$7 -> 1.9821778 | AS10: =AS9+$AN$8 -> 2.6616283 | AT10: =AT9+$AN$9 -> 2.8203086 | AY10: =AY9+$AW$6 -> 1.6793957 | AZ10: =AZ9+$AW$7 -> 2.0029891 | BA10: =BA9+$AW$8 -> 2.6822584 | BB10: =BB9+$AW$9 -> 2.8410027 | BG10: =BG9+$BE$6 -> 4.255166 | BH10: =BH9+$BE$7 -> 5.7524071 | BI10: =BI9+$BE$8 -> 6.7895098 | BJ10: =BJ9+$BE$9 -> 7.0233957 | BO10: =BO9+$BM$6 -> 2.2767603 | BP10: =BP9+$BM$7 -> 2.6846736 | BQ10: =BQ9+$BM$8 -> 3.4057717 | BR10: =BR9+$BM$9 -> 3.5401021 | BW10: =BW9+$BU$6 -> 5.4001009 | BX10: =BX9+$BU$7 -> 6.1579773 | BY10: =BY9+$BU$8 -> 7.7401089 | BZ10: =BZ9+$BU$9 -> 8.0382912
AA11: 2024 | AB11: =AB10+$AC$7 -> 1.1174918 | AF11: 2025 | AH11: =AH10+$AE$6 -> 1.7507818 | AI11: =AI10+$AE$7 -> 2.1112888 | AJ11: =AJ10+$AE$8 -> 2.8245041 | AK11: =AK10+$AE$9 -> 2.9973444 | AO11: 2025 | AQ11: =AQ10+$AN$6 -> 1.6899749 | AR11: =AR10+$AN$7 -> 2.0358896 | AS11: =AS10+$AN$8 -> 2.721364 | AT11: =AT10+$AN$9 -> 2.8953996 | AY11: =AY10+$AW$6 -> 1.7164487 | AZ11: =AZ10+$AW$7 -> 2.0620543 | BA11: =BA10+$AW$8 -> 2.7473544 | BB11: =BB10+$AW$9 -> 2.9214516 | BG11: =BG10+$BE$6 -> 4.1948027 | BH11: =BH10+$BE$7 -> 5.6634287 | BI11: =BI10+$BE$8 -> 6.6975237 | BJ11: =BJ10+$BE$9 -> 6.9288741 | BO11: =BO10+$BM$6 -> 2.2573165 | BP11: =BP10+$BM$7 -> 2.6649881 | BQ11: =BQ10+$BM$8 -> 3.3832929 | BR11: =BR10+$BM$9 -> 3.5162199 | BW11: =BW10+$BU$6 -> 5.3405323 | BX11: =BX10+$BU$7 -> 6.0856909 | BY11: =BY10+$BU$8 -> 7.6701767 | BZ11: =BZ10+$BU$9 -> 7.9643162
AA12: 2025 | AB12: =AB11+$AC$7 -> 1.1234144 | AF12: 2026 | AH12: =AH11+$AE$6 -> 1.7884615 | AI12: =AI11+$AE$7 -> 2.1703846 | AJ12: =AJ11+$AE$8 -> 2.8885142 | AK12: =AK11+$AE$9 -> 3.0767576 | AO12: 2026 | AQ12: =AQ11+$AN$6 -> 1.7216868 | AR12: =AR11+$AN$7 -> 2.0896014 | AS12: =AS11+$AN$8 -> 2.7810996 | AT12: =AT11+$AN$9 -> 2.9704906 | AY12: =AY11+$AW$6 -> 1.7535017 | AZ12: =AZ11+$AW$7 -> 2.1211195 | BA12: =BA11+$AW$8 -> 2.8124505 | BB12: =BB11+$AW$9 -> 3.0019005 | BG12: =BG11+$BE$6 -> 4.1344394 | BH12: =BH11+$BE$7 -> 5.5744504 | BI12: =BI11+$BE$8 -> 6.6055376 | BJ12: =BJ11+$BE$9 -> 6.8343525 | BO12: =BO11+$BM$6 -> 2.2378728 | BP12: =BP11+$BM$7 -> 2.6453026 | BQ12: =BQ11+$BM$8 -> 3.3608141 | BR12: =BR11+$BM$9 -> 3.4923377 | BW12: =BW11+$BU$6 -> 5.2809638 | BX12: =BX11+$BU$7 -> 6.0134046 | BY12: =BY11+$BU$8 -> 7.6002446 | BZ12: =BZ11+$BU$9 -> 7.8903413
A13: Year 2050 (SSP585, no adaptation, no socio-economic projections) | AA13: 2026 | AB13: =AB12+$AC$7 -> 1.1293369 | AF13: 2027 | AH13: =AH12+$AE$6 -> 1.8261412 | AI13: =AI12+$AE$7 -> 2.2294804 | AJ13: =AJ12+$AE$8 -> 2.9525242 | AK13: =AK12+$AE$9 -> 3.1561708 | AO13: 2027 | AQ13: =AQ12+$AN$6 -> 1.7533988 | AR13: =AR12+$AN$7 -> 2.1433132 | AS13: =AS12+$AN$8 -> 2.8408353 | AT13: =AT12+$AN$9 -> 3.0455816 | AY13: =AY12+$AW$6 -> 1.7905547 | AZ13: =AZ12+$AW$7 -> 2.1801847 | BA13: =BA12+$AW$8 -> 2.8775465 | BB13: =BB12+$AW$9 -> 3.0823494 | BG13: =BG12+$BE$6 -> 4.0740762 | BH13: =BH12+$BE$7 -> 5.4854721 | BI13: =BI12+$BE$8 -> 6.5135515 | BJ13: =BJ12+$BE$9 -> 6.739831 | BO13: =BO12+$BM$6 -> 2.218429 | BP13: =BP12+$BM$7 -> 2.6256171 | BQ13: =BQ12+$BM$8 -> 3.3383354 | BR13: =BR12+$BM$9 -> 3.4684555 | BW13: =BW12+$BU$6 -> 5.2213952 | BX13: =BX12+$BU$7 -> 5.9411183 | BY13: =BY12+$BU$8 -> 7.5303124 | BZ13: =BZ12+$BU$9 -> 7.8163663
AA14: 2027 | AB14: =AB13+$AC$7 -> 1.1352595 | AF14: 2028 | AH14: =AH13+$AE$6 -> 1.8638208 | AI14: =AI13+$AE$7 -> 2.2885762 | AJ14: =AJ13+$AE$8 -> 3.0165343 | AK14: =AK13+$AE$9 -> 3.235584 | AO14: 2028 | AQ14: =AQ13+$AN$6 -> 1.7851107 | AR14: =AR13+$AN$7 -> 2.1970249 | AS14: =AS13+$AN$8 -> 2.900571 | AT14: =AT13+$AN$9 -> 3.1206726 | AY14: =AY13+$AW$6 -> 1.8276077 | AZ14: =AZ13+$AW$7 -> 2.2392499 | BA14: =BA13+$AW$8 -> 2.9426426 | BB14: =BB13+$AW$9 -> 3.1627983 | BG14: =BG13+$BE$6 -> 4.0137129 | BH14: =BH13+$BE$7 -> 5.3964938 | BI14: =BI13+$BE$8 -> 6.4215653 | BJ14: =BJ13+$BE$9 -> 6.6453094 | BO14: =BO13+$BM$6 -> 2.1989852 | BP14: =BP13+$BM$7 -> 2.6059316 | BQ14: =BQ13+$BM$8 -> 3.3158566 | BR14: =BR13+$BM$9 -> 3.4445733 | BW14: =BW13+$BU$6 -> 5.1618267 | BX14: =BX13+$BU$7 -> 5.868832 | BY14: =BY13+$BU$8 -> 7.4603803 | BZ14: =BZ13+$BU$9 -> 7.7423914
A15: RP | B15: Housing | D15: Services Sector | F15: Productive Sector | H15: Roads | L15: Schools | P15: Health Centers | AA15: 2028 | AB15: =AB14+$AC$7 -> 1.1411821 | AF15: 2029 | AH15: =AH14+$AE$6 -> 1.9015005 | AI15: =AI14+$AE$7 -> 2.347672 | AJ15: =AJ14+$AE$8 -> 3.0805444 | AK15: =AK14+$AE$9 -> 3.3149971 | AO15: 2029 | AQ15: =AQ14+$AN$6 -> 1.8168227 | AR15: =AR14+$AN$7 -> 2.2507367 | AS15: =AS14+$AN$8 -> 2.9603066 | AT15: =AT14+$AN$9 -> 3.1957636 | AY15: =AY14+$AW$6 -> 1.8646607 | AZ15: =AZ14+$AW$7 -> 2.2983151 | BA15: =BA14+$AW$8 -> 3.0077386 | BB15: =BB14+$AW$9 -> 3.2432472 | BG15: =BG14+$BE$6 -> 3.9533496 | BH15: =BH14+$BE$7 -> 5.3075155 | BI15: =BI14+$BE$8 -> 6.3295792 | BJ15: =BJ14+$BE$9 -> 6.5507878 | BO15: =BO14+$BM$6 -> 2.1795414 | BP15: =BP14+$BM$7 -> 2.5862461 | BQ15: =BQ14+$BM$8 -> 3.2933778 | BR15: =BR14+$BM$9 -> 3.4206912 | BW15: =BW14+$BU$6 -> 5.1022581 | BX15: =BX14+$BU$7 -> 5.7965456 | BY15: =BY14+$BU$8 -> 7.3904481 | BZ15: =BZ14+$BU$9 -> 7.6684164
B16: US$ million | C16: % of total asset value | D16: US$ million | E16: % of total asset value | F16: US$ million | G16: % of total asset value | H16: km | I16: % of asset | J16: US$ million | K16: % of total asset value | L16: Number | M16: % of asset | N16: US$ million | O16: % of total asset value | P16: Number | Q16: % of asset | R16: US$ million | S16: % of total asset value | AA16: 2029 | AB16: =AB15+$AC$7 -> 1.1471047 | AF16: 2030 | AH16: =AH15+$AE$6 -> 1.9391802 | AI16: =AI15+$AE$7 -> 2.4067678 | AJ16: =AJ15+$AE$8 -> 3.1445544 | AK16: =AK15+$AE$9 -> 3.3944103 | AO16: 2030 | AQ16: =AQ15+$AN$6 -> 1.8485346 | AR16: =AR15+$AN$7 -> 2.3044485 | AS16: =AS15+$AN$8 -> 3.0200423 | AT16: =AT15+$AN$9 -> 3.2708545 | AY16: =AY15+$AW$6 -> 1.9017137 | AZ16: =AZ15+$AW$7 -> 2.3573803 | BA16: =BA15+$AW$8 -> 3.0728347 | BB16: =BB15+$AW$9 -> 3.3236961 | BG16: =BG15+$BE$6 -> 3.8929864 | BH16: =BH15+$BE$7 -> 5.2185372 | BI16: =BI15+$BE$8 -> 6.2375931 | BJ16: =BJ15+$BE$9 -> 6.4562663 | BO16: =BO15+$BM$6 -> 2.1600976 | BP16: =BP15+$BM$7 -> 2.5665606 | BQ16: =BQ15+$BM$8 -> 3.270899 | BR16: =BR15+$BM$9 -> 3.396809 | BW16: =BW15+$BU$6 -> 5.0426896 | BX16: =BX15+$BU$7 -> 5.7242593 | BY16: =BY15+$BU$8 -> 7.320516 | BZ16: =BZ15+$BU$9 -> 7.5944415
A17: 10 | B17: 160.97013 | C17: 2.6927737 | D17: 483.22921 | E17: 2.4827737 | F17: 665.06326 | G17: =E17+0.16 -> 2.6427737 | H17: 415.85769 | I17: 2.5957037 | J17: 12.231177 | K17: 2.685721 | L17: 586.5 | M17: 5.1267483 | N17: 10.739274 | O17: 1.7712221 | P17: 85.5 | Q17: 5.7809331 | R17: 3.816387 | S17: 3.8513185 | AA17: 2030 | AB17: =AB16+$AC$7 -> 1.1530272 | AF17: 2031 | AH17: =AH16+$AE$6 -> 1.9768599 | AI17: =AI16+$AE$7 -> 2.4658636 | AJ17: =AJ16+$AE$8 -> 3.2085645 | AK17: =AK16+$AE$9 -> 3.4738235 | AO17: 2031 | AQ17: =AQ16+$AN$6 -> 1.8802466 | AR17: =AR16+$AN$7 -> 2.3581603 | AS17: =AS16+$AN$8 -> 3.079778 | AT17: =AT16+$AN$9 -> 3.3459455 | AY17: =AY16+$AW$6 -> 1.9387667 | AZ17: =AZ16+$AW$7 -> 2.4164455 | BA17: =BA16+$AW$8 -> 3.1379307 | BB17: =BB16+$AW$9 -> 3.404145 | BG17: =BG16+$BE$6 -> 3.8326231 | BH17: =BH16+$BE$7 -> 5.1295588 | BI17: =BI16+$BE$8 -> 6.145607 | BJ17: =BJ16+$BE$9 -> 6.3617447 | BO17: =BO16+$BM$6 -> 2.1406539 | BP17: =BP16+$BM$7 -> 2.5468751 | BQ17: =BQ16+$BM$8 -> 3.2484203 | BR17: =BR16+$BM$9 -> 3.3729268 | BW17: =BW16+$BU$6 -> 4.983121 | BX17: =BX16+$BU$7 -> 5.651973 | BY17: =BY16+$BU$8 -> 7.2505838 | BZ17: =BZ16+$BU$9 -> 7.5204665
A18: 25 | B18: 214.52635 | C18: 3.588684 | D18: 657.60273 | E18: 3.378684 | F18: 873.9256 | G18: =E18+0.16 -> 3.538684 | H18: 528.18554 | I18: 3.2968325 | J18: 15.66159 | K18: 3.4389708 | L18: 735 | M18: 6.4248252 | N18: 13.174427 | O18: 2.1728505 | P18: 102 | Q18: 6.8965517 | R18: 4.2397265 | S18: 4.2785328 | AA18: 2031 | AB18: =AB17+$AC$7 -> 1.1589498 | AF18: 2032 | AH18: =AH17+$AE$6 -> 2.0145395 | AI18: =AI17+$AE$7 -> 2.5249594 | AJ18: =AJ17+$AE$8 -> 3.2725745 | AK18: =AK17+$AE$9 -> 3.5532367 | AO18: 2032 | AQ18: =AQ17+$AN$6 -> 1.9119585 | AR18: =AR17+$AN$7 -> 2.411872 | AS18: =AS17+$AN$8 -> 3.1395136 | AT18: =AT17+$AN$9 -> 3.4210365 | AY18: =AY17+$AW$6 -> 1.9758197 | AZ18: =AZ17+$AW$7 -> 2.4755106 | BA18: =BA17+$AW$8 -> 3.2030267 | BB18: =BB17+$AW$9 -> 3.4845939 | BG18: =BG17+$BE$6 -> 3.7722598 | BH18: =BH17+$BE$7 -> 5.0405805 | BI18: =BI17+$BE$8 -> 6.0536209 | BJ18: =BJ17+$BE$9 -> 6.2672231 | BO18: =BO17+$BM$6 -> 2.1212101 | BP18: =BP17+$BM$7 -> 2.5271896 | BQ18: =BQ17+$BM$8 -> 3.2259415 | BR18: =BR17+$BM$9 -> 3.3490446 | BW18: =BW17+$BU$6 -> 4.9235524 | BX18: =BX17+$BU$7 -> 5.5796867 | BY18: =BY17+$BU$8 -> 7.1806517 | BZ18: =BZ17+$BU$9 -> 7.4464916
A19: 100 | B19: 297.85707 | C19: 4.4247556 | D19: 928.91896 | E19: 4.2147556 | F19: 1198.9046 | G19: =E19+0.16 -> 4.3747556 | H19: 693.53492 | I19: 4.3289116 | J19: 20.028564 | K19: 4.3978708 | L19: 891 | M19: 7.7884615 | N19: 17.106248 | O19: 2.8213235 | P19: 139 | Q19: 9.3982421 | R19: 5.8681615 | S19: 5.9218729 | AA19: 2032 | AB19: =AB18+$AC$7 -> 1.1648724 | AF19: 2033 | AH19: =AH18+$AE$6 -> 2.0522192 | AI19: =AI18+$AE$7 -> 2.5840552 | AJ19: =AJ18+$AE$8 -> 3.3365846 | AK19: =AK18+$AE$9 -> 3.6326499 | AO19: 2033 | AQ19: =AQ18+$AN$6 -> 1.9436705 | AR19: =AR18+$AN$7 -> 2.4655838 | AS19: =AS18+$AN$8 -> 3.1992493 | AT19: =AT18+$AN$9 -> 3.4961275 | AY19: =AY18+$AW$6 -> 2.0128727 | AZ19: =AZ18+$AW$7 -> 2.5345758 | BA19: =BA18+$AW$8 -> 3.2681228 | BB19: =BB18+$AW$9 -> 3.5650428 | BG19: =BG18+$BE$6 -> 3.7118966 | BH19: =BH18+$BE$7 -> 4.9516022 | BI19: =BI18+$BE$8 -> 5.9616348 | BJ19: =BJ18+$BE$9 -> 6.1727016 | BO19: =BO18+$BM$6 -> 2.1017663 | BP19: =BP18+$BM$7 -> 2.5075041 | BQ19: =BQ18+$BM$8 -> 3.2034627 | BR19: =BR18+$BM$9 -> 3.3251624 | BW19: =BW18+$BU$6 -> 4.8639839 | BX19: =BX18+$BU$7 -> 5.5074003 | BY19: =BY18+$BU$8 -> 7.1107195 | BZ19: =BZ18+$BU$9 -> 7.3725166
A20: 200 | B20: 314.01284 | C20: 4.9826742 | D20: 981.52046 | E20: 4.7726742 | F20: 1261.91 | G20: =E20+0.16 -> 4.9326742 | H20: 714.04189 | I20: 4.4569121 | J20: 20.793498 | K20: 4.565835 | L20: 924.5 | M20: 8.0812937 | N20: 17.699483 | O20: 2.9191653 | P20: 144.5 | Q20: 9.7701149 | R20: 6.05948 | S20: 6.1149425 | U20: weighted average | AA20: 2033 | AB20: =AB19+$AC$7 -> 1.170795 | AF20: 2034 | AH20: =AH19+$AE$6 -> 2.0898989 | AI20: =AI19+$AE$7 -> 2.643151 | AJ20: =AJ19+$AE$8 -> 3.4005946 | AK20: =AK19+$AE$9 -> 3.7120631 | AO20: 2034 | AQ20: =AQ19+$AN$6 -> 1.9753825 | AR20: =AR19+$AN$7 -> 2.5192956 | AS20: =AS19+$AN$8 -> 3.258985 | AT20: =AT19+$AN$9 -> 3.5712185 | AY20: =AY19+$AW$6 -> 2.0499257 | AZ20: =AZ19+$AW$7 -> 2.593641 | BA20: =BA19+$AW$8 -> 3.3332188 | BB20: =BB19+$AW$9 -> 3.6454917 | BG20: =BG19+$BE$6 -> 3.6515333 | BH20: =BH19+$BE$7 -> 4.8626239 | BI20: =BI19+$BE$8 -> 5.8696486 | BJ20: =BJ19+$BE$9 -> 6.07818 | BO20: =BO19+$BM$6 -> 2.0823225 | BP20: =BP19+$BM$7 -> 2.4878186 | BQ20: =BQ19+$BM$8 -> 3.1809839 | BR20: =BR19+$BM$9 -> 3.3012802 | BW20: =BW19+$BU$6 -> 4.8044153 | BX20: =BX19+$BU$7 -> 5.435114 | BY20: =BY19+$BU$8 -> 7.0407874 | BZ20: =BZ19+$BU$9 -> 7.2985417
A21: AAL | B21: 75.959706 | C21: 1.2706848 | D21: 206.44406 | E21: 1.0606848 | F21: 333.53361 | G21: 1.4306848 | H21: 236.06882 | I21: 1.4734962 | J21: 6.8610879 | K21: 1.5065573 | L21: 321.53483 | M21: 2.8106192 | N21: 5.8761273 | O21: 2.0092701 | P21: 48 | Q21: 3.2672865 | R21: 1.9910461 | S21: 2.0092701 | U21: ='CGE-Flood Weighted Av Calcs'!C24 -> 1.2714787 | AA21: 2034 | AB21: =AB20+$AC$7 -> 1.1767175 | AF21: 2035 | AH21: =AH20+$AE$6 -> 2.1275786 | AI21: =AI20+$AE$7 -> 2.7022468 | AJ21: =AJ20+$AE$8 -> 3.4646047 | AK21: =AK20+$AE$9 -> 3.7914763 | AO21: 2035 | AQ21: =AQ20+$AN$6 -> 2.0070944 | AR21: =AR20+$AN$7 -> 2.5730074 | AS21: =AS20+$AN$8 -> 3.3187206 | AT21: =AT20+$AN$9 -> 3.6463095 | AY21: =AY20+$AW$6 -> 2.0869787 | AZ21: =AZ20+$AW$7 -> 2.6527062 | BA21: =BA20+$AW$8 -> 3.3983149 | BB21: =BB20+$AW$9 -> 3.7259406 | BG21: =BG20+$BE$6 -> 3.59117 | BH21: =BH20+$BE$7 -> 4.7736456 | BI21: =BI20+$BE$8 -> 5.7776625 | BJ21: =BJ20+$BE$9 -> 5.9836584 | BO21: =BO20+$BM$6 -> 2.0628787 | BP21: =BP20+$BM$7 -> 2.4681331 | BQ21: =BQ20+$BM$8 -> 3.1585051 | BR21: =BR20+$BM$9 -> 3.277398 | BW21: =BW20+$BU$6 -> 4.7448468 | BX21: =BX20+$BU$7 -> 5.3628277 | BY21: =BY20+$BU$8 -> 6.9708552 | BZ21: =BZ20+$BU$9 -> 7.2245667
AA22: 2035 | AB22: =AB21+$AC$7 -> 1.1826401 | AF22: 2036 | AH22: =AH21+$AE$6 -> 2.1652583 | AI22: =AI21+$AE$7 -> 2.7613427 | AJ22: =AJ21+$AE$8 -> 3.5286148 | AK22: =AK21+$AE$9 -> 3.8708895 | AO22: 2036 | AQ22: =AQ21+$AN$6 -> 2.0388064 | AR22: =AR21+$AN$7 -> 2.6267191 | AS22: =AS21+$AN$8 -> 3.3784563 | AT22: =AT21+$AN$9 -> 3.7214004 | AY22: =AY21+$AW$6 -> 2.1240317 | AZ22: =AZ21+$AW$7 -> 2.7117714 | BA22: =BA21+$AW$8 -> 3.4634109 | BB22: =BB21+$AW$9 -> 3.8063895 | BG22: =BG21+$BE$6 -> 3.5308068 | BH22: =BH21+$BE$7 -> 4.6846673 | BI22: =BI21+$BE$8 -> 5.6856764 | BJ22: =BJ21+$BE$9 -> 5.8891369 | BO22: =BO21+$BM$6 -> 2.043435 | BP22: =BP21+$BM$7 -> 2.4484476 | BQ22: =BQ21+$BM$8 -> 3.1360264 | BR22: =BR21+$BM$9 -> 3.2535159 | BW22: =BW21+$BU$6 -> 4.6852782 | BX22: =BX21+$BU$7 -> 5.2905414 | BY22: =BY21+$BU$8 -> 6.9009231 | BZ22: =BZ21+$BU$9 -> 7.1505918
AA23: 2036 | AB23: =AB22+$AC$7 -> 1.1885627 | AF23: 2037 | AH23: =AH22+$AE$6 -> 2.2029379 | AI23: =AI22+$AE$7 -> 2.8204385 | AJ23: =AJ22+$AE$8 -> 3.5926248 | AK23: =AK22+$AE$9 -> 3.9503027 | AO23: 2037 | AQ23: =AQ22+$AN$6 -> 2.0705183 | AR23: =AR22+$AN$7 -> 2.6804309 | AS23: =AS22+$AN$8 -> 3.4381919 | AT23: =AT22+$AN$9 -> 3.7964914 | AY23: =AY22+$AW$6 -> 2.1610847 | AZ23: =AZ22+$AW$7 -> 2.7708366 | BA23: =BA22+$AW$8 -> 3.528507 | BB23: =BB22+$AW$9 -> 3.8868385 | BG23: =BG22+$BE$6 -> 3.4704435 | BH23: =BH22+$BE$7 -> 4.5956889 | BI23: =BI22+$BE$8 -> 5.5936903 | BJ23: =BJ22+$BE$9 -> 5.7946153 | BO23: =BO22+$BM$6 -> 2.0239912 | BP23: =BP22+$BM$7 -> 2.4287621 | BQ23: =BQ22+$BM$8 -> 3.1135476 | BR23: =BR22+$BM$9 -> 3.2296337 | BW23: =BW22+$BU$6 -> 4.6257097 | BX23: =BX22+$BU$7 -> 5.218255 | BY23: =BY22+$BU$8 -> 6.8309909 | BZ23: =BZ22+$BU$9 -> 7.0766168
A24: Year 2050 (SSP585, no adaptation, with socio-economic projections) | AA24: 2037 | AB24: =AB23+$AC$7 -> 1.1944853 | AF24: 2038 | AH24: =AH23+$AE$6 -> 2.2406176 | AI24: =AI23+$AE$7 -> 2.8795343 | AJ24: =AJ23+$AE$8 -> 3.6566349 | AK24: =AK23+$AE$9 -> 4.0297159 | AO24: 2038 | AQ24: =AQ23+$AN$6 -> 2.1022303 | AR24: =AR23+$AN$7 -> 2.7341427 | AS24: =AS23+$AN$8 -> 3.4979276 | AT24: =AT23+$AN$9 -> 3.8715824 | AY24: =AY23+$AW$6 -> 2.1981377 | AZ24: =AZ23+$AW$7 -> 2.8299018 | BA24: =BA23+$AW$8 -> 3.593603 | BB24: =BB23+$AW$9 -> 3.9672874 | BG24: =BG23+$BE$6 -> 3.4100802 | BH24: =BH23+$BE$7 -> 4.5067106 | BI24: =BI23+$BE$8 -> 5.5017042 | BJ24: =BJ23+$BE$9 -> 5.7000937 | BO24: =BO23+$BM$6 -> 2.0045474 | BP24: =BP23+$BM$7 -> 2.4090766 | BQ24: =BQ23+$BM$8 -> 3.0910688 | BR24: =BR23+$BM$9 -> 3.2057515 | BW24: =BW23+$BU$6 -> 4.5661411 | BX24: =BX23+$BU$7 -> 5.1459687 | BY24: =BY23+$BU$8 -> 6.7610587 | BZ24: =BZ23+$BU$9 -> 7.0026419
AA25: 2038 | AB25: =AB24+$AC$7 -> 1.2004078 | AF25: 2039 | AH25: =AH24+$AE$6 -> 2.2782973 | AI25: =AI24+$AE$7 -> 2.9386301 | AJ25: =AJ24+$AE$8 -> 3.7206449 | AK25: =AK24+$AE$9 -> 4.1091291 | AO25: 2039 | AQ25: =AQ24+$AN$6 -> 2.1339422 | AR25: =AR24+$AN$7 -> 2.7878545 | AS25: =AS24+$AN$8 -> 3.5576633 | AT25: =AT24+$AN$9 -> 3.9466734 | AY25: =AY24+$AW$6 -> 2.2351907 | AZ25: =AZ24+$AW$7 -> 2.8889669 | BA25: =BA24+$AW$8 -> 3.6586991 | BB25: =BB24+$AW$9 -> 4.0477363 | BG25: =BG24+$BE$6 -> 3.349717 | BH25: =BH24+$BE$7 -> 4.4177323 | BI25: =BI24+$BE$8 -> 5.4097181 | BJ25: =BJ24+$BE$9 -> 5.6055722 | BO25: =BO24+$BM$6 -> 1.9851036 | BP25: =BP24+$BM$7 -> 2.3893911 | BQ25: =BQ24+$BM$8 -> 3.06859 | BR25: =BR24+$BM$9 -> 3.1818693 | BW25: =BW24+$BU$6 -> 4.5065726 | BX25: =BX24+$BU$7 -> 5.0736824 | BY25: =BY24+$BU$8 -> 6.6911266 | BZ25: =BZ24+$BU$9 -> 6.928667
A26: RP | B26: Housing | D26: Services Sector | F26: Productive Sector | H26: Roads | L26: Schools | P26: Health Centers | AA26: 2039 | AB26: =AB25+$AC$7 -> 1.2063304 | AF26: 2040 | AH26: =AH25+$AE$6 -> 2.315977 | AI26: =AI25+$AE$7 -> 2.9977259 | AJ26: =AJ25+$AE$8 -> 3.784655 | AK26: =AK25+$AE$9 -> 4.1885423 | AO26: 2040 | AQ26: =AQ25+$AN$6 -> 2.1656542 | AR26: =AR25+$AN$7 -> 2.8415662 | AS26: =AS25+$AN$8 -> 3.6173989 | AT26: =AT25+$AN$9 -> 4.0217644 | AY26: =AY25+$AW$6 -> 2.2722437 | AZ26: =AZ25+$AW$7 -> 2.9480321 | BA26: =BA25+$AW$8 -> 3.7237951 | BB26: =BB25+$AW$9 -> 4.1281852 | BG26: =BG25+$BE$6 -> 3.2893537 | BH26: =BH25+$BE$7 -> 4.328754 | BI26: =BI25+$BE$8 -> 5.3177319 | BJ26: =BJ25+$BE$9 -> 5.5110506 | BO26: =BO25+$BM$6 -> 1.9656598 | BP26: =BP25+$BM$7 -> 2.3697056 | BQ26: =BQ25+$BM$8 -> 3.0461113 | BR26: =BR25+$BM$9 -> 3.1579871 | BW26: =BW25+$BU$6 -> 4.447004 | BX26: =BX25+$BU$7 -> 5.0013961 | BY26: =BY25+$BU$8 -> 6.6211944 | BZ26: =BZ25+$BU$9 -> 6.854692
B27: US$ million | C27: % of total asset value | D27: US$ million | E27: % of total asset value | F27: US$ million | G27: % of total asset value | H27: km | I27: % of asset | J27: US$ million | K27: % of total asset value | L27: Number | M27: % of asset | N27: US$ million | O27: % of total asset value | P27: Number | Q27: % of asset | R27: US$ million | S27: % of total asset value | AA27: 2040 | AB27: =AB26+$AC$7 -> 1.212253 | AF27: 2041 | AH27: =AH26+$AE$6 -> 2.3536566 | AI27: =AI26+$AE$7 -> 3.0568217 | AJ27: =AJ26+$AE$8 -> 3.8486651 | AK27: =AK26+$AE$9 -> 4.2679555 | AO27: 2041 | AQ27: =AQ26+$AN$6 -> 2.1973661 | AR27: =AR26+$AN$7 -> 2.895278 | AS27: =AS26+$AN$8 -> 3.6771346 | AT27: =AT26+$AN$9 -> 4.0968554 | AY27: =AY26+$AW$6 -> 2.3092967 | AZ27: =AZ26+$AW$7 -> 3.0070973 | BA27: =BA26+$AW$8 -> 3.7888912 | BB27: =BB26+$AW$9 -> 4.2086341 | BG27: =BG26+$BE$6 -> 3.2289904 | BH27: =BH26+$BE$7 -> 4.2397757 | BI27: =BI26+$BE$8 -> 5.2257458 | BJ27: =BJ26+$BE$9 -> 5.416529 | BO27: =BO26+$BM$6 -> 1.9462161 | BP27: =BP26+$BM$7 -> 2.3500201 | BQ27: =BQ26+$BM$8 -> 3.0236325 | BR27: =BR26+$BM$9 -> 3.1341049 | BW27: =BW26+$BU$6 -> 4.3874355 | BX27: =BX26+$BU$7 -> 4.9291097 | BY27: =BY26+$BU$8 -> 6.5512623 | BZ27: =BZ26+$BU$9 -> 6.7807171
A28: 10 | AA28: 2041 | AB28: =AB27+$AC$7 -> 1.2181756 | AF28: 2042 | AH28: =AH27+$AE$6 -> 2.3913363 | AI28: =AI27+$AE$7 -> 3.1159175 | AJ28: =AJ27+$AE$8 -> 3.9126751 | AK28: =AK27+$AE$9 -> 4.3473687 | AO28: 2042 | AQ28: =AQ27+$AN$6 -> 2.2290781 | AR28: =AR27+$AN$7 -> 2.9489898 | AS28: =AS27+$AN$8 -> 3.7368703 | AT28: =AT27+$AN$9 -> 4.1719463 | AY28: =AY27+$AW$6 -> 2.3463497 | AZ28: =AZ27+$AW$7 -> 3.0661625 | BA28: =BA27+$AW$8 -> 3.8539872 | BB28: =BB27+$AW$9 -> 4.289083 | BG28: =BG27+$BE$6 -> 3.1686272 | BH28: =BH27+$BE$7 -> 4.1507974 | BI28: =BI27+$BE$8 -> 5.1337597 | BJ28: =BJ27+$BE$9 -> 5.3220075 | BO28: =BO27+$BM$6 -> 1.9267723 | BP28: =BP27+$BM$7 -> 2.3303346 | BQ28: =BQ27+$BM$8 -> 3.0011537 | BR28: =BR27+$BM$9 -> 3.1102227 | BW28: =BW27+$BU$6 -> 4.3278669 | BX28: =BX27+$BU$7 -> 4.8568234 | BY28: =BY27+$BU$8 -> 6.4813301 | BZ28: =BZ27+$BU$9 -> 6.7067421
A29: 25 | AA29: 2042 | AB29: =AB28+$AC$7 -> 1.2240981 | AF29: 2043 | AH29: =AH28+$AE$6 -> 2.429016 | AI29: =AI28+$AE$7 -> 3.1750133 | AJ29: =AJ28+$AE$8 -> 3.9766852 | AK29: =AK28+$AE$9 -> 4.4267819 | AO29: 2043 | AQ29: =AQ28+$AN$6 -> 2.26079 | AR29: =AR28+$AN$7 -> 3.0027016 | AS29: =AS28+$AN$8 -> 3.7966059 | AT29: =AT28+$AN$9 -> 4.2470373 | AY29: =AY28+$AW$6 -> 2.3834027 | AZ29: =AZ28+$AW$7 -> 3.1252277 | BA29: =BA28+$AW$8 -> 3.9190833 | BB29: =BB28+$AW$9 -> 4.3695319 | BG29: =BG28+$BE$6 -> 3.1082639 | BH29: =BH28+$BE$7 -> 4.0618191 | BI29: =BI28+$BE$8 -> 5.0417736 | BJ29: =BJ28+$BE$9 -> 5.2274859 | BO29: =BO28+$BM$6 -> 1.9073285 | BP29: =BP28+$BM$7 -> 2.3106491 | BQ29: =BQ28+$BM$8 -> 2.9786749 | BR29: =BR28+$BM$9 -> 3.0863406 | BW29: =BW28+$BU$6 -> 4.2682983 | BX29: =BX28+$BU$7 -> 4.7845371 | BY29: =BY28+$BU$8 -> 6.411398 | BZ29: =BZ28+$BU$9 -> 6.6327672
A30: 100 | AA30: 2043 | AB30: =AB29+$AC$7 -> 1.2300207 | AF30: 2044 | AH30: =AH29+$AE$6 -> 2.4666957 | AI30: =AI29+$AE$7 -> 3.2341091 | AJ30: =AJ29+$AE$8 -> 4.0406952 | AK30: =AK29+$AE$9 -> 4.5061951 | AO30: 2044 | AQ30: =AQ29+$AN$6 -> 2.292502 | AR30: =AR29+$AN$7 -> 3.0564133 | AS30: =AS29+$AN$8 -> 3.8563416 | AT30: =AT29+$AN$9 -> 4.3221283 | AY30: =AY29+$AW$6 -> 2.4204557 | AZ30: =AZ29+$AW$7 -> 3.1842929 | BA30: =BA29+$AW$8 -> 3.9841793 | BB30: =BB29+$AW$9 -> 4.4499808 | BG30: =BG29+$BE$6 -> 3.0479006 | BH30: =BH29+$BE$7 -> 3.9728407 | BI30: =BI29+$BE$8 -> 4.9497875 | BJ30: =BJ29+$BE$9 -> 5.1329644 | BO30: =BO29+$BM$6 -> 1.8878847 | BP30: =BP29+$BM$7 -> 2.2909636 | BQ30: =BQ29+$BM$8 -> 2.9561961 | BR30: =BR29+$BM$9 -> 3.0624584 | BW30: =BW29+$BU$6 -> 4.2087298 | BX30: =BX29+$BU$7 -> 4.7122508 | BY30: =BY29+$BU$8 -> 6.3414658 | BZ30: =BZ29+$BU$9 -> 6.5587922
A31: 200 | AA31: 2044 | AB31: =AB30+$AC$7 -> 1.2359433 | AF31: 2045 | AH31: =AH30+$AE$6 -> 2.5043753 | AI31: =AI30+$AE$7 -> 3.2932049 | AJ31: =AJ30+$AE$8 -> 4.1047053 | AK31: =AK30+$AE$9 -> 4.5856082 | AO31: 2045 | AQ31: =AQ30+$AN$6 -> 2.324214 | AR31: =AR30+$AN$7 -> 3.1101251 | AS31: =AS30+$AN$8 -> 3.9160773 | AT31: =AT30+$AN$9 -> 4.3972193 | AY31: =AY30+$AW$6 -> 2.4575087 | AZ31: =AZ30+$AW$7 -> 3.2433581 | BA31: =BA30+$AW$8 -> 4.0492754 | BB31: =BB30+$AW$9 -> 4.5304297 | BG31: =BG30+$BE$6 -> 2.9875374 | BH31: =BH30+$BE$7 -> 3.8838624 | BI31: =BI30+$BE$8 -> 4.8578014 | BJ31: =BJ30+$BE$9 -> 5.0384428 | BO31: =BO30+$BM$6 -> 1.8684409 | BP31: =BP30+$BM$7 -> 2.271278 | BQ31: =BQ30+$BM$8 -> 2.9337174 | BR31: =BR30+$BM$9 -> 3.0385762 | BW31: =BW30+$BU$6 -> 4.1491612 | BX31: =BX30+$BU$7 -> 4.6399644 | BY31: =BY30+$BU$8 -> 6.2715337 | BZ31: =BZ30+$BU$9 -> 6.4848173
A32: AAL | AA32: 2045 | AB32: =AB31+$AC$7 -> 1.2418659 | AF32: 2046 | AH32: =AH31+$AE$6 -> 2.542055 | AI32: =AI31+$AE$7 -> 3.3523007 | AJ32: =AJ31+$AE$8 -> 4.1687154 | AK32: =AK31+$AE$9 -> 4.6650214 | AO32: 2046 | AQ32: =AQ31+$AN$6 -> 2.3559259 | AR32: =AR31+$AN$7 -> 3.1638369 | AS32: =AS31+$AN$8 -> 3.9758129 | AT32: =AT31+$AN$9 -> 4.4723103 | AY32: =AY31+$AW$6 -> 2.4945617 | AZ32: =AZ31+$AW$7 -> 3.3024232 | BA32: =BA31+$AW$8 -> 4.1143714 | BB32: =BB31+$AW$9 -> 4.6108786 | BG32: =BG31+$BE$6 -> 2.9271741 | BH32: =BH31+$BE$7 -> 3.7948841 | BI32: =BI31+$BE$8 -> 4.7658152 | BJ32: =BJ31+$BE$9 -> 4.9439212 | BO32: =BO31+$BM$6 -> 1.8489972 | BP32: =BP31+$BM$7 -> 2.2515925 | BQ32: =BQ31+$BM$8 -> 2.9112386 | BR32: =BR31+$BM$9 -> 3.014694 | BW32: =BW31+$BU$6 -> 4.0895927 | BX32: =BX31+$BU$7 -> 4.5676781 | BY32: =BY31+$BU$8 -> 6.2016015 | BZ32: =BZ31+$BU$9 -> 6.4108423
AA33: 2046 | AB33: =AB32+$AC$7 -> 1.2477884 | AF33: 2047 | AH33: =AH32+$AE$6 -> 2.5797347 | AI33: =AI32+$AE$7 -> 3.4113966 | AJ33: =AJ32+$AE$8 -> 4.2327254 | AK33: =AK32+$AE$9 -> 4.7444346 | AO33: 2047 | AQ33: =AQ32+$AN$6 -> 2.3876379 | AR33: =AR32+$AN$7 -> 3.2175487 | AS33: =AS32+$AN$8 -> 4.0355486 | AT33: =AT32+$AN$9 -> 4.5474013 | AY33: =AY32+$AW$6 -> 2.5316147 | AZ33: =AZ32+$AW$7 -> 3.3614884 | BA33: =BA32+$AW$8 -> 4.1794675 | BB33: =BB32+$AW$9 -> 4.6913275 | BG33: =BG32+$BE$6 -> 2.8668108 | BH33: =BH32+$BE$7 -> 3.7059058 | BI33: =BI32+$BE$8 -> 4.6738291 | BJ33: =BJ32+$BE$9 -> 4.8493997 | BO33: =BO32+$BM$6 -> 1.8295534 | BP33: =BP32+$BM$7 -> 2.231907 | BQ33: =BQ32+$BM$8 -> 2.8887598 | BR33: =BR32+$BM$9 -> 2.9908118 | BW33: =BW32+$BU$6 -> 4.0300241 | BX33: =BX32+$BU$7 -> 4.4953918 | BY33: =BY32+$BU$8 -> 6.1316694 | BZ33: =BZ32+$BU$9 -> 6.3368674
AA34: 2047 | AB34: =AB33+$AC$7 -> 1.253711 | AF34: 2048 | AH34: =AH33+$AE$6 -> 2.6174144 | AI34: =AI33+$AE$7 -> 3.4704924 | AJ34: =AJ33+$AE$8 -> 4.2967355 | AK34: =AK33+$AE$9 -> 4.8238478 | AO34: 2048 | AQ34: =AQ33+$AN$6 -> 2.4193498 | AR34: =AR33+$AN$7 -> 3.2712604 | AS34: =AS33+$AN$8 -> 4.0952843 | AT34: =AT33+$AN$9 -> 4.6224923 | AY34: =AY33+$AW$6 -> 2.5686677 | AZ34: =AZ33+$AW$7 -> 3.4205536 | BA34: =BA33+$AW$8 -> 4.2445635 | BB34: =BB33+$AW$9 -> 4.7717764 | BG34: =BG33+$BE$6 -> 2.8064476 | BH34: =BH33+$BE$7 -> 3.6169275 | BI34: =BI33+$BE$8 -> 4.581843 | BJ34: =BJ33+$BE$9 -> 4.7548781 | BO34: =BO33+$BM$6 -> 1.8101096 | BP34: =BP33+$BM$7 -> 2.2122215 | BQ34: =BQ33+$BM$8 -> 2.866281 | BR34: =BR33+$BM$9 -> 2.9669296 | BW34: =BW33+$BU$6 -> 3.9704556 | BX34: =BX33+$BU$7 -> 4.4231055 | BY34: =BY33+$BU$8 -> 6.0617372 | BZ34: =BZ33+$BU$9 -> 6.2628924
A35: Year 2050 (SSP126, no adaptation, no socio-economic projections) | AA35: 2048 | AB35: =AB34+$AC$7 -> 1.2596336 | AF35: 2049 | AH35: =AH34+$AE$6 -> 2.6550941 | AI35: =AI34+$AE$7 -> 3.5295882 | AJ35: =AJ34+$AE$8 -> 4.3607455 | AK35: =AK34+$AE$9 -> 4.903261 | AO35: 2049 | AQ35: =AQ34+$AN$6 -> 2.4510618 | AR35: =AR34+$AN$7 -> 3.3249722 | AS35: =AS34+$AN$8 -> 4.1550199 | AT35: =AT34+$AN$9 -> 4.6975832 | AY35: =AY34+$AW$6 -> 2.6057207 | AZ35: =AZ34+$AW$7 -> 3.4796188 | BA35: =BA34+$AW$8 -> 4.3096596 | BB35: =BB34+$AW$9 -> 4.8522253 | BG35: =BG34+$BE$6 -> 2.7460843 | BH35: =BH34+$BE$7 -> 3.5279492 | BI35: =BI34+$BE$8 -> 4.4898569 | BJ35: =BJ34+$BE$9 -> 4.6603565 | BO35: =BO34+$BM$6 -> 1.7906658 | BP35: =BP34+$BM$7 -> 2.192536 | BQ35: =BQ34+$BM$8 -> 2.8438022 | BR35: =BR34+$BM$9 -> 2.9430474 | BW35: =BW34+$BU$6 -> 3.910887 | BX35: =BX34+$BU$7 -> 4.3508191 | BY35: =BY34+$BU$8 -> 5.991805 | BZ35: =BZ34+$BU$9 -> 6.1889175
AA36: 2049 | AB36: =AB35+$AC$7 -> 1.2655562 | AF36: 2050 | AH36: =C17 -> 2.6927737 | AI36: =C18 -> 3.588684 | AJ36: =C19 -> 4.4247556 | AK36: =C20 -> 4.9826742 | AO36: 2050 | AQ36: =E17 -> 2.4827737 | AR36: =E18 -> 3.378684 | AS36: =E19 -> 4.2147556 | AT36: =E20 -> 4.7726742 | AY36: =G17 -> 2.6427737 | AZ36: =G18 -> 3.538684 | BA36: =G19 -> 4.3747556 | BB36: =G20 -> 4.9326742 | BG36: =K17 -> 2.685721 | BH36: =K18 -> 3.4389708 | BI36: =K19 -> 4.3978708 | BJ36: =K20 -> 4.565835 | BO36: =O17 -> 1.7712221 | BP36: =O18 -> 2.1728505 | BQ36: =O19 -> 2.8213235 | BR36: =O20 -> 2.9191653 | BW36: =S17 -> 3.8513185 | BX36: =S18 -> 4.2785328 | BY36: =S19 -> 5.9218729 | BZ36: =S20 -> 6.1149425
A37: RP | B37: Housing | D37: Services Sector | F37: Productive Sector | H37: Roads | L37: Schools | P37: Health Centers | AA37: 2050 | AB37: =U21 -> 1.2714787
B38: US$ million | C38: % of total asset value | D38: US$ million | E38: % of total asset value | F38: US$ million | G38: % of total asset value | H38: km | I38: % of asset | J38: US$ million | K38: % of total asset value | L38: Number | M38: % of asset | N38: US$ million | O38: % of total asset value | P38: Number | Q38: % of asset | R38: US$ million | S38: % of total asset value
A39: 10
A40: 25
A41: 100
A42: 200
...

Sheet Drought (national AAL PML)
A2: Baseline period (1981 - 2016) | G2: This mock data is based on Iizumi (2019), covering 1981-2016.
A4: RP | B4: Crop Yield - Maize | D4: Crop Yield - Rice
B5: Production loss* (tonne/ha) | C5: Reduction (% below expected yield) | D5: Production loss* (tonne) | E5: Reduction (% below expected yield)
A6: 2 | B6: 0.12096701 | C6: 0.0224 | D6: 0.0061105529 | E6: 0.0012
A7: 5 | B7: 0.99426736 | C7: 0.16 | D7: 0.26392538 | E7: 0.054
A8: 10 | B8: 1.3261502 | C8: 0.2128 | D8: 0.40643754 | E8: 0.09
A9: 25 | B9: 1.8171128 | C9: 0.2928 | D9: 0.61930518 | E9: 0.1392
A10: AAL | B10: 0.37760392 | C10: 0.061168 | D10: 0.10479582 | E10: 0.022356
B11: *Production based on average expected production of last 5 years
A13: Year 2050 (SSP585, no adaptation, no socio-economic projections)
A15: RP | B15: Crop Yield - Maize | D15: Crop Yield - Rice
B16: Production* (tonne/ha) | C16: Reduction (% below expected yield) | D16: Production* (tonne) | E16: Reduction (% below expected yield)
A17: 2 | B17: =B6*1.5 -> 0.18145052 | C17: =C6*1.5 -> 0.0336 | D17: =D6*1.5 -> 0.0091658294 | E17: =E6*1.5 -> 0.0018
A18: 5 | B18: =B7*1.5 -> 1.491401 | C18: =C7*1.5 -> 0.24 | D18: =D7*1.5 -> 0.39588807 | E18: =E7*1.5 -> 0.081
A19: 10 | B19: =B8*1.5 -> 1.9892253 | C19: =C8*1.5 -> 0.3192 | D19: =D8*1.5 -> 0.6096563 | E19: =E8*1.5 -> 0.135
A20: 25 | B20: =B9*1.5 -> 2.7256692 | C20: =C9*1.5 -> 0.4392 | D20: =D9*1.5 -> 0.92895776 | E20: =E9*1.5 -> 0.2088
A21: AAL | B21: =B10*1.5 -> 0.56640589 | C21: =C10*1.5 -> 0.091752 | D21: =D10*1.5 -> 0.15719373 | E21: =E10*1.5 -> 0.033534
A24: Year 2050 (SSP585, no adaptation, with socio-economic projections)
A26: RP | B26: Crop Yield - Maize | D26: Crop Yield - Rice
B27: Production* (tonne/ha) | C27: Reduction (% below expected yield) | D27: Production* (tonne) | E27: Reduction (% below expected yield)
A28: 2
A29: 5
A30: 10
A31: 25
A32: AAL
A35: Year 2050 (SSP126, no adaptation, no socio-economic projections)
A37: RP | B37: Crop Yield - Maize | D37: Crop Yield - Rice
B38: Production* (tonne/ha) | C38: Reduction (% below expected yield) | D38: Production* (tonne) | E38: Reduction (% below expected yield)
A39: 2
A40: 5
A41: 10
A42: 25
A43: AAL
A46: Year 2050 (SSP126, no adaptation, with socio-economic projections)
A48: RP | B48: Crop Yield - Maize | D48: Crop Yield - Rice
B49: Production* (tonne/ha) | C49: Reduction (% below expected yield) | D49: Production* (tonne) | E49: Reduction (% below expected yield)
A50: 2
A51: 5
A52: 10
A53: 25
...

Sheet Flood Affected Population
B2: Base year | D2: no adaptation | L2: with adaptation
D3: 2050 | L3: 2050
D4: SSP126 | H4: SSP585 | L4: SSP126 | P4: SSP585
D5: no socio-economic projections | F5: with socio-economic projections | H5: no socio-economic projections | J5: with socio-economic projections | L5: no socio-economic projections | N5: with socio-economic projections | P5: no socio-economic projections | R5: with socio-economic projections
B6: Number | C6: % | D6: Number | E6: % | F6: Number | G6: % | H6: Number | I6: % | J6: Number | K6: % | L6: Number | M6: % | N6: Number | O6: % | P6: Number | Q6: % | R6: Number | S6: %
A7: Banteay Meanchey | B7: 1603.3048 | C7: 0.25814779 | H7: 1587.2188 | I7: 0.25555779
A8: Battambang | B8: 3829.8006 | C8: 0.17845105 | H8: 3526.453 | I8: 0.16431645
A9: Kampong Cham | B9: 13205.662 | C9: 3.708988 | H9: 11334.354 | I9: 3.1834058
A10: Kampong Chhnang | B10: 6010.7442 | C10: 2.6125131 | H10: 5464.8481 | I10: 2.3752445
A11: Kampong Speu | B11: 1168.53 | C11: 0.28295297 | H11: 708.50154 | I11: 0.17155966
A12: Kampong Thom | B12: 3687.5133 | C12: 1.0654101 | H12: 4020.015 | I12: 1.1614778
A13: Kampot | B13: 1774.8178 | C13: 0.32590659 | H13: 1819.1327 | I13: 0.33404404
A14: Kandal | B14: 24797.286 | C14: 3.9428558 | H14: 20223.687 | I14: 3.2156373
A15: Koh Kong | B15: 362.29142 | C15: 0.67195987 | H15: 169.38077 | I15: 0.31415891
A16: Kratié | B16: 7171.5451 | C16: 2.8285279 | H16: 6044.065 | I16: 2.3838386
A17: Mondulkiri | B17: 613.94015 | C17: 0.4158601 | H17: 483.55986 | I17: 0.32754536
A18: Phnom Penh | B18: 25853.186 | C18: 1.0373306 | H18: 24103.712 | I18: 0.96713495
... A32: Total | B32: 169237.74 | C32: 1.0387505 | H32: 149981.58 | I32: 0.92055968

Sheet Drought Affected Population
B2: Base year | D2: no adaptation
D3: 2050
D4: SSP126 | H4: SSP585
D5: no socio-economic projections | F5: with socio-economic projections | H5: no socio-economic projections | J5: with socio-economic projections
B6: Number | C6: % | D6: Number | E6: % | F6: Number | G6: % | H6: Number | I6: % | J6: Number | K6: %
A7: Banteay Meanchey
A8: Battambang
A9: Kampong Cham
A10: Kampong Chhnang
A11: Kampong Speu
A12: Kampong Thom
A13: Kampot
A14: Kandal
A15: Koh Kong
A16: Kratié
A17: Mondulkiri
A18: Phnom Penh
... A32: Total

Sheet Flood AAL (admin 1)
B2: Base year | D2: no adaptation | L2: with adaptation
D3: 2050 | L3: 2050
D4: SSP126 | H4: SSP585 | L4: SSP126 | P4: SSP585
D5: no socio-economic projections | F5: with socio-economic projections | H5: no socio-economic projections | J5: with socio-economic projections | L5: no socio-economic projections | N5: with socio-economic projections | P5: no socio-economic projections | R5: with socio-economic projections
B6: Number | C6: % | D6: AAL | E6: % | F6: AAL | G6: % | H6: AAL | I6: % | J6: AAL | K6: % | L6: AAL | M6: % | N6: AAL | O6: % | P6: AAL | Q6: % | R6: AAL | S6: %
A7: Banteay Meanchey
A8: Battambang
A9: Kampong Cham
A10: Kampong Chhnang
A11: Kampong Speu
A12: Kampong Thom
A13: Kampot
A14: Kandal
A15: Koh Kong
A16: Kratié
A17: Mondulkiri
A18: Phnom Penh
... A32: Total

Sheet Drought AAL (admin 1)
B2: Base year | D2: no adaptation
D3: 2050
D4: SSP126 | H4: SSP585
D5: no socio-economic projections | F5: with socio-economic projections | H5: no socio-economic projections | J5: with socio-economic projections
B6: Number | C6: % | D6: AAL | E6: % | F6: AAL | G6: % | H6: AAL | I6: % | J6: AAL | K6: %
A7: Banteay Meanchey
A8: Battambang
A9: Kampong Cham
A10: Kampong Chhnang
A11: Kampong Speu
A12: Kampong Thom
A13: Kampot
A14: Kandal
A15: Koh Kong
A16: Kratié
A17: Mondulkiri
A18: Phnom Penh
... A32: Total
