Workbook

Sheet Flood (national AAL PML)
A2: Base year 2020 (no climate change)
B5: Housing | C5: Services | D5: Industry | E5: Total
A6: 10 | B6: 92.689411 | C6: 298.13222 | D6: 357.43199 | E6: 880.69007
A7: 25 | B7: 107.72409 | C7: 344.05971 | D7: 412.4164 | E7: 1024.9027
A8: 100 | B8: 148.57835 | C8: 471.64263 | D8: 565.35041 | E8: 1386.9241
A9: 200 | B9: 154.2632 | C9: 490.57679 | D9: 588.07132 | E9: 1441.209
A10: Annual average | B10: 56.327998 | C10: 180.32301 | D10: 216.18826 | E10: 534.4987
A14: Year 2050 (SSP585, no adaptation, with socio-economic projections)
B17: Housing | C17: Services | D17: Industry | E17: Total
A18: 10 | B18: 1462.8132 | C18: 4894.3245 | D18: 5872.4238 | E18: 12511.639
A19: 25 | B19: 1677.4659 | C19: 5623.1096 | D19: 6746.8152 | E19: 14401.088
A20: 100 | B20: 2143.348 | C20: 7125.3364 | D20: 8538.0277 | E20: 18248.325
A21: 200 | B21: 2210.5224 | C21: 7396.5671 | D21: 8870.6763 | E21: 18937.76
A22: Annual average | B22: 1256.3529 | C22: 4190.7359 | D22: 5027.0316 | E22: 10648.899
A26: Year 2050 (SSP126, no adaptation, with socio-economic projections)
B29: Housing | C29: Services | D29: Industry | E29: Total
A30: 10 | B30: 943.81882 | C30: 3135.8717 | D30: 3762.7042 | E30: 7973.6488
A31: 25 | B31: 1241.9118 | C31: 4157.1925 | D31: 4988.1875 | E31: 10566.447
A32: 100 | B32: 1382.5573 | C32: 4610.7651 | D32: 5530.4307 | E32: 11737.242
A33: 200 | B33: 1410.0363 | C33: 4703.0831 | D33: 5640.0917 | E33: 11982.571
A34: Annual average | B34: 392.6141 | C34: 1299.3769 | D34: 1557.8388 | E34: 3315.8299

Sheet Drought (national AAL PML)
A2: Base year 2020 (no climate change)
A4: RP | B4: asset 1 | D4: asset 2 | F4: asset 3
B5: US$ million | C5: % of total asset value | D5: US$ million | E5: % of total asset value | F5: US$ million | G5: % of total asset value
A6: 10
A7: 25
A8: 100
A9: 200
A10: AAL
A13: Year 2050 (SSP585, no adaptation, no socio-economic projections)
A15: RP | B15: asset 1 | D15: asset 2 | F15: asset 3
B16: US$ million | C16: % of total asset value | D16: US$ million | E16: % of total asset value | F16: US$ million | G16: % of total asset value
A17: 10
A18: 25
A19: 100
A20: 200
A21: 500
A22: 1000
A23: AAL
A26: Year 2050 (SSP585, no adaptation, with socio-economic projections)
A28: RP | B28: asset 1 | D28: asset 2 | F28: asset 3
B29: US$ million | C29: % of total asset value | D29: US$ million | E29: % of total asset value | F29: US$ million | G29: % of total asset value
A30: 10
A31: 25
A32: 100
A33: 200
A34: 500
A35: 1000
A36: AAL
A39: Year 2050 (SSP126, no adaptation, no socio-economic projections)
A41: RP | B41: asset 1 | D41: asset 2 | F41: asset 3
B42: US$ million | C42: % of total asset value | D42: US$ million | E42: % of total asset value | F42: US$ million | G42: % of total asset value
A43: 10
A44: 25
A45: 100
A46: 200
A47: 500
A48: 1000
A49: AAL
A52: Year 2050 (SSP126, no adaptation, with socio-economic projections)
A54: RP | B54: asset 1 | D54: asset 2 | F54: asset 3
...

Sheet Flood Affected Population
B2: Base year | D2: no adaptation | N2: with adaptation
D3: 2050 | N3: 2050
D4: SSP126 | J4: SSP585 | N4: SSP126 | R4: SSP585
D5: no socio-economic projections | F5: with socio-economic projections | J5: no socio-economic projections | L5: with socio-economic projections | N5: no socio-economic projections | P5: with socio-economic projections | R5: no socio-economic projections | T5: with socio-economic projections
B6: Number | C6: % | D6: Number | E6: % | F6: Number | G6: % | J6: Number | K6: % | L6: Number | M6: % | N6: Number | O6: % | P6: Number | Q6: % | R6: Number | S6: % | T6: Number | U6: %
A7: Banteay Meanchey | B7: 1652.0816 | C7: 0.26600133 | D7: 2367.8064 | E7: 0.38121406 | F7: 6162.6238 | G7: 0.75458221 | H7: =F7/B7 -> 3.7302175 | J7: 6506.8966 | K7: 1.0476028 | L7: 14726.704 | M7: 1.8032106 | P7: 3346.2638 | Q7: 0.43806937 | T7: 9251.0989 | U7: 1.2110889
A8: Battambang | B8: 5083.0475 | C8: 0.23684658 | D8: 4794.814 | E8: 0.22341803 | F8: 9107.0336 | G8: 0.32548619 | H8: =F8/B8 -> 1.7916483 | J8: 12259.057 | K8: 0.57122015 | L8: 23335.75 | M8: 0.83402178 | P8: 6648.7957 | Q8: 0.24695176 | T8: 17387.778 | U8: 0.64582257
A9: Kampong Cham | B9: 23252.328 | C9: 6.5307293 | D9: 19170.477 | E9: 5.3842817 | F9: 65423.365 | G9: 10.372581 | H9: =F9/B9 -> 2.8136265 | J9: 42717.481 | K9: 11.997769 | L9: 128551.02 | M9: 20.381188 | P9: 26428.11 | Q9: 5.2750073 | T9: 59363.963 | U9: 11.84895
A10: Kampong Chhnang | B10: 11520.532 | C10: 5.0072904 | D10: 14069.527 | E10: 6.1150122 | F10: 30880.498 | G10: 8.148517 | H10: =F10/B10 -> 2.6804749 | J10: 38466.425 | K10: 16.718591 | L10: 83525.125 | M10: 22.039991 | P10: 18853.664 | Q10: 5.9711728 | T10: 50706.485 | U10: 16.059328
A11: Kampong Speu | B11: 1397.9829 | C11: 0.3385137 | D11: 1202.5064 | E11: 0.29118989 | F11: 2287.2042 | G11: 0.32850015 | H11: =F11/B11 -> 1.6360744 | J11: 1887.8665 | K11: 0.45715153 | L11: 3574.0698 | M11: 0.51332647 | P11: 1811.574 | Q11: 0.29899004 | T11: 2908.2996 | U11: 0.4799984
A12: Kampong Thom | B12: 5529.4801 | C12: 1.597598 | D12: 6273.7159 | E12: 1.8126089 | F12: 10777.384 | G12: 2.1047384 | H12: =F12/B12 -> 1.9490773 | J12: 15474.598 | K12: 4.4709377 | L12: 25997.079 | M12: 5.0770252 | P12: 7795.7084 | Q12: 1.7621124 | T12: 19582.155 | U12: 4.4262762
A13: Kampot | B13: 2351.9713 | C13: 0.43188825 | D13: 2152.6412 | E13: 0.39528562 | F13: 3712.901 | G13: 0.44754226 | H13: =F13/B13 -> 1.5786336 | J13: 6170.4675 | K13: 1.1330718 | L13: 11261.054 | M13: 1.3573746 | P13: 3041.3463 | Q13: 0.39492671 | T13: 9219.8115 | U13: 1.1972164
A14: Kandal | B14: 44867.915 | C14: 7.1341564 | D14: 46491.338 | E14: 7.3925327 | F14: 100115.2 | G14: 9.4753673 | H14: =F14/B14 -> 2.2313317 | J14: 120170.19 | K14: 19.108119 | L14: 272055.08 | M14: 25.748555 | P14: 66872.601 | Q14: 7.4531791 | T14: 171257.04 | U14: 19.087181
A15: Koh Kong | B15: 542.39843 | C15: 1.0060133 | D15: 631.11238 | E15: 1.1705554 | F15: 1031.1663 | G15: 1.4740301 | H15: =F15/B15 -> 1.9011232 | J15: 815.43792 | K15: 1.5124331 | L15: 1188.024 | M15: 1.6982549 | P15: 756.36708 | Q15: 1.1949395 | T15: 945.60943 | U15: 1.4939123
A16: Kratié | B16: 13414.602 | C16: 5.2908508 | D16: 22783.151 | E16: 8.9858986 | F16: 80949.252 | G16: 21.730351 | H16: =F16/B16 -> 6.0344133 | J16: 48634.623 | K16: 19.181974 | L16: 133439.88 | M16: 35.821152 | P16: 31630.79 | Q16: 10.06044 | T16: 69435.449 | U16: 22.08453
A17: Mondulkiri | B17: 1084.4311 | C17: 0.73455306 | D17: 3948.4122 | E17: 2.6745067 | F17: 4112.6759 | G17: 2.1704856 | H17: =F17/B17 -> 3.7924732 | J17: 5792.4565 | K17: 3.9235934 | L17: 6285.0074 | M17: 3.3169446 | P17: 4065.2338 | Q17: 2.1840982 | T17: 6090.0622 | U17: 3.2719628
A18: Phnom Penh | B18: 35994.252 | C18: 1.4442298 | D18: 63350.861 | E18: 2.5418604 | F18: 76040.412 | G18: 2.9333523 | H18: =F18/B18 -> 2.112571 | J18: 297210.67 | K18: 11.925142 | L18: 322061.72 | M18: 12.423926 | P18: 68185.71 | Q18: 2.6572102 | T18: 306156.57 | U18: 11.93098
... A31: Tboung Khmum | B31: 11035.38 | C31: 1.8621831 | D31: 12610.166 | E31: 2.127962 | F31: 44764.082 | G31: 4.7675072 | H31: =F31/B31 -> 4.0564151 | J31: 41272.551 | K31: 6.9647315 | L31: 111261.54 | M31: 11.849683 | P31: 19038.986 | Q31: 2.3025809 | T31: 63369.485 | U31: 7.6639254
A32: Total | B32: =SUM(B7:B31) -> 284185.12 | C32: 1.7442766 | D32: 334984.33 | E32: 2.0560706 | F32: 675523.67 | G32: 3.1306822 | J32: 896130.26 | K32: 5.5002785 | L32: 1622263.4 | M32: 7.5183023 | P32: 447053.13 | Q32: 2.2115883 | T32: 1137427.7 | U32: 5.6268965

Sheet Drought Affected Population
B2: Base year | D2: no adaptation
D3: 2050
D4: SSP126 | H4: SSP585
D5: no socio-economic projections | F5: with socio-economic projections | H5: no socio-economic projections | J5: with socio-economic projections
B6: Number | C6: % | D6: Number | E6: % | F6: Number | G6: % | H6: Number | I6: % | J6: Number | K6: %
A7: Banteay Meanchey
A8: Battambang
A9: Kampong Cham
A10: Kampong Chhnang
A11: Kampong Speu
A12: Kampong Thom
A13: Kampot
A14: Kandal
A15: Koh Kong
A16: Kratié
A17: Mondulkiri
A18: Phnom Penh
... A32: Total

Sheet Flood AAL (admin 1)
B2: Base year | D2: no adaptation | L2: with adaptation
D3: 2050 | L3: 2050
D4: SSP126 | H4: SSP585 | L4: SSP126 | P4: SSP585
D5: no socio-economic projections | F5: with socio-economic projections | H5: no socio-economic projections | J5: with socio-economic projections | L5: no socio-economic projections | N5: with socio-economic projections | P5: no socio-economic projections | R5: with socio-economic projections
B6: AAL [million$] | C6: % | D6: AAL | E6: % | F6: AAL | G6: % | H6: AAL | I6: % | J6: AAL | K6: % | L6: AAL | M6: % | N6: AAL | O6: % | P6: AAL | Q6: % | R6: AAL | S6: %
A7: Banteay Meanchey | B7: 2.2192595 | C7: 0.11372062 | D7: 3.3691258 | E7: 0.17264276 | F7: 123.29363 | G7: 1.3704307 | H7: 9.4811951 | I7: 0.48584108 | J7: 364.20157 | K7: 4.0481655 | N7: 4.6686153 | O7: 0.19058209 | R7: 13.214329 | S7: 0.53943497
A8: Battambang | B8: 7.6527398 | C8: 0.18245795 | D8: 8.1497874 | E8: 0.19430865 | F8: 14.368729 | G8: 0.2430677 | H8: 20.00976 | I8: 0.47707617 | J8: 39.58546 | K8: 0.66964494 | N8: 10.764296 | O8: 0.19970245 | R8: 28.070619 | S8: 0.52077456
A9: Kampong Cham | B9: 51.525438 | C9: 2.4497996 | D9: 29.623017 | E9: 1.4084393 | F9: 102.3207 | G9: 2.682866 | H9: 93.368918 | I9: 4.4392662 | J9: 307.35177 | K9: 8.0588155 | N9: 43.446352 | O9: 1.4865304 | R9: 137.67271 | S9: 4.7105142
A10: Kampong Chhnang | B10: 35.710091 | C10: 2.8243632 | D10: 32.803733 | E10: 2.5944951 | F10: 76.04402 | G10: 1.1463486 | H10: 66.622842 | I10: 5.2692977 | J10: 149.57172 | K10: 2.254764 | N10: 47.497475 | O10: 2.8434666 | R10: 93.807769 | S10: 5.6158618
A11: Kampong Speu | B11: 1.2650459 | C11: 0.060316057 | D11: 1.0681459 | E11: 0.050928075 | F11: 1.8513186 | G11: 0.053682215 | H11: 2.4699108 | I11: 0.11776275 | J11: 4.5158247 | K11: 0.13094422 | N11: 1.5625122 | O11: 0.052107175 | R11: 3.6931436 | S11: 0.12316017
A12: Kampong Thom | B12: 8.5217081 | C12: 0.49651175 | D12: 10.113644 | E12: 0.58926486 | F12: 17.548454 | G12: 0.62794489 | H12: 24.205307 | I12: 1.4103064 | J12: 50.588146 | K12: 1.8102203 | N12: 12.586276 | O12: 0.57248099 | R12: 31.773035 | S12: 1.4451818
A13: Kampot | B13: 1.6559165 | C13: 0.091031344 | D13: 1.5356377 | E13: 0.08441921 | F13: 2.72251 | G13: 0.093790182 | H13: 7.7478555 | I13: 0.4259259 | J13: 14.658152 | K13: 0.5049718 | N13: 2.100855 | O13: 0.08018923 | R13: 11.553967 | S13: 0.44101271
A14: Kandal | B14: 102.98567 | C14: 3.1816174 | D14: 84.275862 | E14: 2.6036006 | F14: 531.53442 | G14: 6.4985999 | H14: 187.70726 | I14: 5.7989882 | J14: 1057.0166 | K14: 12.923204 | N14: 132.2872 | O14: 2.9396406 | R14: 294.06315 | S14: 6.5345702
A15: Koh Kong | B15: 0.49509882 | C15: 0.13424737 | D15: 0.94247456 | E15: 0.25555449 | F15: 1.4961215 | G15: 0.31999443 | H15: 1.3461442 | I15: 0.36501058 | J15: 2.2400927 | K15: 0.47911694 | N15: 1.1670248 | O15: 0.27628917 | R15: 1.7168422 | S15: 0.40645658
A16: Kratié | B16: 37.551358 | C16: 3.4319558 | D16: 28.739726 | E16: 2.6266285 | F16: 481.40872 | G16: 14.835174 | H16: 108.16967 | I16: 9.8860216 | J16: 1811.4535 | K16: 55.822062 | N16: 43.403071 | O16: 3.2910509 | R16: 158.3972 | S16: 12.010516
A17: Mondulkiri | B17: 1.2671934 | C17: 0.31264067 | D17: 1.9640595 | E17: 0.48457078 | F17: 2.4548719 | G17: 0.50377302 | H17: 5.1910945 | I17: 1.2807416 | J17: 6.3004403 | K17: 1.2929358 | N17: 2.3935039 | O17: 0.50384602 | R17: 6.1388734 | S17: 1.2922673
A18: Phnom Penh | B18: 35.571597 | C18: 0.26065839 | D18: 48.555899 | E18: 0.35580361 | F18: 66.621346 | G18: 0.47667244 | H18: 265.21201 | I18: 1.943397 | J18: 332.4547 | K18: 2.378697 | N18: 59.109716 | O18: 0.42583817 | R18: 313.98042 | S18: 2.2619775
... A32: Total | B32: 534.51948 | C32: 1.0070843 | D32: 465.869 | E32: 0.87774046 | F32: 3315.8299 | G32: 3.4608607 | H32: 1380.4419 | I32: 2.6008807 | J32: 10648.899 | K32: 11.11467 | N32: 686.46232 | O32: 1.0471519 | R32: 1995.9647 | S32: 3.0447092

Sheet Drought AAL (admin 1)
B2: Base year | D2: no adaptation
D3: 2050
D4: SSP126 | H4: SSP585
D5: no socio-economic projections | F5: with socio-economic projections | H5: no socio-economic projections | J5: with socio-economic projections
B6: Number | C6: % | D6: AAL | E6: % | F6: AAL | G6: % | H6: AAL | I6: % | J6: AAL | K6: %
A7: Banteay Meanchey
A8: Battambang
A9: Kampong Cham
A10: Kampong Chhnang
A11: Kampong Speu
A12: Kampong Thom
A13: Kampot
A14: Kandal
A15: Koh Kong
A16: Kratié
A17: Mondulkiri
A18: Phnom Penh
... A32: Total

Sheet graph_AALpop
C1: NO ADAPTATION | E1: WITH ADAPTATION
B2: Scenario | C2: People Affected | D2: % | E2: People Affected | F2: %
B3: Future Climate SSP585 & SEP | C3: ='Flood Affected Population'!L32 -> 1622263.4 | D3: ='Flood Affected Population'!M32/100 -> 0.075183023 | E3: ='Flood Affected Population'!T32 -> 1137427.7 | F3: ='Flood Affected Population'!U32/100 -> 0.056268965
B4: Future Climate SSP126 & SEP | C4: ='Flood Affected Population'!F32 -> 675523.67 | D4: ='Flood Affected Population'!G32/100 -> 0.031306822 | E4: ='Flood Affected Population'!P32 -> 447053.13 | F4: ='Flood Affected Population'!Q32/100 -> 0.022115883
B5: Present Climate | C5: ='Flood Affected Population'!B32 -> 284185.12 | D5: ='Flood Affected Population'!C32/100 -> 0.017442766

Sheet graph_AALeconomic
C1: NO ADAPTATION | K1: WITH ADAPTATION
B2: Scenario | C2: Direct Loss total $ | D2: % | E2: housing | F2: service | G2: industrial | H2: transportation | I2: school | J2: health | K2: Direct Loss total $ | L2: % | M2: housing | N2: service | O2: industrial | P2: transportation | Q2: school | R2: health
B3: Future Climate SSP585 & SEP | C3: =SUM(E3:J3)*1000000 -> #REF! | E3: ='Flood (national AAL PML)'!B22 -> 1256.3529 | F3: ='Flood (national AAL PML)'!C22 -> 4190.7359 | G3: ='Flood (national AAL PML)'!D22 -> 5027.0316 | H3: ='Flood (national AAL PML)'!#REF! -> #REF! | I3: ='Flood (national AAL PML)'!#REF! -> #REF! | J3: ='Flood (national AAL PML)'!#REF! -> #REF! | K3: =SUM(M3:R3)*1000000 -> #REF! | M3: ='Flood (national AAL PML)'!#REF! -> #REF! | N3: ='Flood (national AAL PML)'!#REF! -> #REF! | O3: ='Flood (national AAL PML)'!#REF! -> #REF! | P3: =H3 -> #REF! | Q3: =I3 -> #REF! | R3: =J3 -> #REF!
B4: Future Climate SSP126 & SEP | C4: =SUM(E4:J4)*1000000 -> #REF! | E4: ='Flood (national AAL PML)'!B34 -> 392.6141 | F4: ='Flood (national AAL PML)'!C34 -> 1299.3769 | G4: ='Flood (national AAL PML)'!D34 -> 1557.8388 | H4: ='Flood (national AAL PML)'!#REF! -> #REF! | I4: ='Flood (national AAL PML)'!#REF! -> #REF! | J4: ='Flood (national AAL PML)'!#REF! -> #REF! | K4: =SUM(M4:R4)*1000000 -> #REF! | M4: ='Flood (national AAL PML)'!#REF! -> #REF! | N4: ='Flood (national AAL PML)'!#REF! -> #REF! | O4: ='Flood (national AAL PML)'!#REF! -> #REF! | P4: =H4 -> #REF! | Q4: =I4 -> #REF! | R4: =J4 -> #REF!
B5: Present Climate | C5: =SUM(E5:J5)*1000000 -> #REF! | E5: ='Flood (national AAL PML)'!B10 -> 56.327998 | F5: ='Flood (national AAL PML)'!C10 -> 180.32301 | G5: ='Flood (national AAL PML)'!D10 -> 216.18826 | H5: ='Flood (national AAL PML)'!#REF! -> #REF! | I5: ='Flood (national AAL PML)'!#REF! -> #REF! | J5: ='Flood (national AAL PML)'!#REF! -> #REF! | K5: =SUM(M5:R5) -> 0

Sheet graph_AALbua
C1: NO ADAPTATION | K1: WITH ADAPTATION
B2: Scenario | C2: Direct Loss total $ | D2: % | E2: housing | F2: service | G2: industrial | H2: transportation | I2: school | J2: health | K2: Direct Loss total $ | L2: % | M2: housing | N2: service | O2: industrial | P2: transportation | Q2: school | R2: health
B3: Future Climate SSP585 & SEP | C3: =SUM(E3:G3)*1000000 -> 1.047412e+10 | E3: ='Flood (national AAL PML)'!B22 -> 1256.3529 | F3: ='Flood (national AAL PML)'!C22 -> 4190.7359 | G3: ='Flood (national AAL PML)'!D22 -> 5027.0316 | H3: ='Flood (national AAL PML)'!#REF! -> #REF! | I3: ='Flood (national AAL PML)'!#REF! -> #REF! | J3: ='Flood (national AAL PML)'!#REF! -> #REF! | K3: =SUM(M3:O3)*1000000 -> #REF! | M3: ='Flood (national AAL PML)'!#REF! -> #REF! | N3: ='Flood (national AAL PML)'!#REF! -> #REF! | O3: ='Flood (national AAL PML)'!#REF! -> #REF! | P3: =H3 -> #REF! | Q3: =I3 -> #REF! | R3: =J3 -> #REF!
B4: Future Climate SSP126 & SEP | C4: =SUM(E4:G4)*1000000 -> 3.2498299e+09 | E4: ='Flood (national AAL PML)'!B34 -> 392.6141 | F4: ='Flood (national AAL PML)'!C34 -> 1299.3769 | G4: ='Flood (national AAL PML)'!D34 -> 1557.8388 | H4: ='Flood (national AAL PML)'!#REF! -> #REF! | I4: ='Flood (national AAL PML)'!#REF! -> #REF! | J4: ='Flood (national AAL PML)'!#REF! -> #REF! | K4: =SUM(M4:O4)*1000000 -> #REF! | M4: ='Flood (national AAL PML)'!#REF! -> #REF! | N4: ='Flood (national AAL PML)'!#REF! -> #REF! | O4: ='Flood (national AAL PML)'!#REF! -> #REF! | P4: =H4 -> #REF! | Q4: =I4 -> #REF! | R4: =J4 -> #REF!
B5: Present Climate | C5: =SUM(E5:G5)*1000000 -> 4.5283927e+08 | E5: ='Flood (national AAL PML)'!B10 -> 56.327998 | F5: ='Flood (national AAL PML)'!C10 -> 180.32301 | G5: ='Flood (national AAL PML)'!D10 -> 216.18826 | H5: ='Flood (national AAL PML)'!#REF! -> #REF! | I5: ='Flood (national AAL PML)'!#REF! -> #REF! | J5: ='Flood (national AAL PML)'!#REF! -> #REF! | K5: =SUM(M5:R5) -> 0

Sheet graph_PMLpop
P2: Return Period | Q2: 2 | R2: 5 | S2: 10 | T2: 25 | U2: 50 | V2: 100 | W2: 250
P3: POP 2020 - Current Climate | Q3: 215654.81 | R3: 356854.06 | S3: 411510.75 | T3: 532600.57 | U3: 607229.85 | V3: 688797.21 | W3: 707243.97
P4: POP 2050 - SSP 126 - Projected | Q4: 482527.16 | R4: 765305.45 | S4: 914190.05 | T4: 1178543.5 | U4: 1373504.8 | V4: 1572703.5 | W4: 1874093.2
P5: POP 2050 - SSP 126 - Mitigated | Q5: 334522.9 | R5: 545188.49 | S5: 661415.42 | T5: 865920.38 | U5: 1026381.5 | V5: 1233181.4 | W5: 1587844.2
P6: POP 2050 - SSP 585 - Projected | Q6: 1090938.3 | R6: 1709206.2 | S6: 2433346 | T6: 2707529.8 | U6: 3432323.1 | V6: 3705143.3 | W6: 3918848.4
P7: POP 2050 - SSP 585 - Mitigated | Q7: 775319.77 | R7: 1295190.1 | S7: 2063402.7 | T7: 2335126.4 | U7: 2938883.5 | V7: 3230913.8 | W7: 3363531.7
U9: =(U5-U4)*100/U4 -> -25.272812
U11: =(U7-U6)*100/U6 -> -14.376255

Sheet graph_PMLeco
C1: present | J1: future SSP126 | Q1: future SSP585
C2: no adaptation
B3: Return Period | C3: housing | D3: service | E3: productive | F3: transportation | G3: school | H3: health | I3: TOT | J3: housing | K3: service | L3: productive | M3: transportation | N3: school | O3: health | P3: TOT | Q3: housing | R3: service | S3: productive | T3: transportation | U3: school | V3: health | W3: TOT
B4: 10 | C4: ='Flood (national AAL PML)'!B6 -> 92.689411 | D4: ='Flood (national AAL PML)'!C6 -> 298.13222 | E4: ='Flood (national AAL PML)'!D6 -> 357.43199 | F4: ='Flood (national AAL PML)'!#REF! -> #REF! | G4: ='Flood (national AAL PML)'!#REF! -> #REF! | H4: ='Flood (national AAL PML)'!#REF! -> #REF! | I4: =SUM(C4:H4) -> #REF! | J4: ='Flood (national AAL PML)'!B30 -> 943.81882 | K4: ='Flood (national AAL PML)'!C30 -> 3135.8717 | L4: ='Flood (national AAL PML)'!D30 -> 3762.7042 | M4: ='Flood (national AAL PML)'!#REF! -> #REF! | N4: ='Flood (national AAL PML)'!#REF! -> #REF! | O4: ='Flood (national AAL PML)'!#REF! -> #REF! | P4: =SUM(J4:O4) -> #REF! | Q4: ='Flood (national AAL PML)'!B18 -> 1462.8132 | R4: ='Flood (national AAL PML)'!C18 -> 4894.3245 | S4: ='Flood (national AAL PML)'!D18 -> 5872.4238 | T4: ='Flood (national AAL PML)'!#REF! -> #REF! | U4: ='Flood (national AAL PML)'!#REF! -> #REF! | V4: ='Flood (national AAL PML)'!#REF! -> #REF! | W4: =SUM(Q4:V4) -> #REF!
B5: 25 | C5: ='Flood (national AAL PML)'!B7 -> 107.72409 | D5: ='Flood (national AAL PML)'!C7 -> 344.05971 | E5: ='Flood (national AAL PML)'!D7 -> 412.4164 | F5: ='Flood (national AAL PML)'!#REF! -> #REF! | G5: ='Flood (national AAL PML)'!#REF! -> #REF! | H5: ='Flood (national AAL PML)'!#REF! -> #REF! | I5: =SUM(C5:H5) -> #REF! | J5: ='Flood (national AAL PML)'!B31 -> 1241.9118 | K5: ='Flood (national AAL PML)'!C31 -> 4157.1925 | L5: ='Flood (national AAL PML)'!D31 -> 4988.1875 | M5: ='Flood (national AAL PML)'!#REF! -> #REF! | N5: ='Flood (national AAL PML)'!#REF! -> #REF! | O5: ='Flood (national AAL PML)'!#REF! -> #REF! | P5: =SUM(J5:O5) -> #REF! | Q5: ='Flood (national AAL PML)'!B19 -> 1677.4659 | R5: ='Flood (national AAL PML)'!C19 -> 5623.1096 | S5: ='Flood (national AAL PML)'!D19 -> 6746.8152 | T5: ='Flood (national AAL PML)'!#REF! -> #REF! | U5: ='Flood (national AAL PML)'!#REF! -> #REF! | V5: ='Flood (national AAL PML)'!#REF! -> #REF! | W5: =SUM(Q5:V5) -> #REF!
B6: 100 | C6: ='Flood (national AAL PML)'!B8 -> 148.57835 | D6: ='Flood (national AAL PML)'!C8 -> 471.64263 | E6: ='Flood (national AAL PML)'!D8 -> 565.35041 | F6: ='Flood (national AAL PML)'!#REF! -> #REF! | G6: ='Flood (national AAL PML)'!#REF! -> #REF! | H6: ='Flood (national AAL PML)'!#REF! -> #REF! | I6: =SUM(C6:H6) -> #REF! | J6: ='Flood (national AAL PML)'!B32 -> 1382.5573 | K6: ='Flood (national AAL PML)'!C32 -> 4610.7651 | L6: ='Flood (national AAL PML)'!D32 -> 5530.4307 | M6: ='Flood (national AAL PML)'!#REF! -> #REF! | N6: ='Flood (national AAL PML)'!#REF! -> #REF! | O6: ='Flood (national AAL PML)'!#REF! -> #REF! | P6: =SUM(J6:O6) -> #REF! | Q6: ='Flood (national AAL PML)'!B20 -> 2143.348 | R6: ='Flood (national AAL PML)'!C20 -> 7125.3364 | S6: ='Flood (national AAL PML)'!D20 -> 8538.0277 | T6: ='Flood (national AAL PML)'!#REF! -> #REF! | U6: ='Flood (national AAL PML)'!#REF! -> #REF! | V6: ='Flood (national AAL PML)'!#REF! -> #REF! | W6: =SUM(Q6:V6) -> #REF!
B7: 200 | C7: ='Flood (national AAL PML)'!B9 -> 154.2632 | D7: ='Flood (national AAL PML)'!C9 -> 490.57679 | E7: ='Flood (national AAL PML)'!D9 -> 588.07132 | F7: ='Flood (national AAL PML)'!#REF! -> #REF! | G7: ='Flood (national AAL PML)'!#REF! -> #REF! | H7: ='Flood (national AAL PML)'!#REF! -> #REF! | I7: =SUM(C7:H7) -> #REF! | J7: ='Flood (national AAL PML)'!B33 -> 1410.0363 | K7: ='Flood (national AAL PML)'!C33 -> 4703.0831 | L7: ='Flood (national AAL PML)'!D33 -> 5640.0917 | M7: ='Flood (national AAL PML)'!#REF! -> #REF! | N7: ='Flood (national AAL PML)'!#REF! -> #REF! | O7: ='Flood (national AAL PML)'!#REF! -> #REF! | P7: =SUM(J7:O7) -> #REF! | Q7: ='Flood (national AAL PML)'!B21 -> 2210.5224 | R7: ='Flood (national AAL PML)'!C21 -> 7396.5671 | S7: ='Flood (national AAL PML)'!D21 -> 8870.6763 | T7: ='Flood (national AAL PML)'!#REF! -> #REF! | U7: ='Flood (national AAL PML)'!#REF! -> #REF! | V7: ='Flood (national AAL PML)'!#REF! -> #REF! | W7: =SUM(Q7:V7) -> #REF!
C8: with adaptation
B9: Return Period | J9: housing | K9: service | L9: productive | M9: transportation | N9: school | O9: health | P9: TOT | Q9: housing | R9: service | S9: productive | T9: transportation | U9: school | V9: health | W9: TOT
B10: 10 | J10: ='Flood (national AAL PML)'!#REF! -> #REF! | K10: ='Flood (national AAL PML)'!#REF! -> #REF! | L10: ='Flood (national AAL PML)'!#REF! -> #REF! | M10: ='Flood (national AAL PML)'!#REF! -> #REF! | N10: ='Flood (national AAL PML)'!#REF! -> #REF! | O10: ='Flood (national AAL PML)'!#REF! -> #REF! | P10: =SUM(J10:O10) -> #REF! | Q10: ='Flood (national AAL PML)'!#REF! -> #REF! | R10: ='Flood (national AAL PML)'!#REF! -> #REF! | S10: ='Flood (national AAL PML)'!#REF! -> #REF! | T10: ='Flood (national AAL PML)'!#REF! -> #REF! | U10: ='Flood (national AAL PML)'!#REF! -> #REF! | V10: ='Flood (national AAL PML)'!#REF! -> #REF! | W10: =SUM(Q10:V10) -> #REF!
B11: 25 | J11: ='Flood (national AAL PML)'!#REF! -> #REF! | K11: ='Flood (national AAL PML)'!#REF! -> #REF! | L11: ='Flood (national AAL PML)'!#REF! -> #REF! | M11: ='Flood (national AAL PML)'!#REF! -> #REF! | N11: ='Flood (national AAL PML)'!#REF! -> #REF! | O11: ='Flood (national AAL PML)'!#REF! -> #REF! | P11: =SUM(J11:O11) -> #REF! | Q11: ='Flood (national AAL PML)'!#REF! -> #REF! | R11: ='Flood (national AAL PML)'!#REF! -> #REF! | S11: ='Flood (national AAL PML)'!#REF! -> #REF! | T11: ='Flood (national AAL PML)'!#REF! -> #REF! | U11: ='Flood (national AAL PML)'!#REF! -> #REF! | V11: ='Flood (national AAL PML)'!#REF! -> #REF! | W11: =SUM(Q11:V11) -> #REF!
B12: 100 | J12: ='Flood (national AAL PML)'!#REF! -> #REF! | K12: ='Flood (national AAL PML)'!#REF! -> #REF! | L12: ='Flood (national AAL PML)'!#REF! -> #REF! | M12: ='Flood (national AAL PML)'!#REF! -> #REF! | N12: ='Flood (national AAL PML)'!#REF! -> #REF! | O12: ='Flood (national AAL PML)'!#REF! -> #REF! | P12: =SUM(J12:O12) -> #REF! | Q12: ='Flood (national AAL PML)'!#REF! -> #REF! | R12: ='Flood (national AAL PML)'!#REF! -> #REF! | S12: ='Flood (national AAL PML)'!#REF! -> #REF! | T12: ='Flood (national AAL PML)'!#REF! -> #REF! | U12: ='Flood (national AAL PML)'!#REF! -> #REF! | V12: ='Flood (national AAL PML)'!#REF! -> #REF! | W12: =SUM(Q12:V12) -> #REF!
B13: 200 | J13: ='Flood (national AAL PML)'!#REF! -> #REF! | K13: ='Flood (national AAL PML)'!#REF! -> #REF! | L13: ='Flood (national AAL PML)'!#REF! -> #REF! | M13: ='Flood (national AAL PML)'!#REF! -> #REF! | N13: ='Flood (national AAL PML)'!#REF! -> #REF! | O13: ='Flood (national AAL PML)'!#REF! -> #REF! | P13: =SUM(J13:O13) -> #REF! | Q13: ='Flood (national AAL PML)'!#REF! -> #REF! | R13: ='Flood (national AAL PML)'!#REF! -> #REF! | S13: ='Flood (national AAL PML)'!#REF! -> #REF! | T13: ='Flood (national AAL PML)'!#REF! -> #REF! | U13: ='Flood (national AAL PML)'!#REF! -> #REF! | V13: ='Flood (national AAL PML)'!#REF! -> #REF! | W13: =SUM(Q13:V13) -> #REF!

Sheet graph_PMLbua
C1: present | G1: future SSP126 | K1: future SSP585
C2: no adaptation
B3: Return Period | C3: housing | D3: service | E3: productive | F3: TOT | G3: housing | H3: service | I3: productive | J3: TOT | K3: housing | L3: service | M3: productive | N3: TOT
B4: 10 | C4: ='Flood (national AAL PML)'!B6 -> 92.689411 | D4: ='Flood (national AAL PML)'!C6 -> 298.13222 | E4: ='Flood (national AAL PML)'!D6 -> 357.43199 | F4: =SUM(C4:E4) -> 748.25362 | G4: ='Flood (national AAL PML)'!B30 -> 943.81882 | H4: ='Flood (national AAL PML)'!C30 -> 3135.8717 | I4: ='Flood (national AAL PML)'!D30 -> 3762.7042 | J4: =SUM(G4:I4) -> 7842.3947 | K4: ='Flood (national AAL PML)'!B18 -> 1462.8132 | L4: ='Flood (national AAL PML)'!C18 -> 4894.3245 | M4: ='Flood (national AAL PML)'!D18 -> 5872.4238 | N4: =SUM(K4:M4) -> 12229.561
B5: 25 | C5: ='Flood (national AAL PML)'!B7 -> 107.72409 | D5: ='Flood (national AAL PML)'!C7 -> 344.05971 | E5: ='Flood (national AAL PML)'!D7 -> 412.4164 | F5: =SUM(C5:E5) -> 864.2002 | G5: ='Flood (national AAL PML)'!B31 -> 1241.9118 | H5: ='Flood (national AAL PML)'!C31 -> 4157.1925 | I5: ='Flood (national AAL PML)'!D31 -> 4988.1875 | J5: =SUM(G5:I5) -> 10387.292 | K5: ='Flood (national AAL PML)'!B19 -> 1677.4659 | L5: ='Flood (national AAL PML)'!C19 -> 5623.1096 | M5: ='Flood (national AAL PML)'!D19 -> 6746.8152 | N5: =SUM(K5:M5) -> 14047.391
B6: 100 | C6: ='Flood (national AAL PML)'!B8 -> 148.57835 | D6: ='Flood (national AAL PML)'!C8 -> 471.64263 | E6: ='Flood (national AAL PML)'!D8 -> 565.35041 | F6: =SUM(C6:E6) -> 1185.5714 | G6: ='Flood (national AAL PML)'!B32 -> 1382.5573 | H6: ='Flood (national AAL PML)'!C32 -> 4610.7651 | I6: ='Flood (national AAL PML)'!D32 -> 5530.4307 | J6: =SUM(G6:I6) -> 11523.753 | K6: ='Flood (national AAL PML)'!B20 -> 2143.348 | L6: ='Flood (national AAL PML)'!C20 -> 7125.3364 | M6: ='Flood (national AAL PML)'!D20 -> 8538.0277 | N6: =SUM(K6:M6) -> 17806.712
B7: 200 | C7: ='Flood (national AAL PML)'!B9 -> 154.2632 | D7: ='Flood (national AAL PML)'!C9 -> 490.57679 | E7: ='Flood (national AAL PML)'!D9 -> 588.07132 | F7: =SUM(C7:E7) -> 1232.9113 | G7: ='Flood (national AAL PML)'!B33 -> 1410.0363 | H7: ='Flood (national AAL PML)'!C33 -> 4703.0831 | I7: ='Flood (national AAL PML)'!D33 -> 5640.0917 | J7: =SUM(G7:I7) -> 11753.211 | K7: ='Flood (national AAL PML)'!B21 -> 2210.5224 | L7: ='Flood (national AAL PML)'!C21 -> 7396.5671 | M7: ='Flood (national AAL PML)'!D21 -> 8870.6763 | N7: =SUM(K7:M7) -> 18477.766
C8: with adaptation
B9: Return Period | G9: housing | H9: service | I9: productive | J9: TOT | K9: housing | L9: service | M9: productive | N9: TOT
B10: 10 | G10: ='Flood (national AAL PML)'!#REF! -> #REF! | H10: ='Flood (national AAL PML)'!#REF! -> #REF! | I10: ='Flood (national AAL PML)'!#REF! -> #REF! | J10: =SUM(G10:I10) -> #REF! | K10: ='Flood (national AAL PML)'!#REF! -> #REF! | L10: ='Flood (national AAL PML)'!#REF! -> #REF! | M10: ='Flood (national AAL PML)'!#REF! -> #REF! | N10: =SUM(K10:M10) -> #REF!
B11: 25 | G11: ='Flood (national AAL PML)'!#REF! -> #REF! | H11: ='Flood (national AAL PML)'!#REF! -> #REF! | I11: ='Flood (national AAL PML)'!#REF! -> #REF! | J11: =SUM(G11:I11) -> #REF! | K11: ='Flood (national AAL PML)'!#REF! -> #REF! | L11: ='Flood (national AAL PML)'!#REF! -> #REF! | M11: ='Flood (national AAL PML)'!#REF! -> #REF! | N11: =SUM(K11:M11) -> #REF!
B12: 100 | G12: ='Flood (national AAL PML)'!#REF! -> #REF! | H12: ='Flood (national AAL PML)'!#REF! -> #REF! | I12: ='Flood (national AAL PML)'!#REF! -> #REF! | J12: =SUM(G12:I12) -> #REF! | K12: ='Flood (national AAL PML)'!#REF! -> #REF! | L12: ='Flood (national AAL PML)'!#REF! -> #REF! | M12: ='Flood (national AAL PML)'!#REF! -> #REF! | N12: =SUM(K12:M12) -> #REF!
B13: 200 | G13: ='Flood (national AAL PML)'!#REF! -> #REF! | H13: ='Flood (national AAL PML)'!#REF! -> #REF! | I13: ='Flood (national AAL PML)'!#REF! -> #REF! | J13: =SUM(G13:I13) -> #REF! | K13: ='Flood (national AAL PML)'!#REF! -> #REF! | L13: ='Flood (national AAL PML)'!#REF! -> #REF! | M13: ='Flood (national AAL PML)'!#REF! -> #REF! | N13: =SUM(K13:M13) -> #REF!
