Workbook

Sheet CGE-Flood Weighted Av Calcs
A1: 2020
A2: sector | B2: AAL | C2: %AAL per sector | D2: total asset value
A3: housing | B3: ='Flood (national AAL PML)'!B10 -> 56.327998 | C3: =(B3/D3)*100 -> 0.94947125 | D3: =('Flood (national AAL PML)'!B10*100)/'Flood (national AAL PML)'!C10 -> 5932.5649 | E3: =D3/$D$12 -> 0.11179621
A4: services | B4: ='Flood (national AAL PML)'!D10 -> 180.32301 | C4: =(B4/D4)*100 -> 0.92626481 | D4: =('Flood (national AAL PML)'!D10*100)/'Flood (national AAL PML)'!E10 -> 19467.76 | E4: =D4/$D$12 -> 0.36686017
A5: productive | B5: ='Flood (national AAL PML)'!F10 -> 216.18826 | C5: =(B5/D5)*100 -> 0.92611724 | D5: =('Flood (national AAL PML)'!F10*100)/'Flood (national AAL PML)'!G10 -> 23343.509 | E5: =D5/$D$12 -> 0.43989671
A6: roads | B6: ='Flood (national AAL PML)'!J10 -> 70.478123 | C6: =(B6/D6)*100 -> 1.948361 | D6: =('Flood (national AAL PML)'!J10*100)/'Flood (national AAL PML)'!K10 -> 3617.303 | E6: =D6/$D$12 -> 0.068166261
A7: schools | B7: ='Flood (national AAL PML)'!N10 -> 8.079959 | C7: =(B7/D7)*100 -> 1.3337888 | D7: =('Flood (national AAL PML)'!N10*100)/'Flood (national AAL PML)'!O10 -> 605.79 | E7: =D7/$D$12 -> 0.011415809
A8: health centers | B8: ='Flood (national AAL PML)'!R10 -> 3.1013483 | C8: =(B8/D8)*100 -> 3.133973 | D8: =('Flood (national AAL PML)'!R10*100)/'Flood (national AAL PML)'!S10 -> 98.959 | E8: =D8/$D$12 -> 0.0018648327
C10: =SUMPRODUCT(C3:C8,D3:D8)/SUM(D3:D8) -> 1.007236
B11: =SUM(B3:B8,'Flood (national AAL PML)'!T10) -> 594.3987
A12: asset value (all sectors) | D12: =SUM(D3:D8) -> 53065.886
A17: 2050
A18: sector | B18: AAL | C18: %AAL per sector | D18: total asset value
A19: housing | B19: ='Flood (national AAL PML)'!B21 -> 151.21875 | C19: =(B19/D19)*100 -> 2.5489494 | D19: =('Flood (national AAL PML)'!B21*100)/'Flood (national AAL PML)'!C21 -> 5932.5912 | E19: =D19/$D$27 -> 0.11179536
A20: services | B20: ='Flood (national AAL PML)'!D21 -> 479.48056 | C20: =(B20/D20)*100 -> 2.4629358 | D20: =('Flood (national AAL PML)'!D21*100)/'Flood (national AAL PML)'!E21 -> 19467.847 | E20: =D20/$D$27 -> 0.36685738
A21: productive | B21: ='Flood (national AAL PML)'!F21 -> 574.96418 | C21: =(B21/D21)*100 -> 2.4630471 | D21: =('Flood (national AAL PML)'!F21*100)/'Flood (national AAL PML)'!G21 -> 23343.613 | E21: =D21/$D$27 -> 0.43989336
A22: roads | B22: ='Flood (national AAL PML)'!J21 -> 148.34601 | C22: =(B22/D22)*100 -> 4.1010115 | D22: =('Flood (national AAL PML)'!J21*100)/'Flood (national AAL PML)'!K21 -> 3617.303 | E22: =D22/$D$27 -> 0.068165438
A23: schools | B23: ='Flood (national AAL PML)'!N21 -> 18.424418 | C23: =(B23/D23)*100 -> 3.0392598 | D23: =('Flood (national AAL PML)'!N21*100)/'Flood (national AAL PML)'!O21 -> 606.214 | E23: =D23/$D$27 -> 0.011423661
A24: health centers | B24: ='Flood (national AAL PML)'!R21 -> 8.0079496 | C24: =(B24/D24)*100 -> 8.0921893 | D24: =('Flood (national AAL PML)'!R21*100)/'Flood (national AAL PML)'!S21 -> 98.959 | E24: =D24/$D$27 -> 0.0018648102
C25: =SUMPRODUCT(C19:C24,D19:D24)/SUM(D19:D24) -> 2.6013421
A27: asset value (all sectors) | D27: =SUM(D19:D24) -> 53066.527

Sheet Flood (national AAL PML)
A2: Base year 2020 (no climate change) | AH2: Housing | AP2: Services | AX2: Productive Sector | BF2: Roads | BN2: Schools | BV2: Health Centers
A4: RP | B4: Housing | D4: Services Sector | F4: Industrial Sector | H4: Roads | L4: Schools | P4: Health Centers | T4: Agriculture | AG4: 1 | AH4: =1/AH5 -> 0.1 | AI4: =1/AI5 -> 0.04 | AJ4: =1/AJ5 -> 0.01 | AK4: =1/AK5 -> 0.005 | AP4: 1 | AQ4: =1/AQ5 -> 0.1 | AR4: =1/AR5 -> 0.04 | AS4: =1/AS5 -> 0.01 | AT4: =1/AT5 -> 0.005 | AX4: 1 | AY4: =1/AY5 -> 0.1 | AZ4: =1/AZ5 -> 0.04 | BA4: =1/BA5 -> 0.01 | BB4: =1/BB5 -> 0.005 | BF4: 1 | BG4: =1/BG5 -> 0.1 | BH4: =1/BH5 -> 0.04 | BI4: =1/BI5 -> 0.01 | BJ4: =1/BJ5 -> 0.005 | BN4: 1 | BO4: =1/BO5 -> 0.1 | BP4: =1/BP5 -> 0.04 | BQ4: =1/BQ5 -> 0.01 | BR4: =1/BR5 -> 0.005 | BV4: 1 | BW4: =1/BW5 -> 0.1 | BX4: =1/BX5 -> 0.04 | BY4: =1/BY5 -> 0.01 | BZ4: =1/BZ5 -> 0.005
B5: US$ million | C5: % of total asset value | D5: US$ million | E5: % of total asset value | F5: US$ million | G5: % of total asset value | H5: km | I5: % of asset | J5: US$ million | K5: % of total asset value | L5: Number | M5: % of asset | N5: US$ million | O5: % of total asset value | P5: Number | Q5: % of asset | R5: US$ million | S5: % of total asset value | T5: US$ million | AB5: CGE interpolation | AF5: RP | AG5: 1 | AH5: 10 | AI5: 25 | AJ5: 100 | AK5: 200 | AO5: RP | AP5: 1 | AQ5: 10 | AR5: 25 | AS5: 100 | AT5: 200 | AX5: 1 | AY5: 10 | AZ5: 25 | BA5: 100 | BB5: 200 | BF5: 1 | BG5: 10 | BH5: 25 | BI5: 100 | BJ5: 200 | BN5: 1 | BO5: 10 | BP5: 25 | BQ5: 100 | BR5: 200 | BV5: 1 | BW5: 10 | BX5: 25 | BY5: 100 | BZ5: 200
A6: 10 | B6: 92.689411 | C6: 1.5623834 | D6: 298.13222 | E6: 1.5314151 | F6: 357.43199 | G6: 1.5311837 | H6: 1385.6159 | I6: 3.2014437 | J6: 112.59323 | K6: 3.1126291 | L6: 269.1568 | M6: 2.3531807 | N6: 14.26354 | O6: 2.3545354 | P6: 83.906 | Q6: 5.6808396 | R6: 5.5796796 | S6: 5.6383751 | T6: =MINDSET!C58 -> 144 | AE6: =(AH36-AH6)/30 -> 0.091746034 | AF6: 2020 | AG6: 0 | AH6: =C6 -> 1.5623834 | AI6: =C7 -> 1.8158097 | AJ6: =C8 -> 2.5044538 | AK6: =C9 -> 2.6002784 | AN6: =($AQ36-$AQ6)/30 -> 0.087612605 | AO6: 2020 | AP6: 0 | AQ6: =E6 -> 1.5314151 | AR6: =E7 -> 1.7673307 | AS6: =E8 -> 2.4226856 | AT6: =E9 -> 2.5199447 | AW6: =(AY36-AY6)/30 -> 0.087659767 | AX6: 0 | AY6: =G6 -> 1.5311837 | AZ6: =G7 -> 1.7667284 | BA6: =G8 -> 2.4218742 | BB6: =G9 -> 2.5192071 | BE6: =(BG36-BG6)/30 -> 0.11759469 | BF6: 0 | BG6: =K6 -> 3.1126291 | BH6: =K7 -> 3.8034416 | BI6: =K8 -> 4.761555 | BJ6: =K9 -> 4.9215119 | BM6: =(BO36-BO6)/30 -> 0.091013244 | BN6: 0 | BO6: =O6 -> 2.3545354 | BP6: =O7 -> 2.7634156 | BQ6: =O8 -> 3.4956868 | BR6: =O9 -> 3.6356308 | BU6: =(BW36-BW6)/30 -> 0.18413496 | BV6: 0 | BW6: =S6 -> 5.6383751 | BX6: =S7 -> 6.4471226 | BY6: =S8 -> 8.0198375 | BZ6: =S9 -> 8.3341909
A7: 25 | B7: 107.72409 | C7: 1.8158097 | D7: 344.05971 | E7: 1.7673307 | F7: 412.4164 | G7: 1.7667284 | H7: 1740.7415 | I7: 4.0219557 | J7: 137.58201 | K7: 3.8034416 | L7: 315.733 | M7: 2.7603865 | N7: 16.740495 | O7: 2.7634156 | P7: 95.926001 | Q7: 6.4946514 | R7: 6.380008 | S7: 6.4471226 | T7: =MINDSET!D58 -> 242 | AA7: 2020 | AB7: =U10 -> 1.007236 | AC7: =(AB37-AB7)/30 -> 0.053136869 | AE7: =(AI36-AI6)/30 -> 0.16349108 | AF7: 2021 | AG7: 0 | AH7: =AH6+$AE$6 -> 1.6541295 | AI7: =AI6+$AE$7 -> 1.9793008 | AJ7: =AJ6+$AE$8 -> 2.7509651 | AK7: =AK6+$AE$9 -> 2.8782746 | AN7: =(AR36-AR6)/30 -> 0.15437556 | AO7: 2021 | AQ7: =AQ6+$AN$6 -> 1.6190277 | AR7: =AR6+$AN$7 -> 1.9217063 | AS7: =AS6+$AN$8 -> 2.6552861 | AT7: =AT6+$AN$9 -> 2.7832633 | AW7: =(AZ36-AZ6)/30 -> 0.1544948 | AY7: =AY6+$AW$6 -> 1.6188434 | AZ7: =AZ6+$AW$7 -> 1.9212232 | BA7: =BA6+$AW$8 -> 2.6546965 | BB7: =BB6+$AW$9 -> 2.7827846 | BE7: =(BH36-BH6)/30 -> 0.15203534 | BG7: =BG6+$BE$6 -> 3.2302238 | BH7: =BH6+$BE$7 -> 3.9554769 | BI7: =BI6+$BE$8 -> 4.9518502 | BJ7: =BJ6+$BE$9 -> 5.1218224 | BM7: =(BP36-BP6)/30 -> 0.11840314 | BO7: =BO6+$BM$6 -> 2.4455487 | BP7: =BP6+$BM$7 -> 2.8818187 | BQ7: =BQ6+$BM$8 -> 3.6356788 | BR7: =BR6+$BM$9 -> 3.7767011 | BU7: =(BX36-BX6)/30 -> 0.21767772 | BW7: =BW6+$BU$6 -> 5.8225101 | BX7: =BX6+$BU$7 -> 6.6648003 | BY7: =BY6+$BU$8 -> 8.2987114 | BZ7: =BZ6+$BU$9 -> 8.6255503
A8: 100 | B8: 148.57835 | C8: 2.5044538 | D8: 471.64263 | E8: 2.4226856 | F8: 565.35041 | G8: 2.4218742 | H8: 2124.2693 | I8: 4.9080906 | J8: 172.23987 | K8: 4.761555 | L8: 399.5764 | M8: 3.4934114 | N8: 21.176521 | O8: 3.4956868 | P8: 119.199 | Q8: 8.0703452 | R8: 7.936351 | S8: 8.0198375 | T8: =MINDSET!E58 -> 330 | AA8: 2021 | AB8: =AB7+$AC$7 -> 1.0603729 | AE8: =(AJ36-AJ6)/30 -> 0.24651124 | AF8: 2022 | AH8: =AH7+$AE$6 -> 1.7458755 | AI8: =AI7+$AE$7 -> 2.1427919 | AJ8: =AJ7+$AE$8 -> 2.9974763 | AK8: =AK7+$AE$9 -> 3.1562707 | AN8: =(AS36-AS6)/30 -> 0.23260051 | AO8: 2022 | AQ8: =AQ7+$AN$6 -> 1.7066403 | AR8: =AR7+$AN$7 -> 2.0760819 | AS8: =AS7+$AN$8 -> 2.8878866 | AT8: =AT7+$AN$9 -> 3.0465818 | AW8: =(BA36-BA6)/30 -> 0.23282232 | AY8: =AY7+$AW$6 -> 1.7065032 | AZ8: =AZ7+$AW$7 -> 2.075718 | BA8: =BA7+$AW$8 -> 2.8875188 | BB8: =BB7+$AW$9 -> 3.046362 | BE8: =(BI36-BI6)/30 -> 0.19029518 | BG8: =BG7+$BE$6 -> 3.3478185 | BH8: =BH7+$BE$7 -> 4.1075123 | BI8: =BI7+$BE$8 -> 5.1421454 | BJ8: =BJ7+$BE$9 -> 5.3221329 | BM8: =(BQ36-BQ6)/30 -> 0.13999194 | BO8: =BO7+$BM$6 -> 2.5365619 | BP8: =BP7+$BM$7 -> 3.0002219 | BQ8: =BQ7+$BM$8 -> 3.7756707 | BR8: =BR7+$BM$9 -> 3.9177714 | BU8: =(BY36-BY6)/30 -> 0.27887385 | BW8: =BW7+$BU$6 -> 6.006645 | BX8: =BX7+$BU$7 -> 6.882478 | BY8: =BY7+$BU$8 -> 8.5775852 | BZ8: =BZ7+$BU$9 -> 8.9169097
A9: 200 | B9: 154.2632 | C9: 2.6002784 | D9: 490.57679 | E9: 2.5199447 | F9: 588.07132 | G9: 2.5192071 | H9: 2178.8823 | I9: 5.0342732 | J9: 178.026 | K9: 4.9215119 | L9: 419.1248 | M9: 3.664319 | N9: 22.024288 | O9: 3.6356308 | P9: 122.715 | Q9: 8.3083954 | R9: 8.247432 | S9: 8.3341909 | T9: =MINDSET!F58 -> 540 | U9: weighted average (%of damage of total capital in the dataset) | AA9: 2022 | AB9: =AB8+$AC$7 -> 1.1135097 | AE9: =(AK36-AK6)/30 -> 0.27799615 | AF9: 2023 | AH9: =AH8+$AE$6 -> 1.8376215 | AI9: =AI8+$AE$7 -> 2.3062829 | AJ9: =AJ8+$AE$8 -> 3.2439875 | AK9: =AK8+$AE$9 -> 3.4342668 | AN9: =(AT36-AT6)/30 -> 0.26331855 | AO9: 2023 | AQ9: =AQ8+$AN$6 -> 1.7942529 | AR9: =AR8+$AN$7 -> 2.2304574 | AS9: =AS8+$AN$8 -> 3.1204872 | AT9: =AT8+$AN$9 -> 3.3099004 | AW9: =(BB36-BB6)/30 -> 0.26357749 | AY9: =AY8+$AW$6 -> 1.794163 | AZ9: =AZ8+$AW$7 -> 2.2302128 | BA9: =BA8+$AW$8 -> 3.1203411 | BB9: =BB8+$AW$9 -> 3.3099395 | BE9: =(BJ36-BJ6)/30 -> 0.2003105 | BG9: =BG8+$BE$6 -> 3.4654131 | BH9: =BH8+$BE$7 -> 4.2595476 | BI9: =BI8+$BE$8 -> 5.3324406 | BJ9: =BJ8+$BE$9 -> 5.5224434 | BM9: =(BR36-BR6)/30 -> 0.1410703 | BO9: =BO8+$BM$6 -> 2.6275752 | BP9: =BP8+$BM$7 -> 3.118625 | BQ9: =BQ8+$BM$8 -> 3.9156626 | BR9: =BR8+$BM$9 -> 4.0588417 | BU9: =(BZ36-BZ6)/30 -> 0.29135936 | BW9: =BW8+$BU$6 -> 6.19078 | BX9: =BX8+$BU$7 -> 7.1001557 | BY9: =BY8+$BU$8 -> 8.8564591 | BZ9: =BZ8+$BU$9 -> 9.208269
A10: AAL | B10: 56.327998 | C10: 0.94947125 | D10: 180.32301 | E10: 0.92626481 | F10: 216.18826 | G10: 0.92611724 | H10: 905.13021 | I10: 2.0912891 | J10: 70.478123 | K10: 1.948361 | L10: 152.44233 | M10: 1.3327708 | N10: 8.079959 | O10: 1.3337888 | P10: 46.613182 | Q10: 3.1559365 | R10: 3.1013483 | S10: 3.133973 | T10: 59.9 | U10: ='CGE-Flood Weighted Av Calcs'!C10 -> 1.007236 | AA10: 2023 | AB10: =AB9+$AC$7 -> 1.1666466 | AF10: 2024 | AH10: =AH9+$AE$6 -> 1.9293676 | AI10: =AI9+$AE$7 -> 2.469774 | AJ10: =AJ9+$AE$8 -> 3.4904988 | AK10: =AK9+$AE$9 -> 3.712263 | AO10: 2024 | AQ10: =AQ9+$AN$6 -> 1.8818655 | AR10: =AR9+$AN$7 -> 2.384833 | AS10: =AS9+$AN$8 -> 3.3530877 | AT10: =AT9+$AN$9 -> 3.5732189 | AY10: =AY9+$AW$6 -> 1.8818227 | AZ10: =AZ9+$AW$7 -> 2.3847076 | BA10: =BA9+$AW$8 -> 3.3531634 | BB10: =BB9+$AW$9 -> 3.573517 | BG10: =BG9+$BE$6 -> 3.5830078 | BH10: =BH9+$BE$7 -> 4.4115829 | BI10: =BI9+$BE$8 -> 5.5227358 | BJ10: =BJ9+$BE$9 -> 5.7227539 | BO10: =BO9+$BM$6 -> 2.7185884 | BP10: =BP9+$BM$7 -> 3.2370281 | BQ10: =BQ9+$BM$8 -> 4.0556546 | BR10: =BR9+$BM$9 -> 4.199912 | BW10: =BW9+$BU$6 -> 6.3749149 | BX10: =BX9+$BU$7 -> 7.3178335 | BY10: =BY9+$BU$8 -> 9.1353329 | BZ10: =BZ9+$BU$9 -> 9.4996284
B11: =(B10+D10+F10)/(B10/C10+D10/E10+F10/G10) -> 0.92901857 | AA11: 2024 | AB11: =AB10+$AC$7 -> 1.2197835 | AF11: 2025 | AH11: =AH10+$AE$6 -> 2.0211136 | AI11: =AI10+$AE$7 -> 2.6332651 | AJ11: =AJ10+$AE$8 -> 3.73701 | AK11: =AK10+$AE$9 -> 3.9902591 | AO11: 2025 | AQ11: =AQ10+$AN$6 -> 1.9694781 | AR11: =AR10+$AN$7 -> 2.5392085 | AS11: =AS10+$AN$8 -> 3.5856882 | AT11: =AT10+$AN$9 -> 3.8365375 | AY11: =AY10+$AW$6 -> 1.9694825 | AZ11: =AZ10+$AW$7 -> 2.5392024 | BA11: =BA10+$AW$8 -> 3.5859858 | BB11: =BB10+$AW$9 -> 3.8370945 | BG11: =BG10+$BE$6 -> 3.7006025 | BH11: =BH10+$BE$7 -> 4.5636183 | BI11: =BI10+$BE$8 -> 5.7130309 | BJ11: =BJ10+$BE$9 -> 5.9230644 | BO11: =BO10+$BM$6 -> 2.8096017 | BP11: =BP10+$BM$7 -> 3.3554313 | BQ11: =BQ10+$BM$8 -> 4.1956465 | BR11: =BR10+$BM$9 -> 4.3409823 | BW11: =BW10+$BU$6 -> 6.5590499 | BX11: =BX10+$BU$7 -> 7.5355112 | BY11: =BY10+$BU$8 -> 9.4142068 | BZ11: =BZ10+$BU$9 -> 9.7909878
AA12: 2025 | AB12: =AB11+$AC$7 -> 1.2729203 | AF12: 2026 | AH12: =AH11+$AE$6 -> 2.1128596 | AI12: =AI11+$AE$7 -> 2.7967562 | AJ12: =AJ11+$AE$8 -> 3.9835212 | AK12: =AK11+$AE$9 -> 4.2682553 | AO12: 2026 | AQ12: =AQ11+$AN$6 -> 2.0570907 | AR12: =AR11+$AN$7 -> 2.6935841 | AS12: =AS11+$AN$8 -> 3.8182887 | AT12: =AT11+$AN$9 -> 4.099856 | AY12: =AY11+$AW$6 -> 2.0571423 | AZ12: =AZ11+$AW$7 -> 2.6936972 | BA12: =BA11+$AW$8 -> 3.8188081 | BB12: =BB11+$AW$9 -> 4.100672 | BG12: =BG11+$BE$6 -> 3.8181972 | BH12: =BH11+$BE$7 -> 4.7156536 | BI12: =BI11+$BE$8 -> 5.9033261 | BJ12: =BJ11+$BE$9 -> 6.1233749 | BO12: =BO11+$BM$6 -> 2.9006149 | BP12: =BP11+$BM$7 -> 3.4738344 | BQ12: =BQ11+$BM$8 -> 4.3356385 | BR12: =BR11+$BM$9 -> 4.4820526 | BW12: =BW11+$BU$6 -> 6.7431848 | BX12: =BX11+$BU$7 -> 7.7531889 | BY12: =BY11+$BU$8 -> 9.6930806 | BZ12: =BZ11+$BU$9 -> 10.082347
A13: Year 2050 (SSP585, no adaptation, no socio-economic projections) | AA13: 2026 | AB13: =AB12+$AC$7 -> 1.3260572 | AF13: 2027 | AH13: =AH12+$AE$6 -> 2.2046057 | AI13: =AI12+$AE$7 -> 2.9602473 | AJ13: =AJ12+$AE$8 -> 4.2300325 | AK13: =AK12+$AE$9 -> 4.5462514 | AO13: 2027 | AQ13: =AQ12+$AN$6 -> 2.1447033 | AR13: =AR12+$AN$7 -> 2.8479596 | AS13: =AS12+$AN$8 -> 4.0508892 | AT13: =AT12+$AN$9 -> 4.3631746 | AY13: =AY12+$AW$6 -> 2.1448021 | AZ13: =AZ12+$AW$7 -> 2.848192 | BA13: =BA12+$AW$8 -> 4.0516304 | BB13: =BB12+$AW$9 -> 4.3642495 | BG13: =BG12+$BE$6 -> 3.9357919 | BH13: =BH12+$BE$7 -> 4.8676889 | BI13: =BI12+$BE$8 -> 6.0936213 | BJ13: =BJ12+$BE$9 -> 6.3236854 | BO13: =BO12+$BM$6 -> 2.9916281 | BP13: =BP12+$BM$7 -> 3.5922376 | BQ13: =BQ12+$BM$8 -> 4.4756304 | BR13: =BR12+$BM$9 -> 4.6231229 | BW13: =BW12+$BU$6 -> 6.9273198 | BX13: =BX12+$BU$7 -> 7.9708666 | BY13: =BY12+$BU$8 -> 9.9719545 | BZ13: =BZ12+$BU$9 -> 10.373706
AA14: 2027 | AB14: =AB13+$AC$7 -> 1.3791941 | AF14: 2028 | AH14: =AH13+$AE$6 -> 2.2963517 | AI14: =AI13+$AE$7 -> 3.1237384 | AJ14: =AJ13+$AE$8 -> 4.4765437 | AK14: =AK13+$AE$9 -> 4.8242476 | AO14: 2028 | AQ14: =AQ13+$AN$6 -> 2.2323159 | AR14: =AR13+$AN$7 -> 3.0023352 | AS14: =AS13+$AN$8 -> 4.2834897 | AT14: =AT13+$AN$9 -> 4.6264931 | AY14: =AY13+$AW$6 -> 2.2324618 | AZ14: =AZ13+$AW$7 -> 3.0026868 | BA14: =BA13+$AW$8 -> 4.2844527 | BB14: =BB13+$AW$9 -> 4.627827 | BG14: =BG13+$BE$6 -> 4.0533866 | BH14: =BH13+$BE$7 -> 5.0197243 | BI14: =BI13+$BE$8 -> 6.2839165 | BJ14: =BJ13+$BE$9 -> 6.5239959 | BO14: =BO13+$BM$6 -> 3.0826414 | BP14: =BP13+$BM$7 -> 3.7106407 | BQ14: =BQ13+$BM$8 -> 4.6156224 | BR14: =BR13+$BM$9 -> 4.7641932 | BW14: =BW13+$BU$6 -> 7.1114548 | BX14: =BX13+$BU$7 -> 8.1885444 | BY14: =BY13+$BU$8 -> 10.250828 | BZ14: =BZ13+$BU$9 -> 10.665066
A15: RP | B15: Housing | D15: Services Sector | F15: Productive Sector | H15: Roads | L15: Schools | P15: Health Centers | AA15: 2028 | AB15: =AB14+$AC$7 -> 1.4323309 | AF15: 2029 | AH15: =AH14+$AE$6 -> 2.3880977 | AI15: =AI14+$AE$7 -> 3.2872294 | AJ15: =AJ14+$AE$8 -> 4.723055 | AK15: =AK14+$AE$9 -> 5.1022437 | AO15: 2029 | AQ15: =AQ14+$AN$6 -> 2.3199285 | AR15: =AR14+$AN$7 -> 3.1567107 | AS15: =AS14+$AN$8 -> 4.5160902 | AT15: =AT14+$AN$9 -> 4.8898117 | AY15: =AY14+$AW$6 -> 2.3201216 | AZ15: =AZ14+$AW$7 -> 3.1571816 | BA15: =BA14+$AW$8 -> 4.517275 | BB15: =BB14+$AW$9 -> 4.8914045 | BG15: =BG14+$BE$6 -> 4.1709813 | BH15: =BH14+$BE$7 -> 5.1717596 | BI15: =BI14+$BE$8 -> 6.4742116 | BJ15: =BJ14+$BE$9 -> 6.7243064 | BO15: =BO14+$BM$6 -> 3.1736546 | BP15: =BP14+$BM$7 -> 3.8290438 | BQ15: =BQ14+$BM$8 -> 4.7556143 | BR15: =BR14+$BM$9 -> 4.9052635 | BW15: =BW14+$BU$6 -> 7.2955897 | BX15: =BX14+$BU$7 -> 8.4062221 | BY15: =BY14+$BU$8 -> 10.529702 | BZ15: =BZ14+$BU$9 -> 10.956425
B16: US$ million | C16: % of total asset value | D16: US$ million | E16: % of total asset value | F16: US$ million | G16: % of total asset value | H16: km | I16: % of asset | J16: US$ million | K16: % of total asset value | L16: Number | M16: % of asset | N16: US$ million | O16: % of total asset value | P16: Number | Q16: % of asset | R16: US$ million | S16: % of total asset value | AA16: 2029 | AB16: =AB15+$AC$7 -> 1.4854678 | AF16: 2030 | AH16: =AH15+$AE$6 -> 2.4798438 | AI16: =AI15+$AE$7 -> 3.4507205 | AJ16: =AJ15+$AE$8 -> 4.9695662 | AK16: =AK15+$AE$9 -> 5.3802399 | AO16: 2030 | AQ16: =AQ15+$AN$6 -> 2.4075411 | AR16: =AR15+$AN$7 -> 3.3110863 | AS16: =AS15+$AN$8 -> 4.7486907 | AT16: =AT15+$AN$9 -> 5.1531302 | AY16: =AY15+$AW$6 -> 2.4077814 | AZ16: =AZ15+$AW$7 -> 3.3116764 | BA16: =BA15+$AW$8 -> 4.7500974 | BB16: =BB15+$AW$9 -> 5.1549819 | BG16: =BG15+$BE$6 -> 4.288576 | BH16: =BH15+$BE$7 -> 5.323795 | BI16: =BI15+$BE$8 -> 6.6645068 | BJ16: =BJ15+$BE$9 -> 6.9246169 | BO16: =BO15+$BM$6 -> 3.2646679 | BP16: =BP15+$BM$7 -> 3.947447 | BQ16: =BQ15+$BM$8 -> 4.8956063 | BR16: =BR15+$BM$9 -> 5.0463338 | BW16: =BW15+$BU$6 -> 7.4797247 | BX16: =BX15+$BU$7 -> 8.6238998 | BY16: =BY15+$BU$8 -> 10.808576 | BZ16: =BZ15+$BU$9 -> 11.247785
A17: 10 | B17: 255.97734 | C17: 4.3147645 | D17: 809.82217 | E17: 4.1597932 | F17: 971.32228 | G17: 4.1609767 | H17: 3140.9923 | I17: 7.2572132 | J17: 240.20592 | K17: 6.6404699 | L17: 581.6146 | M17: 5.0849327 | N17: 30.825574 | O17: 5.0849328 | P17: 164.869 | Q17: 11.162424 | R17: 11.046223 | S17: 11.162424 | AA17: 2030 | AB17: =AB16+$AC$7 -> 1.5386047 | AF17: 2031 | AH17: =AH16+$AE$6 -> 2.5715898 | AI17: =AI16+$AE$7 -> 3.6142116 | AJ17: =AJ16+$AE$8 -> 5.2160774 | AK17: =AK16+$AE$9 -> 5.658236 | AO17: 2031 | AQ17: =AQ16+$AN$6 -> 2.4951537 | AR17: =AR16+$AN$7 -> 3.4654619 | AS17: =AS16+$AN$8 -> 4.9812912 | AT17: =AT16+$AN$9 -> 5.4164488 | AY17: =AY16+$AW$6 -> 2.4954411 | AZ17: =AZ16+$AW$7 -> 3.4661712 | BA17: =BA16+$AW$8 -> 4.9829197 | BB17: =BB16+$AW$9 -> 5.4185594 | BG17: =BG16+$BE$6 -> 4.4061707 | BH17: =BH16+$BE$7 -> 5.4758303 | BI17: =BI16+$BE$8 -> 6.854802 | BJ17: =BJ16+$BE$9 -> 7.1249274 | BO17: =BO16+$BM$6 -> 3.3556811 | BP17: =BP16+$BM$7 -> 4.0658501 | BQ17: =BQ16+$BM$8 -> 5.0355982 | BR17: =BR16+$BM$9 -> 5.1874041 | BW17: =BW16+$BU$6 -> 7.6638596 | BX17: =BX16+$BU$7 -> 8.8415775 | BY17: =BY16+$BU$8 -> 11.08745 | BZ17: =BZ16+$BU$9 -> 11.539144
A18: 25 | B18: 398.7023 | C18: 6.7205422 | D18: 1245.6691 | E18: 6.3985974 | F18: 1494.3583 | G18: 6.4015724 | H18: 3811.0608 | I18: 8.805396 | J18: 302.56937 | K18: 8.3645017 | L18: 722.36802 | M18: 6.3155098 | N18: 38.285504 | O18: 6.3155097 | P18: 191.677 | Q18: 12.977454 | R18: 12.842359 | S18: 12.977454 | AA18: 2031 | AB18: =AB17+$AC$7 -> 1.5917416 | AF18: 2032 | AH18: =AH17+$AE$6 -> 2.6633358 | AI18: =AI17+$AE$7 -> 3.7777027 | AJ18: =AJ17+$AE$8 -> 5.4625887 | AK18: =AK17+$AE$9 -> 5.9362321 | AO18: 2032 | AQ18: =AQ17+$AN$6 -> 2.5827664 | AR18: =AR17+$AN$7 -> 3.6198374 | AS18: =AS17+$AN$8 -> 5.2138917 | AT18: =AT17+$AN$9 -> 5.6797674 | AY18: =AY17+$AW$6 -> 2.5831009 | AZ18: =AZ17+$AW$7 -> 3.620666 | BA18: =BA17+$AW$8 -> 5.215742 | BB18: =BB17+$AW$9 -> 5.6821369 | BG18: =BG17+$BE$6 -> 4.5237654 | BH18: =BH17+$BE$7 -> 5.6278656 | BI18: =BI17+$BE$8 -> 7.0450972 | BJ18: =BJ17+$BE$9 -> 7.3252379 | BO18: =BO17+$BM$6 -> 3.4466944 | BP18: =BP17+$BM$7 -> 4.1842532 | BQ18: =BQ17+$BM$8 -> 5.1755901 | BR18: =BR17+$BM$9 -> 5.3284744 | BW18: =BW17+$BU$6 -> 7.8479946 | BX18: =BX17+$BU$7 -> 9.0592553 | BY18: =BY17+$BU$8 -> 11.366324 | BZ18: =BZ17+$BU$9 -> 11.830503
A19: 100 | B19: 587.31413 | C19: 9.899791 | D19: 1830.114 | E19: 9.4007008 | F19: 2195.8271 | G19: 9.4065437 | H19: 4628.7882 | I19: 10.694742 | J19: 378.74647 | K19: 10.47041 | L19: 880.20501 | M19: 7.6954451 | N19: 46.650866 | O19: 7.6954451 | P19: 242.022 | Q19: 16.386053 | R19: 16.215474 | S19: 16.386053 | AA19: 2032 | AB19: =AB18+$AC$7 -> 1.6448784 | AF19: 2033 | AH19: =AH18+$AE$6 -> 2.7550819 | AI19: =AI18+$AE$7 -> 3.9411938 | AJ19: =AJ18+$AE$8 -> 5.7090999 | AK19: =AK18+$AE$9 -> 6.2142283 | AO19: 2033 | AQ19: =AQ18+$AN$6 -> 2.670379 | AR19: =AR18+$AN$7 -> 3.774213 | AS19: =AS18+$AN$8 -> 5.4464922 | AT19: =AT18+$AN$9 -> 5.9430859 | AY19: =AY18+$AW$6 -> 2.6707607 | AZ19: =AZ18+$AW$7 -> 3.7751608 | BA19: =BA18+$AW$8 -> 5.4485643 | BB19: =BB18+$AW$9 -> 5.9457144 | BG19: =BG18+$BE$6 -> 4.6413601 | BH19: =BH18+$BE$7 -> 5.779901 | BI19: =BI18+$BE$8 -> 7.2353924 | BJ19: =BJ18+$BE$9 -> 7.5255484 | BO19: =BO18+$BM$6 -> 3.5377076 | BP19: =BP18+$BM$7 -> 4.3026564 | BQ19: =BQ18+$BM$8 -> 5.3155821 | BR19: =BR18+$BM$9 -> 5.4695447 | BW19: =BW18+$BU$6 -> 8.0321295 | BX19: =BX18+$BU$7 -> 9.276933 | BY19: =BY18+$BU$8 -> 11.645198 | BZ19: =BZ18+$BU$9 -> 12.121863
A20: 200 | B20: 649.03514 | C20: 10.940163 | D20: 2028.4525 | E20: 10.419501 | F20: 2433.9292 | G20: 10.426532 | H20: 4773.8522 | I20: 11.02991 | J20: 395.40113 | K20: 10.930827 | L20: 899.91207 | M20: 7.8677398 | N20: 47.69534 | O20: 7.8677398 | P20: 252.19733 | Q20: 17.074972 | R20: 16.897221 | S20: 17.074972 | U20: weighted average | AA20: 2033 | AB20: =AB19+$AC$7 -> 1.6980153 | AF20: 2034 | AH20: =AH19+$AE$6 -> 2.8468279 | AI20: =AI19+$AE$7 -> 4.1046849 | AJ20: =AJ19+$AE$8 -> 5.9556112 | AK20: =AK19+$AE$9 -> 6.4922244 | AO20: 2034 | AQ20: =AQ19+$AN$6 -> 2.7579916 | AR20: =AR19+$AN$7 -> 3.9285885 | AS20: =AS19+$AN$8 -> 5.6790927 | AT20: =AT19+$AN$9 -> 6.2064045 | AY20: =AY19+$AW$6 -> 2.7584204 | AZ20: =AZ19+$AW$7 -> 3.9296556 | BA20: =BA19+$AW$8 -> 5.6813866 | BB20: =BB19+$AW$9 -> 6.2092919 | BG20: =BG19+$BE$6 -> 4.7589548 | BH20: =BH19+$BE$7 -> 5.9319363 | BI20: =BI19+$BE$8 -> 7.4256875 | BJ20: =BJ19+$BE$9 -> 7.7258589 | BO20: =BO19+$BM$6 -> 3.6287209 | BP20: =BP19+$BM$7 -> 4.4210595 | BQ20: =BQ19+$BM$8 -> 5.455574 | BR20: =BR19+$BM$9 -> 5.610615 | BW20: =BW19+$BU$6 -> 8.2162645 | BX20: =BX19+$BU$7 -> 9.4946107 | BY20: =BY19+$BU$8 -> 11.924071 | BZ20: =BZ19+$BU$9 -> 12.413222
A21: AAL | B21: 151.21875 | C21: 2.5489494 | D21: 479.48056 | E21: 2.4629358 | F21: 574.96418 | G21: 2.4630471 | H21: 1930.6804 | I21: 4.4608067 | J21: 148.34601 | K21: 4.1010115 | L21: 347.63053 | M21: 3.0392598 | N21: 18.424418 | O21: 3.0392598 | P21: 119.52164 | Q21: 8.0921893 | R21: 8.0079496 | S21: 8.0921893 | U21: ='CGE-Flood Weighted Av Calcs'!C25 -> 2.6013421 | AA21: 2034 | AB21: =AB20+$AC$7 -> 1.7511522 | AF21: 2035 | AH21: =AH20+$AE$6 -> 2.9385739 | AI21: =AI20+$AE$7 -> 4.2681759 | AJ21: =AJ20+$AE$8 -> 6.2021224 | AK21: =AK20+$AE$9 -> 6.7702206 | AO21: 2035 | AQ21: =AQ20+$AN$6 -> 2.8456042 | AR21: =AR20+$AN$7 -> 4.0829641 | AS21: =AS20+$AN$8 -> 5.9116932 | AT21: =AT20+$AN$9 -> 6.469723 | AY21: =AY20+$AW$6 -> 2.8460802 | AZ21: =AZ20+$AW$7 -> 4.0841504 | BA21: =BA20+$AW$8 -> 5.9142089 | BB21: =BB20+$AW$9 -> 6.4728694 | BG21: =BG20+$BE$6 -> 4.8765495 | BH21: =BH20+$BE$7 -> 6.0839716 | BI21: =BI20+$BE$8 -> 7.6159827 | BJ21: =BJ20+$BE$9 -> 7.9261694 | BO21: =BO20+$BM$6 -> 3.7197341 | BP21: =BP20+$BM$7 -> 4.5394626 | BQ21: =BQ20+$BM$8 -> 5.595566 | BR21: =BR20+$BM$9 -> 5.7516853 | BW21: =BW20+$BU$6 -> 8.4003995 | BX21: =BX20+$BU$7 -> 9.7122884 | BY21: =BY20+$BU$8 -> 12.202945 | BZ21: =BZ20+$BU$9 -> 12.704581
B22: =(B21+D21+F21)/(B21/C21+D21/E21+F21/G21) -> 2.4734578 | AA22: 2035 | AB22: =AB21+$AC$7 -> 1.804289 | AF22: 2036 | AH22: =AH21+$AE$6 -> 3.03032 | AI22: =AI21+$AE$7 -> 4.431667 | AJ22: =AJ21+$AE$8 -> 6.4486336 | AK22: =AK21+$AE$9 -> 7.0482167 | AO22: 2036 | AQ22: =AQ21+$AN$6 -> 2.9332168 | AR22: =AR21+$AN$7 -> 4.2373396 | AS22: =AS21+$AN$8 -> 6.1442937 | AT22: =AT21+$AN$9 -> 6.7330416 | AY22: =AY21+$AW$6 -> 2.93374 | AZ22: =AZ21+$AW$7 -> 4.2386452 | BA22: =BA21+$AW$8 -> 6.1470313 | BB22: =BB21+$AW$9 -> 6.7364469 | BG22: =BG21+$BE$6 -> 4.9941442 | BH22: =BH21+$BE$7 -> 6.236007 | BI22: =BI21+$BE$8 -> 7.8062779 | BJ22: =BJ21+$BE$9 -> 8.1264799 | BO22: =BO21+$BM$6 -> 3.8107473 | BP22: =BP21+$BM$7 -> 4.6578658 | BQ22: =BQ21+$BM$8 -> 5.7355579 | BR22: =BR21+$BM$9 -> 5.8927556 | BW22: =BW21+$BU$6 -> 8.5845344 | BX22: =BX21+$BU$7 -> 9.9299662 | BY22: =BY21+$BU$8 -> 12.481819 | BZ22: =BZ21+$BU$9 -> 12.995941
AA23: 2036 | AB23: =AB22+$AC$7 -> 1.8574259 | AF23: 2037 | AH23: =AH22+$AE$6 -> 3.122066 | AI23: =AI22+$AE$7 -> 4.5951581 | AJ23: =AJ22+$AE$8 -> 6.6951449 | AK23: =AK22+$AE$9 -> 7.3262129 | AO23: 2037 | AQ23: =AQ22+$AN$6 -> 3.0208294 | AR23: =AR22+$AN$7 -> 4.3917152 | AS23: =AS22+$AN$8 -> 6.3768942 | AT23: =AT22+$AN$9 -> 6.9963601 | AY23: =AY22+$AW$6 -> 3.0213997 | AZ23: =AZ22+$AW$7 -> 4.39314 | BA23: =BA22+$AW$8 -> 6.3798536 | BB23: =BB22+$AW$9 -> 7.0000244 | BG23: =BG22+$BE$6 -> 5.1117389 | BH23: =BH22+$BE$7 -> 6.3880423 | BI23: =BI22+$BE$8 -> 7.9965731 | BJ23: =BJ22+$BE$9 -> 8.3267904 | BO23: =BO22+$BM$6 -> 3.9017606 | BP23: =BP22+$BM$7 -> 4.7762689 | BQ23: =BQ22+$BM$8 -> 5.8755499 | BR23: =BR22+$BM$9 -> 6.0338259 | BW23: =BW22+$BU$6 -> 8.7686694 | BX23: =BX22+$BU$7 -> 10.147644 | BY23: =BY22+$BU$8 -> 12.760693 | BZ23: =BZ22+$BU$9 -> 13.2873
A24: Year 2050 (SSP585, no adaptation, with socio-economic projections) | AA24: 2037 | AB24: =AB23+$AC$7 -> 1.9105628 | AF24: 2038 | AH24: =AH23+$AE$6 -> 3.213812 | AI24: =AI23+$AE$7 -> 4.7586492 | AJ24: =AJ23+$AE$8 -> 6.9416561 | AK24: =AK23+$AE$9 -> 7.604209 | AO24: 2038 | AQ24: =AQ23+$AN$6 -> 3.108442 | AR24: =AR23+$AN$7 -> 4.5460907 | AS24: =AS23+$AN$8 -> 6.6094947 | AT24: =AT23+$AN$9 -> 7.2596787 | AY24: =AY23+$AW$6 -> 3.1090595 | AZ24: =AZ23+$AW$7 -> 4.5476348 | BA24: =BA23+$AW$8 -> 6.6126759 | BB24: =BB23+$AW$9 -> 7.2636018 | BG24: =BG23+$BE$6 -> 5.2293336 | BH24: =BH23+$BE$7 -> 6.5400776 | BI24: =BI23+$BE$8 -> 8.1868682 | BJ24: =BJ23+$BE$9 -> 8.5271009 | BO24: =BO23+$BM$6 -> 3.9927738 | BP24: =BP23+$BM$7 -> 4.8946721 | BQ24: =BQ23+$BM$8 -> 6.0155418 | BR24: =BR23+$BM$9 -> 6.1748962 | BW24: =BW23+$BU$6 -> 8.9528043 | BX24: =BX23+$BU$7 -> 10.365322 | BY24: =BY23+$BU$8 -> 13.039567 | BZ24: =BZ23+$BU$9 -> 13.57866
AA25: 2038 | AB25: =AB24+$AC$7 -> 1.9636996 | AF25: 2039 | AH25: =AH24+$AE$6 -> 3.3055581 | AI25: =AI24+$AE$7 -> 4.9221403 | AJ25: =AJ24+$AE$8 -> 7.1881673 | AK25: =AK24+$AE$9 -> 7.8822052 | AO25: 2039 | AQ25: =AQ24+$AN$6 -> 3.1960546 | AR25: =AR24+$AN$7 -> 4.7004663 | AS25: =AS24+$AN$8 -> 6.8420953 | AT25: =AT24+$AN$9 -> 7.5229972 | AY25: =AY24+$AW$6 -> 3.1967193 | AZ25: =AZ24+$AW$7 -> 4.7021296 | BA25: =BA24+$AW$8 -> 6.8454982 | BB25: =BB24+$AW$9 -> 7.5271793 | BG25: =BG24+$BE$6 -> 5.3469283 | BH25: =BH24+$BE$7 -> 6.692113 | BI25: =BI24+$BE$8 -> 8.3771634 | BJ25: =BJ24+$BE$9 -> 8.7274114 | BO25: =BO24+$BM$6 -> 4.0837871 | BP25: =BP24+$BM$7 -> 5.0130752 | BQ25: =BQ24+$BM$8 -> 6.1555338 | BR25: =BR24+$BM$9 -> 6.3159665 | BW25: =BW24+$BU$6 -> 9.1369393 | BX25: =BX24+$BU$7 -> 10.582999 | BY25: =BY24+$BU$8 -> 13.318441 | BZ25: =BZ24+$BU$9 -> 13.870019
A26: RP | B26: Housing | D26: Services Sector | F26: Productive Sector | H26: Roads | L26: Schools | P26: Health Centers | AA26: 2039 | AB26: =AB25+$AC$7 -> 2.0168365 | AF26: 2040 | AH26: =AH25+$AE$6 -> 3.3973041 | AI26: =AI25+$AE$7 -> 5.0856313 | AJ26: =AJ25+$AE$8 -> 7.4346786 | AK26: =AK25+$AE$9 -> 8.1602013 | AO26: 2040 | AQ26: =AQ25+$AN$6 -> 3.2836672 | AR26: =AR25+$AN$7 -> 4.8548419 | AS26: =AS25+$AN$8 -> 7.0746958 | AT26: =AT25+$AN$9 -> 7.7863158 | AY26: =AY25+$AW$6 -> 3.284379 | AZ26: =AZ25+$AW$7 -> 4.8566244 | BA26: =BA25+$AW$8 -> 7.0783205 | BB26: =BB25+$AW$9 -> 7.7907568 | BG26: =BG25+$BE$6 -> 5.464523 | BH26: =BH25+$BE$7 -> 6.8441483 | BI26: =BI25+$BE$8 -> 8.5674586 | BJ26: =BJ25+$BE$9 -> 8.9277219 | BO26: =BO25+$BM$6 -> 4.1748003 | BP26: =BP25+$BM$7 -> 5.1314783 | BQ26: =BQ25+$BM$8 -> 6.2955257 | BR26: =BR25+$BM$9 -> 6.4570368 | BW26: =BW25+$BU$6 -> 9.3210742 | BX26: =BX25+$BU$7 -> 10.800677 | BY26: =BY25+$BU$8 -> 13.597314 | BZ26: =BZ25+$BU$9 -> 14.161378
B27: US$ million | C27: % of total asset value | D27: US$ million | E27: % of total asset value | F27: US$ million | G27: % of total asset value | H27: km | I27: % of asset | J27: US$ million | K27: % of total asset value | L27: Number | M27: % of asset | N27: US$ million | O27: % of total asset value | P27: Number | Q27: % of asset | R27: US$ million | S27: % of total asset value | AA27: 2040 | AB27: =AB26+$AC$7 -> 2.0699734 | AF27: 2041 | AH27: =AH26+$AE$6 -> 3.4890501 | AI27: =AI26+$AE$7 -> 5.2491224 | AJ27: =AJ26+$AE$8 -> 7.6811898 | AK27: =AK26+$AE$9 -> 8.4381975 | AO27: 2041 | AQ27: =AQ26+$AN$6 -> 3.3712798 | AR27: =AR26+$AN$7 -> 5.0092174 | AS27: =AS26+$AN$8 -> 7.3072963 | AT27: =AT26+$AN$9 -> 8.0496343 | AY27: =AY26+$AW$6 -> 3.3720388 | AZ27: =AZ26+$AW$7 -> 5.0111192 | BA27: =BA26+$AW$8 -> 7.3111428 | BB27: =BB26+$AW$9 -> 8.0543343 | BG27: =BG26+$BE$6 -> 5.5821176 | BH27: =BH26+$BE$7 -> 6.9961836 | BI27: =BI26+$BE$8 -> 8.7577538 | BJ27: =BJ26+$BE$9 -> 9.1280324 | BO27: =BO26+$BM$6 -> 4.2658136 | BP27: =BP26+$BM$7 -> 5.2498815 | BQ27: =BQ26+$BM$8 -> 6.4355176 | BR27: =BR26+$BM$9 -> 6.5981071 | BW27: =BW26+$BU$6 -> 9.5052092 | BX27: =BX26+$BU$7 -> 11.018355 | BY27: =BY26+$BU$8 -> 13.876188 | BZ27: =BZ26+$BU$9 -> 14.452738
A28: 10 | B28: 1462.8132 | C28: 13.453487 | D28: 4894.3245 | E28: 13.349927 | F28: 5872.4238 | G28: 13.360896 | AA28: 2041 | AB28: =AB27+$AC$7 -> 2.1231102 | AF28: 2042 | AH28: =AH27+$AE$6 -> 3.5807962 | AI28: =AI27+$AE$7 -> 5.4126135 | AJ28: =AJ27+$AE$8 -> 7.9277011 | AK28: =AK27+$AE$9 -> 8.7161936 | AO28: 2042 | AQ28: =AQ27+$AN$6 -> 3.4588924 | AR28: =AR27+$AN$7 -> 5.163593 | AS28: =AS27+$AN$8 -> 7.5398968 | AT28: =AT27+$AN$9 -> 8.3129529 | AY28: =AY27+$AW$6 -> 3.4596986 | AZ28: =AZ27+$AW$7 -> 5.165614 | BA28: =BA27+$AW$8 -> 7.5439652 | BB28: =BB27+$AW$9 -> 8.3179118 | BG28: =BG27+$BE$6 -> 5.6997123 | BH28: =BH27+$BE$7 -> 7.148219 | BI28: =BI27+$BE$8 -> 8.948049 | BJ28: =BJ27+$BE$9 -> 9.3283429 | BO28: =BO27+$BM$6 -> 4.3568268 | BP28: =BP27+$BM$7 -> 5.3682846 | BQ28: =BQ27+$BM$8 -> 6.5755096 | BR28: =BR27+$BM$9 -> 6.7391774 | BW28: =BW27+$BU$6 -> 9.6893442 | BX28: =BX27+$BU$7 -> 11.236033 | BY28: =BY27+$BU$8 -> 14.155062 | BZ28: =BZ27+$BU$9 -> 14.744097
A29: 25 | B29: 1677.4659 | C29: 15.427647 | D29: 5623.1096 | E29: 15.337786 | F29: 6746.8152 | G29: 15.350305 | AA29: 2042 | AB29: =AB28+$AC$7 -> 2.1762471 | AF29: 2043 | AH29: =AH28+$AE$6 -> 3.6725422 | AI29: =AI28+$AE$7 -> 5.5761046 | AJ29: =AJ28+$AE$8 -> 8.1742123 | AK29: =AK28+$AE$9 -> 8.9941897 | AO29: 2043 | AQ29: =AQ28+$AN$6 -> 3.546505 | AR29: =AR28+$AN$7 -> 5.3179685 | AS29: =AS28+$AN$8 -> 7.7724973 | AT29: =AT28+$AN$9 -> 8.5762714 | AY29: =AY28+$AW$6 -> 3.5473583 | AZ29: =AZ28+$AW$7 -> 5.3201088 | BA29: =BA28+$AW$8 -> 7.7767875 | BB29: =BB28+$AW$9 -> 8.5814893 | BG29: =BG28+$BE$6 -> 5.817307 | BH29: =BH28+$BE$7 -> 7.3002543 | BI29: =BI28+$BE$8 -> 9.1383441 | BJ29: =BJ28+$BE$9 -> 9.5286534 | BO29: =BO28+$BM$6 -> 4.4478401 | BP29: =BP28+$BM$7 -> 5.4866877 | BQ29: =BQ28+$BM$8 -> 6.7155015 | BR29: =BR28+$BM$9 -> 6.8802477 | BW29: =BW28+$BU$6 -> 9.8734791 | BX29: =BX28+$BU$7 -> 11.45371 | BY29: =BY28+$BU$8 -> 14.433936 | BZ29: =BZ28+$BU$9 -> 15.035456
A30: 100 | B30: 2143.348 | C30: 19.712363 | D30: 7125.3364 | E30: 19.435311 | F30: 8538.0277 | G30: 19.425659 | AA30: 2043 | AB30: =AB29+$AC$7 -> 2.229384 | AF30: 2044 | AH30: =AH29+$AE$6 -> 3.7642882 | AI30: =AI29+$AE$7 -> 5.7395957 | AJ30: =AJ29+$AE$8 -> 8.4207235 | AK30: =AK29+$AE$9 -> 9.2721859 | AO30: 2044 | AQ30: =AQ29+$AN$6 -> 3.6341176 | AR30: =AR29+$AN$7 -> 5.4723441 | AS30: =AS29+$AN$8 -> 8.0050978 | AT30: =AT29+$AN$9 -> 8.83959 | AY30: =AY29+$AW$6 -> 3.6350181 | AZ30: =AZ29+$AW$7 -> 5.4746036 | BA30: =BA29+$AW$8 -> 8.0096098 | BB30: =BB29+$AW$9 -> 8.8450668 | BG30: =BG29+$BE$6 -> 5.9349017 | BH30: =BH29+$BE$7 -> 7.4522897 | BI30: =BI29+$BE$8 -> 9.3286393 | BJ30: =BJ29+$BE$9 -> 9.7289639 | BO30: =BO29+$BM$6 -> 4.5388533 | BP30: =BP29+$BM$7 -> 5.6050909 | BQ30: =BQ29+$BM$8 -> 6.8554935 | BR30: =BR29+$BM$9 -> 7.021318 | BW30: =BW29+$BU$6 -> 10.057614 | BX30: =BX29+$BU$7 -> 11.671388 | BY30: =BY29+$BU$8 -> 14.71281 | BZ30: =BZ29+$BU$9 -> 15.326816
A31: 200 | B31: 2210.5224 | C31: 20.330165 | D31: 7396.5671 | E31: 20.17513 | F31: 8870.6763 | G31: 20.182498 | AA31: 2044 | AB31: =AB30+$AC$7 -> 2.2825209 | AF31: 2045 | AH31: =AH30+$AE$6 -> 3.8560343 | AI31: =AI30+$AE$7 -> 5.9030868 | AJ31: =AJ30+$AE$8 -> 8.6672348 | AK31: =AK30+$AE$9 -> 9.550182 | AO31: 2045 | AQ31: =AQ30+$AN$6 -> 3.7217302 | AR31: =AR30+$AN$7 -> 5.6267196 | AS31: =AS30+$AN$8 -> 8.2376983 | AT31: =AT30+$AN$9 -> 9.1029086 | AY31: =AY30+$AW$6 -> 3.7226779 | AZ31: =AZ30+$AW$7 -> 5.6290984 | BA31: =BA30+$AW$8 -> 8.2424321 | BB31: =BB30+$AW$9 -> 9.1086443 | BG31: =BG30+$BE$6 -> 6.0524964 | BH31: =BH30+$BE$7 -> 7.604325 | BI31: =BI30+$BE$8 -> 9.5189345 | BJ31: =BJ30+$BE$9 -> 9.9292744 | BO31: =BO30+$BM$6 -> 4.6298665 | BP31: =BP30+$BM$7 -> 5.723494 | BQ31: =BQ30+$BM$8 -> 6.9954854 | BR31: =BR30+$BM$9 -> 7.1623883 | BW31: =BW30+$BU$6 -> 10.241749 | BX31: =BX30+$BU$7 -> 11.889066 | BY31: =BY30+$BU$8 -> 14.991684 | BZ31: =BZ30+$BU$9 -> 15.618175
A32: AAL | B32: 1256.3529 | C32: 11.554672 | D32: 4190.7359 | E32: 11.430795 | F32: 5027.0316 | G32: 11.437466 | AA32: 2045 | AB32: =AB31+$AC$7 -> 2.3356577 | AF32: 2046 | AH32: =AH31+$AE$6 -> 3.9477803 | AI32: =AI31+$AE$7 -> 6.0665778 | AJ32: =AJ31+$AE$8 -> 8.913746 | AK32: =AK31+$AE$9 -> 9.8281782 | AO32: 2046 | AQ32: =AQ31+$AN$6 -> 3.8093428 | AR32: =AR31+$AN$7 -> 5.7810952 | AS32: =AS31+$AN$8 -> 8.4702988 | AT32: =AT31+$AN$9 -> 9.3662271 | AY32: =AY31+$AW$6 -> 3.8103376 | AZ32: =AZ31+$AW$7 -> 5.7835932 | BA32: =BA31+$AW$8 -> 8.4752544 | BB32: =BB31+$AW$9 -> 9.3722217 | BG32: =BG31+$BE$6 -> 6.1700911 | BH32: =BH31+$BE$7 -> 7.7563603 | BI32: =BI31+$BE$8 -> 9.7092297 | BJ32: =BJ31+$BE$9 -> 10.129585 | BO32: =BO31+$BM$6 -> 4.7208798 | BP32: =BP31+$BM$7 -> 5.8418971 | BQ32: =BQ31+$BM$8 -> 7.1354774 | BR32: =BR31+$BM$9 -> 7.3034586 | BW32: =BW31+$BU$6 -> 10.425884 | BX32: =BX31+$BU$7 -> 12.106743 | BY32: =BY31+$BU$8 -> 15.270558 | BZ32: =BZ31+$BU$9 -> 15.909534
B33: =(B32+D32+F32)/(B32/C32+D32/E32+F32/G32) -> 11.448722 | AA33: 2046 | AB33: =AB32+$AC$7 -> 2.3887946 | AF33: 2047 | AH33: =AH32+$AE$6 -> 4.0395264 | AI33: =AI32+$AE$7 -> 6.2300689 | AJ33: =AJ32+$AE$8 -> 9.1602573 | AK33: =AK32+$AE$9 -> 10.106174 | AO33: 2047 | AQ33: =AQ32+$AN$6 -> 3.8969554 | AR33: =AR32+$AN$7 -> 5.9354707 | AS33: =AS32+$AN$8 -> 8.7028993 | AT33: =AT32+$AN$9 -> 9.6295457 | AY33: =AY32+$AW$6 -> 3.8979974 | AZ33: =AZ32+$AW$7 -> 5.938088 | BA33: =BA32+$AW$8 -> 8.7080767 | BB33: =BB32+$AW$9 -> 9.6357992 | BG33: =BG32+$BE$6 -> 6.2876858 | BH33: =BH32+$BE$7 -> 7.9083957 | BI33: =BI32+$BE$8 -> 9.8995248 | BJ33: =BJ32+$BE$9 -> 10.329895 | BO33: =BO32+$BM$6 -> 4.811893 | BP33: =BP32+$BM$7 -> 5.9603003 | BQ33: =BQ32+$BM$8 -> 7.2754693 | BR33: =BR32+$BM$9 -> 7.4445289 | BW33: =BW32+$BU$6 -> 10.610019 | BX33: =BX32+$BU$7 -> 12.324421 | BY33: =BY32+$BU$8 -> 15.549431 | BZ33: =BZ32+$BU$9 -> 16.200894
AA34: 2047 | AB34: =AB33+$AC$7 -> 2.4419315 | AF34: 2048 | AH34: =AH33+$AE$6 -> 4.1312724 | AI34: =AI33+$AE$7 -> 6.39356 | AJ34: =AJ33+$AE$8 -> 9.4067685 | AK34: =AK33+$AE$9 -> 10.38417 | AO34: 2048 | AQ34: =AQ33+$AN$6 -> 3.984568 | AR34: =AR33+$AN$7 -> 6.0898463 | AS34: =AS33+$AN$8 -> 8.9354998 | AT34: =AT33+$AN$9 -> 9.8928642 | AY34: =AY33+$AW$6 -> 3.9856572 | AZ34: =AZ33+$AW$7 -> 6.0925828 | BA34: =BA33+$AW$8 -> 8.9408991 | BB34: =BB33+$AW$9 -> 9.8993767 | BG34: =BG33+$BE$6 -> 6.4052805 | BH34: =BH33+$BE$7 -> 8.060431 | BI34: =BI33+$BE$8 -> 10.08982 | BJ34: =BJ33+$BE$9 -> 10.530206 | BO34: =BO33+$BM$6 -> 4.9029063 | BP34: =BP33+$BM$7 -> 6.0787034 | BQ34: =BQ33+$BM$8 -> 7.4154613 | BR34: =BR33+$BM$9 -> 7.5855992 | BW34: =BW33+$BU$6 -> 10.794154 | BX34: =BX33+$BU$7 -> 12.542099 | BY34: =BY33+$BU$8 -> 15.828305 | BZ34: =BZ33+$BU$9 -> 16.492253
A35: Year 2050 (SSP126, no adaptation, no socio-economic projections) | AA35: 2048 | AB35: =AB34+$AC$7 -> 2.4950683 | AF35: 2049 | AH35: =AH34+$AE$6 -> 4.2230184 | AI35: =AI34+$AE$7 -> 6.5570511 | AJ35: =AJ34+$AE$8 -> 9.6532797 | AK35: =AK34+$AE$9 -> 10.662167 | AO35: 2049 | AQ35: =AQ34+$AN$6 -> 4.0721806 | AR35: =AR34+$AN$7 -> 6.2442219 | AS35: =AS34+$AN$8 -> 9.1681003 | AT35: =AT34+$AN$9 -> 10.156183 | AY35: =AY34+$AW$6 -> 4.0733169 | AZ35: =AZ34+$AW$7 -> 6.2470776 | BA35: =BA34+$AW$8 -> 9.1737214 | BB35: =BB34+$AW$9 -> 10.162954 | BG35: =BG34+$BE$6 -> 6.5228752 | BH35: =BH34+$BE$7 -> 8.2124663 | BI35: =BI34+$BE$8 -> 10.280115 | BJ35: =BJ34+$BE$9 -> 10.730516 | BO35: =BO34+$BM$6 -> 4.9939195 | BP35: =BP34+$BM$7 -> 6.1971066 | BQ35: =BQ34+$BM$8 -> 7.5554532 | BR35: =BR34+$BM$9 -> 7.7266695 | BW35: =BW34+$BU$6 -> 10.978289 | BX35: =BX34+$BU$7 -> 12.759777 | BY35: =BY34+$BU$8 -> 16.107179 | BZ35: =BZ34+$BU$9 -> 16.783613
AA36: 2049 | AB36: =AB35+$AC$7 -> 2.5482052 | AF36: 2050 | AH36: =C17 -> 4.3147645 | AI36: =C18 -> 6.7205422 | AJ36: =C19 -> 9.899791 | AK36: =C20 -> 10.940163 | AO36: 2050 | AQ36: =E17 -> 4.1597932 | AR36: =E18 -> 6.3985974 | AS36: =E19 -> 9.4007008 | AT36: =E20 -> 10.419501 | AY36: =G17 -> 4.1609767 | AZ36: =G18 -> 6.4015724 | BA36: =G19 -> 9.4065437 | BB36: =G20 -> 10.426532 | BG36: =K17 -> 6.6404699 | BH36: =K18 -> 8.3645017 | BI36: =K19 -> 10.47041 | BJ36: =K20 -> 10.930827 | BO36: =O17 -> 5.0849328 | BP36: =O18 -> 6.3155097 | BQ36: =O19 -> 7.6954451 | BR36: =O20 -> 7.8677398 | BW36: =S17 -> 11.162424 | BX36: =S18 -> 12.977454 | BY36: =S19 -> 16.386053 | BZ36: =S20 -> 17.074972
A37: RP | B37: Housing | D37: Services Sector | F37: Productive Sector | H37: Roads | L37: Schools | P37: Health Centers | AA37: 2050 | AB37: =U21 -> 2.6013421
B38: US$ million | C38: % of total asset value | D38: US$ million | E38: % of total asset value | F38: US$ million | G38: % of total asset value | H38: km | I38: % of asset | J38: US$ million | K38: % of total asset value | L38: Number | M38: % of asset | N38: US$ million | O38: % of total asset value | P38: Number | Q38: % of asset | R38: US$ million | S38: % of total asset value
A39: 10 | B39: 92.110701 | C39: 1.5526217 | D39: 296.13614 | E39: 1.5211551 | F39: 355.22143 | G39: 1.5217072 | H39: 1432.6084 | I39: 3.3100191 | J39: 112.35875 | K39: 3.106147 | L39: 249.3656 | M39: 2.1801504 | N39: 13.216377 | O39: 2.1801504 | P39: 84.761001 | Q39: 5.7387272 | R39: 5.678987 | S39: 5.7387272
A40: 25 | B40: 127.69091 | C40: 2.1523632 | D40: 410.16144 | E40: 2.106866 | F40: 492.00771 | G40: 2.107676 | H40: 1975.8847 | I40: 4.5652504 | J40: 153.68206 | K40: 4.2485261 | L40: 347.235 | M40: 3.0358017 | N40: 18.403455 | O40: 3.0358017 | P40: 105.512 | Q40: 7.1436697 | R40: 7.0693041 | S40: 7.1436697
A41: 100 | B41: 173.01309 | C41: 2.9163158 | D41: 555.8557 | E41: 2.8552501 | F41: 666.55344 | G41: 2.8553997 | H41: 2447.7032 | I41: 5.6553796 | J41: 182.64105 | K41: 5.0490946 | L41: 422.4004 | M41: 3.6929568 | N41: 22.387221 | O41: 3.6929568 | P41: 126.277 | Q41: 8.5495598 | R41: 8.460559 | S41: 8.5495599
A42: 200 | B42: 197.68943 | C42: 3.3322611 | D42: 624.93368 | E42: 3.2100812 | F42: 749.42885 | G42: 3.2104236 | H42: 2686.5775 | I42: 6.2072951 | J42: 197.00296 | K42: 5.4461281 | L42: 442.8104 | M42: 3.8713971 | N42: 23.468951 | O42: 3.8713971 | P42: 132.65033 | Q42: 8.9810651 | R42: 8.8875723 | S42: 8.9810652
...

Sheet MINDSET
A1: Risk curves corresponding to flood and drought
A2: Housing
A3: Return Period | B3: 1 | C3: 10 | D3: 25 | E3: 100 | F3: 200
A4: Exceedance Probability (1/return period) | B4: =1/B3 -> 1 | C4: =1/C3 -> 0.1 | D4: =1/D3 -> 0.04 | E4: =1/E3 -> 0.01 | F4: =1/F3 -> 0.005
A5: Probable Maximum Losses (US$million) | B5: 0 | C5: 92.69 | D5: 107.72 | E5: 148.58 | F5: 154.26
A6: Probable Maximum Losses (% value) | B6: 0 | C6: ='[1]Flood (national AAL PML)'!$C$6 -> 1.5623834 | D6: ='[1]Flood (national AAL PML)'!$C$7 -> 1.8158097 | E6: 2.5 | F6: 2.6
A8: Flood
A9: Services
A10: Return Period | B10: 1 | C10: 10 | D10: 25 | E10: 100 | F10: 200
A11: Exceedance Probability (1/return period) | B11: =1/B10 -> 1 | C11: =1/C10 -> 0.1 | D11: =1/D10 -> 0.04 | E11: =1/E10 -> 0.01 | F11: =1/F10 -> 0.005
A12: Probable Maximum Losses (US$million) | B12: 0 | C12: 298.13222 | D12: 344.05971 | E12: 471.64263 | F12: 490.57679
A13: Probable Maximum Losses (% value) | B13: 0 | C13: 1.5314151 | D13: 1.7673307 | E13: 2.42 | F13: 2.52
A14: % of innundated asset (2020, 1m) | B14: 0 | C14: 0.25 | D14: 0.29 | E14: 0.33 | F14: 0.34
A15: % of innundated asset (2020, 2m) | B15: 0 | C15: 0.09 | D15: 0.16 | E15: 0.18 | F15: 0.19
A16: % of innundated asset (2030, 1m, SSP585) | B16: 0 | C16: =Interpolation!B15 -> 0.32051116 | D16: =Interpolation!F15 -> 0.36158403 | E16: =Interpolation!J15 -> 0.39891607 | F16: =Interpolation!N15 -> 0.4119898
A17: % of innundated asset (2030, 2m, SSP585) | B17: 0 | C17: =Interpolation!B52 -> 0.21351988 | D17: =Interpolation!F52 -> 0.27467409 | E17: =Interpolation!J52 -> 0.29886157 | F17: =Interpolation!N52 -> 0.31192852
A18: % of innundated asset (2050, 1m,SSP585) | B18: 0 | C18: =Inundation!C14 -> 0.46153347 | D18: =Inundation!C15 -> 0.50475209 | E18: =Inundation!C16 -> 0.5367482 | F18: =Inundation!C17 -> 0.55596941
A19: % of innundated asset (2050, 2m,SSP585) | B19: 0 | C19: =Inundation!I14 -> 0.46055964 | D19: =Inundation!I15 -> 0.50402228 | E19: =Inundation!I16 -> 0.5365847 | F19: =Inundation!I17 -> 0.55578557
A20: Innundation duration | B20: 0 | C20: 7 | D20: 8 | E20: 14 | F20: 21
A22: Productive
A23: Return Period | B23: 1 | C23: 10 | D23: 25 | E23: 100 | F23: 200
A24: Exceedance Probability (1/return period) | B24: 1 | C24: 0.1 | D24: 0.04 | E24: 0.01 | F24: 0.005
A25: Probable Maximum Losses (US$million) | B25: 0 | C25: 357.43199 | D25: 412.4164 | E25: 565.35041 | F25: 588.07132
A26: Probable Maximum Losses (% value) | B26: 0 | C26: 1.5311837 | D26: 1.7667284 | E26: 2.4218742 | F26: 2.5192071
A27: % of innundated asset (2020, 1m) | B27: 0 | C27: =Inundation!E4 -> 0.29 | D27: 0.35 | E27: 0.39 | F27: 0.4
A28: % of innundated asset (2020, 2m) | B28: 0 | C28: =Inundation!K4 -> 0.087210612 | D28: =Inundation!K5 -> 0.15629636 | E28: =Inundation!K6 -> 0.17649637 | F28: =Inundation!K7 -> 0.19014795
A29: % of innundated asset (2030, 1m,SSP585) | B29: 0 | C29: =Interpolation!B89 -> 0.34723764 | D29: =Interpolation!F89 -> 0.40164564 | E29: =Interpolation!J89 -> 0.43898271 | F29: =Interpolation!N89 -> 0.45205741
A30: % of innundated asset (2030, 2m,SSP585) | B30: 0 | C30: =Interpolation!B125 -> 0.21172198 | D30: =Interpolation!F125 -> 0.27227006 | E30: =Interpolation!J125 -> 0.29659244 | F30: =Interpolation!N125 -> 0.31209474
A31: % of innundated asset (2050, 1m,SSP585) | B31: 0 | C31: =Inundation!E14 -> 0.46171291 | D31: =Inundation!E15 -> 0.50493692 | E31: =Inundation!E16 -> 0.53694812 | F31: =Inundation!E17 -> 0.55617224
A32: % of innundated asset (2050, 2m,SSP585) | B32: 0 | C32: =Inundation!K14 -> 0.46074473 | D32: =Inundation!K15 -> 0.50421747 | E32: =Inundation!K16 -> 0.53678458 | F32: =Inundation!K17 -> 0.55598831
A34: Roads
A35: Return Period | B35: 1 | C35: 10 | D35: 25 | E35: 100 | F35: 200
A36: Exceedance Probability (1/return period) | B36: 1 | C36: 0.1 | D36: 0.04 | E36: 0.01 | F36: 0.005
A37: Probable Maximum Losses (US$million) | B37: 0 | C37: 19.126417 | D37: 26.511668 | E37: 30.602299 | F37: 31.846409
A38: Probable Maximum Losses (% value) | B38: 0 | C38: 4.9440017 | D38: 6.8530205 | E38: 7.9104108 | F38: 8.2320018
A41: Schools
A42: Return Period | B42: 1 | C42: 10 | D42: 25 | E42: 100 | F42: 200
A43: Exceedance Probability (1/return period) | B43: 1 | C43: 0.1 | D43: 0.04 | E43: 0.01 | F43: 0.005
A44: Probable Maximum Losses (US$million) | B44: 0 | C44: 14.26354 | D44: 16.740495 | E44: 21.176521 | F44: 22.024288
A45: Probable Maximum Losses (% value) | B45: 0 | C45: 2.3545354 | D45: 2.7634156 | E45: 3.4956868 | F45: 3.6356308
...

Sheet Sheet1
B1: baseline | F1: risk-informed planning
B2: 10 yr | C2: 25 yr | D2: 100 yr | E2: 200 yr | F2: 10 yr | G2: 25 yr | H2: 100 yr | I2: 200 yr
A3: Housing | B3: 92.689411 | C3: 107.72409 | D3: 148.57835 | E3: 154.2632 | F3: =B3*0.7 -> 64.882588 | G3: =C3*0.7 -> 75.406863 | H3: =D3*0.7 -> 104.00484 | I3: =E3*0.7 -> 107.98424
A4: Service | B4: 298.13222 | C4: 344.05971 | D4: 471.64263 | E4: 490.57679 | F4: =B4*0.6 -> 178.87933 | G4: =C4*0.6 -> 206.43583 | H4: =D4*0.7 -> 330.14984 | I4: =E4*0.7 -> 343.40375
A5: Industrial | B5: 357.43199 | C5: 412.4164 | D5: 565.35041 | E5: 588.07132 | F5: =B5*0.7 -> 250.2024 | G5: =C5*0.7 -> 288.69148 | H5: =D5*0.7 -> 395.74529 | I5: =E5*0.7 -> 411.64992
A6: Road | B6: 162.67653 | C6: 220.98389 | D6: 258.93896 | E6: 267.76727 | F6: =B6*0.8 -> 130.14123 | G6: =C6*0.8 -> 176.78711 | H6: =D6*0.9 -> 233.04506 | I6: =E6*0.9 -> 240.99055
A7: School | B7: 14.26354 | C7: 16.740495 | D7: 21.176521 | E7: 22.024288 | F7: =B7*0.7 -> 9.9844782 | G7: =C7*0.7 -> 11.718347 | H7: =D7*0.7 -> 14.823565 | I7: =E7*0.7 -> 15.417002
A8: Hospitals | B8: 5.5796796 | C8: 6.380008 | D8: 7.936351 | E8: 8.247432 | F8: =B8*0.7 -> 3.9057757 | G8: =C8*0.7 -> 4.4660056 | H8: =D8*0.7 -> 5.5554457 | I8: =E8*0.7 -> 5.7732024

Sheet Interpolation
A1: Services - 2020/2050 - 1 m
A2: 10 | E2: 25 | I2: 100 | M2: 200
B3: interpolation | F3: interpolation | J3: interpolation | N3: interpolation
A5: 2020 | B5: =MINDSET!C14 -> 0.25 | C5: =(B35-B5)/30 -> 0.0070511156 | E5: 2020 | F5: =MINDSET!D14 -> 0.29 | G5: =(F35-F5)/30 -> 0.0071584029 | I5: 2020 | J5: =MINDSET!E14 -> 0.33 | K5: =(J35-J5)/30 -> 0.0068916068 | M5: 2020 | N5: =MINDSET!F14 -> 0.34 | O5: =(N35-N5)/30 -> 0.0071989802
A6: 2021 | B6: =B5+$C$5 -> 0.25705112 | E6: 2021 | F6: =F5+$G$5 -> 0.2971584 | I6: 2021 | J6: =J5+$K$5 -> 0.33689161 | M6: 2021 | N6: =N5+$O$5 -> 0.34719898
A7: 2022 | B7: =B6+$C$5 -> 0.26410223 | E7: 2022 | F7: =F6+$G$5 -> 0.30431681 | I7: 2022 | J7: =J6+$K$5 -> 0.34378321 | M7: 2022 | N7: =N6+$O$5 -> 0.35439796
A8: 2023 | B8: =B7+$C$5 -> 0.27115335 | E8: 2023 | F8: =F7+$G$5 -> 0.31147521 | I8: 2023 | J8: =J7+$K$5 -> 0.35067482 | M8: 2023 | N8: =N7+$O$5 -> 0.36159694
A9: 2024 | B9: =B8+$C$5 -> 0.27820446 | E9: 2024 | F9: =F8+$G$5 -> 0.31863361 | I9: 2024 | J9: =J8+$K$5 -> 0.35756643 | M9: 2024 | N9: =N8+$O$5 -> 0.36879592
A10: 2025 | B10: =B9+$C$5 -> 0.28525558 | E10: 2025 | F10: =F9+$G$5 -> 0.32579201 | I10: 2025 | J10: =J9+$K$5 -> 0.36445803 | M10: 2025 | N10: =N9+$O$5 -> 0.3759949
A11: 2026 | B11: =B10+$C$5 -> 0.29230669 | E11: 2026 | F11: =F10+$G$5 -> 0.33295042 | I11: 2026 | J11: =J10+$K$5 -> 0.37134964 | M11: 2026 | N11: =N10+$O$5 -> 0.38319388
A12: 2027 | B12: =B11+$C$5 -> 0.29935781 | E12: 2027 | F12: =F11+$G$5 -> 0.34010882 | I12: 2027 | J12: =J11+$K$5 -> 0.37824125 | M12: 2027 | N12: =N11+$O$5 -> 0.39039286
A13: 2028 | B13: =B12+$C$5 -> 0.30640893 | E13: 2028 | F13: =F12+$G$5 -> 0.34726722 | I13: 2028 | J13: =J12+$K$5 -> 0.38513285 | M13: 2028 | N13: =N12+$O$5 -> 0.39759184
A14: 2029 | B14: =B13+$C$5 -> 0.31346004 | E14: 2029 | F14: =F13+$G$5 -> 0.35442563 | I14: 2029 | J14: =J13+$K$5 -> 0.39202446 | M14: 2029 | N14: =N13+$O$5 -> 0.40479082
A15: 2030 | B15: =B14+$C$5 -> 0.32051116 | E15: 2030 | F15: =F14+$G$5 -> 0.36158403 | I15: 2030 | J15: =J14+$K$5 -> 0.39891607 | M15: 2030 | N15: =N14+$O$5 -> 0.4119898
A16: 2031 | B16: =B15+$C$5 -> 0.32756227 | E16: 2031 | F16: =F15+$G$5 -> 0.36874243 | I16: 2031 | J16: =J15+$K$5 -> 0.40580767 | M16: 2031 | N16: =N15+$O$5 -> 0.41918878
A17: 2032 | B17: =B16+$C$5 -> 0.33461339 | E17: 2032 | F17: =F16+$G$5 -> 0.37590084 | I17: 2032 | J17: =J16+$K$5 -> 0.41269928 | M17: 2032 | N17: =N16+$O$5 -> 0.42638776
... A34: 2049 | B34: =B33+$C$5 -> 0.45448235 | E34: 2049 | F34: =F33+$G$5 -> 0.49759368 | I34: 2049 | J34: =J33+$K$5 -> 0.5298566 | M34: 2049 | N34: =N33+$O$5 -> 0.54877043
A35: 2050 | B35: =MINDSET!C18 -> 0.46153347 | E35: 2050 | F35: =MINDSET!D18 -> 0.50475209 | I35: 2050 | J35: =MINDSET!E18 -> 0.5367482 | M35: 2050 | N35: =MINDSET!F18 -> 0.55596941
A38: Services - 2020/2050 - 2 m
A39: 10 | E39: 25 | I39: 100 | M39: 200
B40: interpolation | F40: interpolation | J40: interpolation | N40: interpolation
A42: 2020 | B42: =MINDSET!C15 -> 0.09 | C42: =(B72-B42)/30 -> 0.012351988 | E42: 2020 | F42: =MINDSET!D15 -> 0.16 | G42: =(F72-F42)/30 -> 0.011467409 | I42: 2020 | J42: =MINDSET!E15 -> 0.18 | K42: =(J72-J42)/30 -> 0.011886157 | M42: 2020 | N42: =MINDSET!F15 -> 0.19 | O42: =(N72-N42)/30 -> 0.012192852
A43: 2021 | B43: =B42+$C$42 -> 0.10235199 | E43: 2021 | F43: =F42+$G$42 -> 0.17146741 | I43: 2021 | J43: =J42+$K$42 -> 0.19188616 | M43: 2021 | N43: =N42+$O$42 -> 0.20219285
A44: 2022 | B44: =B43+$C$42 -> 0.11470398 | E44: 2022 | F44: =F43+$G$42 -> 0.18293482 | I44: 2022 | J44: =J43+$K$42 -> 0.20377231 | M44: 2022 | N44: =N43+$O$42 -> 0.2143857
A45: 2023 | B45: =B44+$C$42 -> 0.12705596 | E45: 2023 | F45: =F44+$G$42 -> 0.19440223 | I45: 2023 | J45: =J44+$K$42 -> 0.21565847 | M45: 2023 | N45: =N44+$O$42 -> 0.22657856
A46: 2024 | B46: =B45+$C$42 -> 0.13940795 | E46: 2024 | F46: =F45+$G$42 -> 0.20586964 | I46: 2024 | J46: =J45+$K$42 -> 0.22754463 | M46: 2024 | N46: =N45+$O$42 -> 0.23877141
A47: 2025 | B47: =B46+$C$42 -> 0.15175994 | E47: 2025 | F47: =F46+$G$42 -> 0.21733705 | I47: 2025 | J47: =J46+$K$42 -> 0.23943078 | M47: 2025 | N47: =N46+$O$42 -> 0.25096426
A48: 2026 | B48: =B47+$C$42 -> 0.16411193 | E48: 2026 | F48: =F47+$G$42 -> 0.22880446 | I48: 2026 | J48: =J47+$K$42 -> 0.25131694 | M48: 2026 | N48: =N47+$O$42 -> 0.26315711
A49: 2027 | B49: =B48+$C$42 -> 0.17646392 | E49: 2027 | F49: =F48+$G$42 -> 0.24027187 | I49: 2027 | J49: =J48+$K$42 -> 0.2632031 | M49: 2027 | N49: =N48+$O$42 -> 0.27534997
A50: 2028 | B50: =B49+$C$42 -> 0.1888159 | E50: 2028 | F50: =F49+$G$42 -> 0.25173928 | I50: 2028 | J50: =J49+$K$42 -> 0.27508925 | M50: 2028 | N50: =N49+$O$42 -> 0.28754282
A51: 2029 | B51: =B50+$C$42 -> 0.20116789 | E51: 2029 | F51: =F50+$G$42 -> 0.26320668 | I51: 2029 | J51: =J50+$K$42 -> 0.28697541 | M51: 2029 | N51: =N50+$O$42 -> 0.29973567
A52: 2030 | B52: =B51+$C$42 -> 0.21351988 | E52: 2030 | F52: =F51+$G$42 -> 0.27467409 | I52: 2030 | J52: =J51+$K$42 -> 0.29886157 | M52: 2030 | N52: =N51+$O$42 -> 0.31192852
A53: 2031 | B53: =B52+$C$42 -> 0.22587187 | E53: 2031 | F53: =F52+$G$42 -> 0.2861415 | I53: 2031 | J53: =J52+$K$42 -> 0.31074772 | M53: 2031 | N53: =N52+$O$42 -> 0.32412138
A54: 2032 | B54: =B53+$C$42 -> 0.23822386 | E54: 2032 | F54: =F53+$G$42 -> 0.29760891 | I54: 2032 | J54: =J53+$K$42 -> 0.32263388 | M54: 2032 | N54: =N53+$O$42 -> 0.33631423
... A71: 2049 | B71: =B70+$C$42 -> 0.44820766 | E71: 2049 | F71: =F70+$G$42 -> 0.49255487 | I71: 2049 | J71: =J70+$K$42 -> 0.52469855 | M71: 2049 | N71: =N70+$O$42 -> 0.54359272
A72: 2050 | B72: =MINDSET!C19 -> 0.46055964 | E72: 2050 | F72: =MINDSET!D19 -> 0.50402228 | I72: 2050 | J72: =MINDSET!E19 -> 0.5365847 | M72: 2050 | N72: =MINDSET!F19 -> 0.55578557
A75: Production - 2020/2050 - 1 m
A76: 10 | E76: 25 | I76: 100 | M76: 200
B77: interpolation | F77: interpolation | J77: interpolation | N77: interpolation
A79: 2020 | B79: =MINDSET!C27 -> 0.29 | C79: =(B109-B79)/30 -> 0.0057237638 | E79: 2020 | F79: =MINDSET!D27 -> 0.35 | G79: =(F109-F79)/30 -> 0.0051645639 | I79: 2020 | J79: =MINDSET!E27 -> 0.39 | K79: =(J109-J79)/30 -> 0.0048982708 | M79: 2020 | N79: =MINDSET!F27 -> 0.4 | O79: =(N109-N79)/30 -> 0.0052057412
...

Sheet Inundation
B1: 2020 - 1m cutoff | H1: 2020 - 2m cutoff
B2: services | D2: production | H2: services | J2: production | M2: duration (days)
B3: US$ million | C3: % | D3: US$ million | E3: % | H3: US$ million | I3: % | J3: US$ million | K3: %
A4: 10 | B4: 4775 | C4: 0.25 | D4: 5729 | E4: 0.29 | G4: 10 | H4: 1697.1107 | I4: =H4/$H$8 -> 0.08717545 | J4: 2035.8018 | K4: =J4/$J$8 -> 0.087210612 | M4: 7
A5: 25 | B5: 5639 | C5: 0.29 | D5: 6765 | E5: 0.35 | G5: 25 | H5: 3041.3836 | I5: =H5/$H$8 -> 0.15622668 | J5: 3648.5056 | K5: =J5/$J$8 -> 0.15629636 | M5: 8
A6: 100 | B6: 6369 | C6: 0.33 | D6: 7641 | E6: 0.39 | G6: 100 | H6: 3434.4242 | I6: =H6/$H$8 -> 0.17641599 | J6: 4120.0447 | K6: =J6/$J$8 -> 0.17649637 | M6: 14
A7: 200 | B7: 6524 | C7: 0.34 | D7: 7826 | E7: 0.4 | G7: 200 | H7: 3700.0709 | I7: =H7/$H$8 -> 0.19006146 | J7: 4438.7207 | K7: =J7/$J$8 -> 0.19014795 | M7: 21
A8: total asset | B8: 19467.76 | D8: 23343.51 | H8: 19467.76 | J8: 23343.51
B11: 2050 - 1m cutoff | H11: 2050 - 2m cutoff | M11: duration (days)
B12: Services | D12: Production | H12: services | J12: production
B13: US$ million | C13: % | D13: US$ million | H13: US$ million | I13: % | J13: US$ million | K13: %
A14: 10 | B14: ='GIS output'!D46 -> 8985.0228 | C14: =B14/$B$8 -> 0.46153347 | D14: ='GIS output'!D6 -> 10778 | E14: =D14/$D$8 -> 0.46171291 | G14: 10 | H14: ='GIS output'!D66 -> 8966.0646 | I14: =H14/$H$8 -> 0.46055964 | J14: ='GIS output'!D26 -> 10755.399 | K14: =J14/$J$8 -> 0.46074473
A15: 25 | B15: ='GIS output'!D50 -> 9826.3925 | C15: =B15/$B$8 -> 0.50475209 | D15: ='GIS output'!D10 -> 11787 | E15: =D15/$D$8 -> 0.50493692 | G15: 25 | H15: ='GIS output'!D70 -> 9812.1848 | I15: =H15/$H$8 -> 0.50402228 | J15: ='GIS output'!D30 -> 11770.206 | K15: =J15/$J$8 -> 0.50421747
A16: 100 | B16: ='GIS output'!D54 -> 10449.285 | C16: =B16/$B$8 -> 0.5367482 | D16: ='GIS output'!D14 -> 12534.254 | E16: =D16/$D$8 -> 0.53694812 | G16: 100 | H16: ='GIS output'!D74 -> 10446.102 | I16: =H16/$H$8 -> 0.5365847 | J16: ='GIS output'!D34 -> 12530.436 | K16: =J16/$J$8 -> 0.53678458
A17: 200 | B17: ='GIS output'!D58 -> 10823.479 | C17: =B17/$B$8 -> 0.55596941 | D17: ='GIS output'!D18 -> 12983.012 | E17: =D17/$D$8 -> 0.55617224 | G17: 200 | H17: ='GIS output'!D78 -> 10819.9 | I17: =H17/$H$8 -> 0.55578557 | J17: ='GIS output'!D38 -> 12978.719 | K17: =J17/$J$8 -> 0.55598831

Sheet GIS output
A1: Production | B1: 2050 - 1m cutoff
A2: GIS output
A3: Value | B3: COUNT | C3: AREA | D3: SUM
A4: 10:
A5: 0 | B5: 28145170 | C5: 19.545281 | D5: 0
A6: 1 | B6: 5342830 | C6: 3.7103032 | D6: 10778
A8: 25:
A9: 0 | B9: 27710956 | C9: 19.243743 | D9: 0
A10: 1 | B10: 5777044 | C10: 4.0118411 | D10: 11787
A12: 100:
A13: 0 | B13: 27188102 | C13: 18.88065 | D13: 0
A14: 1 | B14: 6299898 | C14: 4.3749346 | D14: 12534.254
A16: 200:
A17: 0 | B17: 26910078 | C17: 18.687577 | D17: 0
A18: 1 | B18: 6577922 | C18: 4.5680071 | D18: 12983.012
A21: Production | B21: 2050 - 2m cutoff
A22: GIS output
A23: Value | B23: COUNT | C23: AREA | D23: SUM
A24: 10:
A25: 0 | B25: 28154370 | C25: 19.55167 | D25: 0
A26: 1 | B26: 5333630 | C26: 3.7039143 | D26: 10755.399
A28: 25:
A29: 0 | B29: 27718912 | C29: 19.249268 | D29: 0
A30: 1 | B30: 5769088 | C30: 4.0063161 | D30: 11770.206
A32: 100:
A33: 0 | B33: 27190601 | C33: 18.882385 | D33: 0
A34: 1 | B34: 6297399 | C34: 4.3731992 | D34: 12530.436
A36: 200:
A37: 0 | B37: 26912478 | C37: 18.689244 | D37: 0
A38: 1 | B38: 6575522 | C38: 4.5663404 | D38: 12978.719
A41: Services | B41: 2050 - 1m cutoff
A42: GIS output
A43: Value | B43: COUNT | C43: AREA | D43: SUM
A44: 10:
A45: 0 | B45: 28145170 | C45: 19.545281 | D45: 0
A46: 1 | B46: 5342830 | C46: 3.7103032 | D46: 8985.0228
A48: 25:
A49: 0 | B49: 27710956 | C49: 19.243743 | D49: 0
A50: 1 | B50: 5777044 | C50: 4.0118411 | D50: 9826.3925
A52: 100:
...

Sheet Drought (national AAL PML)
B2: Baseline period (1981 - 2016)
C4: Rice | E4: Maize
B5: Return Period | C5: Yield Reduction (% below expected yield)* | D5: Production Loss (tonnes)** | E5: Yield Reduction (% below expected yield)* | F5: Production Loss (tonnes)**
B6: 2 | C6: =4.7160759734853/100 -> 0.04716076 | D6: 397617.45 | E6: =7.13476295814538/100 -> 0.07134763 | F6: 73335.922
B7: 5 | C7: =6.84286556635579/100 -> 0.068428656 | D7: 576929.37 | E7: =10.2035265381599/100 -> 0.10203527 | F7: 104878.75
B8: 10 | C8: =8.36912839857312/100 -> 0.083691284 | D8: 705610.24 | E8: =12.3887339066809/100 -> 0.12388734 | F8: 127339.79
B9: 15 | C9: =9.18715610745094/100 -> 0.091871561 | D9: 774579.03 | E9: =13.5555488473993/100 -> 0.13555549 | F9: 139333.1
B10: 20 | C10: =9.73018535069361/100 -> 0.097301854 | D10: 820362.41 | E10: =14.3288183376401/100 -> 0.14328818 | F10: 147281.29
B11: AAL | C11: =2.53871993731417/100 -> 0.025387199 | D11: 214042.21 | E11: =7.84795158509794/100 -> 0.078479516 | F11: 80666.557
C12: *Yield (t/ha) reduction in percentage points (i.e. 4 means 4%)
C13: **Production (annual) based on average yield (in last 6 years) and harvested area (MapSPAM)
B16: Year 2050 (SSP126)
C18: Rice | E18: Maize
B19: Return Period | C19: Yield Reduction (% below expected yield)* | D19: Production Loss (tonnes)** | E19: Yield Reduction (% below expected yield)* | F19: Production Loss (tonnes)**
B20: 2 | C20: =6.40004335319037/100 -> 0.064000434 | D20: 539594.55 | E20: =7.56197162272405/100 -> 0.075619716 | F20: 77727.061
B21: 5 | C21: =8.51452909343315/100 -> 0.085145291 | D21: 717869.13 | E21: =10.401587632389/100 -> 0.10401588 | F21: 106914.56
B22: 10 | C22: =9.94428693267809/100 -> 0.099442869 | D22: 838413.55 | E22: =12.3894373998802/100 -> 0.12389437 | F22: 127347.02
B23: 15 | C23: =10.6927692211079/100 -> 0.10692769 | D23: 901518.9 | E23: =13.4442064297443/100 -> 0.13444206 | F23: 138188.65
B24: 20 | C24: =11.1848813530385/100 -> 0.11184881 | D24: 943009.4 | E24: =14.1414774881386/100 -> 0.14141477 | F24: 145355.68
B25: AAL | C25: =3.89903126956886/100 -> 0.038990313 | D25: 328731.53 | E25: =8.40725854085626/100 -> 0.084072585 | F25: 86415.492
B28: Year 2050 (SSP585)
C30: Rice | E30: Maize
B31: Return Period | C31: Yield Reduction (% below expected yield)* | D31: Production Loss (tonnes)** | E31: Yield Reduction (% below expected yield)* | F31: Production Loss (tonnes)**
B32: 2 | C32: =7.31895102120787/100 -> 0.07318951 | D32: 617068.65 | E32: =9.4386590213691/100 -> 0.09438659 | F32: 97016.924
B33: 5 | C33: =9.04688962752753/100 -> 0.090468896 | D33: 762753.02 | E33: =12.1089019523378/100 -> 0.12108902 | F33: 124463.49
B34: 10 | C34: =10.1689404844908/100 -> 0.1016894 | D34: 857354.33 | E34: =13.8717867980552/100 -> 0.13871787 | F34: 142583.61
B35: 15 | C35: =10.7468218054863/100 -> 0.10746822 | D35: 906076.13 | E35: =14.7856187991053/100 -> 0.14785619 | F35: 151976.6
B36: 20 | C36: =11.1242151947609/100 -> 0.11124215 | D36: 937894.57 | E36: =15.3839815546018/100 -> 0.15383982 | F36: 158126.97
B37: AAL | C37: =5.25190564917735/100 -> 0.052519056 | D37: 442793.83 | E37: =12.5125207718581/100 -> 0.12512521 | F37: 128612.16

Sheet Drought interpolation
A1: Rice
A2: 2 | E2: 5 | I2: 10 | M2: 15 | Q2: 20
B3: interpolation | F3: interpolation | J3: interpolation | N3: interpolation | R3: interpolation
A5: 1999 | B5: 4.716076 | C5: 0.051036766 | E5: 1999 | F5: 6.8428656 | G5: 0.043216158 | I5: 1999 | J5: 8.3691284 | K5: 0.035290433 | M5: 1999 | N5: 9.1871561 | O5: 0.03058168 | Q5: 1999 | R5: 9.7301854 | S5: 0.027333919
A6: 2000 | B6: 4.7671127 | E6: 2000 | F6: 6.8860817 | I6: 2000 | J6: 8.4044188 | M6: 2000 | N6: 9.2177378 | Q6: 2000 | R6: 9.7575193
A7: 2001 | B7: 4.8181495 | E7: 2001 | F7: 6.9292979 | I7: 2001 | J7: 8.4397093 | M7: 2001 | N7: 9.2483195 | Q7: 2001 | R7: 9.7848532
A8: 2002 | B8: 4.8691863 | E8: 2002 | F8: 6.972514 | I8: 2002 | J8: 8.4749997 | M8: 2002 | N8: 9.2789011 | Q8: 2002 | R8: 9.8121871
A9: 2003 | B9: 4.920223 | E9: 2003 | F9: 7.0157302 | I9: 2003 | J9: 8.5102901 | M9: 2003 | N9: 9.3094828 | Q9: 2003 | R9: 9.839521
A10: 2004 | B10: 4.9712598 | E10: 2004 | F10: 7.0589464 | I10: 2004 | J10: 8.5455806 | M10: 2004 | N10: 9.3400645 | Q10: 2004 | R10: 9.8668549
A11: 2005 | B11: 5.0222966 | E11: 2005 | F11: 7.1021625 | I11: 2005 | J11: 8.580871 | M11: 2005 | N11: 9.3706462 | Q11: 2005 | R11: 9.8941889
A12: 2006 | B12: 5.0733333 | E12: 2006 | F12: 7.1453787 | I12: 2006 | J12: 8.6161614 | M12: 2006 | N12: 9.4012279 | Q12: 2006 | R12: 9.9215228
A13: 2007 | B13: 5.1243701 | E13: 2007 | F13: 7.1885948 | I13: 2007 | J13: 8.6514519 | M13: 2007 | N13: 9.4318096 | Q13: 2007 | R13: 9.9488567
A14: 2008 | B14: 5.1754069 | E14: 2008 | F14: 7.231811 | I14: 2008 | J14: 8.6867423 | M14: 2008 | N14: 9.4623912 | Q14: 2008 | R14: 9.9761906
A15: 2009 | B15: 5.2264436 | E15: 2009 | F15: 7.2750271 | I15: 2009 | J15: 8.7220327 | M15: 2009 | N15: 9.4929729 | Q15: 2009 | R15: 10.003525
A16: 2010 | B16: 5.2774804 | E16: 2010 | F16: 7.3182433 | I16: 2010 | J16: 8.7573232 | M16: 2010 | N16: 9.5235546 | Q16: 2010 | R16: 10.030858
A17: 2011 | B17: 5.3285172 | E17: 2011 | F17: 7.3614595 | I17: 2011 | J17: 8.7926136 | M17: 2011 | N17: 9.5541363 | Q17: 2011 | R17: 10.058192
