Workbook

Sheet MFModRaw
B1: KHMNYGDPMKTPKN_0 | C1: KHMNYGDPMKTPKN_111 | D1: KHMNYGDPMKTPKN_112 | E1: KHMNYGDPMKTPKN_113 | F1: KHMNYGDPMKTPKN_114 | G1: KHMNYGDPMKTPKN_121 | H1: KHMNYGDPMKTPKN_122 | I1: KHMNYGDPMKTPKN_123 | J1: KHMNYGDPMKTPKN_124 | K1: KHMNYGDPMKTPKN_131 | L1: KHMNYGDPMKTPKN_132 | M1: KHMNYGDPMKTPKN_133 | N1: KHMNYGDPMKTPKN_134 | O1: KHMNYGDPMKTPKN_211 | P1: KHMNYGDPMKTPKN_212 | Q1: KHMNYGDPMKTPKN_213 | R1: KHMNYGDPMKTPKN_214 | S1: KHMNYGDPMKTPKN_221 | T1: KHMNYGDPMKTPKN_222 | U1: KHMNYGDPMKTPKN_223 | V1: KHMNYGDPMKTPKN_224 | W1: KHMNYGDPMKTPKN_231 | X1: KHMNYGDPMKTPKN_232 | Y1: KHMNYGDPMKTPKN_233 | Z1: KHMNYGDPMKTPKN_234
A2: 2015 | B2: 95406125 | C2: 95406125 | D2: 95406125 | E2: 95406125 | F2: 95406125 | G2: 95406125 | H2: 95406125 | I2: 95406125 | J2: 95406125 | K2: 95406125 | L2: 95406125 | M2: 95406125 | N2: 95406125 | O2: 95406125 | P2: 95406125 | Q2: 95406125 | R2: 95406125 | S2: 95406125 | T2: 95406125 | U2: 95406125 | V2: 95406125 | W2: 95406125 | X2: 95406125 | Y2: 95406125 | Z2: 95406125
A3: 2016 | B3: 1.0294846e+08 | C3: 1.0294846e+08 | D3: 1.0294846e+08 | E3: 1.0294846e+08 | F3: 1.0294846e+08 | G3: 1.0294846e+08 | H3: 1.0294846e+08 | I3: 1.0294846e+08 | J3: 1.0294846e+08 | K3: 1.0294846e+08 | L3: 1.0294846e+08 | M3: 1.0294846e+08 | N3: 1.0294846e+08 | O3: 1.0294846e+08 | P3: 1.0294846e+08 | Q3: 1.0294846e+08 | R3: 1.0294846e+08 | S3: 1.0294846e+08 | T3: 1.0294846e+08 | U3: 1.0294846e+08 | V3: 1.0294846e+08 | W3: 1.0294846e+08 | X3: 1.0294846e+08 | Y3: 1.0294846e+08 | Z3: 1.0294846e+08
A4: 2017 | B4: 1.1126159e+08 | C4: 1.1126159e+08 | D4: 1.1126159e+08 | E4: 1.1126159e+08 | F4: 1.1126159e+08 | G4: 1.1126159e+08 | H4: 1.1126159e+08 | I4: 1.1126159e+08 | J4: 1.1126159e+08 | K4: 1.1126159e+08 | L4: 1.1126159e+08 | M4: 1.1126159e+08 | N4: 1.1126159e+08 | O4: 1.1126159e+08 | P4: 1.1126159e+08 | Q4: 1.1126159e+08 | R4: 1.1126159e+08 | S4: 1.1126159e+08 | T4: 1.1126159e+08 | U4: 1.1126159e+08 | V4: 1.1126159e+08 | W4: 1.1126159e+08 | X4: 1.1126159e+08 | Y4: 1.1126159e+08 | Z4: 1.1126159e+08
A5: 2018 | B5: 1.2102615e+08 | C5: 1.2102615e+08 | D5: 1.2102615e+08 | E5: 1.2102615e+08 | F5: 1.2102615e+08 | G5: 1.2102615e+08 | H5: 1.2102615e+08 | I5: 1.2102615e+08 | J5: 1.2102615e+08 | K5: 1.2102615e+08 | L5: 1.2102615e+08 | M5: 1.2102615e+08 | N5: 1.2102615e+08 | O5: 1.2102615e+08 | P5: 1.2102615e+08 | Q5: 1.2102615e+08 | R5: 1.2102615e+08 | S5: 1.2102615e+08 | T5: 1.2102615e+08 | U5: 1.2102615e+08 | V5: 1.2102615e+08 | W5: 1.2102615e+08 | X5: 1.2102615e+08 | Y5: 1.2102615e+08 | Z5: 1.2102615e+08
A6: 2019 | B6: 1.3063194e+08 | C6: 1.3063194e+08 | D6: 1.3063194e+08 | E6: 1.3063194e+08 | F6: 1.3063194e+08 | G6: 1.3063194e+08 | H6: 1.3063194e+08 | I6: 1.3063194e+08 | J6: 1.3063194e+08 | K6: 1.3063194e+08 | L6: 1.3063194e+08 | M6: 1.3063194e+08 | N6: 1.3063194e+08 | O6: 1.3063194e+08 | P6: 1.3063194e+08 | Q6: 1.3063194e+08 | R6: 1.3063194e+08 | S6: 1.3063194e+08 | T6: 1.3063194e+08 | U6: 1.3063194e+08 | V6: 1.3063194e+08 | W6: 1.3063194e+08 | X6: 1.3063194e+08 | Y6: 1.3063194e+08 | Z6: 1.3063194e+08
A7: 2020 | B7: 1.2598703e+08 | C7: 1.2598703e+08 | D7: 1.2598703e+08 | E7: 1.2598703e+08 | F7: 1.2598703e+08 | G7: 1.2598715e+08 | H7: 1.2598715e+08 | I7: 1.2598715e+08 | J7: 1.2598715e+08 | K7: 1.2598728e+08 | L7: 1.2598728e+08 | M7: 1.2598728e+08 | N7: 1.2598728e+08 | O7: 1.2598703e+08 | P7: 1.2598703e+08 | Q7: 1.2598703e+08 | R7: 1.2598703e+08 | S7: 1.2598715e+08 | T7: 1.2598715e+08 | U7: 1.2598715e+08 | V7: 1.2598715e+08 | W7: 1.2598728e+08 | X7: 1.2598728e+08 | Y7: 1.2598728e+08 | Z7: 1.2598728e+08
A8: 2021 | B8: 1.2987983e+08 | C8: 1.2980125e+08 | D8: 1.2987814e+08 | E8: 1.2987983e+08 | F8: 1.2979955e+08 | G8: 1.2980371e+08 | H8: 1.2988214e+08 | I8: 1.2987998e+08 | J8: 1.2980631e+08 | K8: 1.2980365e+08 | L8: 1.2988464e+08 | M8: 1.2987996e+08 | N8: 1.2980886e+08 | O8: 1.2980125e+08 | P8: 1.2987868e+08 | Q8: 1.2987983e+08 | R8: 1.298001e+08 | S8: 1.2980371e+08 | T8: 1.2988268e+08 | U8: 1.2987998e+08 | V8: 1.2980685e+08 | W8: 1.2980365e+08 | X8: 1.2988518e+08 | Y8: 1.2987995e+08 | Z8: 1.2980941e+08
A9: 2022 | B9: 1.3650808e+08 | C9: 1.3619747e+08 | D9: 1.365012e+08 | E9: 1.3650808e+08 | F9: 1.3619054e+08 | G9: 1.3620733e+08 | H9: 1.3651987e+08 | I9: 1.3650954e+08 | J9: 1.3622097e+08 | K9: 1.3620725e+08 | L9: 1.3653158e+08 | M9: 1.3650968e+08 | N9: 1.3623312e+08 | O9: 1.3619282e+08 | P9: 1.3650308e+08 | Q9: 1.3650808e+08 | R9: 1.3618778e+08 | S9: 1.3620283e+08 | T9: 1.3652176e+08 | U9: 1.3650952e+08 | V9: 1.3621835e+08 | W9: 1.3620276e+08 | X9: 1.3653347e+08 | Y9: 1.3650966e+08 | Z9: 1.3623051e+08
A10: 2023 | B10: 1.4333428e+08 | C10: 1.4270422e+08 | D10: 1.4332005e+08 | E10: 1.4333428e+08 | F10: 1.4268993e+08 | G10: 1.4272429e+08 | H10: 1.4336228e+08 | I10: 1.4333822e+08 | J10: 1.4275693e+08 | K10: 1.4272427e+08 | L10: 1.4338876e+08 | M10: 1.4333867e+08 | N10: 1.4278456e+08 | O10: 1.4268639e+08 | P10: 1.4332296e+08 | Q10: 1.4333428e+08 | R10: 1.4267502e+08 | S10: 1.4270705e+08 | T10: 1.4336521e+08 | U10: 1.4333815e+08 | V10: 1.4274256e+08 | W10: 1.4270705e+08 | X10: 1.433917e+08 | Y10: 1.433386e+08 | Z10: 1.4277023e+08
A11: 2024 | B11: 1.5196078e+08 | C11: 1.5081509e+08 | D11: 1.5193527e+08 | E11: 1.5196078e+08 | F11: 1.5078952e+08 | G11: 1.5085203e+08 | H11: 1.520189e+08 | I11: 1.5196951e+08 | J11: 1.5091951e+08 | K11: 1.5085254e+08 | L11: 1.5207146e+08 | M11: 1.5197081e+08 | N11: 1.5097458e+08 | O11: 1.5076351e+08 | P11: 1.5193836e+08 | Q11: 1.5196078e+08 | R11: 1.5074102e+08 | S11: 1.5080216e+08 | T11: 1.5202201e+08 | U11: 1.5196933e+08 | V11: 1.5087258e+08 | W11: 1.5080274e+08 | X11: 1.5207457e+08 | Y11: 1.5197064e+08 | Z11: 1.5092774e+08
A12: 2025 | B12: 1.5732787e+08 | C12: 1.5558524e+08 | D12: 1.5728896e+08 | E12: 1.5732787e+08 | F12: 1.5554637e+08 | G12: 1.5564179e+08 | H12: 1.5742459e+08 | I12: 1.573428e+08 | J12: 1.5575378e+08 | K12: 1.5564313e+08 | L12: 1.5750988e+08 | M12: 1.5734519e+08 | N12: 1.5584331e+08 | O12: 1.5547825e+08 | P12: 1.5729223e+08 | Q12: 1.5732787e+08 | R12: 1.5544263e+08 | S12: 1.5553837e+08 | T12: 1.5742787e+08 | U12: 1.5734246e+08 | V12: 1.5565329e+08 | W12: 1.5553989e+08 | X12: 1.5751316e+08 | Y12: 1.5734486e+08 | Z12: 1.5574301e+08
A13: 2026 | B13: 1.611743e+08 | C13: 1.5875619e+08 | D13: 1.6112075e+08 | E13: 1.611743e+08 | F13: 1.587029e+08 | G13: 1.5883504e+08 | H13: 1.6131943e+08 | I13: 1.6119716e+08 | J13: 1.5900265e+08 | K13: 1.5883757e+08 | L13: 1.6144442e+08 | M13: 1.6120094e+08 | N13: 1.5913396e+08 | O13: 1.5857245e+08 | P13: 1.6112285e+08 | Q13: 1.611743e+08 | R13: 1.5852124e+08 | S13: 1.5865745e+08 | T13: 1.6132153e+08 | U13: 1.611966e+08 | V13: 1.5882651e+08 | W13: 1.5866034e+08 | X13: 1.6144651e+08 | Y13: 1.6120038e+08 | Z13: 1.5895817e+08
... A37: 2050 | B37: 2.2213448e+08 | C37: 1.9810657e+08 | D37: 2.2153725e+08 | E37: 2.2213448e+08 | F37: 1.9757191e+08 | G37: 1.9898597e+08 | H37: 2.2569789e+08 | I37: 2.2248999e+08 | J37: 2.0250824e+08 | K37: 1.991873e+08 | L37: 2.2832347e+08 | M37: 2.2253324e+08 | N37: 2.0514343e+08 | O37: 1.7978645e+08 | P37: 2.204202e+08 | Q37: 2.2213448e+08 | R37: 1.7838478e+08 | S37: 1.8130559e+08 | T37: 2.2447811e+08 | U37: 2.2245665e+08 | V37: 1.8348813e+08 | W37: 1.8170813e+08 | X37: 2.2703835e+08 | Y37: 2.2249798e+08 | Z37: 1.8606406e+08
B41: Scenario Codes
B42: Baseline
B43: 0 | C43: No additional climate change
B44: Climate Scenarios
B45: 100 | C45: Optimistic
B46: 200 | C46: Pessimistic
B47: EWS Scenarios
B48: 10 | C48: Control
B49: 20 | C49: Status Quo
B50: 30 | C50: Improvement
B51: Channel Scenarios
B52: 1 | C52: DRR
B53: 2 | C53: Agriculture
B54: 3 | C54: Hydro
B55: 4 | C55: ALL
B56: e.g. _222 = Pessimistic StatusQuo Agriculture

Sheet All
B1: Baseline | C1: Control_Optimistic | D1: StatusQuo_Optimistic | E1: Improvement_Optimistic | F1: Control_Pessimistic | G1: StatusQuo_Pessimistic | H1: Improvement_Pessimistic
B2: KHMNYGDPMKTPKN_0 | C2: KHMNYGDPMKTPKN_114 | D2: KHMNYGDPMKTPKN_124 | E2: KHMNYGDPMKTPKN_134 | F2: KHMNYGDPMKTPKN_214 | G2: KHMNYGDPMKTPKN_224 | H2: KHMNYGDPMKTPKN_234 | L2: =C1 -> Control_Optimistic | M2: =D1 -> StatusQuo_Optimistic | N2: =E1 -> Improvement_Optimistic | O2: =F1 -> Control_Pessimistic | P2: =G1 -> StatusQuo_Pessimistic | Q2: =H1 -> Improvement_Pessimistic
A3: 2015 | B3: {=INDEX(MFModRaw!$B$2:$Z$37,_xlfn.XMATCH($A3,MFModRaw!$A$2:$A$37),_xlfn.XMATCH(B$2,MFModRaw!$B$1:$Z$1))} -> 95406125 | C3: {=INDEX(MFModRaw!$B$2:$Z$37,_xlfn.XMATCH($A3,MFModRaw!$A$2:$A$37),_xlfn.XMATCH(C$2,MFModRaw!$B$1:$Z$1))} -> 95406125 | D3: {=INDEX(MFModRaw!$B$2:$Z$37,_xlfn.XMATCH($A3,MFModRaw!$A$2:$A$37),_xlfn.XMATCH(D$2,MFModRaw!$B$1:$Z$1))} -> 95406125 | E3: {=INDEX(MFModRaw!$B$2:$Z$37,_xlfn.XMATCH($A3,MFModRaw!$A$2:$A$37),_xlfn.XMATCH(E$2,MFModRaw!$B$1:$Z$1))} -> 95406125 | F3: {=INDEX(MFModRaw!$B$2:$Z$37,_xlfn.XMATCH($A3,MFModRaw!$A$2:$A$37),_xlfn.XMATCH(F$2,MFModRaw!$B$1:$Z$1))} -> 95406125 | G3: {=INDEX(MFModRaw!$B$2:$Z$37,_xlfn.XMATCH($A3,MFModRaw!$A$2:$A$37),_xlfn.XMATCH(G$2,MFModRaw!$B$1:$Z$1))} -> 95406125 | H3: {=INDEX(MFModRaw!$B$2:$Z$37,_xlfn.XMATCH($A3,MFModRaw!$A$2:$A$37),_xlfn.XMATCH(H$2,MFModRaw!$B$1:$Z$1))} -> 95406125 | K3: 2015 | L3: =C3/$B3-1 -> 0 | M3: =D3/$B3-1 -> 0 | N3: =E3/$B3-1 -> 0 | O3: =F3/$B3-1 -> 0 | P3: =G3/$B3-1 -> 0 | Q3: =H3/$B3-1 -> 0
A4: 2016 | B4: {=INDEX(MFModRaw!$B$2:$Z$37,_xlfn.XMATCH($A4,MFModRaw!$A$2:$A$37),_xlfn.XMATCH(B$2,MFModRaw!$B$1:$Z$1))} -> 1.0294846e+08 | C4: {=INDEX(MFModRaw!$B$2:$Z$37,_xlfn.XMATCH($A4,MFModRaw!$A$2:$A$37),_xlfn.XMATCH(C$2,MFModRaw!$B$1:$Z$1))} -> 1.0294846e+08 | D4: {=INDEX(MFModRaw!$B$2:$Z$37,_xlfn.XMATCH($A4,MFModRaw!$A$2:$A$37),_xlfn.XMATCH(D$2,MFModRaw!$B$1:$Z$1))} -> 1.0294846e+08 | E4: {=INDEX(MFModRaw!$B$2:$Z$37,_xlfn.XMATCH($A4,MFModRaw!$A$2:$A$37),_xlfn.XMATCH(E$2,MFModRaw!$B$1:$Z$1))} -> 1.0294846e+08 | F4: {=INDEX(MFModRaw!$B$2:$Z$37,_xlfn.XMATCH($A4,MFModRaw!$A$2:$A$37),_xlfn.XMATCH(F$2,MFModRaw!$B$1:$Z$1))} -> 1.0294846e+08 | G4: {=INDEX(MFModRaw!$B$2:$Z$37,_xlfn.XMATCH($A4,MFModRaw!$A$2:$A$37),_xlfn.XMATCH(G$2,MFModRaw!$B$1:$Z$1))} -> 1.0294846e+08 | H4: {=INDEX(MFModRaw!$B$2:$Z$37,_xlfn.XMATCH($A4,MFModRaw!$A$2:$A$37),_xlfn.XMATCH(H$2,MFModRaw!$B$1:$Z$1))} -> 1.0294846e+08 | K4: 2016 | L4: =C4/$B4-1 -> 0 | M4: =D4/$B4-1 -> 0 | N4: =E4/$B4-1 -> 0 | O4: =F4/$B4-1 -> 0 | P4: =G4/$B4-1 -> 0 | Q4: =H4/$B4-1 -> 0
A5: 2017 | B5: {=INDEX(MFModRaw!$B$2:$Z$37,_xlfn.XMATCH($A5,MFModRaw!$A$2:$A$37),_xlfn.XMATCH(B$2,MFModRaw!$B$1:$Z$1))} -> 1.1126159e+08 | C5: {=INDEX(MFModRaw!$B$2:$Z$37,_xlfn.XMATCH($A5,MFModRaw!$A$2:$A$37),_xlfn.XMATCH(C$2,MFModRaw!$B$1:$Z$1))} -> 1.1126159e+08 | D5: {=INDEX(MFModRaw!$B$2:$Z$37,_xlfn.XMATCH($A5,MFModRaw!$A$2:$A$37),_xlfn.XMATCH(D$2,MFModRaw!$B$1:$Z$1))} -> 1.1126159e+08 | E5: {=INDEX(MFModRaw!$B$2:$Z$37,_xlfn.XMATCH($A5,MFModRaw!$A$2:$A$37),_xlfn.XMATCH(E$2,MFModRaw!$B$1:$Z$1))} -> 1.1126159e+08 | F5: {=INDEX(MFModRaw!$B$2:$Z$37,_xlfn.XMATCH($A5,MFModRaw!$A$2:$A$37),_xlfn.XMATCH(F$2,MFModRaw!$B$1:$Z$1))} -> 1.1126159e+08 | G5: {=INDEX(MFModRaw!$B$2:$Z$37,_xlfn.XMATCH($A5,MFModRaw!$A$2:$A$37),_xlfn.XMATCH(G$2,MFModRaw!$B$1:$Z$1))} -> 1.1126159e+08 | H5: {=INDEX(MFModRaw!$B$2:$Z$37,_xlfn.XMATCH($A5,MFModRaw!$A$2:$A$37),_xlfn.XMATCH(H$2,MFModRaw!$B$1:$Z$1))} -> 1.1126159e+08 | K5: 2017 | L5: =C5/$B5-1 -> 0 | M5: =D5/$B5-1 -> 0 | N5: =E5/$B5-1 -> 0 | O5: =F5/$B5-1 -> 0 | P5: =G5/$B5-1 -> 0 | Q5: =H5/$B5-1 -> 0
A6: 2018 | B6: {=INDEX(MFModRaw!$B$2:$Z$37,_xlfn.XMATCH($A6,MFModRaw!$A$2:$A$37),_xlfn.XMATCH(B$2,MFModRaw!$B$1:$Z$1))} -> 1.2102615e+08 | C6: {=INDEX(MFModRaw!$B$2:$Z$37,_xlfn.XMATCH($A6,MFModRaw!$A$2:$A$37),_xlfn.XMATCH(C$2,MFModRaw!$B$1:$Z$1))} -> 1.2102615e+08 | D6: {=INDEX(MFModRaw!$B$2:$Z$37,_xlfn.XMATCH($A6,MFModRaw!$A$2:$A$37),_xlfn.XMATCH(D$2,MFModRaw!$B$1:$Z$1))} -> 1.2102615e+08 | E6: {=INDEX(MFModRaw!$B$2:$Z$37,_xlfn.XMATCH($A6,MFModRaw!$A$2:$A$37),_xlfn.XMATCH(E$2,MFModRaw!$B$1:$Z$1))} -> 1.2102615e+08 | F6: {=INDEX(MFModRaw!$B$2:$Z$37,_xlfn.XMATCH($A6,MFModRaw!$A$2:$A$37),_xlfn.XMATCH(F$2,MFModRaw!$B$1:$Z$1))} -> 1.2102615e+08 | G6: {=INDEX(MFModRaw!$B$2:$Z$37,_xlfn.XMATCH($A6,MFModRaw!$A$2:$A$37),_xlfn.XMATCH(G$2,MFModRaw!$B$1:$Z$1))} -> 1.2102615e+08 | H6: {=INDEX(MFModRaw!$B$2:$Z$37,_xlfn.XMATCH($A6,MFModRaw!$A$2:$A$37),_xlfn.XMATCH(H$2,MFModRaw!$B$1:$Z$1))} -> 1.2102615e+08 | K6: 2018 | L6: =C6/$B6-1 -> 0 | M6: =D6/$B6-1 -> 0 | N6: =E6/$B6-1 -> 0 | O6: =F6/$B6-1 -> 0 | P6: =G6/$B6-1 -> 0 | Q6: =H6/$B6-1 -> 0
A7: 2019 | B7: {=INDEX(MFModRaw!$B$2:$Z$37,_xlfn.XMATCH($A7,MFModRaw!$A$2:$A$37),_xlfn.XMATCH(B$2,MFModRaw!$B$1:$Z$1))} -> 1.3063194e+08 | C7: {=INDEX(MFModRaw!$B$2:$Z$37,_xlfn.XMATCH($A7,MFModRaw!$A$2:$A$37),_xlfn.XMATCH(C$2,MFModRaw!$B$1:$Z$1))} -> 1.3063194e+08 | D7: {=INDEX(MFModRaw!$B$2:$Z$37,_xlfn.XMATCH($A7,MFModRaw!$A$2:$A$37),_xlfn.XMATCH(D$2,MFModRaw!$B$1:$Z$1))} -> 1.3063194e+08 | E7: {=INDEX(MFModRaw!$B$2:$Z$37,_xlfn.XMATCH($A7,MFModRaw!$A$2:$A$37),_xlfn.XMATCH(E$2,MFModRaw!$B$1:$Z$1))} -> 1.3063194e+08 | F7: {=INDEX(MFModRaw!$B$2:$Z$37,_xlfn.XMATCH($A7,MFModRaw!$A$2:$A$37),_xlfn.XMATCH(F$2,MFModRaw!$B$1:$Z$1))} -> 1.3063194e+08 | G7: {=INDEX(MFModRaw!$B$2:$Z$37,_xlfn.XMATCH($A7,MFModRaw!$A$2:$A$37),_xlfn.XMATCH(G$2,MFModRaw!$B$1:$Z$1))} -> 1.3063194e+08 | H7: {=INDEX(MFModRaw!$B$2:$Z$37,_xlfn.XMATCH($A7,MFModRaw!$A$2:$A$37),_xlfn.XMATCH(H$2,MFModRaw!$B$1:$Z$1))} -> 1.3063194e+08 | K7: 2019 | L7: =C7/$B7-1 -> 0 | M7: =D7/$B7-1 -> 0 | N7: =E7/$B7-1 -> 0 | O7: =F7/$B7-1 -> 0 | P7: =G7/$B7-1 -> 0 | Q7: =H7/$B7-1 -> 0
A8: 2020 | B8: {=INDEX(MFModRaw!$B$2:$Z$37,_xlfn.XMATCH($A8,MFModRaw!$A$2:$A$37),_xlfn.XMATCH(B$2,MFModRaw!$B$1:$Z$1))} -> 1.2598703e+08 | C8: {=INDEX(MFModRaw!$B$2:$Z$37,_xlfn.XMATCH($A8,MFModRaw!$A$2:$A$37),_xlfn.XMATCH(C$2,MFModRaw!$B$1:$Z$1))} -> 1.2598703e+08 | D8: {=INDEX(MFModRaw!$B$2:$Z$37,_xlfn.XMATCH($A8,MFModRaw!$A$2:$A$37),_xlfn.XMATCH(D$2,MFModRaw!$B$1:$Z$1))} -> 1.2598715e+08 | E8: {=INDEX(MFModRaw!$B$2:$Z$37,_xlfn.XMATCH($A8,MFModRaw!$A$2:$A$37),_xlfn.XMATCH(E$2,MFModRaw!$B$1:$Z$1))} -> 1.2598728e+08 | F8: {=INDEX(MFModRaw!$B$2:$Z$37,_xlfn.XMATCH($A8,MFModRaw!$A$2:$A$37),_xlfn.XMATCH(F$2,MFModRaw!$B$1:$Z$1))} -> 1.2598703e+08 | G8: {=INDEX(MFModRaw!$B$2:$Z$37,_xlfn.XMATCH($A8,MFModRaw!$A$2:$A$37),_xlfn.XMATCH(G$2,MFModRaw!$B$1:$Z$1))} -> 1.2598715e+08 | H8: {=INDEX(MFModRaw!$B$2:$Z$37,_xlfn.XMATCH($A8,MFModRaw!$A$2:$A$37),_xlfn.XMATCH(H$2,MFModRaw!$B$1:$Z$1))} -> 1.2598728e+08 | K8: 2020 | L8: =C8/$B8-1 -> 0 | M8: =D8/$B8-1 -> 9.8388951e-07 | N8: =E8/$B8-1 -> 1.9678185e-06 | O8: =F8/$B8-1 -> 0 | P8: =G8/$B8-1 -> 9.8388951e-07 | Q8: =H8/$B8-1 -> 1.9678185e-06
A9: 2021 | B9: {=INDEX(MFModRaw!$B$2:$Z$37,_xlfn.XMATCH($A9,MFModRaw!$A$2:$A$37),_xlfn.XMATCH(B$2,MFModRaw!$B$1:$Z$1))} -> 1.2987983e+08 | C9: {=INDEX(MFModRaw!$B$2:$Z$37,_xlfn.XMATCH($A9,MFModRaw!$A$2:$A$37),_xlfn.XMATCH(C$2,MFModRaw!$B$1:$Z$1))} -> 1.2979955e+08 | D9: {=INDEX(MFModRaw!$B$2:$Z$37,_xlfn.XMATCH($A9,MFModRaw!$A$2:$A$37),_xlfn.XMATCH(D$2,MFModRaw!$B$1:$Z$1))} -> 1.2980631e+08 | E9: {=INDEX(MFModRaw!$B$2:$Z$37,_xlfn.XMATCH($A9,MFModRaw!$A$2:$A$37),_xlfn.XMATCH(E$2,MFModRaw!$B$1:$Z$1))} -> 1.2980886e+08 | F9: {=INDEX(MFModRaw!$B$2:$Z$37,_xlfn.XMATCH($A9,MFModRaw!$A$2:$A$37),_xlfn.XMATCH(F$2,MFModRaw!$B$1:$Z$1))} -> 1.298001e+08 | G9: {=INDEX(MFModRaw!$B$2:$Z$37,_xlfn.XMATCH($A9,MFModRaw!$A$2:$A$37),_xlfn.XMATCH(G$2,MFModRaw!$B$1:$Z$1))} -> 1.2980685e+08 | H9: {=INDEX(MFModRaw!$B$2:$Z$37,_xlfn.XMATCH($A9,MFModRaw!$A$2:$A$37),_xlfn.XMATCH(H$2,MFModRaw!$B$1:$Z$1))} -> 1.2980941e+08 | K9: 2021 | L9: =C9/$B9-1 -> -0.00061811396 | M9: =D9/$B9-1 -> -0.00056608629 | N9: =E9/$B9-1 -> -0.00054642254 | O9: =F9/$B9-1 -> -0.00061390114 | P9: =G9/$B9-1 -> -0.00056188043 | Q9: =H9/$B9-1 -> -0.00054221004
A10: 2022 | B10: {=INDEX(MFModRaw!$B$2:$Z$37,_xlfn.XMATCH($A10,MFModRaw!$A$2:$A$37),_xlfn.XMATCH(B$2,MFModRaw!$B$1:$Z$1))} -> 1.3650808e+08 | C10: {=INDEX(MFModRaw!$B$2:$Z$37,_xlfn.XMATCH($A10,MFModRaw!$A$2:$A$37),_xlfn.XMATCH(C$2,MFModRaw!$B$1:$Z$1))} -> 1.3619054e+08 | D10: {=INDEX(MFModRaw!$B$2:$Z$37,_xlfn.XMATCH($A10,MFModRaw!$A$2:$A$37),_xlfn.XMATCH(D$2,MFModRaw!$B$1:$Z$1))} -> 1.3622097e+08 | E10: {=INDEX(MFModRaw!$B$2:$Z$37,_xlfn.XMATCH($A10,MFModRaw!$A$2:$A$37),_xlfn.XMATCH(E$2,MFModRaw!$B$1:$Z$1))} -> 1.3623312e+08 | F10: {=INDEX(MFModRaw!$B$2:$Z$37,_xlfn.XMATCH($A10,MFModRaw!$A$2:$A$37),_xlfn.XMATCH(F$2,MFModRaw!$B$1:$Z$1))} -> 1.3618778e+08 | G10: {=INDEX(MFModRaw!$B$2:$Z$37,_xlfn.XMATCH($A10,MFModRaw!$A$2:$A$37),_xlfn.XMATCH(G$2,MFModRaw!$B$1:$Z$1))} -> 1.3621835e+08 | H10: {=INDEX(MFModRaw!$B$2:$Z$37,_xlfn.XMATCH($A10,MFModRaw!$A$2:$A$37),_xlfn.XMATCH(H$2,MFModRaw!$B$1:$Z$1))} -> 1.3623051e+08 | K10: 2022 | L10: =C10/$B10-1 -> -0.0023261383 | M10: =D10/$B10-1 -> -0.0021032237 | N10: =E10/$B10-1 -> -0.0020142114 | O10: =F10/$B10-1 -> -0.0023463452 | P10: =G10/$B10-1 -> -0.0021223937 | Q10: =H10/$B10-1 -> -0.0020333117
A11: 2023 | B11: {=INDEX(MFModRaw!$B$2:$Z$37,_xlfn.XMATCH($A11,MFModRaw!$A$2:$A$37),_xlfn.XMATCH(B$2,MFModRaw!$B$1:$Z$1))} -> 1.4333428e+08 | C11: {=INDEX(MFModRaw!$B$2:$Z$37,_xlfn.XMATCH($A11,MFModRaw!$A$2:$A$37),_xlfn.XMATCH(C$2,MFModRaw!$B$1:$Z$1))} -> 1.4268993e+08 | D11: {=INDEX(MFModRaw!$B$2:$Z$37,_xlfn.XMATCH($A11,MFModRaw!$A$2:$A$37),_xlfn.XMATCH(D$2,MFModRaw!$B$1:$Z$1))} -> 1.4275693e+08 | E11: {=INDEX(MFModRaw!$B$2:$Z$37,_xlfn.XMATCH($A11,MFModRaw!$A$2:$A$37),_xlfn.XMATCH(E$2,MFModRaw!$B$1:$Z$1))} -> 1.4278456e+08 | F11: {=INDEX(MFModRaw!$B$2:$Z$37,_xlfn.XMATCH($A11,MFModRaw!$A$2:$A$37),_xlfn.XMATCH(F$2,MFModRaw!$B$1:$Z$1))} -> 1.4267502e+08 | G11: {=INDEX(MFModRaw!$B$2:$Z$37,_xlfn.XMATCH($A11,MFModRaw!$A$2:$A$37),_xlfn.XMATCH(G$2,MFModRaw!$B$1:$Z$1))} -> 1.4274256e+08 | H11: {=INDEX(MFModRaw!$B$2:$Z$37,_xlfn.XMATCH($A11,MFModRaw!$A$2:$A$37),_xlfn.XMATCH(H$2,MFModRaw!$B$1:$Z$1))} -> 1.4277023e+08 | K11: 2023 | L11: =C11/$B11-1 -> -0.0044954207 | M11: =D11/$B11-1 -> -0.0040279766 | N11: =E11/$B11-1 -> -0.0038352041 | O11: =F11/$B11-1 -> -0.0045994312 | P11: =G11/$B11-1 -> -0.0041282063 | Q11: =H11/$B11-1 -> -0.0039352157
A12: 2024 | B12: {=INDEX(MFModRaw!$B$2:$Z$37,_xlfn.XMATCH($A12,MFModRaw!$A$2:$A$37),_xlfn.XMATCH(B$2,MFModRaw!$B$1:$Z$1))} -> 1.5196078e+08 | C12: {=INDEX(MFModRaw!$B$2:$Z$37,_xlfn.XMATCH($A12,MFModRaw!$A$2:$A$37),_xlfn.XMATCH(C$2,MFModRaw!$B$1:$Z$1))} -> 1.5078952e+08 | D12: {=INDEX(MFModRaw!$B$2:$Z$37,_xlfn.XMATCH($A12,MFModRaw!$A$2:$A$37),_xlfn.XMATCH(D$2,MFModRaw!$B$1:$Z$1))} -> 1.5091951e+08 | E12: {=INDEX(MFModRaw!$B$2:$Z$37,_xlfn.XMATCH($A12,MFModRaw!$A$2:$A$37),_xlfn.XMATCH(E$2,MFModRaw!$B$1:$Z$1))} -> 1.5097458e+08 | F12: {=INDEX(MFModRaw!$B$2:$Z$37,_xlfn.XMATCH($A12,MFModRaw!$A$2:$A$37),_xlfn.XMATCH(F$2,MFModRaw!$B$1:$Z$1))} -> 1.5074102e+08 | G12: {=INDEX(MFModRaw!$B$2:$Z$37,_xlfn.XMATCH($A12,MFModRaw!$A$2:$A$37),_xlfn.XMATCH(G$2,MFModRaw!$B$1:$Z$1))} -> 1.5087258e+08 | H12: {=INDEX(MFModRaw!$B$2:$Z$37,_xlfn.XMATCH($A12,MFModRaw!$A$2:$A$37),_xlfn.XMATCH(H$2,MFModRaw!$B$1:$Z$1))} -> 1.5092774e+08 | K12: 2024 | L12: =C12/$B12-1 -> -0.0077076383 | M12: =D12/$B12-1 -> -0.0068522415 | N12: =E12/$B12-1 -> -0.0064898465 | O12: =F12/$B12-1 -> -0.0080267764 | P12: =G12/$B12-1 -> -0.0071610386 | Q12: =H12/$B12-1 -> -0.0067980629
A13: 2025 | B13: {=INDEX(MFModRaw!$B$2:$Z$37,_xlfn.XMATCH($A13,MFModRaw!$A$2:$A$37),_xlfn.XMATCH(B$2,MFModRaw!$B$1:$Z$1))} -> 1.5732787e+08 | C13: {=INDEX(MFModRaw!$B$2:$Z$37,_xlfn.XMATCH($A13,MFModRaw!$A$2:$A$37),_xlfn.XMATCH(C$2,MFModRaw!$B$1:$Z$1))} -> 1.5554637e+08 | D13: {=INDEX(MFModRaw!$B$2:$Z$37,_xlfn.XMATCH($A13,MFModRaw!$A$2:$A$37),_xlfn.XMATCH(D$2,MFModRaw!$B$1:$Z$1))} -> 1.5575378e+08 | E13: {=INDEX(MFModRaw!$B$2:$Z$37,_xlfn.XMATCH($A13,MFModRaw!$A$2:$A$37),_xlfn.XMATCH(E$2,MFModRaw!$B$1:$Z$1))} -> 1.5584331e+08 | F13: {=INDEX(MFModRaw!$B$2:$Z$37,_xlfn.XMATCH($A13,MFModRaw!$A$2:$A$37),_xlfn.XMATCH(F$2,MFModRaw!$B$1:$Z$1))} -> 1.5544263e+08 | G13: {=INDEX(MFModRaw!$B$2:$Z$37,_xlfn.XMATCH($A13,MFModRaw!$A$2:$A$37),_xlfn.XMATCH(G$2,MFModRaw!$B$1:$Z$1))} -> 1.5565329e+08 | H13: {=INDEX(MFModRaw!$B$2:$Z$37,_xlfn.XMATCH($A13,MFModRaw!$A$2:$A$37),_xlfn.XMATCH(H$2,MFModRaw!$B$1:$Z$1))} -> 1.5574301e+08 | K13: 2025 | L13: =C13/$B13-1 -> -0.011323455 | M13: =D13/$B13-1 -> -0.010005158 | N13: =E13/$B13-1 -> -0.0094360788 | O13: =F13/$B13-1 -> -0.011982869 | P13: =G13/$B13-1 -> -0.010643877 | Q13: =H13/$B13-1 -> -0.010073556
A14: 2026 | B14: {=INDEX(MFModRaw!$B$2:$Z$37,_xlfn.XMATCH($A14,MFModRaw!$A$2:$A$37),_xlfn.XMATCH(B$2,MFModRaw!$B$1:$Z$1))} -> 1.611743e+08 | C14: {=INDEX(MFModRaw!$B$2:$Z$37,_xlfn.XMATCH($A14,MFModRaw!$A$2:$A$37),_xlfn.XMATCH(C$2,MFModRaw!$B$1:$Z$1))} -> 1.587029e+08 | D14: {=INDEX(MFModRaw!$B$2:$Z$37,_xlfn.XMATCH($A14,MFModRaw!$A$2:$A$37),_xlfn.XMATCH(D$2,MFModRaw!$B$1:$Z$1))} -> 1.5900265e+08 | E14: {=INDEX(MFModRaw!$B$2:$Z$37,_xlfn.XMATCH($A14,MFModRaw!$A$2:$A$37),_xlfn.XMATCH(E$2,MFModRaw!$B$1:$Z$1))} -> 1.5913396e+08 | F14: {=INDEX(MFModRaw!$B$2:$Z$37,_xlfn.XMATCH($A14,MFModRaw!$A$2:$A$37),_xlfn.XMATCH(F$2,MFModRaw!$B$1:$Z$1))} -> 1.5852124e+08 | G14: {=INDEX(MFModRaw!$B$2:$Z$37,_xlfn.XMATCH($A14,MFModRaw!$A$2:$A$37),_xlfn.XMATCH(G$2,MFModRaw!$B$1:$Z$1))} -> 1.5882651e+08 | H14: {=INDEX(MFModRaw!$B$2:$Z$37,_xlfn.XMATCH($A14,MFModRaw!$A$2:$A$37),_xlfn.XMATCH(H$2,MFModRaw!$B$1:$Z$1))} -> 1.5895817e+08 | K14: 2026 | L14: =C14/$B14-1 -> -0.015333709 | M14: =D14/$B14-1 -> -0.01347391 | N14: =E14/$B14-1 -> -0.012659158 | O14: =F14/$B14-1 -> -0.016460781 | P14: =G14/$B14-1 -> -0.01456673 | Q14: =H14/$B14-1 -> -0.0137499
... A38: 2050 | B38: {=INDEX(MFModRaw!$B$2:$Z$37,_xlfn.XMATCH($A38,MFModRaw!$A$2:$A$37),_xlfn.XMATCH(B$2,MFModRaw!$B$1:$Z$1))} -> 2.2213448e+08 | C38: {=INDEX(MFModRaw!$B$2:$Z$37,_xlfn.XMATCH($A38,MFModRaw!$A$2:$A$37),_xlfn.XMATCH(C$2,MFModRaw!$B$1:$Z$1))} -> 1.9757191e+08 | D38: {=INDEX(MFModRaw!$B$2:$Z$37,_xlfn.XMATCH($A38,MFModRaw!$A$2:$A$37),_xlfn.XMATCH(D$2,MFModRaw!$B$1:$Z$1))} -> 2.0250824e+08 | E38: {=INDEX(MFModRaw!$B$2:$Z$37,_xlfn.XMATCH($A38,MFModRaw!$A$2:$A$37),_xlfn.XMATCH(E$2,MFModRaw!$B$1:$Z$1))} -> 2.0514343e+08 | F38: {=INDEX(MFModRaw!$B$2:$Z$37,_xlfn.XMATCH($A38,MFModRaw!$A$2:$A$37),_xlfn.XMATCH(F$2,MFModRaw!$B$1:$Z$1))} -> 1.7838478e+08 | G38: {=INDEX(MFModRaw!$B$2:$Z$37,_xlfn.XMATCH($A38,MFModRaw!$A$2:$A$37),_xlfn.XMATCH(G$2,MFModRaw!$B$1:$Z$1))} -> 1.8348813e+08 | H38: {=INDEX(MFModRaw!$B$2:$Z$37,_xlfn.XMATCH($A38,MFModRaw!$A$2:$A$37),_xlfn.XMATCH(H$2,MFModRaw!$B$1:$Z$1))} -> 1.8606406e+08 | K38: 2050 | L38: =C38/$B38-1 -> -0.11057521 | M38: =D38/$B38-1 -> -0.088352958 | N38: =E38/$B38-1 -> -0.076489918 | O38: =F38/$B38-1 -> -0.19695141 | P38: =G38/$B38-1 -> -0.17397728 | Q38: =H38/$B38-1 -> -0.16238102

Sheet DRR
B1: Baseline | C1: Control_Optimistic | D1: StatusQuo_Optimistic | E1: Improvement_Optimistic | F1: Control_Pessimistic | G1: StatusQuo_Pessimistic | H1: Improvement_Pessimistic
B2: KHMNYGDPMKTPKN_0 | C2: KHMNYGDPMKTPKN_111 | D2: KHMNYGDPMKTPKN_121 | E2: KHMNYGDPMKTPKN_131 | F2: KHMNYGDPMKTPKN_211 | G2: KHMNYGDPMKTPKN_221 | H2: KHMNYGDPMKTPKN_231 | L2: =C1 -> Control_Optimistic | M2: =D1 -> StatusQuo_Optimistic | N2: =E1 -> Improvement_Optimistic | O2: =F1 -> Control_Pessimistic | P2: =G1 -> StatusQuo_Pessimistic | Q2: =H1 -> Improvement_Pessimistic
A3: 2015 | B3: {=INDEX(MFModRaw!$B$2:$Z$37,_xlfn.XMATCH($A3,MFModRaw!$A$2:$A$37),_xlfn.XMATCH(B$2,MFModRaw!$B$1:$Z$1))} -> 95406125 | C3: {=INDEX(MFModRaw!$B$2:$Z$37,_xlfn.XMATCH($A3,MFModRaw!$A$2:$A$37),_xlfn.XMATCH(C$2,MFModRaw!$B$1:$Z$1))} -> 95406125 | D3: {=INDEX(MFModRaw!$B$2:$Z$37,_xlfn.XMATCH($A3,MFModRaw!$A$2:$A$37),_xlfn.XMATCH(D$2,MFModRaw!$B$1:$Z$1))} -> 95406125 | E3: {=INDEX(MFModRaw!$B$2:$Z$37,_xlfn.XMATCH($A3,MFModRaw!$A$2:$A$37),_xlfn.XMATCH(E$2,MFModRaw!$B$1:$Z$1))} -> 95406125 | F3: {=INDEX(MFModRaw!$B$2:$Z$37,_xlfn.XMATCH($A3,MFModRaw!$A$2:$A$37),_xlfn.XMATCH(F$2,MFModRaw!$B$1:$Z$1))} -> 95406125 | G3: {=INDEX(MFModRaw!$B$2:$Z$37,_xlfn.XMATCH($A3,MFModRaw!$A$2:$A$37),_xlfn.XMATCH(G$2,MFModRaw!$B$1:$Z$1))} -> 95406125 | H3: {=INDEX(MFModRaw!$B$2:$Z$37,_xlfn.XMATCH($A3,MFModRaw!$A$2:$A$37),_xlfn.XMATCH(H$2,MFModRaw!$B$1:$Z$1))} -> 95406125 | K3: 2015 | L3: =C3/$B3-1 -> 0 | M3: =D3/$B3-1 -> 0 | N3: =E3/$B3-1 -> 0 | O3: =F3/$B3-1 -> 0 | P3: =G3/$B3-1 -> 0 | Q3: =H3/$B3-1 -> 0
A4: 2016 | B4: {=INDEX(MFModRaw!$B$2:$Z$37,_xlfn.XMATCH($A4,MFModRaw!$A$2:$A$37),_xlfn.XMATCH(B$2,MFModRaw!$B$1:$Z$1))} -> 1.0294846e+08 | C4: {=INDEX(MFModRaw!$B$2:$Z$37,_xlfn.XMATCH($A4,MFModRaw!$A$2:$A$37),_xlfn.XMATCH(C$2,MFModRaw!$B$1:$Z$1))} -> 1.0294846e+08 | D4: {=INDEX(MFModRaw!$B$2:$Z$37,_xlfn.XMATCH($A4,MFModRaw!$A$2:$A$37),_xlfn.XMATCH(D$2,MFModRaw!$B$1:$Z$1))} -> 1.0294846e+08 | E4: {=INDEX(MFModRaw!$B$2:$Z$37,_xlfn.XMATCH($A4,MFModRaw!$A$2:$A$37),_xlfn.XMATCH(E$2,MFModRaw!$B$1:$Z$1))} -> 1.0294846e+08 | F4: {=INDEX(MFModRaw!$B$2:$Z$37,_xlfn.XMATCH($A4,MFModRaw!$A$2:$A$37),_xlfn.XMATCH(F$2,MFModRaw!$B$1:$Z$1))} -> 1.0294846e+08 | G4: {=INDEX(MFModRaw!$B$2:$Z$37,_xlfn.XMATCH($A4,MFModRaw!$A$2:$A$37),_xlfn.XMATCH(G$2,MFModRaw!$B$1:$Z$1))} -> 1.0294846e+08 | H4: {=INDEX(MFModRaw!$B$2:$Z$37,_xlfn.XMATCH($A4,MFModRaw!$A$2:$A$37),_xlfn.XMATCH(H$2,MFModRaw!$B$1:$Z$1))} -> 1.0294846e+08 | K4: 2016 | L4: =C4/$B4-1 -> 0 | M4: =D4/$B4-1 -> 0 | N4: =E4/$B4-1 -> 0 | O4: =F4/$B4-1 -> 0 | P4: =G4/$B4-1 -> 0 | Q4: =H4/$B4-1 -> 0
A5: 2017 | B5: {=INDEX(MFModRaw!$B$2:$Z$37,_xlfn.XMATCH($A5,MFModRaw!$A$2:$A$37),_xlfn.XMATCH(B$2,MFModRaw!$B$1:$Z$1))} -> 1.1126159e+08 | C5: {=INDEX(MFModRaw!$B$2:$Z$37,_xlfn.XMATCH($A5,MFModRaw!$A$2:$A$37),_xlfn.XMATCH(C$2,MFModRaw!$B$1:$Z$1))} -> 1.1126159e+08 | D5: {=INDEX(MFModRaw!$B$2:$Z$37,_xlfn.XMATCH($A5,MFModRaw!$A$2:$A$37),_xlfn.XMATCH(D$2,MFModRaw!$B$1:$Z$1))} -> 1.1126159e+08 | E5: {=INDEX(MFModRaw!$B$2:$Z$37,_xlfn.XMATCH($A5,MFModRaw!$A$2:$A$37),_xlfn.XMATCH(E$2,MFModRaw!$B$1:$Z$1))} -> 1.1126159e+08 | F5: {=INDEX(MFModRaw!$B$2:$Z$37,_xlfn.XMATCH($A5,MFModRaw!$A$2:$A$37),_xlfn.XMATCH(F$2,MFModRaw!$B$1:$Z$1))} -> 1.1126159e+08 | G5: {=INDEX(MFModRaw!$B$2:$Z$37,_xlfn.XMATCH($A5,MFModRaw!$A$2:$A$37),_xlfn.XMATCH(G$2,MFModRaw!$B$1:$Z$1))} -> 1.1126159e+08 | H5: {=INDEX(MFModRaw!$B$2:$Z$37,_xlfn.XMATCH($A5,MFModRaw!$A$2:$A$37),_xlfn.XMATCH(H$2,MFModRaw!$B$1:$Z$1))} -> 1.1126159e+08 | K5: 2017 | L5: =C5/$B5-1 -> 0 | M5: =D5/$B5-1 -> 0 | N5: =E5/$B5-1 -> 0 | O5: =F5/$B5-1 -> 0 | P5: =G5/$B5-1 -> 0 | Q5: =H5/$B5-1 -> 0
A6: 2018 | B6: {=INDEX(MFModRaw!$B$2:$Z$37,_xlfn.XMATCH($A6,MFModRaw!$A$2:$A$37),_xlfn.XMATCH(B$2,MFModRaw!$B$1:$Z$1))} -> 1.2102615e+08 | C6: {=INDEX(MFModRaw!$B$2:$Z$37,_xlfn.XMATCH($A6,MFModRaw!$A$2:$A$37),_xlfn.XMATCH(C$2,MFModRaw!$B$1:$Z$1))} -> 1.2102615e+08 | D6: {=INDEX(MFModRaw!$B$2:$Z$37,_xlfn.XMATCH($A6,MFModRaw!$A$2:$A$37),_xlfn.XMATCH(D$2,MFModRaw!$B$1:$Z$1))} -> 1.2102615e+08 | E6: {=INDEX(MFModRaw!$B$2:$Z$37,_xlfn.XMATCH($A6,MFModRaw!$A$2:$A$37),_xlfn.XMATCH(E$2,MFModRaw!$B$1:$Z$1))} -> 1.2102615e+08 | F6: {=INDEX(MFModRaw!$B$2:$Z$37,_xlfn.XMATCH($A6,MFModRaw!$A$2:$A$37),_xlfn.XMATCH(F$2,MFModRaw!$B$1:$Z$1))} -> 1.2102615e+08 | G6: {=INDEX(MFModRaw!$B$2:$Z$37,_xlfn.XMATCH($A6,MFModRaw!$A$2:$A$37),_xlfn.XMATCH(G$2,MFModRaw!$B$1:$Z$1))} -> 1.2102615e+08 | H6: {=INDEX(MFModRaw!$B$2:$Z$37,_xlfn.XMATCH($A6,MFModRaw!$A$2:$A$37),_xlfn.XMATCH(H$2,MFModRaw!$B$1:$Z$1))} -> 1.2102615e+08 | K6: 2018 | L6: =C6/$B6-1 -> 0 | M6: =D6/$B6-1 -> 0 | N6: =E6/$B6-1 -> 0 | O6: =F6/$B6-1 -> 0 | P6: =G6/$B6-1 -> 0 | Q6: =H6/$B6-1 -> 0
A7: 2019 | B7: {=INDEX(MFModRaw!$B$2:$Z$37,_xlfn.XMATCH($A7,MFModRaw!$A$2:$A$37),_xlfn.XMATCH(B$2,MFModRaw!$B$1:$Z$1))} -> 1.3063194e+08 | C7: {=INDEX(MFModRaw!$B$2:$Z$37,_xlfn.XMATCH($A7,MFModRaw!$A$2:$A$37),_xlfn.XMATCH(C$2,MFModRaw!$B$1:$Z$1))} -> 1.3063194e+08 | D7: {=INDEX(MFModRaw!$B$2:$Z$37,_xlfn.XMATCH($A7,MFModRaw!$A$2:$A$37),_xlfn.XMATCH(D$2,MFModRaw!$B$1:$Z$1))} -> 1.3063194e+08 | E7: {=INDEX(MFModRaw!$B$2:$Z$37,_xlfn.XMATCH($A7,MFModRaw!$A$2:$A$37),_xlfn.XMATCH(E$2,MFModRaw!$B$1:$Z$1))} -> 1.3063194e+08 | F7: {=INDEX(MFModRaw!$B$2:$Z$37,_xlfn.XMATCH($A7,MFModRaw!$A$2:$A$37),_xlfn.XMATCH(F$2,MFModRaw!$B$1:$Z$1))} -> 1.3063194e+08 | G7: {=INDEX(MFModRaw!$B$2:$Z$37,_xlfn.XMATCH($A7,MFModRaw!$A$2:$A$37),_xlfn.XMATCH(G$2,MFModRaw!$B$1:$Z$1))} -> 1.3063194e+08 | H7: {=INDEX(MFModRaw!$B$2:$Z$37,_xlfn.XMATCH($A7,MFModRaw!$A$2:$A$37),_xlfn.XMATCH(H$2,MFModRaw!$B$1:$Z$1))} -> 1.3063194e+08 | K7: 2019 | L7: =C7/$B7-1 -> 0 | M7: =D7/$B7-1 -> 0 | N7: =E7/$B7-1 -> 0 | O7: =F7/$B7-1 -> 0 | P7: =G7/$B7-1 -> 0 | Q7: =H7/$B7-1 -> 0
A8: 2020 | B8: {=INDEX(MFModRaw!$B$2:$Z$37,_xlfn.XMATCH($A8,MFModRaw!$A$2:$A$37),_xlfn.XMATCH(B$2,MFModRaw!$B$1:$Z$1))} -> 1.2598703e+08 | C8: {=INDEX(MFModRaw!$B$2:$Z$37,_xlfn.XMATCH($A8,MFModRaw!$A$2:$A$37),_xlfn.XMATCH(C$2,MFModRaw!$B$1:$Z$1))} -> 1.2598703e+08 | D8: {=INDEX(MFModRaw!$B$2:$Z$37,_xlfn.XMATCH($A8,MFModRaw!$A$2:$A$37),_xlfn.XMATCH(D$2,MFModRaw!$B$1:$Z$1))} -> 1.2598715e+08 | E8: {=INDEX(MFModRaw!$B$2:$Z$37,_xlfn.XMATCH($A8,MFModRaw!$A$2:$A$37),_xlfn.XMATCH(E$2,MFModRaw!$B$1:$Z$1))} -> 1.2598728e+08 | F8: {=INDEX(MFModRaw!$B$2:$Z$37,_xlfn.XMATCH($A8,MFModRaw!$A$2:$A$37),_xlfn.XMATCH(F$2,MFModRaw!$B$1:$Z$1))} -> 1.2598703e+08 | G8: {=INDEX(MFModRaw!$B$2:$Z$37,_xlfn.XMATCH($A8,MFModRaw!$A$2:$A$37),_xlfn.XMATCH(G$2,MFModRaw!$B$1:$Z$1))} -> 1.2598715e+08 | H8: {=INDEX(MFModRaw!$B$2:$Z$37,_xlfn.XMATCH($A8,MFModRaw!$A$2:$A$37),_xlfn.XMATCH(H$2,MFModRaw!$B$1:$Z$1))} -> 1.2598728e+08 | K8: 2020 | L8: =C8/$B8-1 -> 0 | M8: =D8/$B8-1 -> 9.8388951e-07 | N8: =E8/$B8-1 -> 1.9678185e-06 | O8: =F8/$B8-1 -> 0 | P8: =G8/$B8-1 -> 9.8388951e-07 | Q8: =H8/$B8-1 -> 1.9678185e-06
A9: 2021 | B9: {=INDEX(MFModRaw!$B$2:$Z$37,_xlfn.XMATCH($A9,MFModRaw!$A$2:$A$37),_xlfn.XMATCH(B$2,MFModRaw!$B$1:$Z$1))} -> 1.2987983e+08 | C9: {=INDEX(MFModRaw!$B$2:$Z$37,_xlfn.XMATCH($A9,MFModRaw!$A$2:$A$37),_xlfn.XMATCH(C$2,MFModRaw!$B$1:$Z$1))} -> 1.2980125e+08 | D9: {=INDEX(MFModRaw!$B$2:$Z$37,_xlfn.XMATCH($A9,MFModRaw!$A$2:$A$37),_xlfn.XMATCH(D$2,MFModRaw!$B$1:$Z$1))} -> 1.2980371e+08 | E9: {=INDEX(MFModRaw!$B$2:$Z$37,_xlfn.XMATCH($A9,MFModRaw!$A$2:$A$37),_xlfn.XMATCH(E$2,MFModRaw!$B$1:$Z$1))} -> 1.2980365e+08 | F9: {=INDEX(MFModRaw!$B$2:$Z$37,_xlfn.XMATCH($A9,MFModRaw!$A$2:$A$37),_xlfn.XMATCH(F$2,MFModRaw!$B$1:$Z$1))} -> 1.2980125e+08 | G9: {=INDEX(MFModRaw!$B$2:$Z$37,_xlfn.XMATCH($A9,MFModRaw!$A$2:$A$37),_xlfn.XMATCH(G$2,MFModRaw!$B$1:$Z$1))} -> 1.2980371e+08 | H9: {=INDEX(MFModRaw!$B$2:$Z$37,_xlfn.XMATCH($A9,MFModRaw!$A$2:$A$37),_xlfn.XMATCH(H$2,MFModRaw!$B$1:$Z$1))} -> 1.2980365e+08 | K9: 2021 | L9: =C9/$B9-1 -> -0.00060500921 | M9: =D9/$B9-1 -> -0.00058607688 | N9: =E9/$B9-1 -> -0.00058653925 | O9: =F9/$B9-1 -> -0.00060500921 | P9: =G9/$B9-1 -> -0.00058607688 | Q9: =H9/$B9-1 -> -0.00058653925
A10: 2022 | B10: {=INDEX(MFModRaw!$B$2:$Z$37,_xlfn.XMATCH($A10,MFModRaw!$A$2:$A$37),_xlfn.XMATCH(B$2,MFModRaw!$B$1:$Z$1))} -> 1.3650808e+08 | C10: {=INDEX(MFModRaw!$B$2:$Z$37,_xlfn.XMATCH($A10,MFModRaw!$A$2:$A$37),_xlfn.XMATCH(C$2,MFModRaw!$B$1:$Z$1))} -> 1.3619747e+08 | D10: {=INDEX(MFModRaw!$B$2:$Z$37,_xlfn.XMATCH($A10,MFModRaw!$A$2:$A$37),_xlfn.XMATCH(D$2,MFModRaw!$B$1:$Z$1))} -> 1.3620733e+08 | E10: {=INDEX(MFModRaw!$B$2:$Z$37,_xlfn.XMATCH($A10,MFModRaw!$A$2:$A$37),_xlfn.XMATCH(E$2,MFModRaw!$B$1:$Z$1))} -> 1.3620725e+08 | F10: {=INDEX(MFModRaw!$B$2:$Z$37,_xlfn.XMATCH($A10,MFModRaw!$A$2:$A$37),_xlfn.XMATCH(F$2,MFModRaw!$B$1:$Z$1))} -> 1.3619282e+08 | G10: {=INDEX(MFModRaw!$B$2:$Z$37,_xlfn.XMATCH($A10,MFModRaw!$A$2:$A$37),_xlfn.XMATCH(G$2,MFModRaw!$B$1:$Z$1))} -> 1.3620283e+08 | H10: {=INDEX(MFModRaw!$B$2:$Z$37,_xlfn.XMATCH($A10,MFModRaw!$A$2:$A$37),_xlfn.XMATCH(H$2,MFModRaw!$B$1:$Z$1))} -> 1.3620276e+08 | K10: 2022 | L10: =C10/$B10-1 -> -0.0022753746 | M10: =D10/$B10-1 -> -0.0022031378 | N10: =E10/$B10-1 -> -0.0022037142 | O10: =F10/$B10-1 -> -0.0023094467 | P10: =G10/$B10-1 -> -0.0022360891 | Q10: =H10/$B10-1 -> -0.0022366436
A11: 2023 | B11: {=INDEX(MFModRaw!$B$2:$Z$37,_xlfn.XMATCH($A11,MFModRaw!$A$2:$A$37),_xlfn.XMATCH(B$2,MFModRaw!$B$1:$Z$1))} -> 1.4333428e+08 | C11: {=INDEX(MFModRaw!$B$2:$Z$37,_xlfn.XMATCH($A11,MFModRaw!$A$2:$A$37),_xlfn.XMATCH(C$2,MFModRaw!$B$1:$Z$1))} -> 1.4270422e+08 | D11: {=INDEX(MFModRaw!$B$2:$Z$37,_xlfn.XMATCH($A11,MFModRaw!$A$2:$A$37),_xlfn.XMATCH(D$2,MFModRaw!$B$1:$Z$1))} -> 1.4272429e+08 | E11: {=INDEX(MFModRaw!$B$2:$Z$37,_xlfn.XMATCH($A11,MFModRaw!$A$2:$A$37),_xlfn.XMATCH(E$2,MFModRaw!$B$1:$Z$1))} -> 1.4272427e+08 | F11: {=INDEX(MFModRaw!$B$2:$Z$37,_xlfn.XMATCH($A11,MFModRaw!$A$2:$A$37),_xlfn.XMATCH(F$2,MFModRaw!$B$1:$Z$1))} -> 1.4268639e+08 | G11: {=INDEX(MFModRaw!$B$2:$Z$37,_xlfn.XMATCH($A11,MFModRaw!$A$2:$A$37),_xlfn.XMATCH(G$2,MFModRaw!$B$1:$Z$1))} -> 1.4270705e+08 | H11: {=INDEX(MFModRaw!$B$2:$Z$37,_xlfn.XMATCH($A11,MFModRaw!$A$2:$A$37),_xlfn.XMATCH(H$2,MFModRaw!$B$1:$Z$1))} -> 1.4270705e+08 | K11: 2023 | L11: =C11/$B11-1 -> -0.0043957149 | M11: =D11/$B11-1 -> -0.0042556714 | N11: =E11/$B11-1 -> -0.0042558378 | O11: =F11/$B11-1 -> -0.0045201082 | P11: =G11/$B11-1 -> -0.0043759589 | Q11: =H11/$B11-1 -> -0.0043760052
A12: 2024 | B12: {=INDEX(MFModRaw!$B$2:$Z$37,_xlfn.XMATCH($A12,MFModRaw!$A$2:$A$37),_xlfn.XMATCH(B$2,MFModRaw!$B$1:$Z$1))} -> 1.5196078e+08 | C12: {=INDEX(MFModRaw!$B$2:$Z$37,_xlfn.XMATCH($A12,MFModRaw!$A$2:$A$37),_xlfn.XMATCH(C$2,MFModRaw!$B$1:$Z$1))} -> 1.5081509e+08 | D12: {=INDEX(MFModRaw!$B$2:$Z$37,_xlfn.XMATCH($A12,MFModRaw!$A$2:$A$37),_xlfn.XMATCH(D$2,MFModRaw!$B$1:$Z$1))} -> 1.5085203e+08 | E12: {=INDEX(MFModRaw!$B$2:$Z$37,_xlfn.XMATCH($A12,MFModRaw!$A$2:$A$37),_xlfn.XMATCH(E$2,MFModRaw!$B$1:$Z$1))} -> 1.5085254e+08 | F12: {=INDEX(MFModRaw!$B$2:$Z$37,_xlfn.XMATCH($A12,MFModRaw!$A$2:$A$37),_xlfn.XMATCH(F$2,MFModRaw!$B$1:$Z$1))} -> 1.5076351e+08 | G12: {=INDEX(MFModRaw!$B$2:$Z$37,_xlfn.XMATCH($A12,MFModRaw!$A$2:$A$37),_xlfn.XMATCH(G$2,MFModRaw!$B$1:$Z$1))} -> 1.5080216e+08 | H12: {=INDEX(MFModRaw!$B$2:$Z$37,_xlfn.XMATCH($A12,MFModRaw!$A$2:$A$37),_xlfn.XMATCH(H$2,MFModRaw!$B$1:$Z$1))} -> 1.5080274e+08 | K12: 2024 | L12: =C12/$B12-1 -> -0.007539386 | M12: =D12/$B12-1 -> -0.007296279 | N12: =E12/$B12-1 -> -0.0072929048 | O12: =F12/$B12-1 -> -0.0078788267 | P12: =G12/$B12-1 -> -0.0076244444 | Q12: =H12/$B12-1 -> -0.0076206191
A13: 2025 | B13: {=INDEX(MFModRaw!$B$2:$Z$37,_xlfn.XMATCH($A13,MFModRaw!$A$2:$A$37),_xlfn.XMATCH(B$2,MFModRaw!$B$1:$Z$1))} -> 1.5732787e+08 | C13: {=INDEX(MFModRaw!$B$2:$Z$37,_xlfn.XMATCH($A13,MFModRaw!$A$2:$A$37),_xlfn.XMATCH(C$2,MFModRaw!$B$1:$Z$1))} -> 1.5558524e+08 | D13: {=INDEX(MFModRaw!$B$2:$Z$37,_xlfn.XMATCH($A13,MFModRaw!$A$2:$A$37),_xlfn.XMATCH(D$2,MFModRaw!$B$1:$Z$1))} -> 1.5564179e+08 | E13: {=INDEX(MFModRaw!$B$2:$Z$37,_xlfn.XMATCH($A13,MFModRaw!$A$2:$A$37),_xlfn.XMATCH(E$2,MFModRaw!$B$1:$Z$1))} -> 1.5564313e+08 | F13: {=INDEX(MFModRaw!$B$2:$Z$37,_xlfn.XMATCH($A13,MFModRaw!$A$2:$A$37),_xlfn.XMATCH(F$2,MFModRaw!$B$1:$Z$1))} -> 1.5547825e+08 | G13: {=INDEX(MFModRaw!$B$2:$Z$37,_xlfn.XMATCH($A13,MFModRaw!$A$2:$A$37),_xlfn.XMATCH(G$2,MFModRaw!$B$1:$Z$1))} -> 1.5553837e+08 | H13: {=INDEX(MFModRaw!$B$2:$Z$37,_xlfn.XMATCH($A13,MFModRaw!$A$2:$A$37),_xlfn.XMATCH(H$2,MFModRaw!$B$1:$Z$1))} -> 1.5553989e+08 | K13: 2025 | L13: =C13/$B13-1 -> -0.011076412 | M13: =D13/$B13-1 -> -0.010716961 | N13: =E13/$B13-1 -> -0.010708447 | O13: =F13/$B13-1 -> -0.011756454 | P13: =G13/$B13-1 -> -0.011374312 | Q13: =H13/$B13-1 -> -0.011364656
A14: 2026 | B14: {=INDEX(MFModRaw!$B$2:$Z$37,_xlfn.XMATCH($A14,MFModRaw!$A$2:$A$37),_xlfn.XMATCH(B$2,MFModRaw!$B$1:$Z$1))} -> 1.611743e+08 | C14: {=INDEX(MFModRaw!$B$2:$Z$37,_xlfn.XMATCH($A14,MFModRaw!$A$2:$A$37),_xlfn.XMATCH(C$2,MFModRaw!$B$1:$Z$1))} -> 1.5875619e+08 | D14: {=INDEX(MFModRaw!$B$2:$Z$37,_xlfn.XMATCH($A14,MFModRaw!$A$2:$A$37),_xlfn.XMATCH(D$2,MFModRaw!$B$1:$Z$1))} -> 1.5883504e+08 | E14: {=INDEX(MFModRaw!$B$2:$Z$37,_xlfn.XMATCH($A14,MFModRaw!$A$2:$A$37),_xlfn.XMATCH(E$2,MFModRaw!$B$1:$Z$1))} -> 1.5883757e+08 | F14: {=INDEX(MFModRaw!$B$2:$Z$37,_xlfn.XMATCH($A14,MFModRaw!$A$2:$A$37),_xlfn.XMATCH(F$2,MFModRaw!$B$1:$Z$1))} -> 1.5857245e+08 | G14: {=INDEX(MFModRaw!$B$2:$Z$37,_xlfn.XMATCH($A14,MFModRaw!$A$2:$A$37),_xlfn.XMATCH(G$2,MFModRaw!$B$1:$Z$1))} -> 1.5865745e+08 | H14: {=INDEX(MFModRaw!$B$2:$Z$37,_xlfn.XMATCH($A14,MFModRaw!$A$2:$A$37),_xlfn.XMATCH(H$2,MFModRaw!$B$1:$Z$1))} -> 1.5866034e+08 | K14: 2026 | L14: =C14/$B14-1 -> -0.015003032 | M14: =D14/$B14-1 -> -0.014513822 | N14: =E14/$B14-1 -> -0.014498132 | O14: =F14/$B14-1 -> -0.016143048 | P14: =G14/$B14-1 -> -0.015615693 | Q14: =H14/$B14-1 -> -0.015597736
... A38: 2050 | B38: {=INDEX(MFModRaw!$B$2:$Z$37,_xlfn.XMATCH($A38,MFModRaw!$A$2:$A$37),_xlfn.XMATCH(B$2,MFModRaw!$B$1:$Z$1))} -> 2.2213448e+08 | C38: {=INDEX(MFModRaw!$B$2:$Z$37,_xlfn.XMATCH($A38,MFModRaw!$A$2:$A$37),_xlfn.XMATCH(C$2,MFModRaw!$B$1:$Z$1))} -> 1.9810657e+08 | D38: {=INDEX(MFModRaw!$B$2:$Z$37,_xlfn.XMATCH($A38,MFModRaw!$A$2:$A$37),_xlfn.XMATCH(D$2,MFModRaw!$B$1:$Z$1))} -> 1.9898597e+08 | E38: {=INDEX(MFModRaw!$B$2:$Z$37,_xlfn.XMATCH($A38,MFModRaw!$A$2:$A$37),_xlfn.XMATCH(E$2,MFModRaw!$B$1:$Z$1))} -> 1.991873e+08 | F38: {=INDEX(MFModRaw!$B$2:$Z$37,_xlfn.XMATCH($A38,MFModRaw!$A$2:$A$37),_xlfn.XMATCH(F$2,MFModRaw!$B$1:$Z$1))} -> 1.7978645e+08 | G38: {=INDEX(MFModRaw!$B$2:$Z$37,_xlfn.XMATCH($A38,MFModRaw!$A$2:$A$37),_xlfn.XMATCH(G$2,MFModRaw!$B$1:$Z$1))} -> 1.8130559e+08 | H38: {=INDEX(MFModRaw!$B$2:$Z$37,_xlfn.XMATCH($A38,MFModRaw!$A$2:$A$37),_xlfn.XMATCH(H$2,MFModRaw!$B$1:$Z$1))} -> 1.8170813e+08 | K38: 2050 | L38: =C38/$B38-1 -> -0.10816829 | M38: =D38/$B38-1 -> -0.10420945 | N38: =E38/$B38-1 -> -0.10330311 | O38: =F38/$B38-1 -> -0.1906414 | P38: =G38/$B38-1 -> -0.18380258 | Q38: =H38/$B38-1 -> -0.18199045

Sheet AGR
B1: Baseline | C1: Control_Optimistic | D1: StatusQuo_Optimistic | E1: Improvement_Optimistic | F1: Control_Pessimistic | G1: StatusQuo_Pessimistic | H1: Improvement_Pessimistic
B2: KHMNYGDPMKTPKN_0 | C2: KHMNYGDPMKTPKN_112 | D2: KHMNYGDPMKTPKN_122 | E2: KHMNYGDPMKTPKN_132 | F2: KHMNYGDPMKTPKN_212 | G2: KHMNYGDPMKTPKN_222 | H2: KHMNYGDPMKTPKN_232 | L2: =C1 -> Control_Optimistic | M2: =D1 -> StatusQuo_Optimistic | N2: =E1 -> Improvement_Optimistic | O2: =F1 -> Control_Pessimistic | P2: =G1 -> StatusQuo_Pessimistic | Q2: =H1 -> Improvement_Pessimistic
A3: 2015 | B3: {=INDEX(MFModRaw!$B$2:$Z$37,_xlfn.XMATCH($A3,MFModRaw!$A$2:$A$37),_xlfn.XMATCH(B$2,MFModRaw!$B$1:$Z$1))} -> 95406125 | C3: {=INDEX(MFModRaw!$B$2:$Z$37,_xlfn.XMATCH($A3,MFModRaw!$A$2:$A$37),_xlfn.XMATCH(C$2,MFModRaw!$B$1:$Z$1))} -> 95406125 | D3: {=INDEX(MFModRaw!$B$2:$Z$37,_xlfn.XMATCH($A3,MFModRaw!$A$2:$A$37),_xlfn.XMATCH(D$2,MFModRaw!$B$1:$Z$1))} -> 95406125 | E3: {=INDEX(MFModRaw!$B$2:$Z$37,_xlfn.XMATCH($A3,MFModRaw!$A$2:$A$37),_xlfn.XMATCH(E$2,MFModRaw!$B$1:$Z$1))} -> 95406125 | F3: {=INDEX(MFModRaw!$B$2:$Z$37,_xlfn.XMATCH($A3,MFModRaw!$A$2:$A$37),_xlfn.XMATCH(F$2,MFModRaw!$B$1:$Z$1))} -> 95406125 | G3: {=INDEX(MFModRaw!$B$2:$Z$37,_xlfn.XMATCH($A3,MFModRaw!$A$2:$A$37),_xlfn.XMATCH(G$2,MFModRaw!$B$1:$Z$1))} -> 95406125 | H3: {=INDEX(MFModRaw!$B$2:$Z$37,_xlfn.XMATCH($A3,MFModRaw!$A$2:$A$37),_xlfn.XMATCH(H$2,MFModRaw!$B$1:$Z$1))} -> 95406125 | K3: 2015 | L3: =C3/$B3-1 -> 0 | M3: =D3/$B3-1 -> 0 | N3: =E3/$B3-1 -> 0 | O3: =F3/$B3-1 -> 0 | P3: =G3/$B3-1 -> 0 | Q3: =H3/$B3-1 -> 0
A4: 2016 | B4: {=INDEX(MFModRaw!$B$2:$Z$37,_xlfn.XMATCH($A4,MFModRaw!$A$2:$A$37),_xlfn.XMATCH(B$2,MFModRaw!$B$1:$Z$1))} -> 1.0294846e+08 | C4: {=INDEX(MFModRaw!$B$2:$Z$37,_xlfn.XMATCH($A4,MFModRaw!$A$2:$A$37),_xlfn.XMATCH(C$2,MFModRaw!$B$1:$Z$1))} -> 1.0294846e+08 | D4: {=INDEX(MFModRaw!$B$2:$Z$37,_xlfn.XMATCH($A4,MFModRaw!$A$2:$A$37),_xlfn.XMATCH(D$2,MFModRaw!$B$1:$Z$1))} -> 1.0294846e+08 | E4: {=INDEX(MFModRaw!$B$2:$Z$37,_xlfn.XMATCH($A4,MFModRaw!$A$2:$A$37),_xlfn.XMATCH(E$2,MFModRaw!$B$1:$Z$1))} -> 1.0294846e+08 | F4: {=INDEX(MFModRaw!$B$2:$Z$37,_xlfn.XMATCH($A4,MFModRaw!$A$2:$A$37),_xlfn.XMATCH(F$2,MFModRaw!$B$1:$Z$1))} -> 1.0294846e+08 | G4: {=INDEX(MFModRaw!$B$2:$Z$37,_xlfn.XMATCH($A4,MFModRaw!$A$2:$A$37),_xlfn.XMATCH(G$2,MFModRaw!$B$1:$Z$1))} -> 1.0294846e+08 | H4: {=INDEX(MFModRaw!$B$2:$Z$37,_xlfn.XMATCH($A4,MFModRaw!$A$2:$A$37),_xlfn.XMATCH(H$2,MFModRaw!$B$1:$Z$1))} -> 1.0294846e+08 | K4: 2016 | L4: =C4/$B4-1 -> 0 | M4: =D4/$B4-1 -> 0 | N4: =E4/$B4-1 -> 0 | O4: =F4/$B4-1 -> 0 | P4: =G4/$B4-1 -> 0 | Q4: =H4/$B4-1 -> 0
A5: 2017 | B5: {=INDEX(MFModRaw!$B$2:$Z$37,_xlfn.XMATCH($A5,MFModRaw!$A$2:$A$37),_xlfn.XMATCH(B$2,MFModRaw!$B$1:$Z$1))} -> 1.1126159e+08 | C5: {=INDEX(MFModRaw!$B$2:$Z$37,_xlfn.XMATCH($A5,MFModRaw!$A$2:$A$37),_xlfn.XMATCH(C$2,MFModRaw!$B$1:$Z$1))} -> 1.1126159e+08 | D5: {=INDEX(MFModRaw!$B$2:$Z$37,_xlfn.XMATCH($A5,MFModRaw!$A$2:$A$37),_xlfn.XMATCH(D$2,MFModRaw!$B$1:$Z$1))} -> 1.1126159e+08 | E5: {=INDEX(MFModRaw!$B$2:$Z$37,_xlfn.XMATCH($A5,MFModRaw!$A$2:$A$37),_xlfn.XMATCH(E$2,MFModRaw!$B$1:$Z$1))} -> 1.1126159e+08 | F5: {=INDEX(MFModRaw!$B$2:$Z$37,_xlfn.XMATCH($A5,MFModRaw!$A$2:$A$37),_xlfn.XMATCH(F$2,MFModRaw!$B$1:$Z$1))} -> 1.1126159e+08 | G5: {=INDEX(MFModRaw!$B$2:$Z$37,_xlfn.XMATCH($A5,MFModRaw!$A$2:$A$37),_xlfn.XMATCH(G$2,MFModRaw!$B$1:$Z$1))} -> 1.1126159e+08 | H5: {=INDEX(MFModRaw!$B$2:$Z$37,_xlfn.XMATCH($A5,MFModRaw!$A$2:$A$37),_xlfn.XMATCH(H$2,MFModRaw!$B$1:$Z$1))} -> 1.1126159e+08 | K5: 2017 | L5: =C5/$B5-1 -> 0 | M5: =D5/$B5-1 -> 0 | N5: =E5/$B5-1 -> 0 | O5: =F5/$B5-1 -> 0 | P5: =G5/$B5-1 -> 0 | Q5: =H5/$B5-1 -> 0
A6: 2018 | B6: {=INDEX(MFModRaw!$B$2:$Z$37,_xlfn.XMATCH($A6,MFModRaw!$A$2:$A$37),_xlfn.XMATCH(B$2,MFModRaw!$B$1:$Z$1))} -> 1.2102615e+08 | C6: {=INDEX(MFModRaw!$B$2:$Z$37,_xlfn.XMATCH($A6,MFModRaw!$A$2:$A$37),_xlfn.XMATCH(C$2,MFModRaw!$B$1:$Z$1))} -> 1.2102615e+08 | D6: {=INDEX(MFModRaw!$B$2:$Z$37,_xlfn.XMATCH($A6,MFModRaw!$A$2:$A$37),_xlfn.XMATCH(D$2,MFModRaw!$B$1:$Z$1))} -> 1.2102615e+08 | E6: {=INDEX(MFModRaw!$B$2:$Z$37,_xlfn.XMATCH($A6,MFModRaw!$A$2:$A$37),_xlfn.XMATCH(E$2,MFModRaw!$B$1:$Z$1))} -> 1.2102615e+08 | F6: {=INDEX(MFModRaw!$B$2:$Z$37,_xlfn.XMATCH($A6,MFModRaw!$A$2:$A$37),_xlfn.XMATCH(F$2,MFModRaw!$B$1:$Z$1))} -> 1.2102615e+08 | G6: {=INDEX(MFModRaw!$B$2:$Z$37,_xlfn.XMATCH($A6,MFModRaw!$A$2:$A$37),_xlfn.XMATCH(G$2,MFModRaw!$B$1:$Z$1))} -> 1.2102615e+08 | H6: {=INDEX(MFModRaw!$B$2:$Z$37,_xlfn.XMATCH($A6,MFModRaw!$A$2:$A$37),_xlfn.XMATCH(H$2,MFModRaw!$B$1:$Z$1))} -> 1.2102615e+08 | K6: 2018 | L6: =C6/$B6-1 -> 0 | M6: =D6/$B6-1 -> 0 | N6: =E6/$B6-1 -> 0 | O6: =F6/$B6-1 -> 0 | P6: =G6/$B6-1 -> 0 | Q6: =H6/$B6-1 -> 0
A7: 2019 | B7: {=INDEX(MFModRaw!$B$2:$Z$37,_xlfn.XMATCH($A7,MFModRaw!$A$2:$A$37),_xlfn.XMATCH(B$2,MFModRaw!$B$1:$Z$1))} -> 1.3063194e+08 | C7: {=INDEX(MFModRaw!$B$2:$Z$37,_xlfn.XMATCH($A7,MFModRaw!$A$2:$A$37),_xlfn.XMATCH(C$2,MFModRaw!$B$1:$Z$1))} -> 1.3063194e+08 | D7: {=INDEX(MFModRaw!$B$2:$Z$37,_xlfn.XMATCH($A7,MFModRaw!$A$2:$A$37),_xlfn.XMATCH(D$2,MFModRaw!$B$1:$Z$1))} -> 1.3063194e+08 | E7: {=INDEX(MFModRaw!$B$2:$Z$37,_xlfn.XMATCH($A7,MFModRaw!$A$2:$A$37),_xlfn.XMATCH(E$2,MFModRaw!$B$1:$Z$1))} -> 1.3063194e+08 | F7: {=INDEX(MFModRaw!$B$2:$Z$37,_xlfn.XMATCH($A7,MFModRaw!$A$2:$A$37),_xlfn.XMATCH(F$2,MFModRaw!$B$1:$Z$1))} -> 1.3063194e+08 | G7: {=INDEX(MFModRaw!$B$2:$Z$37,_xlfn.XMATCH($A7,MFModRaw!$A$2:$A$37),_xlfn.XMATCH(G$2,MFModRaw!$B$1:$Z$1))} -> 1.3063194e+08 | H7: {=INDEX(MFModRaw!$B$2:$Z$37,_xlfn.XMATCH($A7,MFModRaw!$A$2:$A$37),_xlfn.XMATCH(H$2,MFModRaw!$B$1:$Z$1))} -> 1.3063194e+08 | K7: 2019 | L7: =C7/$B7-1 -> 0 | M7: =D7/$B7-1 -> 0 | N7: =E7/$B7-1 -> 0 | O7: =F7/$B7-1 -> 0 | P7: =G7/$B7-1 -> 0 | Q7: =H7/$B7-1 -> 0
A8: 2020 | B8: {=INDEX(MFModRaw!$B$2:$Z$37,_xlfn.XMATCH($A8,MFModRaw!$A$2:$A$37),_xlfn.XMATCH(B$2,MFModRaw!$B$1:$Z$1))} -> 1.2598703e+08 | C8: {=INDEX(MFModRaw!$B$2:$Z$37,_xlfn.XMATCH($A8,MFModRaw!$A$2:$A$37),_xlfn.XMATCH(C$2,MFModRaw!$B$1:$Z$1))} -> 1.2598703e+08 | D8: {=INDEX(MFModRaw!$B$2:$Z$37,_xlfn.XMATCH($A8,MFModRaw!$A$2:$A$37),_xlfn.XMATCH(D$2,MFModRaw!$B$1:$Z$1))} -> 1.2598715e+08 | E8: {=INDEX(MFModRaw!$B$2:$Z$37,_xlfn.XMATCH($A8,MFModRaw!$A$2:$A$37),_xlfn.XMATCH(E$2,MFModRaw!$B$1:$Z$1))} -> 1.2598728e+08 | F8: {=INDEX(MFModRaw!$B$2:$Z$37,_xlfn.XMATCH($A8,MFModRaw!$A$2:$A$37),_xlfn.XMATCH(F$2,MFModRaw!$B$1:$Z$1))} -> 1.2598703e+08 | G8: {=INDEX(MFModRaw!$B$2:$Z$37,_xlfn.XMATCH($A8,MFModRaw!$A$2:$A$37),_xlfn.XMATCH(G$2,MFModRaw!$B$1:$Z$1))} -> 1.2598715e+08 | H8: {=INDEX(MFModRaw!$B$2:$Z$37,_xlfn.XMATCH($A8,MFModRaw!$A$2:$A$37),_xlfn.XMATCH(H$2,MFModRaw!$B$1:$Z$1))} -> 1.2598728e+08 | K8: 2020 | L8: =C8/$B8-1 -> 0 | M8: =D8/$B8-1 -> 9.8388951e-07 | N8: =E8/$B8-1 -> 1.9678185e-06 | O8: =F8/$B8-1 -> 0 | P8: =G8/$B8-1 -> 9.8388951e-07 | Q8: =H8/$B8-1 -> 1.9678185e-06
A9: 2021 | B9: {=INDEX(MFModRaw!$B$2:$Z$37,_xlfn.XMATCH($A9,MFModRaw!$A$2:$A$37),_xlfn.XMATCH(B$2,MFModRaw!$B$1:$Z$1))} -> 1.2987983e+08 | C9: {=INDEX(MFModRaw!$B$2:$Z$37,_xlfn.XMATCH($A9,MFModRaw!$A$2:$A$37),_xlfn.XMATCH(C$2,MFModRaw!$B$1:$Z$1))} -> 1.2987814e+08 | D9: {=INDEX(MFModRaw!$B$2:$Z$37,_xlfn.XMATCH($A9,MFModRaw!$A$2:$A$37),_xlfn.XMATCH(D$2,MFModRaw!$B$1:$Z$1))} -> 1.2988214e+08 | E9: {=INDEX(MFModRaw!$B$2:$Z$37,_xlfn.XMATCH($A9,MFModRaw!$A$2:$A$37),_xlfn.XMATCH(E$2,MFModRaw!$B$1:$Z$1))} -> 1.2988464e+08 | F9: {=INDEX(MFModRaw!$B$2:$Z$37,_xlfn.XMATCH($A9,MFModRaw!$A$2:$A$37),_xlfn.XMATCH(F$2,MFModRaw!$B$1:$Z$1))} -> 1.2987868e+08 | G9: {=INDEX(MFModRaw!$B$2:$Z$37,_xlfn.XMATCH($A9,MFModRaw!$A$2:$A$37),_xlfn.XMATCH(G$2,MFModRaw!$B$1:$Z$1))} -> 1.2988268e+08 | H9: {=INDEX(MFModRaw!$B$2:$Z$37,_xlfn.XMATCH($A9,MFModRaw!$A$2:$A$37),_xlfn.XMATCH(H$2,MFModRaw!$B$1:$Z$1))} -> 1.2988518e+08 | K9: 2021 | L9: =C9/$B9-1 -> -1.3020023e-05 | M9: =D9/$B9-1 -> 1.778853e-05 | N9: =E9/$B9-1 -> 3.7020701e-05 | O9: =F9/$B9-1 -> -8.8348833e-06 | P9: =G9/$B9-1 -> 2.1980927e-05 | Q9: =H9/$B9-1 -> 4.1219533e-05
A10: 2022 | B10: {=INDEX(MFModRaw!$B$2:$Z$37,_xlfn.XMATCH($A10,MFModRaw!$A$2:$A$37),_xlfn.XMATCH(B$2,MFModRaw!$B$1:$Z$1))} -> 1.3650808e+08 | C10: {=INDEX(MFModRaw!$B$2:$Z$37,_xlfn.XMATCH($A10,MFModRaw!$A$2:$A$37),_xlfn.XMATCH(C$2,MFModRaw!$B$1:$Z$1))} -> 1.365012e+08 | D10: {=INDEX(MFModRaw!$B$2:$Z$37,_xlfn.XMATCH($A10,MFModRaw!$A$2:$A$37),_xlfn.XMATCH(D$2,MFModRaw!$B$1:$Z$1))} -> 1.3651987e+08 | E10: {=INDEX(MFModRaw!$B$2:$Z$37,_xlfn.XMATCH($A10,MFModRaw!$A$2:$A$37),_xlfn.XMATCH(E$2,MFModRaw!$B$1:$Z$1))} -> 1.3653158e+08 | F10: {=INDEX(MFModRaw!$B$2:$Z$37,_xlfn.XMATCH($A10,MFModRaw!$A$2:$A$37),_xlfn.XMATCH(F$2,MFModRaw!$B$1:$Z$1))} -> 1.3650308e+08 | G10: {=INDEX(MFModRaw!$B$2:$Z$37,_xlfn.XMATCH($A10,MFModRaw!$A$2:$A$37),_xlfn.XMATCH(G$2,MFModRaw!$B$1:$Z$1))} -> 1.3652176e+08 | H10: {=INDEX(MFModRaw!$B$2:$Z$37,_xlfn.XMATCH($A10,MFModRaw!$A$2:$A$37),_xlfn.XMATCH(H$2,MFModRaw!$B$1:$Z$1))} -> 1.3653347e+08 | K10: 2022 | L10: =C10/$B10-1 -> -5.0395857e-05 | M10: =D10/$B10-1 -> 8.6408451e-05 | N10: =E10/$B10-1 -> 0.0001721688 | O10: =F10/$B10-1 -> -3.6618412e-05 | P10: =G10/$B10-1 -> 0.00010023451 | Q10: =H10/$B10-1 -> 0.00018602686
A11: 2023 | B11: {=INDEX(MFModRaw!$B$2:$Z$37,_xlfn.XMATCH($A11,MFModRaw!$A$2:$A$37),_xlfn.XMATCH(B$2,MFModRaw!$B$1:$Z$1))} -> 1.4333428e+08 | C11: {=INDEX(MFModRaw!$B$2:$Z$37,_xlfn.XMATCH($A11,MFModRaw!$A$2:$A$37),_xlfn.XMATCH(C$2,MFModRaw!$B$1:$Z$1))} -> 1.4332005e+08 | D11: {=INDEX(MFModRaw!$B$2:$Z$37,_xlfn.XMATCH($A11,MFModRaw!$A$2:$A$37),_xlfn.XMATCH(D$2,MFModRaw!$B$1:$Z$1))} -> 1.4336228e+08 | E11: {=INDEX(MFModRaw!$B$2:$Z$37,_xlfn.XMATCH($A11,MFModRaw!$A$2:$A$37),_xlfn.XMATCH(E$2,MFModRaw!$B$1:$Z$1))} -> 1.4338876e+08 | F11: {=INDEX(MFModRaw!$B$2:$Z$37,_xlfn.XMATCH($A11,MFModRaw!$A$2:$A$37),_xlfn.XMATCH(F$2,MFModRaw!$B$1:$Z$1))} -> 1.4332296e+08 | G11: {=INDEX(MFModRaw!$B$2:$Z$37,_xlfn.XMATCH($A11,MFModRaw!$A$2:$A$37),_xlfn.XMATCH(G$2,MFModRaw!$B$1:$Z$1))} -> 1.4336521e+08 | H11: {=INDEX(MFModRaw!$B$2:$Z$37,_xlfn.XMATCH($A11,MFModRaw!$A$2:$A$37),_xlfn.XMATCH(H$2,MFModRaw!$B$1:$Z$1))} -> 1.433917e+08 | K11: 2023 | L11: =C11/$B11-1 -> -9.9269185e-05 | M11: =D11/$B11-1 -> 0.00019536881 | N11: =E11/$B11-1 -> 0.00038013853 | O11: =F11/$B11-1 -> -7.8937898e-05 | P11: =G11/$B11-1 -> 0.00021579198 | Q11: =H11/$B11-1 -> 0.00040062064
A12: 2024 | B12: {=INDEX(MFModRaw!$B$2:$Z$37,_xlfn.XMATCH($A12,MFModRaw!$A$2:$A$37),_xlfn.XMATCH(B$2,MFModRaw!$B$1:$Z$1))} -> 1.5196078e+08 | C12: {=INDEX(MFModRaw!$B$2:$Z$37,_xlfn.XMATCH($A12,MFModRaw!$A$2:$A$37),_xlfn.XMATCH(C$2,MFModRaw!$B$1:$Z$1))} -> 1.5193527e+08 | D12: {=INDEX(MFModRaw!$B$2:$Z$37,_xlfn.XMATCH($A12,MFModRaw!$A$2:$A$37),_xlfn.XMATCH(D$2,MFModRaw!$B$1:$Z$1))} -> 1.520189e+08 | E12: {=INDEX(MFModRaw!$B$2:$Z$37,_xlfn.XMATCH($A12,MFModRaw!$A$2:$A$37),_xlfn.XMATCH(E$2,MFModRaw!$B$1:$Z$1))} -> 1.5207146e+08 | F12: {=INDEX(MFModRaw!$B$2:$Z$37,_xlfn.XMATCH($A12,MFModRaw!$A$2:$A$37),_xlfn.XMATCH(F$2,MFModRaw!$B$1:$Z$1))} -> 1.5193836e+08 | G12: {=INDEX(MFModRaw!$B$2:$Z$37,_xlfn.XMATCH($A12,MFModRaw!$A$2:$A$37),_xlfn.XMATCH(G$2,MFModRaw!$B$1:$Z$1))} -> 1.5202201e+08 | H12: {=INDEX(MFModRaw!$B$2:$Z$37,_xlfn.XMATCH($A12,MFModRaw!$A$2:$A$37),_xlfn.XMATCH(H$2,MFModRaw!$B$1:$Z$1))} -> 1.5207457e+08 | K12: 2024 | L12: =C12/$B12-1 -> -0.00016787462 | M12: =D12/$B12-1 -> 0.00038248171 | N12: =E12/$B12-1 -> 0.00072831913 | O12: =F12/$B12-1 -> -0.00014752301 | P12: =G12/$B12-1 -> 0.00040291318 | Q12: =H12/$B12-1 -> 0.00074880304
A13: 2025 | B13: {=INDEX(MFModRaw!$B$2:$Z$37,_xlfn.XMATCH($A13,MFModRaw!$A$2:$A$37),_xlfn.XMATCH(B$2,MFModRaw!$B$1:$Z$1))} -> 1.5732787e+08 | C13: {=INDEX(MFModRaw!$B$2:$Z$37,_xlfn.XMATCH($A13,MFModRaw!$A$2:$A$37),_xlfn.XMATCH(C$2,MFModRaw!$B$1:$Z$1))} -> 1.5728896e+08 | D13: {=INDEX(MFModRaw!$B$2:$Z$37,_xlfn.XMATCH($A13,MFModRaw!$A$2:$A$37),_xlfn.XMATCH(D$2,MFModRaw!$B$1:$Z$1))} -> 1.5742459e+08 | E13: {=INDEX(MFModRaw!$B$2:$Z$37,_xlfn.XMATCH($A13,MFModRaw!$A$2:$A$37),_xlfn.XMATCH(E$2,MFModRaw!$B$1:$Z$1))} -> 1.5750988e+08 | F13: {=INDEX(MFModRaw!$B$2:$Z$37,_xlfn.XMATCH($A13,MFModRaw!$A$2:$A$37),_xlfn.XMATCH(F$2,MFModRaw!$B$1:$Z$1))} -> 1.5729223e+08 | G13: {=INDEX(MFModRaw!$B$2:$Z$37,_xlfn.XMATCH($A13,MFModRaw!$A$2:$A$37),_xlfn.XMATCH(G$2,MFModRaw!$B$1:$Z$1))} -> 1.5742787e+08 | H13: {=INDEX(MFModRaw!$B$2:$Z$37,_xlfn.XMATCH($A13,MFModRaw!$A$2:$A$37),_xlfn.XMATCH(H$2,MFModRaw!$B$1:$Z$1))} -> 1.5751316e+08 | K13: 2025 | L13: =C13/$B13-1 -> -0.00024726302 | M13: =D13/$B13-1 -> 0.00061480572 | N13: =E13/$B13-1 -> 0.00115689 | O13: =F13/$B13-1 -> -0.00022651938 | P13: =G13/$B13-1 -> 0.00063563179 | Q13: =H13/$B13-1 -> 0.0011777714
A14: 2026 | B14: {=INDEX(MFModRaw!$B$2:$Z$37,_xlfn.XMATCH($A14,MFModRaw!$A$2:$A$37),_xlfn.XMATCH(B$2,MFModRaw!$B$1:$Z$1))} -> 1.611743e+08 | C14: {=INDEX(MFModRaw!$B$2:$Z$37,_xlfn.XMATCH($A14,MFModRaw!$A$2:$A$37),_xlfn.XMATCH(C$2,MFModRaw!$B$1:$Z$1))} -> 1.6112075e+08 | D14: {=INDEX(MFModRaw!$B$2:$Z$37,_xlfn.XMATCH($A14,MFModRaw!$A$2:$A$37),_xlfn.XMATCH(D$2,MFModRaw!$B$1:$Z$1))} -> 1.6131943e+08 | E14: {=INDEX(MFModRaw!$B$2:$Z$37,_xlfn.XMATCH($A14,MFModRaw!$A$2:$A$37),_xlfn.XMATCH(E$2,MFModRaw!$B$1:$Z$1))} -> 1.6144442e+08 | F14: {=INDEX(MFModRaw!$B$2:$Z$37,_xlfn.XMATCH($A14,MFModRaw!$A$2:$A$37),_xlfn.XMATCH(F$2,MFModRaw!$B$1:$Z$1))} -> 1.6112285e+08 | G14: {=INDEX(MFModRaw!$B$2:$Z$37,_xlfn.XMATCH($A14,MFModRaw!$A$2:$A$37),_xlfn.XMATCH(G$2,MFModRaw!$B$1:$Z$1))} -> 1.6132153e+08 | H14: {=INDEX(MFModRaw!$B$2:$Z$37,_xlfn.XMATCH($A14,MFModRaw!$A$2:$A$37),_xlfn.XMATCH(H$2,MFModRaw!$B$1:$Z$1))} -> 1.6144651e+08 | K14: 2026 | L14: =C14/$B14-1 -> -0.00033220208 | M14: =D14/$B14-1 -> 0.00090050362 | N14: =E14/$B14-1 -> 0.001675962 | O14: =F14/$B14-1 -> -0.00031917953 | P14: =G14/$B14-1 -> 0.0009134822 | Q14: =H14/$B14-1 -> 0.0016889159
... A38: 2050 | B38: {=INDEX(MFModRaw!$B$2:$Z$37,_xlfn.XMATCH($A38,MFModRaw!$A$2:$A$37),_xlfn.XMATCH(B$2,MFModRaw!$B$1:$Z$1))} -> 2.2213448e+08 | C38: {=INDEX(MFModRaw!$B$2:$Z$37,_xlfn.XMATCH($A38,MFModRaw!$A$2:$A$37),_xlfn.XMATCH(C$2,MFModRaw!$B$1:$Z$1))} -> 2.2153725e+08 | D38: {=INDEX(MFModRaw!$B$2:$Z$37,_xlfn.XMATCH($A38,MFModRaw!$A$2:$A$37),_xlfn.XMATCH(D$2,MFModRaw!$B$1:$Z$1))} -> 2.2569789e+08 | E38: {=INDEX(MFModRaw!$B$2:$Z$37,_xlfn.XMATCH($A38,MFModRaw!$A$2:$A$37),_xlfn.XMATCH(E$2,MFModRaw!$B$1:$Z$1))} -> 2.2832347e+08 | F38: {=INDEX(MFModRaw!$B$2:$Z$37,_xlfn.XMATCH($A38,MFModRaw!$A$2:$A$37),_xlfn.XMATCH(F$2,MFModRaw!$B$1:$Z$1))} -> 2.204202e+08 | G38: {=INDEX(MFModRaw!$B$2:$Z$37,_xlfn.XMATCH($A38,MFModRaw!$A$2:$A$37),_xlfn.XMATCH(G$2,MFModRaw!$B$1:$Z$1))} -> 2.2447811e+08 | H38: {=INDEX(MFModRaw!$B$2:$Z$37,_xlfn.XMATCH($A38,MFModRaw!$A$2:$A$37),_xlfn.XMATCH(H$2,MFModRaw!$B$1:$Z$1))} -> 2.2703835e+08 | K38: 2050 | L38: =C38/$B38-1 -> -0.0026886034 | M38: =D38/$B38-1 -> 0.016041691 | N38: =E38/$B38-1 -> 0.02786144 | O38: =F38/$B38-1 -> -0.0077172941 | P38: =G38/$B38-1 -> 0.010550487 | Q38: =H38/$B38-1 -> 0.022076125

Sheet HYD
B1: Baseline | C1: Control_Optimistic | D1: StatusQuo_Optimistic | E1: Improvement_Optimistic | F1: Control_Pessimistic | G1: StatusQuo_Pessimistic | H1: Improvement_Pessimistic
B2: KHMNYGDPMKTPKN_0 | C2: KHMNYGDPMKTPKN_113 | D2: KHMNYGDPMKTPKN_123 | E2: KHMNYGDPMKTPKN_133 | F2: KHMNYGDPMKTPKN_213 | G2: KHMNYGDPMKTPKN_223 | H2: KHMNYGDPMKTPKN_233 | L2: =C1 -> Control_Optimistic | M2: =D1 -> StatusQuo_Optimistic | N2: =E1 -> Improvement_Optimistic | O2: =F1 -> Control_Pessimistic | P2: =G1 -> StatusQuo_Pessimistic | Q2: =H1 -> Improvement_Pessimistic
A3: 2015 | B3: {=INDEX(MFModRaw!$B$2:$Z$37,_xlfn.XMATCH($A3,MFModRaw!$A$2:$A$37),_xlfn.XMATCH(B$2,MFModRaw!$B$1:$Z$1))} -> 95406125 | C3: {=INDEX(MFModRaw!$B$2:$Z$37,_xlfn.XMATCH($A3,MFModRaw!$A$2:$A$37),_xlfn.XMATCH(C$2,MFModRaw!$B$1:$Z$1))} -> 95406125 | D3: {=INDEX(MFModRaw!$B$2:$Z$37,_xlfn.XMATCH($A3,MFModRaw!$A$2:$A$37),_xlfn.XMATCH(D$2,MFModRaw!$B$1:$Z$1))} -> 95406125 | E3: {=INDEX(MFModRaw!$B$2:$Z$37,_xlfn.XMATCH($A3,MFModRaw!$A$2:$A$37),_xlfn.XMATCH(E$2,MFModRaw!$B$1:$Z$1))} -> 95406125 | F3: {=INDEX(MFModRaw!$B$2:$Z$37,_xlfn.XMATCH($A3,MFModRaw!$A$2:$A$37),_xlfn.XMATCH(F$2,MFModRaw!$B$1:$Z$1))} -> 95406125 | G3: {=INDEX(MFModRaw!$B$2:$Z$37,_xlfn.XMATCH($A3,MFModRaw!$A$2:$A$37),_xlfn.XMATCH(G$2,MFModRaw!$B$1:$Z$1))} -> 95406125 | H3: {=INDEX(MFModRaw!$B$2:$Z$37,_xlfn.XMATCH($A3,MFModRaw!$A$2:$A$37),_xlfn.XMATCH(H$2,MFModRaw!$B$1:$Z$1))} -> 95406125 | K3: 2015 | L3: =C3/$B3-1 -> 0 | M3: =D3/$B3-1 -> 0 | N3: =E3/$B3-1 -> 0 | O3: =F3/$B3-1 -> 0 | P3: =G3/$B3-1 -> 0 | Q3: =H3/$B3-1 -> 0
A4: 2016 | B4: {=INDEX(MFModRaw!$B$2:$Z$37,_xlfn.XMATCH($A4,MFModRaw!$A$2:$A$37),_xlfn.XMATCH(B$2,MFModRaw!$B$1:$Z$1))} -> 1.0294846e+08 | C4: {=INDEX(MFModRaw!$B$2:$Z$37,_xlfn.XMATCH($A4,MFModRaw!$A$2:$A$37),_xlfn.XMATCH(C$2,MFModRaw!$B$1:$Z$1))} -> 1.0294846e+08 | D4: {=INDEX(MFModRaw!$B$2:$Z$37,_xlfn.XMATCH($A4,MFModRaw!$A$2:$A$37),_xlfn.XMATCH(D$2,MFModRaw!$B$1:$Z$1))} -> 1.0294846e+08 | E4: {=INDEX(MFModRaw!$B$2:$Z$37,_xlfn.XMATCH($A4,MFModRaw!$A$2:$A$37),_xlfn.XMATCH(E$2,MFModRaw!$B$1:$Z$1))} -> 1.0294846e+08 | F4: {=INDEX(MFModRaw!$B$2:$Z$37,_xlfn.XMATCH($A4,MFModRaw!$A$2:$A$37),_xlfn.XMATCH(F$2,MFModRaw!$B$1:$Z$1))} -> 1.0294846e+08 | G4: {=INDEX(MFModRaw!$B$2:$Z$37,_xlfn.XMATCH($A4,MFModRaw!$A$2:$A$37),_xlfn.XMATCH(G$2,MFModRaw!$B$1:$Z$1))} -> 1.0294846e+08 | H4: {=INDEX(MFModRaw!$B$2:$Z$37,_xlfn.XMATCH($A4,MFModRaw!$A$2:$A$37),_xlfn.XMATCH(H$2,MFModRaw!$B$1:$Z$1))} -> 1.0294846e+08 | K4: 2016 | L4: =C4/$B4-1 -> 0 | M4: =D4/$B4-1 -> 0 | N4: =E4/$B4-1 -> 0 | O4: =F4/$B4-1 -> 0 | P4: =G4/$B4-1 -> 0 | Q4: =H4/$B4-1 -> 0
A5: 2017 | B5: {=INDEX(MFModRaw!$B$2:$Z$37,_xlfn.XMATCH($A5,MFModRaw!$A$2:$A$37),_xlfn.XMATCH(B$2,MFModRaw!$B$1:$Z$1))} -> 1.1126159e+08 | C5: {=INDEX(MFModRaw!$B$2:$Z$37,_xlfn.XMATCH($A5,MFModRaw!$A$2:$A$37),_xlfn.XMATCH(C$2,MFModRaw!$B$1:$Z$1))} -> 1.1126159e+08 | D5: {=INDEX(MFModRaw!$B$2:$Z$37,_xlfn.XMATCH($A5,MFModRaw!$A$2:$A$37),_xlfn.XMATCH(D$2,MFModRaw!$B$1:$Z$1))} -> 1.1126159e+08 | E5: {=INDEX(MFModRaw!$B$2:$Z$37,_xlfn.XMATCH($A5,MFModRaw!$A$2:$A$37),_xlfn.XMATCH(E$2,MFModRaw!$B$1:$Z$1))} -> 1.1126159e+08 | F5: {=INDEX(MFModRaw!$B$2:$Z$37,_xlfn.XMATCH($A5,MFModRaw!$A$2:$A$37),_xlfn.XMATCH(F$2,MFModRaw!$B$1:$Z$1))} -> 1.1126159e+08 | G5: {=INDEX(MFModRaw!$B$2:$Z$37,_xlfn.XMATCH($A5,MFModRaw!$A$2:$A$37),_xlfn.XMATCH(G$2,MFModRaw!$B$1:$Z$1))} -> 1.1126159e+08 | H5: {=INDEX(MFModRaw!$B$2:$Z$37,_xlfn.XMATCH($A5,MFModRaw!$A$2:$A$37),_xlfn.XMATCH(H$2,MFModRaw!$B$1:$Z$1))} -> 1.1126159e+08 | K5: 2017 | L5: =C5/$B5-1 -> 0 | M5: =D5/$B5-1 -> 0 | N5: =E5/$B5-1 -> 0 | O5: =F5/$B5-1 -> 0 | P5: =G5/$B5-1 -> 0 | Q5: =H5/$B5-1 -> 0
A6: 2018 | B6: {=INDEX(MFModRaw!$B$2:$Z$37,_xlfn.XMATCH($A6,MFModRaw!$A$2:$A$37),_xlfn.XMATCH(B$2,MFModRaw!$B$1:$Z$1))} -> 1.2102615e+08 | C6: {=INDEX(MFModRaw!$B$2:$Z$37,_xlfn.XMATCH($A6,MFModRaw!$A$2:$A$37),_xlfn.XMATCH(C$2,MFModRaw!$B$1:$Z$1))} -> 1.2102615e+08 | D6: {=INDEX(MFModRaw!$B$2:$Z$37,_xlfn.XMATCH($A6,MFModRaw!$A$2:$A$37),_xlfn.XMATCH(D$2,MFModRaw!$B$1:$Z$1))} -> 1.2102615e+08 | E6: {=INDEX(MFModRaw!$B$2:$Z$37,_xlfn.XMATCH($A6,MFModRaw!$A$2:$A$37),_xlfn.XMATCH(E$2,MFModRaw!$B$1:$Z$1))} -> 1.2102615e+08 | F6: {=INDEX(MFModRaw!$B$2:$Z$37,_xlfn.XMATCH($A6,MFModRaw!$A$2:$A$37),_xlfn.XMATCH(F$2,MFModRaw!$B$1:$Z$1))} -> 1.2102615e+08 | G6: {=INDEX(MFModRaw!$B$2:$Z$37,_xlfn.XMATCH($A6,MFModRaw!$A$2:$A$37),_xlfn.XMATCH(G$2,MFModRaw!$B$1:$Z$1))} -> 1.2102615e+08 | H6: {=INDEX(MFModRaw!$B$2:$Z$37,_xlfn.XMATCH($A6,MFModRaw!$A$2:$A$37),_xlfn.XMATCH(H$2,MFModRaw!$B$1:$Z$1))} -> 1.2102615e+08 | K6: 2018 | L6: =C6/$B6-1 -> 0 | M6: =D6/$B6-1 -> 0 | N6: =E6/$B6-1 -> 0 | O6: =F6/$B6-1 -> 0 | P6: =G6/$B6-1 -> 0 | Q6: =H6/$B6-1 -> 0
A7: 2019 | B7: {=INDEX(MFModRaw!$B$2:$Z$37,_xlfn.XMATCH($A7,MFModRaw!$A$2:$A$37),_xlfn.XMATCH(B$2,MFModRaw!$B$1:$Z$1))} -> 1.3063194e+08 | C7: {=INDEX(MFModRaw!$B$2:$Z$37,_xlfn.XMATCH($A7,MFModRaw!$A$2:$A$37),_xlfn.XMATCH(C$2,MFModRaw!$B$1:$Z$1))} -> 1.3063194e+08 | D7: {=INDEX(MFModRaw!$B$2:$Z$37,_xlfn.XMATCH($A7,MFModRaw!$A$2:$A$37),_xlfn.XMATCH(D$2,MFModRaw!$B$1:$Z$1))} -> 1.3063194e+08 | E7: {=INDEX(MFModRaw!$B$2:$Z$37,_xlfn.XMATCH($A7,MFModRaw!$A$2:$A$37),_xlfn.XMATCH(E$2,MFModRaw!$B$1:$Z$1))} -> 1.3063194e+08 | F7: {=INDEX(MFModRaw!$B$2:$Z$37,_xlfn.XMATCH($A7,MFModRaw!$A$2:$A$37),_xlfn.XMATCH(F$2,MFModRaw!$B$1:$Z$1))} -> 1.3063194e+08 | G7: {=INDEX(MFModRaw!$B$2:$Z$37,_xlfn.XMATCH($A7,MFModRaw!$A$2:$A$37),_xlfn.XMATCH(G$2,MFModRaw!$B$1:$Z$1))} -> 1.3063194e+08 | H7: {=INDEX(MFModRaw!$B$2:$Z$37,_xlfn.XMATCH($A7,MFModRaw!$A$2:$A$37),_xlfn.XMATCH(H$2,MFModRaw!$B$1:$Z$1))} -> 1.3063194e+08 | K7: 2019 | L7: =C7/$B7-1 -> 0 | M7: =D7/$B7-1 -> 0 | N7: =E7/$B7-1 -> 0 | O7: =F7/$B7-1 -> 0 | P7: =G7/$B7-1 -> 0 | Q7: =H7/$B7-1 -> 0
A8: 2020 | B8: {=INDEX(MFModRaw!$B$2:$Z$37,_xlfn.XMATCH($A8,MFModRaw!$A$2:$A$37),_xlfn.XMATCH(B$2,MFModRaw!$B$1:$Z$1))} -> 1.2598703e+08 | C8: {=INDEX(MFModRaw!$B$2:$Z$37,_xlfn.XMATCH($A8,MFModRaw!$A$2:$A$37),_xlfn.XMATCH(C$2,MFModRaw!$B$1:$Z$1))} -> 1.2598703e+08 | D8: {=INDEX(MFModRaw!$B$2:$Z$37,_xlfn.XMATCH($A8,MFModRaw!$A$2:$A$37),_xlfn.XMATCH(D$2,MFModRaw!$B$1:$Z$1))} -> 1.2598715e+08 | E8: {=INDEX(MFModRaw!$B$2:$Z$37,_xlfn.XMATCH($A8,MFModRaw!$A$2:$A$37),_xlfn.XMATCH(E$2,MFModRaw!$B$1:$Z$1))} -> 1.2598728e+08 | F8: {=INDEX(MFModRaw!$B$2:$Z$37,_xlfn.XMATCH($A8,MFModRaw!$A$2:$A$37),_xlfn.XMATCH(F$2,MFModRaw!$B$1:$Z$1))} -> 1.2598703e+08 | G8: {=INDEX(MFModRaw!$B$2:$Z$37,_xlfn.XMATCH($A8,MFModRaw!$A$2:$A$37),_xlfn.XMATCH(G$2,MFModRaw!$B$1:$Z$1))} -> 1.2598715e+08 | H8: {=INDEX(MFModRaw!$B$2:$Z$37,_xlfn.XMATCH($A8,MFModRaw!$A$2:$A$37),_xlfn.XMATCH(H$2,MFModRaw!$B$1:$Z$1))} -> 1.2598728e+08 | K8: 2020 | L8: =C8/$B8-1 -> 0 | M8: =D8/$B8-1 -> 9.8388951e-07 | N8: =E8/$B8-1 -> 1.9678185e-06 | O8: =F8/$B8-1 -> 0 | P8: =G8/$B8-1 -> 9.8388951e-07 | Q8: =H8/$B8-1 -> 1.9678185e-06
